Workbook

Sheet Leeme
B2: Reto Actinver 2026: las 145 acciones de la plataforma, con datos y calculadora de portafolio
B3: Precios actualizados con Yahoo Finance: 8 de octubre de 2026, ~11:10 h CDMX. Precio de compra/venta y volumen del monitor: foto del 2026-10-08. Datos descriptivos del pasado: NO son una recomendación de inversión y no predicen lo que va a pasar.
B5: Qué hay en cada hoja
B6: • Acciones: las 145 de tu monitor (Reto Actinver > Monitores > Acciones), con el precio de compra y de venta que vio la plataforma, la diferencia entre ambos, el volumen disponible y los datos históricos en pesos.
B7: • Mi portafolio: eliges emisoras y porcentajes (celdas amarillas). Revisa las reglas del reto, los costos reales (comisión + diferencia compra-venta) y cuánto se ha movido un portafolio así.
B8: • Correlaciones / Covarianza: qué tanto se mueven juntas (apoyo de la calculadora).
B10: Lo que más cambia el resultado: la diferencia entre precio de compra y de venta
B11: • Si compras al precio de venta y vendes al precio de compra, pierdes esa diferencia cada vez que haces el viaje completo. En las mexicanas es de centésimas de punto porcentual; en muchas del exterior (SIC) es de 2% a 5%.
B12: • 'Sin contraparte' = hoy no hay quien compre o quien venda (precio $0.00): esa orden no se asigna. Son datos de un instante; cambian durante el día.
B13: • Estos precios son una foto del monitor al momento de copiarlo. Vuelve a revisarlo en la plataforma antes de operar.
B15: Cómo leer las columnas históricas
B16: • Todo está en pesos. En las acciones del exterior se usó el precio en dólares por el tipo de cambio del día (aproximación del precio SIC en pesos).
... B35: • Mi portafolio viene llenado con el ganador (Ganar (máx. prob. top 3) · 5 emisoras). No es una recomendación de inversión.

Sheet Pronóstico
A1: Pronóstico, portafolios de 5 a 12 emisoras y ganador
A2: Datos al 8 de octubre de 2026, ~11:10 h CDMX. El pronóstico usa señales reales (precio objetivo de analistas y momento), pero su capacidad de predicción es baja: el resultado lo decide sobre todo el mercado. No es una recomendación de inversión.
A4: Supuestos (celdas amarillas editables)
A5: IC: capacidad de pronóstico de las señales | B5: 0.05 | C5: 0.05 = una buena señal; 0 = sin pronóstico propio por acción
A6: Rendimiento anual esperado de la canasta | B6: 0.08 | C6: Prima de mercado
A7: Sesiones que faltan | B7: ='Mi portafolio'!$H$4 -> 25 | C7: De la hoja Mi portafolio
A8: Rendimiento esperado de la canasta en el lapso | B8: =B6*B7/252 -> 0.0079365079
A9: Mov. típico (±1σ) de la canasta en el lapso | B9: =SQRT(SUM(Covarianza!$B$6:$EO$149)/144^2*B7/252) -> 0.049266704 | C9: Canasta de las 144, mismo peso
A10: Umbral para el top 3 | B10: 0.2 | C10: En una edición pasada los 3 primeros superaron +20%
A12: Escenario | B12: Probabilidad | C12: Rend. de la canasta
A13: Bajista | B13: 0.25 | C13: =B8-B9 -> -0.041330196
A14: Base | B14: 0.5 | C14: =B8 -> 0.0079365079
A15: Alcista | B15: 0.25 | C15: =B8+B9 -> 0.057203212
A18: ¿Cuántas emisoras? Mejor portafolio para cada número (simulación de 60,000 trayectorias)*
A19: Objetivo | B19: Emisoras | C19: Prob. de superar +20% (top 3) | D19: Prob. de superar +30% | E19: Ganancia esperada ($) | F19: Prob. de terminar en positivo | G19: Prob. de perder más de $100k | H19: Peor 5% ($) | I19: Mejor 5% ($) | J19: Composición
A20: Ganar (máx. prob. top 3) | B20: 5 | C20: 0.1556 | D20: 0.0693 | E20: 31585.189 | F20: 0.5829 | G20: 0.2055 | H20: -274081.06 | I20: 340792.77 | J20: PINFRA * 3%, BOLSA A 3%, GFNORTE O 3%, INTC * 41%, MU * 50%
A21: Ganar (máx. prob. top 3) | B21: 6 | C21: 0.1513 | D21: 0.0659 | E21: 31343.091 | F21: 0.5842 | G21: 0.2012 | H21: -268336.3 | I21: 333952.34 | J21: AVGO * 3%, PINFRA * 3%, BOLSA A 3%, GFNORTE O 3%, INTC * 38%, MU * 50%
A22: Ganar (máx. prob. top 3) | B22: 7 | C22: 0.1446 | D22: 0.0619 | E22: 30911.388 | F22: 0.5853 | G22: 0.1957 | H22: -260766.82 | I22: 324738.32 | J22: GOOGL * 3%, AVGO * 3%, PINFRA * 3%, BOLSA A 3%, GFNORTE O 3%, INTC * 35%, MU * 50%
A23: Ganar (máx. prob. top 3) | B23: 8 | C23: 0.1382 | D23: 0.0572 | E23: 30549.94 | F23: 0.5865 | G23: 0.19 | H23: -252650.73 | I23: 315689.88 | J23: LAB B 3%, GOOGL * 3%, AVGO * 3%, PINFRA * 3%, BOLSA A 3%, GFNORTE O 3%, INTC * 32%, MU * 50%
A24: Ganar (máx. prob. top 3) | B24: 9 | C24: 0.1311 | D24: 0.0532 | E24: 30032.257 | F24: 0.5877 | G24: 0.1839 | H24: -245039.44 | I24: 306683.04 | J24: R A 3%, LAB B 3%, GOOGL * 3%, AVGO * 3%, PINFRA * 3%, BOLSA A 3%, GFNORTE O 3%, INTC * 29%, MU * 50%
A25: Ganar (máx. prob. top 3) | B25: 10 | C25: 0.1248 | D25: 0.049 | E25: 29681.039 | F25: 0.5892 | G25: 0.1783 | H25: -237304.31 | I25: 298303.16 | J25: GCC * 3%, R A 3%, LAB B 3%, GOOGL * 3%, AVGO * 3%, PINFRA * 3%, BOLSA A 3%, GFNORTE O 3%, INTC * 26%, MU * 50%
A26: Ganar (máx. prob. top 3) | B26: 11 | C26: 0.1177 | D26: 0.0453 | E26: 29194.975 | F26: 0.59 | G26: 0.1715 | H26: -229623.05 | I26: 289627.57 | J26: BBAJIO O 3%, GCC * 3%, R A 3%, LAB B 3%, GOOGL * 3%, AVGO * 3%, PINFRA * 3%, BOLSA A 3%, GFNORTE O 3%, INTC * 23%, MU * 50%
A27: Ganar (máx. prob. top 3) | B27: 12 | C27: 0.1107 | D27: 0.0415 | E27: 28681.843 | F27: 0.5911 | G27: 0.1658 | H27: -221584.98 | I27: 280803.97 | J27: ORBIA * 3%, BBAJIO O 3%, GCC * 3%, R A 3%, LAB B 3%, GOOGL * 3%, AVGO * 3%, PINFRA * 3%, BOLSA A 3%, GFNORTE O 3%, INTC * 20%, MU * 50%
A28: Balanceado (ganancia/riesgo) | B28: 5 | C28: 0.0291 | D28: 0.0075 | E28: 20109.769 | F28: 0.608 | G28: 0.0756 | H28: -124544.36 | I28: 165154.49 | J28: BABA N 9%, GCC * 17%, CEMEX CPO 23%, LAB B 24%, MU * 28%
A29: Balanceado (ganancia/riesgo) | B29: 6 | C29: 0.0271 | D29: 0.0068 | E29: 19717.541 | F29: 0.6077 | G29: 0.0727 | H29: -121803.07 | I29: 161832.37 | J29: GENTERA * 6%, BABA N 8%, GCC * 15%, CEMEX CPO 21%, LAB B 22%, MU * 28%
A30: Balanceado (ganancia/riesgo) | B30: 7 | C30: 0.0258 | D30: 0.0065 | E30: 19431.341 | F30: 0.6073 | G30: 0.0709 | H30: -120155.04 | I30: 159563.77 | J30: GOOGL * 3%, GENTERA * 5%, BABA N 7%, GCC * 15%, CEMEX CPO 21%, LAB B 21%, MU * 27%
A31: Balanceado (ganancia/riesgo) | B31: 8 | C31: 0.0239 | D31: 0.006 | E31: 18927.635 | F31: 0.6072 | G31: 0.0683 | H31: -117612.89 | I31: 155752.97 | J31: SIGMAF A 3%, GOOGL * 3%, GENTERA * 5%, BABA N 7%, GCC * 14%, CEMEX CPO 20%, LAB B 21%, MU * 27%
... A36: Referencia | B36: 5 | C36: 0.0077 | D36: 0.0017 | E36: 5324.7583 | F36: 0.5405 | G36: 0.0457 | H36: -95996.047 | I36: 105529.47 | J36: NVDA * 30%, GFNORTE O 20%, GMEXICO B 20%, MSFT * 15%, GOOGL * 15%
A38: Ganador
A39: Portafolio ganador (máxima probabilidad de top 3) | B39: Ganar (máx. prob. top 3) · 5 emisoras
A40: Composición | B40: PINFRA * 3%, BOLSA A 3%, GFNORTE O 3%, INTC * 41%, MU * 50%
A41: Ganancia esperada con pronóstico ($) | B41: =Portafolios!F28 -> 31585.189
A42: Si el mercado baja ($) | B42: =Portafolios!F25 -> -68690.52
A43: Escenario base ($) | B43: =Portafolios!F26 -> 31585.189
A44: Si el mercado sube ($) | B44: =Portafolios!F27 -> 131860.9
A45: Ganancia esperada sin pronóstico propio, IC = 0 ($)* | B45: 5173
A46: Prob. de superar +20% sin pronóstico propio* | B46: 0.1263
A48: Cómo se pronostica cada acción: beta × rendimiento esperado de la canasta + alfa − costo. Alfa = IC × mov. típico × puntaje; el puntaje promedia el potencial al precio objetivo de analistas (5 o más analistas) y el momento de 12 meses sin el último mes, estandarizados entre las 144.
A49: Por qué gana un portafolio concentrado: el premio es para los 3 primeros, así que importa la probabilidad de un resultado muy alto, no el promedio. Más emisoras bajan el riesgo, pero también la probabilidad de llegar a +20%. El ganador mete el máximo permitido (50%) en la acción con mejor pronóstico y casi todo lo demás en la segunda; las otras 3 cumplen el mínimo de 5 emisoras.
A50: Universo: operables, diferencia compra-venta de 1.5% o menos y con liquidez (mexicanas: al menos $20 millones operados al día; SIC: al menos $40,000 en el mejor nivel del monitor). Para el objetivo de ganar solo entran emisoras con pronóstico positivo.
...

Sheet Órdenes
A1: Órdenes para el portafolio ganador
A2: Actualiza el precio (celda amarilla) con el precio de venta que veas en la plataforma justo antes de mandar la orden; los títulos se recalculan. Horario: 7:30 a 14:00 (desde el 3 de noviembre, 8:30 a 15:00). Las órdenes asignadas no se cancelan.
A4: Emisora | B4: Tipo | C4: Peso | D4: Precio de venta ($) | E4: Títulos a comprar | F4: Importe ($) | G4: Comisión + IVA ($) | H4: Total ($) | I4: Próximo reporte
A5: MU * | B5: =INDEX(Acciones!$B$5:$B$148,MATCH($A5,Acciones!$A$5:$A$148,0)) -> Exterior (SIC) | C5: 0.5 | D5: 19524.99 | E5: =INT(C5*'Mi portafolio'!$C$4*0.997/D5) -> 25 | F5: =E5*D5 -> 488124.75 | G5: =F5*'Mi portafolio'!$C$5 -> 566.22471 | H5: =F5+G5 -> 488690.97 | I5: =INDEX(Acciones!$Y$5:$Y$148,MATCH($A5,Acciones!$A$5:$A$148,0)) -> 2026-12-23
A6: INTC * | B6: =INDEX(Acciones!$B$5:$B$148,MATCH($A6,Acciones!$A$5:$A$148,0)) -> Exterior (SIC) | C6: 0.41 | D6: 1999.99 | E6: =INT(C6*'Mi portafolio'!$C$4*0.997/D6) -> 204 | F6: =E6*D6 -> 407997.96 | G6: =F6*'Mi portafolio'!$C$5 -> 473.27763 | H6: =F6+G6 -> 408471.24 | I6: =INDEX(Acciones!$Y$5:$Y$148,MATCH($A6,Acciones!$A$5:$A$148,0)) -> 2026-10-29
A7: PINFRA * | B7: =INDEX(Acciones!$B$5:$B$148,MATCH($A7,Acciones!$A$5:$A$148,0)) -> Mexicana | C7: 0.03 | D7: 274.13 | E7: =INT(C7*'Mi portafolio'!$C$4*0.997/D7) -> 109 | F7: =E7*D7 -> 29880.17 | G7: =F7*'Mi portafolio'!$C$5 -> 34.660997 | H7: =F7+G7 -> 29914.831 | I7: =INDEX(Acciones!$Y$5:$Y$148,MATCH($A7,Acciones!$A$5:$A$148,0)) -> 2026-10-22
A8: GFNORTE O | B8: =INDEX(Acciones!$B$5:$B$148,MATCH($A8,Acciones!$A$5:$A$148,0)) -> Mexicana | C8: 0.03 | D8: 189.55 | E8: =INT(C8*'Mi portafolio'!$C$4*0.997/D8) -> 157 | F8: =E8*D8 -> 29759.35 | G8: =F8*'Mi portafolio'!$C$5 -> 34.520846 | H8: =F8+G8 -> 29793.871 | I8: =INDEX(Acciones!$Y$5:$Y$148,MATCH($A8,Acciones!$A$5:$A$148,0)) -> 2026-11-03
A9: BOLSA A | B9: =INDEX(Acciones!$B$5:$B$148,MATCH($A9,Acciones!$A$5:$A$148,0)) -> Mexicana | C9: 0.03 | D9: 35.25 | E9: =INT(C9*'Mi portafolio'!$C$4*0.997/D9) -> 848 | F9: =E9*D9 -> 29892 | G9: =F9*'Mi portafolio'!$C$5 -> 34.67472 | H9: =F9+G9 -> 29926.675 | I9: =INDEX(Acciones!$Y$5:$Y$148,MATCH($A9,Acciones!$A$5:$A$148,0)) -> 2026-10-20
A10: Total | C10: =SUM(C5:C9) -> 1 | F10: =SUM(F5:F9) -> 985654.23 | G10: =SUM(G5:G9) -> 1143.3589 | H10: =SUM(H5:H9) -> 986797.59
A11: Efectivo que queda | H11: ='Mi portafolio'!$C$4-H10 -> 13202.411
A13: Cómo operar:
A14: 1. Revisa que el poder de compra sea $1,000,000 y que las 5 emisoras estén operables.
A15: 2. Primero las dos posiciones grandes, con orden limitada al precio de venta que ves, para no pagar de más.
A16: 3. Luego las tres chicas: cumplen el mínimo de 5 emisoras.
A17: 4. Debe quedar un poco de efectivo para comisiones. No hace falta mover nada después: cada compra y venta cuesta.
A18: 5. Si una orden no se asigna, vuelve a revisar el precio de venta: el monitor cambia durante el día.

Sheet Mi portafolio
A1: Mi portafolio del Reto Actinver 2026
A2: Elige emisoras en las celdas amarillas (lista desplegable) y su porcentaje. Todo lo demás se calcula solo.
A4: Capital del reto ($) | C4: 1000000 | E4: Sesiones que faltan (aprox.) | H4: 25
A5: Comisión por operación (0.10% + 16% IVA) | C5: =0.001*1.16 -> 0.00116
A7: Emisora | B7: Peso (%) | C7: Tipo | D7: Perfil por volatilidad | E7: Volatilidad anual | F7: Mov. típico ±1σ (25 ses.) | G7: Peor caída 1 año | H7: Diferencia compra-venta | I7: ¿Operable hoy? | J7: Importe a comprar ($) | K7: Costo estimado ida y vuelta ($) | L7: Peor ventana 25 ses. (3a) en $ | M7: Mejor ventana 25 ses. (3a) en $ | N7: Beta | O7: Peso × beta
A8: MU * | B8: 0.5 | C8: =IF($A8="","",INDEX(Acciones!$B$5:$B$148,MATCH($A8,Acciones!$A$5:$A$148,0))) -> Exterior (SIC) | D8: =IF($A8="","",INDEX(Acciones!$U$5:$U$148,MATCH($A8,Acciones!$A$5:$A$148,0))) -> Mayor movimiento | E8: =IF($A8="","",INDEX(Acciones!$O$5:$O$148,MATCH($A8,Acciones!$A$5:$A$148,0))) -> 0.80749836 | F8: =IF($A8="","",E8*SQRT($H$4/252)) -> 0.25433808 | G8: =IF($A8="","",INDEX(Acciones!$Q$5:$Q$148,MATCH($A8,Acciones!$A$5:$A$148,0))) -> -0.39731057 | H8: =IF($A8="","",IF(INDEX(Acciones!$G$5:$G$148,MATCH($A8,Acciones!$A$5:$A$148,0))="","n/d",INDEX(Acciones!$G$5:$G$148,MATCH($A8,Acciones!$A$5:$A$148,0)))) -> 0.0090021865 | I8: =IF($A8="","",INDEX(Acciones!$J$5:$J$148,MATCH($A8,Acciones!$A$5:$A$148,0))) -> Sí | J8: =IF(OR($A8="",$B8=""),"",$B8*$C$4) -> 500000 | K8: =IF(J8="","",J8*(IF(ISNUMBER(H8),H8,0)+2*$C$5)) -> 5661.0932 | L8: =IF(J8="","",J8*INDEX(Acciones!$T$5:$T$148,MATCH($A8,Acciones!$A$5:$A$148,0))) -> -171250.29 | M8: =IF(J8="","",J8*INDEX(Acciones!$S$5:$S$148,MATCH($A8,Acciones!$A$5:$A$148,0))) -> 553587.28 | N8: =IF($A8="","",INDEX(Acciones!$R$5:$R$148,MATCH($A8,Acciones!$A$5:$A$148,0))) -> 1.3721711 | O8: =IF(OR($A8="",$B8=""),0,$B8*N8) -> 0.68608554
A9: INTC * | B9: 0.41 | C9: =IF($A9="","",INDEX(Acciones!$B$5:$B$148,MATCH($A9,Acciones!$A$5:$A$148,0))) -> Exterior (SIC) | D9: =IF($A9="","",INDEX(Acciones!$U$5:$U$148,MATCH($A9,Acciones!$A$5:$A$148,0))) -> Mayor movimiento | E9: =IF($A9="","",INDEX(Acciones!$O$5:$O$148,MATCH($A9,Acciones!$A$5:$A$148,0))) -> 0.77688602 | F9: =IF($A9="","",E9*SQRT($H$4/252)) -> 0.2446961 | G9: =IF($A9="","",INDEX(Acciones!$Q$5:$Q$148,MATCH($A9,Acciones!$A$5:$A$148,0))) -> -0.41604291 | H9: =IF($A9="","",IF(INDEX(Acciones!$G$5:$G$148,MATCH($A9,Acciones!$A$5:$A$148,0))="","n/d",INDEX(Acciones!$G$5:$G$148,MATCH($A9,Acciones!$A$5:$A$148,0)))) -> 0.010040201 | I9: =IF($A9="","",INDEX(Acciones!$J$5:$J$148,MATCH($A9,Acciones!$A$5:$A$148,0))) -> Sí | J9: =IF(OR($A9="",$B9=""),"",$B9*$C$4) -> 410000 | K9: =IF(J9="","",J9*(IF(ISNUMBER(H9),H9,0)+2*$C$5)) -> 5067.6824 | L9: =IF(J9="","",J9*INDEX(Acciones!$T$5:$T$148,MATCH($A9,Acciones!$A$5:$A$148,0))) -> -165455.89 | M9: =IF(J9="","",J9*INDEX(Acciones!$S$5:$S$148,MATCH($A9,Acciones!$A$5:$A$148,0))) -> 596188.59 | N9: =IF($A9="","",INDEX(Acciones!$R$5:$R$148,MATCH($A9,Acciones!$A$5:$A$148,0))) -> 1.440998 | O9: =IF(OR($A9="",$B9=""),0,$B9*N9) -> 0.59080917
A10: PINFRA * | B10: 0.03 | C10: =IF($A10="","",INDEX(Acciones!$B$5:$B$148,MATCH($A10,Acciones!$A$5:$A$148,0))) -> Mexicana | D10: =IF($A10="","",INDEX(Acciones!$U$5:$U$148,MATCH($A10,Acciones!$A$5:$A$148,0))) -> Menor movimiento | E10: =IF($A10="","",INDEX(Acciones!$O$5:$O$148,MATCH($A10,Acciones!$A$5:$A$148,0))) -> 0.24898937 | F10: =IF($A10="","",E10*SQRT($H$4/252)) -> 0.07842428 | G10: =IF($A10="","",INDEX(Acciones!$Q$5:$Q$148,MATCH($A10,Acciones!$A$5:$A$148,0))) -> -0.16145538 | H10: =IF($A10="","",IF(INDEX(Acciones!$G$5:$G$148,MATCH($A10,Acciones!$A$5:$A$148,0))="","n/d",INDEX(Acciones!$G$5:$G$148,MATCH($A10,Acciones!$A$5:$A$148,0)))) -> 0.0002553859 | I10: =IF($A10="","",INDEX(Acciones!$J$5:$J$148,MATCH($A10,Acciones!$A$5:$A$148,0))) -> Sí | J10: =IF(OR($A10="",$B10=""),"",$B10*$C$4) -> 30000 | K10: =IF(J10="","",J10*(IF(ISNUMBER(H10),H10,0)+2*$C$5)) -> 77.261577 | L10: =IF(J10="","",J10*INDEX(Acciones!$T$5:$T$148,MATCH($A10,Acciones!$A$5:$A$148,0))) -> -4021.2204 | M10: =IF(J10="","",J10*INDEX(Acciones!$S$5:$S$148,MATCH($A10,Acciones!$A$5:$A$148,0))) -> 5986.5525 | N10: =IF($A10="","",INDEX(Acciones!$R$5:$R$148,MATCH($A10,Acciones!$A$5:$A$148,0))) -> 1.023781 | O10: =IF(OR($A10="",$B10=""),0,$B10*N10) -> 0.03071343
A11: GFNORTE O | B11: 0.03 | C11: =IF($A11="","",INDEX(Acciones!$B$5:$B$148,MATCH($A11,Acciones!$A$5:$A$148,0))) -> Mexicana | D11: =IF($A11="","",INDEX(Acciones!$U$5:$U$148,MATCH($A11,Acciones!$A$5:$A$148,0))) -> Menor movimiento | E11: =IF($A11="","",INDEX(Acciones!$O$5:$O$148,MATCH($A11,Acciones!$A$5:$A$148,0))) -> 0.25786944 | F11: =IF($A11="","",E11*SQRT($H$4/252)) -> 0.081221238 | G11: =IF($A11="","",INDEX(Acciones!$Q$5:$Q$148,MATCH($A11,Acciones!$A$5:$A$148,0))) -> -0.11808635 | H11: =IF($A11="","",IF(INDEX(Acciones!$G$5:$G$148,MATCH($A11,Acciones!$A$5:$A$148,0))="","n/d",INDEX(Acciones!$G$5:$G$148,MATCH($A11,Acciones!$A$5:$A$148,0)))) -> 0.0003165893 | I11: =IF($A11="","",INDEX(Acciones!$J$5:$J$148,MATCH($A11,Acciones!$A$5:$A$148,0))) -> Sí | J11: =IF(OR($A11="",$B11=""),"",$B11*$C$4) -> 30000 | K11: =IF(J11="","",J11*(IF(ISNUMBER(H11),H11,0)+2*$C$5)) -> 79.097679 | L11: =IF(J11="","",J11*INDEX(Acciones!$T$5:$T$148,MATCH($A11,Acciones!$A$5:$A$148,0))) -> -7351.8883 | M11: =IF(J11="","",J11*INDEX(Acciones!$S$5:$S$148,MATCH($A11,Acciones!$A$5:$A$148,0))) -> 9839.1127 | N11: =IF($A11="","",INDEX(Acciones!$R$5:$R$148,MATCH($A11,Acciones!$A$5:$A$148,0))) -> 1.100209 | O11: =IF(OR($A11="",$B11=""),0,$B11*N11) -> 0.033006271
A12: BOLSA A | B12: 0.03 | C12: =IF($A12="","",INDEX(Acciones!$B$5:$B$148,MATCH($A12,Acciones!$A$5:$A$148,0))) -> Mexicana | D12: =IF($A12="","",INDEX(Acciones!$U$5:$U$148,MATCH($A12,Acciones!$A$5:$A$148,0))) -> Menor movimiento | E12: =IF($A12="","",INDEX(Acciones!$O$5:$O$148,MATCH($A12,Acciones!$A$5:$A$148,0))) -> 0.26448767 | F12: =IF($A12="","",E12*SQRT($H$4/252)) -> 0.083305786 | G12: =IF($A12="","",INDEX(Acciones!$Q$5:$Q$148,MATCH($A12,Acciones!$A$5:$A$148,0))) -> -0.11782474 | H12: =IF($A12="","",IF(INDEX(Acciones!$G$5:$G$148,MATCH($A12,Acciones!$A$5:$A$148,0))="","n/d",INDEX(Acciones!$G$5:$G$148,MATCH($A12,Acciones!$A$5:$A$148,0)))) -> 0.0008514261 | I12: =IF($A12="","",INDEX(Acciones!$J$5:$J$148,MATCH($A12,Acciones!$A$5:$A$148,0))) -> Sí | J12: =IF(OR($A12="",$B12=""),"",$B12*$C$4) -> 30000 | K12: =IF(J12="","",J12*(IF(ISNUMBER(H12),H12,0)+2*$C$5)) -> 95.142783 | L12: =IF(J12="","",J12*INDEX(Acciones!$T$5:$T$148,MATCH($A12,Acciones!$A$5:$A$148,0))) -> -4092.0106 | M12: =IF(J12="","",J12*INDEX(Acciones!$S$5:$S$148,MATCH($A12,Acciones!$A$5:$A$148,0))) -> 9026.3945 | N12: =IF($A12="","",INDEX(Acciones!$R$5:$R$148,MATCH($A12,Acciones!$A$5:$A$148,0))) -> 0.57477112 | O12: =IF(OR($A12="",$B12=""),0,$B12*N12) -> 0.017243134
C13: =IF($A13="","",INDEX(Acciones!$B$5:$B$148,MATCH($A13,Acciones!$A$5:$A$148,0))) | D13: =IF($A13="","",INDEX(Acciones!$U$5:$U$148,MATCH($A13,Acciones!$A$5:$A$148,0))) | E13: =IF($A13="","",INDEX(Acciones!$O$5:$O$148,MATCH($A13,Acciones!$A$5:$A$148,0))) | F13: =IF($A13="","",E13*SQRT($H$4/252)) | G13: =IF($A13="","",INDEX(Acciones!$Q$5:$Q$148,MATCH($A13,Acciones!$A$5:$A$148,0))) | H13: =IF($A13="","",IF(INDEX(Acciones!$G$5:$G$148,MATCH($A13,Acciones!$A$5:$A$148,0))="","n/d",INDEX(Acciones!$G$5:$G$148,MATCH($A13,Acciones!$A$5:$A$148,0)))) | I13: =IF($A13="","",INDEX(Acciones!$J$5:$J$148,MATCH($A13,Acciones!$A$5:$A$148,0))) | J13: =IF(OR($A13="",$B13=""),"",$B13*$C$4) | K13: =IF(J13="","",J13*(IF(ISNUMBER(H13),H13,0)+2*$C$5)) | L13: =IF(J13="","",J13*INDEX(Acciones!$T$5:$T$148,MATCH($A13,Acciones!$A$5:$A$148,0))) | M13: =IF(J13="","",J13*INDEX(Acciones!$S$5:$S$148,MATCH($A13,Acciones!$A$5:$A$148,0))) | N13: =IF($A13="","",INDEX(Acciones!$R$5:$R$148,MATCH($A13,Acciones!$A$5:$A$148,0))) | O13: =IF(OR($A13="",$B13=""),0,$B13*N13) -> 0
C14: =IF($A14="","",INDEX(Acciones!$B$5:$B$148,MATCH($A14,Acciones!$A$5:$A$148,0))) | D14: =IF($A14="","",INDEX(Acciones!$U$5:$U$148,MATCH($A14,Acciones!$A$5:$A$148,0))) | E14: =IF($A14="","",INDEX(Acciones!$O$5:$O$148,MATCH($A14,Acciones!$A$5:$A$148,0))) | F14: =IF($A14="","",E14*SQRT($H$4/252)) | G14: =IF($A14="","",INDEX(Acciones!$Q$5:$Q$148,MATCH($A14,Acciones!$A$5:$A$148,0))) | H14: =IF($A14="","",IF(INDEX(Acciones!$G$5:$G$148,MATCH($A14,Acciones!$A$5:$A$148,0))="","n/d",INDEX(Acciones!$G$5:$G$148,MATCH($A14,Acciones!$A$5:$A$148,0)))) | I14: =IF($A14="","",INDEX(Acciones!$J$5:$J$148,MATCH($A14,Acciones!$A$5:$A$148,0))) | J14: =IF(OR($A14="",$B14=""),"",$B14*$C$4) | K14: =IF(J14="","",J14*(IF(ISNUMBER(H14),H14,0)+2*$C$5)) | L14: =IF(J14="","",J14*INDEX(Acciones!$T$5:$T$148,MATCH($A14,Acciones!$A$5:$A$148,0))) | M14: =IF(J14="","",J14*INDEX(Acciones!$S$5:$S$148,MATCH($A14,Acciones!$A$5:$A$148,0))) | N14: =IF($A14="","",INDEX(Acciones!$R$5:$R$148,MATCH($A14,Acciones!$A$5:$A$148,0))) | O14: =IF(OR($A14="",$B14=""),0,$B14*N14) -> 0
C15: =IF($A15="","",INDEX(Acciones!$B$5:$B$148,MATCH($A15,Acciones!$A$5:$A$148,0))) | D15: =IF($A15="","",INDEX(Acciones!$U$5:$U$148,MATCH($A15,Acciones!$A$5:$A$148,0))) | E15: =IF($A15="","",INDEX(Acciones!$O$5:$O$148,MATCH($A15,Acciones!$A$5:$A$148,0))) | F15: =IF($A15="","",E15*SQRT($H$4/252)) | G15: =IF($A15="","",INDEX(Acciones!$Q$5:$Q$148,MATCH($A15,Acciones!$A$5:$A$148,0))) | H15: =IF($A15="","",IF(INDEX(Acciones!$G$5:$G$148,MATCH($A15,Acciones!$A$5:$A$148,0))="","n/d",INDEX(Acciones!$G$5:$G$148,MATCH($A15,Acciones!$A$5:$A$148,0)))) | I15: =IF($A15="","",INDEX(Acciones!$J$5:$J$148,MATCH($A15,Acciones!$A$5:$A$148,0))) | J15: =IF(OR($A15="",$B15=""),"",$B15*$C$4) | K15: =IF(J15="","",J15*(IF(ISNUMBER(H15),H15,0)+2*$C$5)) | L15: =IF(J15="","",J15*INDEX(Acciones!$T$5:$T$148,MATCH($A15,Acciones!$A$5:$A$148,0))) | M15: =IF(J15="","",J15*INDEX(Acciones!$S$5:$S$148,MATCH($A15,Acciones!$A$5:$A$148,0))) | N15: =IF($A15="","",INDEX(Acciones!$R$5:$R$148,MATCH($A15,Acciones!$A$5:$A$148,0))) | O15: =IF(OR($A15="",$B15=""),0,$B15*N15) -> 0
C16: =IF($A16="","",INDEX(Acciones!$B$5:$B$148,MATCH($A16,Acciones!$A$5:$A$148,0))) | D16: =IF($A16="","",INDEX(Acciones!$U$5:$U$148,MATCH($A16,Acciones!$A$5:$A$148,0))) | E16: =IF($A16="","",INDEX(Acciones!$O$5:$O$148,MATCH($A16,Acciones!$A$5:$A$148,0))) | F16: =IF($A16="","",E16*SQRT($H$4/252)) | G16: =IF($A16="","",INDEX(Acciones!$Q$5:$Q$148,MATCH($A16,Acciones!$A$5:$A$148,0))) | H16: =IF($A16="","",IF(INDEX(Acciones!$G$5:$G$148,MATCH($A16,Acciones!$A$5:$A$148,0))="","n/d",INDEX(Acciones!$G$5:$G$148,MATCH($A16,Acciones!$A$5:$A$148,0)))) | I16: =IF($A16="","",INDEX(Acciones!$J$5:$J$148,MATCH($A16,Acciones!$A$5:$A$148,0))) | J16: =IF(OR($A16="",$B16=""),"",$B16*$C$4) | K16: =IF(J16="","",J16*(IF(ISNUMBER(H16),H16,0)+2*$C$5)) | L16: =IF(J16="","",J16*INDEX(Acciones!$T$5:$T$148,MATCH($A16,Acciones!$A$5:$A$148,0))) | M16: =IF(J16="","",J16*INDEX(Acciones!$S$5:$S$148,MATCH($A16,Acciones!$A$5:$A$148,0))) | N16: =IF($A16="","",INDEX(Acciones!$R$5:$R$148,MATCH($A16,Acciones!$A$5:$A$148,0))) | O16: =IF(OR($A16="",$B16=""),0,$B16*N16) -> 0
C17: =IF($A17="","",INDEX(Acciones!$B$5:$B$148,MATCH($A17,Acciones!$A$5:$A$148,0))) | D17: =IF($A17="","",INDEX(Acciones!$U$5:$U$148,MATCH($A17,Acciones!$A$5:$A$148,0))) | E17: =IF($A17="","",INDEX(Acciones!$O$5:$O$148,MATCH($A17,Acciones!$A$5:$A$148,0))) | F17: =IF($A17="","",E17*SQRT($H$4/252)) | G17: =IF($A17="","",INDEX(Acciones!$Q$5:$Q$148,MATCH($A17,Acciones!$A$5:$A$148,0))) | H17: =IF($A17="","",IF(INDEX(Acciones!$G$5:$G$148,MATCH($A17,Acciones!$A$5:$A$148,0))="","n/d",INDEX(Acciones!$G$5:$G$148,MATCH($A17,Acciones!$A$5:$A$148,0)))) | I17: =IF($A17="","",INDEX(Acciones!$J$5:$J$148,MATCH($A17,Acciones!$A$5:$A$148,0))) | J17: =IF(OR($A17="",$B17=""),"",$B17*$C$4) | K17: =IF(J17="","",J17*(IF(ISNUMBER(H17),H17,0)+2*$C$5)) | L17: =IF(J17="","",J17*INDEX(Acciones!$T$5:$T$148,MATCH($A17,Acciones!$A$5:$A$148,0))) | M17: =IF(J17="","",J17*INDEX(Acciones!$S$5:$S$148,MATCH($A17,Acciones!$A$5:$A$148,0))) | N17: =IF($A17="","",INDEX(Acciones!$R$5:$R$148,MATCH($A17,Acciones!$A$5:$A$148,0))) | O17: =IF(OR($A17="",$B17=""),0,$B17*N17) -> 0
C18: =IF($A18="","",INDEX(Acciones!$B$5:$B$148,MATCH($A18,Acciones!$A$5:$A$148,0))) | D18: =IF($A18="","",INDEX(Acciones!$U$5:$U$148,MATCH($A18,Acciones!$A$5:$A$148,0))) | E18: =IF($A18="","",INDEX(Acciones!$O$5:$O$148,MATCH($A18,Acciones!$A$5:$A$148,0))) | F18: =IF($A18="","",E18*SQRT($H$4/252)) | G18: =IF($A18="","",INDEX(Acciones!$Q$5:$Q$148,MATCH($A18,Acciones!$A$5:$A$148,0))) | H18: =IF($A18="","",IF(INDEX(Acciones!$G$5:$G$148,MATCH($A18,Acciones!$A$5:$A$148,0))="","n/d",INDEX(Acciones!$G$5:$G$148,MATCH($A18,Acciones!$A$5:$A$148,0)))) | I18: =IF($A18="","",INDEX(Acciones!$J$5:$J$148,MATCH($A18,Acciones!$A$5:$A$148,0))) | J18: =IF(OR($A18="",$B18=""),"",$B18*$C$4) | K18: =IF(J18="","",J18*(IF(ISNUMBER(H18),H18,0)+2*$C$5)) | L18: =IF(J18="","",J18*INDEX(Acciones!$T$5:$T$148,MATCH($A18,Acciones!$A$5:$A$148,0))) | M18: =IF(J18="","",J18*INDEX(Acciones!$S$5:$S$148,MATCH($A18,Acciones!$A$5:$A$148,0))) | N18: =IF($A18="","",INDEX(Acciones!$R$5:$R$148,MATCH($A18,Acciones!$A$5:$A$148,0))) | O18: =IF(OR($A18="",$B18=""),0,$B18*N18) -> 0
C19: =IF($A19="","",INDEX(Acciones!$B$5:$B$148,MATCH($A19,Acciones!$A$5:$A$148,0))) | D19: =IF($A19="","",INDEX(Acciones!$U$5:$U$148,MATCH($A19,Acciones!$A$5:$A$148,0))) | E19: =IF($A19="","",INDEX(Acciones!$O$5:$O$148,MATCH($A19,Acciones!$A$5:$A$148,0))) | F19: =IF($A19="","",E19*SQRT($H$4/252)) | G19: =IF($A19="","",INDEX(Acciones!$Q$5:$Q$148,MATCH($A19,Acciones!$A$5:$A$148,0))) | H19: =IF($A19="","",IF(INDEX(Acciones!$G$5:$G$148,MATCH($A19,Acciones!$A$5:$A$148,0))="","n/d",INDEX(Acciones!$G$5:$G$148,MATCH($A19,Acciones!$A$5:$A$148,0)))) | I19: =IF($A19="","",INDEX(Acciones!$J$5:$J$148,MATCH($A19,Acciones!$A$5:$A$148,0))) | J19: =IF(OR($A19="",$B19=""),"",$B19*$C$4) | K19: =IF(J19="","",J19*(IF(ISNUMBER(H19),H19,0)+2*$C$5)) | L19: =IF(J19="","",J19*INDEX(Acciones!$T$5:$T$148,MATCH($A19,Acciones!$A$5:$A$148,0))) | M19: =IF(J19="","",J19*INDEX(Acciones!$S$5:$S$148,MATCH($A19,Acciones!$A$5:$A$148,0))) | N19: =IF($A19="","",INDEX(Acciones!$R$5:$R$148,MATCH($A19,Acciones!$A$5:$A$148,0))) | O19: =IF(OR($A19="",$B19=""),0,$B19*N19) -> 0
A21: Resumen y revisión de reglas
A22: Suma de pesos | B22: =SUM($B$8:$B$19) -> 1 | C22: =IF(ABS(B22-1)<0.0005,"OK: 100%",IF(B22<1,"Te falta "&TEXT(1-B22,"0.0%")&" por asignar (queda en efectivo, que no rinde)","Pasas de 100% por "&TEXT(B22-1,"0.0%"))) -> OK: 100%
A23: Emisoras distintas (mín. 5) | B23: =SUMPRODUCT(($A$8:$A$19<>"")*($B$8:$B$19>0)/COUNTIF($A$8:$A$19,$A$8:$A$19&"")) -> 5 | C23: =IF(B23>=5,"OK","REVISAR: necesitas al menos 5") -> OK
A24: Peso máximo en una emisora (máx. 50%) | B24: =MAX($B$8:$B$19) -> 0.5 | C24: =IF(B24<=0.5,"OK","REVISAR: ninguna puede pasar de 50%") -> OK
A25: Emisoras repetidas en la lista | B25: =SUMPRODUCT(($A$8:$A$19<>"")*(COUNTIF($A$8:$A$19,$A$8:$A$19)>1)) -> 0 | C25: =IF(B25=0,"OK","REVISAR: repetiste una emisora") -> OK
A26: Emisoras sin contraparte hoy | B26: =SUMPRODUCT(($A$8:$A$19<>"")*($I$8:$I$19<>"Sí")) -> 0 | C26: =IF(B26=0,"OK","REVISAR: hoy no hay quien compre o venda alguna de tus emisoras") -> OK
A27: Total a invertir ($) | B27: =SUM($J$8:$J$19) -> 1000000
A28: Comisión total de compra ($) | B28: =B27*$C$5 -> 1160
A29: Costo estimado ida y vuelta ($) | B29: =SUM($K$8:$K$19) -> 10980.278 | C29: ="Comisiones + diferencia compra-venta: "&TEXT(B29/$C$4,"0.00%")&" del capital" -> Comisiones + diferencia compra-venta: 1.10% del capital
A30: Volatilidad anual del portafolio | B30: =SQRT(Covarianza!$B$2) -> 0.64990176 | C30: Usa la correlación entre emisoras (hoja Covarianza).
A31: Mov. típico del portafolio (±1σ) en el lapso | B31: =B30*SQRT($H$4/252) -> 0.20469981 | C31: ~2 de cada 3 veces el resultado cae dentro de ± este porcentaje.
A32: Mov. típico en pesos (±1σ) | B32: =B31*SUM($J$8:$J$19) -> 204699.81 | C32: Solo la parte invertida; descuenta costos.
A33: Beta del portafolio vs IPC (aprox.) | B33: =SUM($O$8:$O$19) -> 1.3578575 | C33: 1 = se mueve como el IPC; >1 más; <1 menos.
A35: Los rangos son históricos y orientativos; el precio real puede salirse de ellos. No es una recomendación de inversión.

Sheet Portafolios
A1: Portafolios: ganador, alternativa balanceada y tu idea
A2: Pesos en celdas amarillas (se pueden cambiar). Pronóstico, alfa y costo salen de la hoja Acciones.
A4: Emisora | B4: Pronóstico 25 ses. | C4: Beta vs canasta | D4: Alfa | E4: Costo ida y vuelta | F4: Ganador: Ganar (máx. prob. top 3) · 5 emisoras | G4: Alternativa: Balanceado (ganancia/riesgo) · 5 emisoras | H4: Tu idea (NVDA + Banorte)
A5: PINFRA * | B5: =INDEX(Acciones!$AI$5:$AI$148,MATCH($A5,Acciones!$A$5:$A$148,0)) -> 0.00098557317 | C5: =INDEX(Acciones!$AF$5:$AF$148,MATCH($A5,Acciones!$A$5:$A$148,0)) -> 0.46574944 | D5: =INDEX(Acciones!$AG$5:$AG$148,MATCH($A5,Acciones!$A$5:$A$148,0)) -> -0.00013546506 | E5: =INDEX(Acciones!$AH$5:$AH$148,MATCH($A5,Acciones!$A$5:$A$148,0)) -> 0.0025753859 | F5: 0.03 | G5: 0 | H5: 0
A6: BOLSA A | B6: =INDEX(Acciones!$AI$5:$AI$148,MATCH($A6,Acciones!$A$5:$A$148,0)) -> 0.0019031141 | C6: =INDEX(Acciones!$AF$5:$AF$148,MATCH($A6,Acciones!$A$5:$A$148,0)) -> 0.57983186 | D6: =INDEX(Acciones!$AG$5:$AG$148,MATCH($A6,Acciones!$A$5:$A$148,0)) -> 0.0004727001 | E6: =INDEX(Acciones!$AH$5:$AH$148,MATCH($A6,Acciones!$A$5:$A$148,0)) -> 0.0031714261 | F6: 0.03 | G6: 0 | H6: 0
A7: GFNORTE O | B7: =INDEX(Acciones!$AI$5:$AI$148,MATCH($A7,Acciones!$A$5:$A$148,0)) -> 0.0030148751 | C7: =INDEX(Acciones!$AF$5:$AF$148,MATCH($A7,Acciones!$A$5:$A$148,0)) -> 0.55438802 | D7: =INDEX(Acciones!$AG$5:$AG$148,MATCH($A7,Acciones!$A$5:$A$148,0)) -> 0.0012515595 | E7: =INDEX(Acciones!$AH$5:$AH$148,MATCH($A7,Acciones!$A$5:$A$148,0)) -> 0.0026365893 | F7: 0.03 | G7: 0 | H7: 0.2
A8: INTC * | B8: =INDEX(Acciones!$AI$5:$AI$148,MATCH($A8,Acciones!$A$5:$A$148,0)) -> 0.020417025 | C8: =INDEX(Acciones!$AF$5:$AF$148,MATCH($A8,Acciones!$A$5:$A$148,0)) -> 2.2198287 | D8: =INDEX(Acciones!$AG$5:$AG$148,MATCH($A8,Acciones!$A$5:$A$148,0)) -> 0.015159538 | E8: =INDEX(Acciones!$AH$5:$AH$148,MATCH($A8,Acciones!$A$5:$A$148,0)) -> 0.012360201 | F8: 0.41 | G8: 0 | H8: 0
A9: MU * | B9: =INDEX(Acciones!$AI$5:$AI$148,MATCH($A9,Acciones!$A$5:$A$148,0)) -> 0.046074203 | C9: =INDEX(Acciones!$AF$5:$AF$148,MATCH($A9,Acciones!$A$5:$A$148,0)) -> 2.1544716 | D9: =INDEX(Acciones!$AG$5:$AG$148,MATCH($A9,Acciones!$A$5:$A$148,0)) -> 0.040297408 | E9: =INDEX(Acciones!$AH$5:$AH$148,MATCH($A9,Acciones!$A$5:$A$148,0)) -> 0.011322186 | F9: 0.5 | G9: 0.283 | H9: 0
A10: BABA N | B10: =INDEX(Acciones!$AI$5:$AI$148,MATCH($A10,Acciones!$A$5:$A$148,0)) -> 0.0089938062 | C10: =INDEX(Acciones!$AF$5:$AF$148,MATCH($A10,Acciones!$A$5:$A$148,0)) -> 0.94932214 | D10: =INDEX(Acciones!$AG$5:$AG$148,MATCH($A10,Acciones!$A$5:$A$148,0)) -> 0.0058475834 | E10: =INDEX(Acciones!$AH$5:$AH$148,MATCH($A10,Acciones!$A$5:$A$148,0)) -> 0.0043880799 | F10: 0 | G10: 0.086 | H10: 0
A11: GCC * | B11: =INDEX(Acciones!$AI$5:$AI$148,MATCH($A11,Acciones!$A$5:$A$148,0)) -> 0.0087097642 | C11: =INDEX(Acciones!$AF$5:$AF$148,MATCH($A11,Acciones!$A$5:$A$148,0)) -> 0.61055927 | D11: =INDEX(Acciones!$AG$5:$AG$148,MATCH($A11,Acciones!$A$5:$A$148,0)) -> 0.007554388 | E11: =INDEX(Acciones!$AH$5:$AH$148,MATCH($A11,Acciones!$A$5:$A$148,0)) -> 0.0036903323 | F11: 0 | G11: 0.167 | H11: 0
A12: CEMEX CPO | B12: =INDEX(Acciones!$AI$5:$AI$148,MATCH($A12,Acciones!$A$5:$A$148,0)) -> 0.01259636 | C12: =INDEX(Acciones!$AF$5:$AF$148,MATCH($A12,Acciones!$A$5:$A$148,0)) -> 0.95654766 | D12: =INDEX(Acciones!$AG$5:$AG$148,MATCH($A12,Acciones!$A$5:$A$148,0)) -> 0.0079012467 | E12: =INDEX(Acciones!$AH$5:$AH$148,MATCH($A12,Acciones!$A$5:$A$148,0)) -> 0.002896535 | F12: 0 | G12: 0.227 | H12: 0
A13: LAB B | B13: =INDEX(Acciones!$AI$5:$AI$148,MATCH($A13,Acciones!$A$5:$A$148,0)) -> 0.0083687665 | C13: =INDEX(Acciones!$AF$5:$AF$148,MATCH($A13,Acciones!$A$5:$A$148,0)) -> 0.62552022 | D13: =INDEX(Acciones!$AG$5:$AG$148,MATCH($A13,Acciones!$A$5:$A$148,0)) -> 0.0065089417 | E13: =INDEX(Acciones!$AH$5:$AH$148,MATCH($A13,Acciones!$A$5:$A$148,0)) -> 0.0031046214 | F13: 0 | G13: 0.237 | H13: 0
A14: NVDA * | B14: =INDEX(Acciones!$AI$5:$AI$148,MATCH($A14,Acciones!$A$5:$A$148,0)) -> 0.0078862285 | C14: =INDEX(Acciones!$AF$5:$AF$148,MATCH($A14,Acciones!$A$5:$A$148,0)) -> 1.0939895 | D14: =INDEX(Acciones!$AG$5:$AG$148,MATCH($A14,Acciones!$A$5:$A$148,0)) -> 0.0059578335 | E14: =INDEX(Acciones!$AH$5:$AH$148,MATCH($A14,Acciones!$A$5:$A$148,0)) -> 0.0067540614 | F14: 0 | G14: 0 | H14: 0.3
A15: GMEXICO B | B15: =INDEX(Acciones!$AI$5:$AI$148,MATCH($A15,Acciones!$A$5:$A$148,0)) -> 0.010287097 | C15: =INDEX(Acciones!$AF$5:$AF$148,MATCH($A15,Acciones!$A$5:$A$148,0)) -> 1.2348725 | D15: =INDEX(Acciones!$AG$5:$AG$148,MATCH($A15,Acciones!$A$5:$A$148,0)) -> 0.0028928806 | E15: =INDEX(Acciones!$AH$5:$AH$148,MATCH($A15,Acciones!$A$5:$A$148,0)) -> 0.0024063595 | F15: 0 | G15: 0 | H15: 0.2
A16: MSFT * | B16: =INDEX(Acciones!$AI$5:$AI$148,MATCH($A16,Acciones!$A$5:$A$148,0)) -> -0.0040369448 | C16: =INDEX(Acciones!$AF$5:$AF$148,MATCH($A16,Acciones!$A$5:$A$148,0)) -> 0.78798255 | D16: =INDEX(Acciones!$AG$5:$AG$148,MATCH($A16,Acciones!$A$5:$A$148,0)) -> -0.0061390696 | E16: =INDEX(Acciones!$AH$5:$AH$148,MATCH($A16,Acciones!$A$5:$A$148,0)) -> 0.0041517049 | F16: 0 | G16: 0 | H16: 0.15
A17: GOOGL * | B17: =INDEX(Acciones!$AI$5:$AI$148,MATCH($A17,Acciones!$A$5:$A$148,0)) -> 0.0060269147 | C17: =INDEX(Acciones!$AF$5:$AF$148,MATCH($A17,Acciones!$A$5:$A$148,0)) -> 1.0356739 | D17: =INDEX(Acciones!$AG$5:$AG$148,MATCH($A17,Acciones!$A$5:$A$148,0)) -> 0.0016992723 | E17: =INDEX(Acciones!$AH$5:$AH$148,MATCH($A17,Acciones!$A$5:$A$148,0)) -> 0.0038919918 | F17: 0 | G17: 0 | H17: 0.15
A19: Suma de pesos | F19: =SUM(F$5:F$17) -> 1 | G19: =SUM(G$5:G$17) -> 1 | H19: =SUM(H$5:H$17) -> 1
A20: Emisoras distintas (mín. 5) | F20: =COUNTIF(F$5:F$17,">0") -> 5 | G20: =COUNTIF(G$5:G$17,">0") -> 5 | H20: =COUNTIF(H$5:H$17,">0") -> 5
A21: Peso máximo (máx. 50%) | F21: =MAX(F$5:F$17) -> 0.5 | G21: =MAX(G$5:G$17) -> 0.283 | H21: =MAX(H$5:H$17) -> 0.3
A22: Revisión de reglas | F22: =IF(AND(ABS(F19-1)<0.0005,F20>=5,F21<=0.5),"OK","REVISAR") -> OK | G22: =IF(AND(ABS(G19-1)<0.0005,G20>=5,G21<=0.5),"OK","REVISAR") -> OK | H22: =IF(AND(ABS(H19-1)<0.0005,H20>=5,H21<=0.5),"OK","REVISAR") -> OK
A23: Beta vs canasta | F23: =SUMPRODUCT(F$5:F$17,$C$5:$C$17) -> 2.0353647 | G23: =SUMPRODUCT(G$5:G$17,$C$5:$C$17) -> 1.1587052 | H23: =SUMPRODUCT(H$5:H$17,$C$5:$C$17) -> 0.95959742
A24: Costo estimado ida y vuelta ($) | F24: =SUMPRODUCT(F$5:F$17,$E$5:$E$17)*'Mi portafolio'!$C$4 -> 10980.278 | G24: =SUMPRODUCT(G$5:G$17,$E$5:$E$17)*'Mi portafolio'!$C$4 -> 5591.1479 | H24: =SUMPRODUCT(H$5:H$17,$E$5:$E$17)*'Mi portafolio'!$C$4 -> 4241.3627
A25: Ganancia neta si el mercado baja ($) | F25: ='Mi portafolio'!$C$4*(SUMPRODUCT(F$5:F$17,$C$5:$C$17)*Pronóstico!$C$13+SUMPRODUCT(F$5:F$17,$D$5:$D$17))-F24 -> -68690.52 | G25: ='Mi portafolio'!$C$4*(SUMPRODUCT(G$5:G$17,$C$5:$C$17)*Pronóstico!$C$13+SUMPRODUCT(G$5:G$17,$D$5:$D$17))-G24 -> -36975.816 | H25: ='Mi portafolio'!$C$4*(SUMPRODUCT(H$5:H$17,$C$5:$C$17)*Pronóstico!$C$13+SUMPRODUCT(H$5:H$17,$D$5:$D$17))-H24 -> -41951.444
A26: Ganancia neta, escenario base ($) | F26: ='Mi portafolio'!$C$4*(SUMPRODUCT(F$5:F$17,$C$5:$C$17)*Pronóstico!$C$14+SUMPRODUCT(F$5:F$17,$D$5:$D$17))-F24 -> 31585.189 | G26: ='Mi portafolio'!$C$4*(SUMPRODUCT(G$5:G$17,$C$5:$C$17)*Pronóstico!$C$14+SUMPRODUCT(G$5:G$17,$D$5:$D$17))-G24 -> 20109.769 | H26: ='Mi portafolio'!$C$4*(SUMPRODUCT(H$5:H$17,$C$5:$C$17)*Pronóstico!$C$14+SUMPRODUCT(H$5:H$17,$D$5:$D$17))-H24 -> 5324.7583
A27: Ganancia neta si el mercado sube ($) | F27: ='Mi portafolio'!$C$4*(SUMPRODUCT(F$5:F$17,$C$5:$C$17)*Pronóstico!$C$15+SUMPRODUCT(F$5:F$17,$D$5:$D$17))-F24 -> 131860.9 | G27: ='Mi portafolio'!$C$4*(SUMPRODUCT(G$5:G$17,$C$5:$C$17)*Pronóstico!$C$15+SUMPRODUCT(G$5:G$17,$D$5:$D$17))-G24 -> 77195.354 | H27: ='Mi portafolio'!$C$4*(SUMPRODUCT(H$5:H$17,$C$5:$C$17)*Pronóstico!$C$15+SUMPRODUCT(H$5:H$17,$D$5:$D$17))-H24 -> 52600.961
A28: Ganancia esperada ($) | F28: =Pronóstico!$B$13*F25+Pronóstico!$B$14*F26+Pronóstico!$B$15*F27 -> 31585.189 | G28: =Pronóstico!$B$13*G25+Pronóstico!$B$14*G26+Pronóstico!$B$15*G27 -> 20109.769 | H28: =Pronóstico!$B$13*H25+Pronóstico!$B$14*H26+Pronóstico!$B$15*H27 -> 5324.7583

Sheet Acciones
A1: Las 145 acciones del Reto: mercado y datos históricos (precios actualizados: 8 de octubre de 2026, ~11:10 h CDMX)
A2: Último precio, rendimientos, volatilidad, beta y ventanas: Yahoo Finance al momento indicado (SIC = precio en dólares × tipo de cambio). Precio de compra/venta, diferencia y volumen: foto del monitor de la plataforma. No es una recomendación de inversión.
A4: Emisora | B4: Tipo | C4: Último precio ($) | D4: Var. del día | E4: Precio de compra ($) | F4: Precio de venta ($) | G4: Diferencia compra-venta | H4: Volumen compra | I4: Volumen venta | J4: ¿Operable hoy? | K4: Rend. 1 mes | L4: Rend. 3 meses | M4: Rend. 6 meses | N4: Rend. 12 meses | O4: Volatilidad anual (1 año) | P4: Mov. típico ±1σ en 25 sesiones | Q4: Peor caída (1 año) | R4: Beta vs IPC | S4: Mejor ventana 25 ses. (3 años) | T4: Peor ventana 25 ses. (3 años) | U4: Perfil por volatilidad | V4: Precio objetivo analistas ($) | W4: Potencial al objetivo | X4: Nº de analistas | Y4: Próximo reporte | Z4: ¿Reporta antes del 13-nov? | AA4: Importe operado diario ($, mexicanas) | AB4: Importe en mejor nivel del monitor ($) | AC4: ¿Líquida para el reto? | AD4: Momento 12-1 | AE4: Puntaje (z) | AF4: Beta vs canasta | AG4: Alfa (25 ses.) | AH4: Costo ida y vuelta | AI4: Pronóstico 25 ses. (neto)
A5: BRKB * | B5: Exterior (SIC) | C5: 9256.9408 | D5: 0.017592588 | E5: 9095.02 | F5: 9383.91 | G5: 0.031266962 | H5: 4540 | I5: 4437 | J5: Sí | K5: 0.080341301 | L5: 0.064611655 | M5: 0.13166246 | N5: 0.019998168 | O5: 0.1636282 | P5: 0.051538039 | Q5: -0.14409367 | R5: -0.018943812 | S5: 0.16964278 | T5: -0.10669456 | U5: Menor movimiento | V5: 9941.7935 | X5: 3 | Y5: 2026-11-07 | Z5: Sí | AA5: 4.1587311e+10 | AB5: 41024502 | AC5: Sí | AD5: -0.055855619 | AE5: -0.70161436 | AF5: 0.22234006 | AG5: =Pronóstico!$B$5*P5*AE5 -> -0.0018079914 | AH5: =IF(ISNUMBER(G5),G5,1)+2*'Mi portafolio'!$C$5 -> 0.033586962 | AI5: =AF5*Pronóstico!$B$8+AG5-AH5 -> -0.03363035
A6: SIGMAF A | B6: Mexicana | C6: 18.27 | D6: -0.0097614046 | E6: 18.24 | F6: 18.25 | G6: 0.0005480954 | H6: 915 | I6: 558 | J6: Sí | K6: -0.0041577083 | L6: 0.13925836 | M6: 0.16839548 | N6: 0.26047505 | O6: 0.17140322 | P6: 0.053986941 | Q6: -0.076276235 | R6: 0.27606045 | S6: 0.36138743 | T6: -0.29017615 | U6: Menor movimiento | V6: 21.96154 | W6: 0.20205473 | X6: 13 | Y6: 2026-10-27 | Z6: Sí | AA6: 1.9631986e+08 | AB6: 10177.92 | AC6: Sí | AD6: 0.26573762 | AE6: 0.38109012 | AF6: 0.080961132 | AG6: =Pronóstico!$B$5*P6*AE6 -> 0.0010286945 | AH6: =IF(ISNUMBER(G6),G6,1)+2*'Mi portafolio'!$C$5 -> 0.0028680954 | AI6: =AF6*Pronóstico!$B$8+AG6-AH6 -> -0.0011968522
A7: LIVEPOL C-1 | B7: Mexicana | C7: 102.63 | D7: -0.0027208123 | E7: 102.32 | F7: 102.53 | G7: 0.0020502807 | H7: 90 | I7: 322 | J7: Sí | K7: 0.036099249 | L7: 0.04129585 | M7: -0.028344037 | N7: 0.21008767 | O7: 0.1923828 | P7: 0.060594887 | Q7: -0.093163267 | R7: 0.19070879 | S7: 0.22779885 | T7: -0.16988791 | U7: Menor movimiento | V7: 121.85333 | W7: 0.18730712 | X7: 15 | Y7: 2026-10-26 | Z7: Sí | AA7: 26577589 | AB7: 9227.7 | AC7: Sí | AD7: 0.1679264 | AE7: 0.0099671564 | AF7: 0.13603299 | AG7: =Pronóstico!$B$5*P7*AE7 -> 3.0197936e-05 | AH7: =IF(ISNUMBER(G7),G7,1)+2*'Mi portafolio'!$C$5 -> 0.0043702807 | AI7: =AF7*Pronóstico!$B$8+AG7-AH7 -> -0.0032604558
A8: GRUMA B | B8: Mexicana | C8: 236.31 | D8: 0.0011862344 | E8: 236.41 | F8: 236.52 | G8: 0.0004651851 | H8: 28 | I8: 126 | J8: Sí | K8: 0.00093336623 | L8: -0.15384277 | M8: -0.21367341 | N8: -0.23815012 | O8: 0.19431637 | P8: 0.061203904 | Q8: -0.34068714 | R8: 0.44959422 | S8: 0.19377777 | T8: -0.12940001 | U8: Menor movimiento | V8: 336.53845 | W8: 0.42413969 | X8: 13 | Y8: 2026-10-21 | Z8: Sí | AA8: 1.2808089e+08 | AB8: 6626.2 | AC8: Sí | AD8: -0.23886054 | AE8: -0.046533891 | AF8: 0.32823286 | AG8: =Pronóstico!$B$5*P8*AE8 -> -0.00014240279 | AH8: =IF(ISNUMBER(G8),G8,1)+2*'Mi portafolio'!$C$5 -> 0.0027851851 | AI8: =AF8*Pronóstico!$B$8+AG8-AH8 -> -0.00032256515
A9: KO * | B9: Exterior (SIC) | C9: 1593.9405 | D9: 0.033297739 | E9: 1557.06 | F9: 1593.98 | G9: 0.023433533 | H9: 10809 | I9: 7200 | J9: Sí | K9: 0.082758688 | L9: 0.087189905 | M9: 0.24159178 | N9: 0.29686426 | O9: 0.20368899 | P9: 0.064156003 | Q9: -0.0891337 | R9: 0.014929544 | S9: 0.18931175 | T9: -0.088620351 | U9: Menor movimiento | V9: 1714.2745 | W9: 0.075494699 | X9: 23 | Y9: 2026-10-27 | Z9: Sí | AA9: 2.4643653e+10 | AB9: 11347200 | AC9: Sí | AD9: 0.1977408 | AE9: -0.45693769 | AF9: 0.17451437 | AG9: =Pronóstico!$B$5*P9*AE9 -> -0.0014657648 | AH9: =IF(ISNUMBER(G9),G9,1)+2*'Mi portafolio'!$C$5 -> 0.025753533 | AI9: =AF9*Pronóstico!$B$8+AG9-AH9 -> -0.025834263
A10: FIBRAMQ 12 | B10: Mexicana | C10: 44.7 | D10: -0.0024548227 | E10: 44.5 | F10: 44.64 | G10: 0.0031411263 | H10: 800 | I10: 704 | J10: Sí | K10: 0.050255958 | L10: -0.0025079808 | M10: 0.074129929 | N10: 0.61163255 | O10: 0.20399409 | P10: 0.064252099 | Q10: -0.097821091 | R10: 0.25057426 | S10: 0.23105558 | T10: -0.12913625 | U10: Menor movimiento | V10: 45.2 | W10: 0.011185682 | X10: 5 | Y10: 2026-10-22 | Z10: Sí | AA10: 19640045 | AB10: 31328 | AC10: No | AD10: 0.53451408 | AE10: 0.3343799 | AF10: 0.099824706 | AG10: =Pronóstico!$B$5*P10*AE10 -> 0.0010742305 | AH10: =IF(ISNUMBER(G10),G10,1)+2*'Mi portafolio'!$C$5 -> 0.0054611263 | AI10: =AF10*Pronóstico!$B$8+AG10-AH10 -> -0.0035946362
A11: VESTA * | B11: Mexicana | C11: 61.44 | D11: 0.011859681 | E11: 61.42 | F11: 61.43 | G11: 0.0001628002 | H11: 2852 | I11: 259 | J11: Sí | K11: 0.076020321 | L11: 0.028461291 | M11: -0.020362533 | N11: 0.26323597 | O11: 0.20555417 | P11: 0.064743477 | Q11: -0.10973071 | R11: 0.50655052 | S11: 0.24913269 | T11: -0.15201769 | U11: Menor movimiento | V11: 70.30285 | W11: 0.14425212 | X11: 13 | Y11: 2026-10-22 | Z11: Sí | AA11: 1.2720499e+08 | AB11: 15910.37 | AC11: Sí | AD11: 0.17398895 | AE11: -0.18630461 | AF11: 0.29134221 | AG11: =Pronóstico!$B$5*P11*AE11 -> -0.0006031004 | AH11: =IF(ISNUMBER(G11),G11,1)+2*'Mi portafolio'!$C$5 -> 0.0024828002 | AI11: =AF11*Pronóstico!$B$8+AG11-AH11 -> -0.00077366085
A12: MCD * | B12: Exterior (SIC) | C12: 4296.2705 | D12: 0.034819757 | E12: 4247.15 | F12: 4349.19 | G12: 0.023740336 | H12: 4000 | I12: 4100 | J12: Sí | K12: 0.0016071095 | L12: -0.093719102 | M12: -0.17622049 | N12: -0.22446979 | O12: 0.2083813 | P12: 0.06563394 | Q12: -0.29821461 | R12: 0.11188668 | S12: 0.23320535 | T12: -0.14651694 | U12: Menor movimiento | V12: 5332.5998 | W12: 0.24121604 | X12: 29 | Y12: 2026-11-04 | Z12: Sí | AA12: 2.7266259e+10 | AB12: 16904040 | AC12: Sí | AD12: -0.22571415 | AE12: -0.91878182 | AF12: 0.35088758 | AG12: =Pronóstico!$B$5*P12*AE12 -> -0.0030151635 | AH12: =IF(ISNUMBER(G12),G12,1)+2*'Mi portafolio'!$C$5 -> 0.026060336 | AI12: =AF12*Pronóstico!$B$8+AG12-AH12 -> -0.026290677
A13: JNJ * | B13: Exterior (SIC) | C13: 4646.6234 | D13: 0.00053527089 | E13: 4501.21 | F13: 4649.99 | G13: 0.032515954 | H13: 400 | I13: 400 | J13: Sí | K13: 0.028863284 | L13: 0.035120277 | M13: 0.14045199 | N13: 0.33423234 | O13: 0.20608619 | P13: 0.06491105 | Q13: -0.14032686 | R13: 0.076451413 | S13: 0.20093586 | T13: -0.11843229 | U13: Menor movimiento | V13: 5076.2386 | W13: 0.092457515 | X13: 22 | Y13: 2026-10-13 | Z13: Sí | AA13: 3.1676408e+10 | AB13: 1816800 | AC13: Sí | AD13: 0.29680237 | AE13: -0.070963462 | AF13: 0.17148039 | AG13: =Pronóstico!$B$5*P13*AE13 -> -0.00023031564 | AH13: =IF(ISNUMBER(G13),G13,1)+2*'Mi portafolio'!$C$5 -> 0.034835954 | AI13: =AF13*Pronóstico!$B$8+AG13-AH13 -> -0.033705314
A14: PG * | B14: Exterior (SIC) | C14: 2720.227 | D14: 0.024012943 | E14: 2696.01 | F14: 2749.99 | G14: 0.019823724 | H14: 1805 | I14: 1500 | J14: Sí | K14: 0.12768393 | L14: 0.055358738 | M14: 0.11603236 | N14: 0.0034504537 | O14: 0.20825066 | P14: 0.065592793 | Q14: -0.15054703 | R14: 0.14404813 | S14: 0.15501072 | T14: -0.11334235 | U14: Menor movimiento | V14: 2918.6867 | W14: 0.072957024 | X14: 23 | Y14: 2026-10-22 | Z14: Sí | AA14: 2.088026e+10 | AB14: 4065000 | AC14: Sí | AD14: -0.11016693 | AE14: -1.4063574 | AF14: 0.28100479 | AG14: =Pronóstico!$B$5*P14*AE14 -> -0.0046123454 | AH14: =IF(ISNUMBER(G14),G14,1)+2*'Mi portafolio'!$C$5 -> 0.022143724 | AI14: =AF14*Pronóstico!$B$8+AG14-AH14 -> -0.024525872
A15: WALMEX * | B15: Mexicana | C15: 46.72 | D15: 0.00021422438 | E15: 46.72 | F15: 46.74 | G15: 0.0004279906 | H15: 2268 | I15: 901 | J15: Sí | K15: 0.015659009 | L15: -0.059605298 | M15: -0.18527563 | N15: -0.22272242 | O15: 0.20278226 | P15: 0.063870409 | Q15: -0.27139285 | R15: 0.51770404 | S15: 0.18236067 | T15: -0.1722792 | U15: Menor movimiento | V15: 58.03889 | W15: 0.24227076 | X15: 18 | Y15: 2026-10-27 | Z15: Sí | AA15: 7.9408248e+08 | AB15: 42103.73 | AC15: Sí | AD15: -0.23470616 | AE15: -0.94087878 | AF15: 0.34880215 | AG15: =Pronóstico!$B$5*P15*AE15 -> -0.0030047156 | AH15: =IF(ISNUMBER(G15),G15,1)+2*'Mi portafolio'!$C$5 -> 0.0027479906 | AI15: =AF15*Pronóstico!$B$8+AG15-AH15 -> -0.0029844352
A16: AGNC * | B16: Exterior (SIC) | C16: 154.57279 | D16: 0.016187822 | E16: 153.49 | F16: 154.49 | G16: 0.0064939282 | H16: 3 | I16: 94400 | J16: Sí | K16: -0.11959635 | L16: -0.16827261 | M16: -0.10742562 | N16: -0.038805372 | O16: 0.21637238 | P16: 0.068150895 | Q16: -0.20711613 | R16: 0.4850167 | S16: 0.27763487 | T16: -0.19968507 | U16: Menor movimiento | V16: 196.65744 | W16: 0.27226424 | X16: 9 | Y16: 2026-10-19 | Z16: Sí | AA16: 7.4741164e+09 | AB16: 458.19 | AC16: No | AD16: 0.091765839 | AE16: 0.20194262 | AF16: 0.8128897 | AG16: =Pronóstico!$B$5*P16*AE16 -> 0.00068812851 | AH16: =IF(ISNUMBER(G16),G16,1)+2*'Mi portafolio'!$C$5 -> 0.0088139282 | AI16: =AF16*Pronóstico!$B$8+AG16-AH16 -> -0.0016742942
A17: PFE * | B17: Exterior (SIC) | C17: 502.92886 | D17: -0.00023398528 | E17: 494.96 | F17: 500.99 | G17: 0.012109042 | H17: 21300 | I17: 7100 | J17: Sí | K17: 0.070814403 | L17: 0.19468765 | M17: 0.10899095 | N17: 0.19164434 | O17: 0.21676642 | P17: 0.068275005 | Q17: -0.17472441 | R17: 0.18026826 | S17: 0.21572645 | T17: -0.18000236 | U17: Menor movimiento | V17: 526.96071 | W17: 0.047783794 | X17: 26 | Y17: 2026-11-03 | Z17: Sí | AA17: 1.6128297e+10 | AB17: 3564129 | AC17: Sí | AD17: 0.11283929 | AE17: -0.85343294 | AF17: 0.55461103 | AG17: =Pronóstico!$B$5*P17*AE17 -> -0.0029134069 | AH17: =IF(ISNUMBER(G17),G17,1)+2*'Mi portafolio'!$C$5 -> 0.014429042 | AI17: =AF17*Pronóstico!$B$8+AG17-AH17 -> -0.012940774
... A19: COST * | B19: Exterior (SIC) | C19: 17202.327 | D19: 0.016083073 | E19: 17050.01 | F19: 17256.99 | G19: 0.012066342 | H19: 4820 | I19: 4520 | J19: Sí | K19: 0.12717176 | L19: 0.062796784 | M19: 0.015611839 | N19: 0.0027417381 | O19: 0.21774762 | P19: 0.068584053 | Q19: -0.19236377 | R19: 0.11593723 | S19: 0.23525626 | T19: -0.18956705 | U19: Menor movimiento | V19: 19204.837 | W19: 0.11640925 | X19: 35 | Y19: 2026-12-10 | Z19: No | AA19: 3.8258309e+10 | AB19: 77811800 | AC19: Sí | AD19: -0.11039136 | AE19: -1.190343 | AF19: 0.22688101 | AG19: =Pronóstico!$B$5*P19*AE19 -> -0.0040819275 | AH19: =IF(ISNUMBER(G19),G19,1)+2*'Mi portafolio'!$C$5 -> 0.014386342 | AI19: =AF19*Pronóstico!$B$8+AG19-AH19 -> -0.016667627
A20: ACTINVR B | B20: Mexicana | C20: 21.51 | D20: 0 | E20: 21.51 | F20: 21.55 | G20: 0.0018578727 | H20: 247 | I20: 5153 | J20: Sí | K20: 0.0027032912 | L20: 0.0027032912 | M20: 0.029508048 | N20: 0.15412448 | O20: 0.21962124 | P20: 0.069174188 | Q20: -0.073215979 | R20: 0.12603034 | S20: 0.13520399 | T20: -0.056122388 | U20: Menor movimiento | V20: 26 | X20: 1 | Z20: No | AA20: 347686.37 | AB20: 5322.85 | AC20: No | AD20: 0.15101295 | AE20: 0.55712041 | AF20: 0.096204868 | AG20: =Pronóstico!$B$5*P20*AE20 -> 0.0019269176 | AH20: =IF(ISNUMBER(G20),G20,1)+2*'Mi portafolio'!$C$5 -> 0.0041778727 | AI20: =AF20*Pronóstico!$B$8+AG20-AH20 -> -0.0014874244
A21: PEP * | B21: Exterior (SIC) | C21: 2290.0009 | D21: 0.029865438 | E21: 2270.01 | F21: 2275.34 | G21: 0.0023452539 | H21: 2906 | I21: 2 | J21: Sí | K21: -0.0093760759 | L21: -0.045162345 | M21: -0.12472754 | N21: -0.15899271 | O21: 0.21929056 | P21: 0.069070034 | Q21: -0.2322844 | R21: 0.10174295 | S21: 0.179695 | T21: -0.16973098 | U21: Menor movimiento | V21: 2698.1956 | W21: 0.17825089 | X21: 22 | Y21: 2026-10-08 | Z21: Sí | AA21: 2.2981961e+10 | AB21: 4548 | AC21: No | AD21: -0.15103273 | AE21: -1.005583 | AF21: 0.26474483 | AG21: =Pronóstico!$B$5*P21*AE21 -> -0.0034727824 | AH21: =IF(ISNUMBER(G21),G21,1)+2*'Mi portafolio'!$C$5 -> 0.0046652539 | AI21: =AF21*Pronóstico!$B$8+AG21-AH21 -> -0.0060368869
A22: CHDRAUI B | B22: Mexicana | C22: 86.54 | D22: 0.01204536 | E22: 86.61 | F22: 86.62 | G22: 0.0001154534 | H22: 112 | I22: 97 | J22: Sí | K22: -0.0072272257 | L22: -0.046391174 | M22: -0.14361098 | N22: -0.33565553 | O22: 0.2198246 | P22: 0.069238241 | Q22: -0.37763975 | R22: 0.52338023 | S22: 0.31205047 | T22: -0.17922149 | U22: Menor movimiento | V22: 122.5 | W22: 0.41553039 | X22: 14 | Y22: 2026-10-20 | Z22: Sí | AA22: 1.4192412e+08 | AB22: 8400.2 | AC22: Sí | AD22: -0.33081921 | AE22: -0.36923944 | AF22: 0.27817118 | AG22: =Pronóstico!$B$5*P22*AE22 -> -0.0012782745 | AH22: =IF(ISNUMBER(G22),G22,1)+2*'Mi portafolio'!$C$5 -> 0.0024354534 | AI22: =AF22*Pronóstico!$B$8+AG22-AH22 -> -0.0015060201
A23: BAC * | B23: Exterior (SIC) | C23: 959.11375 | D23: -0.0030782897 | E23: 950.01 | F23: 960.99 | G23: 0.011491366 | H23: 20000 | I23: 16300 | J23: Sí | K23: -0.095293865 | L23: -0.074560759 | M23: 0.033515406 | N23: 0.036061117 | O23: 0.21847827 | P23: 0.068814188 | Q23: -0.18944752 | R23: 0.27670563 | S23: 0.22980018 | T23: -0.26858456 | U23: Menor movimiento | V23: 1216.251 | W23: 0.2680988 | X23: 22 | Y23: 2026-10-14 | Z23: Sí | AA23: 3.9893822e+10 | AB23: 15550200 | AC23: Sí | AD23: 0.14519077 | AE23: 0.34370702 | AF23: 0.7009282 | AG23: =Pronóstico!$B$5*P23*AE23 -> 0.001182596 | AH23: =IF(ISNUMBER(G23),G23,1)+2*'Mi portafolio'!$C$5 -> 0.013811366 | AI23: =AF23*Pronóstico!$B$8+AG23-AH23 -> -0.0070658476
A24: GFINBUR O | B24: Mexicana | C24: 41.58 | D24: 0.0036206016 | E24: 41.58 | F24: 41.59 | G24: 0.0002404713 | H24: 716 | I24: 410 | J24: Sí | K24: -0.034146282 | L24: 0.0058055558 | M24: -0.055895088 | N24: -0.11301244 | O24: 0.2235518 | P24: 0.070412198 | Q24: -0.12223367 | R24: 0.81363975 | S24: 0.23621694 | T24: -0.17531056 | U24: Menor movimiento | V24: 44.71429 | W24: 0.07537975 | X24: 7 | Y24: 2025-07-21 | Z24: No | AA24: 1.4897571e+08 | AB24: 17051.9 | AC24: Sí | AD24: -0.081654349 | AE24: -1.3075298 | AF24: 0.57167421 | AG24: =Pronóstico!$B$5*P24*AE24 -> -0.0046033024 | AH24: =IF(ISNUMBER(G24),G24,1)+2*'Mi portafolio'!$C$5 -> 0.0025604713 | AI24: =AF24*Pronóstico!$B$8+AG24-AH24 -> -0.0026266768
A25: FUNO 11 | B25: Mexicana | C25: 30.37 | D25: 0.010302408 | E25: 30.37 | F25: 30.38 | G25: 0.0003292181 | H25: 6802 | I25: 5146 | J25: Sí | K25: 0.024603962 | L25: 0.031905553 | M25: 0.016941934 | N25: 0.22567808 | O25: 0.2260136 | P25: 0.071187593 | Q25: -0.12018598 | R25: 0.68982327 | S25: 0.19612239 | T25: -0.14241611 | U25: Menor movimiento | V25: 34.46154 | W25: 0.13472308 | X25: 13 | Y25: 2026-10-28 | Z25: Sí | AA25: 1.8404144e+08 | AB25: 156335.48 | AC25: Sí | AD25: 0.1962457 | AE25: -0.16611318 | AF25: 0.29624718 | AG25: =Pronóstico!$B$5*P25*AE25 -> -0.00059125988 | AH25: =IF(ISNUMBER(G25),G25,1)+2*'Mi portafolio'!$C$5 -> 0.0026492181 | AI25: =AF25*Pronóstico!$B$8+AG25-AH25 -> -0.00088930986
A26: FEMSA UBD | B26: Mexicana | C26: 216.08 | D26: 0.024415727 | E26: 215.82 | F26: 216.09 | G26: 0.0012502605 | H26: 291 | I26: 229 | J26: Sí | K26: 0.083107779 | L26: -0.027786485 | M26: 0.09945279 | N26: 0.28512061 | O26: 0.22800933 | P26: 0.071816188 | Q26: -0.13933176 | R26: 0.64848682 | S26: 0.17211638 | T26: -0.1659036 | U26: Menor movimiento | V26: 249.33333 | W26: 0.1538936 | X26: 12 | Y26: 2025-07-22 | Z26: No | AA26: 6.9343941e+08 | AB26: 49422.78 | AC26: Sí | AD26: 0.18651221 | AE26: -0.10012211 | AF26: 0.30660168 | AG26: =Pronóstico!$B$5*P26*AE26 -> -0.00035951943 | AH26: =IF(ISNUMBER(G26),G26,1)+2*'Mi portafolio'!$C$5 -> 0.0035702605 | AI26: =AF26*Pronóstico!$B$8+AG26-AH26 -> -0.0014964333
A27: JPM * | B27: Exterior (SIC) | C27: 5982.3211 | D27: 0.009520457 | E27: 5868.03 | F27: 5994.99 | G27: 0.02140433 | H27: 6702 | I27: 6502 | J27: Sí | K27: 0.0017373364 | L27: 0.026312755 | M27: 0.14342048 | N27: 0.11117476 | O27: 0.23090497 | P27: 0.072728229 | Q27: -0.16264195 | R27: 0.3508067 | S27: 0.23002535 | T27: -0.22107846 | U27: Menor movimiento | V27: 6765.293 | W27: 0.13088096 | X27: 22 | Y27: 2026-10-13 | Z27: Sí | AA27: 5.2304313e+10 | AB27: 38426820 | AC27: Sí | AD27: 0.10924763 | AE27: -0.44995285 | AF27: 0.77428161 | AG27: =Pronóstico!$B$5*P27*AE27 -> -0.0016362137 | AH27: =IF(ISNUMBER(G27),G27,1)+2*'Mi portafolio'!$C$5 -> 0.02372433 | AI27: =AF27*Pronóstico!$B$8+AG27-AH27 -> -0.019215452
A28: V * | B28: Exterior (SIC) | C28: 6859.6556 | D28: 0.025731419 | E28: 6803.63 | F28: 6848.94 | G28: 0.0066375781 | H28: 6600 | I28: 4200 | J28: Sí | K28: 0.10396687 | L28: 0.097481772 | M28: 0.26320587 | N28: 0.097141258 | O28: 0.23656975 | P28: 0.074512468 | Q28: -0.1801713 | R28: 0.093311155 | S28: 0.1912757 | T28: -0.15886462 | U28: Menor movimiento | V28: 7612.6716 | W28: 0.10977461 | X28: 37 | Y28: 2026-10-27 | Z28: Sí | AA28: 3.9731066e+10 | AB28: 28728000 | AC28: Sí | AD28: -0.0061828096 | AE28: -0.90639085 | AF28: 0.52346509 | AG28: =Pronóstico!$B$5*P28*AE28 -> -0.0033768709 | AH28: =IF(ISNUMBER(G28),G28,1)+2*'Mi portafolio'!$C$5 -> 0.0089575781 | AI28: =AF28*Pronóstico!$B$8+AG28-AH28 -> -0.0081799642
A29: KIMBER A | B29: Mexicana | C29: 37.71 | D29: 0.0090982115 | E29: 37.71 | F29: 37.73 | G29: 0.0005302227 | H29: 2983 | I29: 1629 | J29: Sí | K29: -0.009247703 | L29: 0.0011266593 | M29: -0.076516534 | N29: 0.1087984 | O29: 0.23592237 | P29: 0.074308561 | Q29: -0.17579968 | R29: 0.7363349 | S29: 0.15435276 | T29: -0.16163017 | U29: Menor movimiento | V29: 43.59091 | W29: 0.15595094 | X29: 11 | Y29: 2026-10-20 | Z29: Sí | AA29: 1.7979019e+08 | AB29: 61429.59 | AC29: Sí | AD29: 0.11914795 | AE29: -0.29480806 | AF29: 0.45097138 | AG29: =Pronóstico!$B$5*P29*AE29 -> -0.0010953381 | AH29: =IF(ISNUMBER(G29),G29,1)+2*'Mi portafolio'!$C$5 -> 0.0028502227 | AI29: =AF29*Pronóstico!$B$8+AG29-AH29 -> -0.00036642293
A30: KOF UBL | B30: Mexicana | C30: 198.33 | D30: 0.025862515 | E30: 198.69 | F30: 199.08 | G30: 0.0019609322 | H30: 587 | I30: 59 | J30: Sí | K30: 0.076009082 | L30: 0.094174158 | M30: 0.13707268 | N30: 0.2995855 | O30: 0.23309291 | P30: 0.073417366 | Q30: -0.15870433 | R30: 0.58596428 | S30: 0.21101562 | T30: -0.15020504 | U30: Menor movimiento | V30: 213.20769 | W30: 0.075014824 | X30: 13 | Y30: 2025-07-17 | Z30: No | AA30: 1.6318204e+08 | AB30: 11722.71 | AC30: Sí | AD30: 0.20778302 | AE30: -0.42877884 | AF30: 0.38495766 | AG30: =Pronóstico!$B$5*P30*AE30 -> -0.0015739907 | AH30: =IF(ISNUMBER(G30),G30,1)+2*'Mi portafolio'!$C$5 -> 0.0042809322 | AI30: =AF30*Pronóstico!$B$8+AG30-AH30 -> -0.0027997033
A31: MA * | B31: Exterior (SIC) | C31: 10498.243 | D31: 0.024964528 | E31: 10250.01 | F31: 10499.99 | G31: 0.024094458 | H31: 2215 | I31: 2000 | J31: Sí | K31: 0.094091367 | L31: 0.11575001 | M31: 0.17226446 | N31: 0.020495019 | O31: 0.23870872 | P31: 0.075186181 | Q31: -0.2265354 | R31: 0.0085650936 | S31: 0.19867292 | T31: -0.17198753 | U31: Menor movimiento | V31: 12102.856 | W31: 0.15284583 | X31: 37 | Y31: 2026-10-29 | Z31: Sí | AA31: 2.797862e+10 | AB31: 20819940 | AC31: Sí | AD31: -0.067267095 | AE31: -0.87743383 | AF31: 0.50542278 | AG31: =Pronóstico!$B$5*P31*AE31 -> -0.0032985449 | AH31: =IF(ISNUMBER(G31),G31,1)+2*'Mi portafolio'!$C$5 -> 0.026414458 | AI31: =AF31*Pronóstico!$B$8+AG31-AH31 -> -0.025701711
A32: FIBRAPL 14 | B32: Mexicana | C32: 75.98 | D32: 0.012661663 | E32: 75.84 | F32: 75.9 | G32: 0.0007908264 | H32: 863 | I32: 595 | J32: Sí | K32: 0.008494917 | L32: 0.003318486 | M32: -0.069242862 | N32: 0.091180513 | O32: 0.24024941 | P32: 0.07567145 | Q32: -0.15115795 | R32: 0.44505718 | S32: 0.35489541 | T32: -0.13730882 | U32: Menor movimiento | V32: 84.28815 | W32: 0.10934654 | X32: 13 | Y32: 2026-10-21 | Z32: Sí | AA32: 1.4631058e+08 | AB32: 45160.5 | AC32: Sí | AD32: 0.081989105 | AE32: -0.64027549 | AF32: 0.2429347 | AG32: =Pronóstico!$B$5*P32*AE32 -> -0.0024225288 | AH32: =IF(ISNUMBER(G32),G32,1)+2*'Mi portafolio'!$C$5 -> 0.0031108264 | AI32: =AF32*Pronóstico!$B$8+AG32-AH32 -> -0.003605302
... A60: MRK * | B60: Exterior (SIC) | C60: 2558.3023 | D60: -0.00094915838 | E60: 2480.51 | F60: 2603.49 | G60: 0.048379229 | H60: 800 | I60: 1000 | J60: Sí | K60: 0.033596608 | L60: 0.18793359 | M60: 0.27666869 | N60: 0.68851842 | O60: 0.30287054 | P60: 0.095395254 | Q60: -0.12374868 | R60: 0.30803108 | S60: 0.21206506 | T60: -0.19341873 | U60: Movimiento medio | V60: 2836.9508 | W60: 0.10891932 | X60: 25 | Y60: 2026-10-29 | Z60: Sí | AA60: 2.5388129e+10 | AB60: 2024800 | AC60: Sí | AD60: 0.63363386 | AE60: 1.0358925 | AF60: 0.63743921 | AG60: =Pronóstico!$B$5*P60*AE60 -> 0.0049409613 | AH60: =IF(ISNUMBER(G60),G60,1)+2*'Mi portafolio'!$C$5 -> 0.050699229 | AI60: =AF60*Pronóstico!$B$8+AG60-AH60 -> -0.040699226
A61: MEGA CPO | B61: Mexicana | C61: 52.41 | D61: 0.00019088051 | E61: 52.43 | F61: 52.47 | G61: 0.0007626311 | H61: 364 | I61: 59 | J61: Sí | K61: 0.015310096 | L61: -0.14535073 | M61: -0.085248263 | N61: 0.048496415 | O61: 0.30184271 | P61: 0.095071517 | Q61: -0.22542897 | R61: 0.76856516 | S61: 0.3158819 | T61: -0.17648936 | U61: Movimiento medio | V61: 69.62308 | W61: 0.32843122 | X61: 13 | Z61: No | AA61: 55956880 | AB61: 3095.73 | AC61: Sí | AD61: 0.032685895 | AE61: 0.30230636 | AF61: 0.65165283 | AG61: =Pronóstico!$B$5*P61*AE61 -> 0.0014370362 | AH61: =IF(ISNUMBER(G61),G61,1)+2*'Mi portafolio'!$C$5 -> 0.0030826311 | AI61: =AF61*Pronóstico!$B$8+AG61-AH61 -> 0.0035262529
A62: TMO * | B62: Exterior (SIC) | C62: 11704.691 | D62: -0.01569568 | E62: 11328.81 | F62: 11899.99 | G62: 0.049178606 | H62: 3626 | I62: 3726 | J62: Sí | K62: 0.14419268 | L62: 0.26702102 | M62: 0.27876649 | N62: 0.18310166 | O62: 0.30466837 | P62: 0.095961517 | Q62: -0.32460277 | R62: 0.14967227 | S62: 0.23917808 | T62: -0.21857484 | U62: Movimiento medio | V62: 12125.478 | W62: 0.035950247 | X62: 25 | Y62: 2026-10-21 | Z62: Sí | AA62: 2.8026537e+10 | AB62: 43003997 | AC62: Sí | AD62: 0.03400562 | AE62: -1.152287 | AF62: 0.86064042 | AG62: =Pronóstico!$B$5*P62*AE62 -> -0.0055287605 | AH62: =IF(ISNUMBER(G62),G62,1)+2*'Mi portafolio'!$C$5 -> 0.051498606 | AI62: =AF62*Pronóstico!$B$8+AG62-AH62 -> -0.050196887
A63: LAB B | B63: Mexicana | C63: 12.75 | D63: -0.0046764978 | E63: 12.74 | F63: 12.75 | G63: 0.0007846214 | H63: 835 | I63: 753 | J63: Sí | K63: 0.0046840883 | L63: -0.14273157 | M63: -0.27414272 | N63: -0.22112882 | O63: 0.30194093 | P63: 0.095102453 | Q63: -0.35305505 | R63: 0.73312063 | S63: 0.27313876 | T63: -0.22825232 | U63: Movimiento medio | V63: 21.66667 | W63: 0.69934667 | X63: 6 | Y63: 2026-10-21 | Z63: Sí | AA63: 46477058 | AB63: 9593.22 | AC63: Sí | AD63: -0.22476011 | AE63: 1.3688273 | AF63: 0.62552022 | AG63: =Pronóstico!$B$5*P63*AE63 -> 0.0065089417 | AH63: =IF(ISNUMBER(G63),G63,1)+2*'Mi portafolio'!$C$5 -> 0.0031046214 | AI63: =AF63*Pronóstico!$B$8+AG63-AH63 -> 0.0083687665
A64: CUERVO * | B64: Mexicana | C64: 13.91 | D64: 0.016093655 | E64: 13.89 | F64: 13.9 | G64: 0.0007196833 | H64: 300 | I64: 910 | J64: Sí | K64: -0.078301219 | L64: -0.042068942 | M64: -0.083282299 | N64: -0.33156005 | O64: 0.30157746 | P64: 0.09498797 | Q64: -0.43884505 | R64: 0.36704266 | S64: 0.34441944 | T64: -0.27718597 | U64: Movimiento medio | V64: 19.24545 | W64: 0.38356937 | X64: 11 | Y64: 2026-10-28 | Z64: Sí | AA64: 22109779 | AB64: 4167 | AC64: Sí | AD64: -0.27477397 | AE64: -0.35812021 | AF64: 0.39967892 | AG64: =Pronóstico!$B$5*P64*AE64 -> -0.0017008556 | AH64: =IF(ISNUMBER(G64),G64,1)+2*'Mi portafolio'!$C$5 -> 0.0030396833 | AI64: =AF64*Pronóstico!$B$8+AG64-AH64 -> -0.001568484
A65: SITES1 A-1 | B65: Mexicana | C65: 16.36 | D65: -0.0090853796 | E65: 16.36 | F65: 16.41 | G65: 0.0030515716 | H65: 21551 | I65: 100 | J65: Sí | K65: -0.02035929 | L65: -0.049941855 | M65: 0.037659305 | N65: 0.007870041 | O65: 0.30888654 | P65: 0.097290117 | Q65: -0.2230679 | R65: 0.26032041 | S65: 0.66834688 | T65: -0.27544425 | U65: Movimiento medio | V65: 21 | X65: 3 | Y65: 2025-05-12 | Z65: No | AA65: 700014.64 | AB65: 1641 | AC65: No | AD65: 0.028816004 | AE65: -0.1864123 | AF65: 0.034683437 | AG65: =Pronóstico!$B$5*P65*AE65 -> -0.0009068037 | AH65: =IF(ISNUMBER(G65),G65,1)+2*'Mi portafolio'!$C$5 -> 0.0053715716 | AI65: =AF65*Pronóstico!$B$8+AG65-AH65 -> -0.0060031099
