Workbook

Sheet PRECIOS
A1: Fecha | B1: AC | C1: ALSEA | D1: AMXB | E1: BIMBOA | F1: CEMEXCPO | G1: GFNORTEO | H1: TLEVISACPO | I1: WALMEX | J1: IPC
A2: 45936 | B2: 188.69 | C2: 57.84 | D2: 19.17 | E2: 65.01 | F2: 16.47 | G2: 175.48 | H2: 9.37 | I2: 54.63 | J2: 60404.19
A3: 45937 | B3: 183.89 | C3: 55.68 | D3: 19.04 | E3: 62.89 | F3: 16.68 | G3: 175.03 | H3: 9.3 | I3: 54.69 | J3: 60215.75
A4: 45938 | B4: 182.99 | C4: 56.6 | D4: 19.4 | E4: 61.02 | F4: 16.93 | G4: 176.85 | H4: 9.03 | I4: 55.9 | J4: 60888.56
A5: 45939 | B5: 180.1 | C5: 55.38 | D5: 19.5 | E5: 62.06 | F5: 16.79 | G5: 177.07 | H5: 9 | I5: 56.64 | J5: 60819.31
A6: 45940 | B6: 178.24 | C6: 54.11 | D6: 19.62 | E6: 61.33 | F6: 16.96 | G6: 174.73 | H6: 8.69 | I6: 56.47 | J6: 60568.93
A7: 45943 | B7: 178.96 | C7: 55.15 | D7: 19.73 | E7: 61 | F7: 17.19 | G7: 176.96 | H7: 8.75 | I7: 57.03 | J7: 61045.09
A8: 45944 | B8: 176.78 | C8: 54.19 | D8: 19.33 | E8: 61.45 | F8: 17.63 | G8: 173.31 | H8: 8.9 | I8: 58.05 | J8: 60785.62
A9: 45945 | B9: 178.17 | C9: 54.6 | D9: 19.81 | E9: 60.91 | F9: 18.18 | G9: 176.26 | H9: 9.01 | I9: 61.09 | J9: 61637.54
A10: 45946 | B10: 181.97 | C10: 54.89 | D10: 20.67 | E10: 62.7 | F10: 17.96 | G10: 178.07 | H10: 9.06 | I10: 62.31 | J10: 62544.56
A11: 45947 | B11: 179.82 | C11: 54.31 | D11: 20.64 | E11: 62.05 | F11: 17.73 | G11: 173.04 | H11: 8.78 | I11: 61.76 | J11: 61743.92
A12: 45950 | B12: 178.2 | C12: 54.42 | D12: 20.53 | E12: 62.66 | F12: 17.61 | G12: 171.21 | H12: 9.03 | I12: 61.63 | J12: 61672.35
A13: 45951 | B13: 177.17 | C13: 53.47 | D13: 20.54 | E13: 61.09 | F13: 16.81 | G13: 173.17 | H13: 8.86 | I13: 61.7 | J13: 60773.78
... A251: 46297 | B251: 195.57 | C251: 45.79 | D251: 19.36 | E251: 55.1 | F251: 17.44 | G251: 190.25 | H251: 8.21 | I251: 46.17 | J251: 64531.68

Sheet RENDIMIENTOS
A1: Fecha | B1: AC | C1: ALSEA | D1: AMXB | E1: BIMBOA | F1: CEMEXCPO | G1: GFNORTEO | H1: TLEVISACPO | I1: WALMEX | J1: IPC
A2: =PRECIOS!A2 -> 45936
A3: =PRECIOS!A3 -> 45937 | B3: =+LN(PRECIOS!B3/PRECIOS!B2) -> -0.025767704 | C3: =+LN(PRECIOS!C3/PRECIOS!C2) -> -0.038059562 | D3: =+LN(PRECIOS!D3/PRECIOS!D2) -> -0.0068045277 | E3: =+LN(PRECIOS!E3/PRECIOS!E2) -> -0.033153936 | F3: =+LN(PRECIOS!F3/PRECIOS!F2) -> 0.012669853 | G3: =+LN(PRECIOS!G3/PRECIOS!G2) -> -0.0025676885 | H3: =+LN(PRECIOS!H3/PRECIOS!H2) -> -0.0074986961 | I3: =+LN(PRECIOS!I3/PRECIOS!I2) -> 0.001097695 | J3: =+LN(PRECIOS!J3/PRECIOS!J2) -> -0.0031245274
A4: =PRECIOS!A4 -> 45938 | B4: =+LN(PRECIOS!B4/PRECIOS!B3) -> -0.0049062462 | C4: =+LN(PRECIOS!C4/PRECIOS!C3) -> 0.016387969 | D4: =+LN(PRECIOS!D4/PRECIOS!D3) -> 0.018731037 | E4: =+LN(PRECIOS!E4/PRECIOS!E3) -> -0.030185489 | F4: =+LN(PRECIOS!F4/PRECIOS!F3) -> 0.014876799 | G4: =+LN(PRECIOS!G4/PRECIOS!G3) -> 0.010344528 | H4: =+LN(PRECIOS!H4/PRECIOS!H3) -> -0.029462033 | I4: =+LN(PRECIOS!I4/PRECIOS!I3) -> 0.021883503 | J4: =+LN(PRECIOS!J4/PRECIOS!J3) -> 0.011111362
A5: =PRECIOS!A5 -> 45939 | B5: =+LN(PRECIOS!B5/PRECIOS!B4) -> -0.015919254 | C5: =+LN(PRECIOS!C5/PRECIOS!C4) -> -0.021790467 | D5: =+LN(PRECIOS!D5/PRECIOS!D4) -> 0.0051413995 | E5: =+LN(PRECIOS!E5/PRECIOS!E4) -> 0.01689998 | F5: =+LN(PRECIOS!F5/PRECIOS!F4) -> -0.0083037251 | G5: =+LN(PRECIOS!G5/PRECIOS!G4) -> 0.001243219 | H5: =+LN(PRECIOS!H5/PRECIOS!H4) -> -0.0033277901 | I5: =+LN(PRECIOS!I5/PRECIOS!I4) -> 0.013151069 | J5: =+LN(PRECIOS!J5/PRECIOS!J4) -> -0.0011379709
A6: =PRECIOS!A6 -> 45940 | B6: =+LN(PRECIOS!B6/PRECIOS!B5) -> -0.010381295 | C6: =+LN(PRECIOS!C6/PRECIOS!C5) -> -0.023199506 | D6: =+LN(PRECIOS!D6/PRECIOS!D5) -> 0.0061349886 | E6: =+LN(PRECIOS!E6/PRECIOS!E5) -> -0.011832539 | F6: =+LN(PRECIOS!F6/PRECIOS!F5) -> 0.010074159 | G6: =+LN(PRECIOS!G6/PRECIOS!G5) -> -0.013303209 | H6: =+LN(PRECIOS!H6/PRECIOS!H5) -> -0.035051638 | I6: =+LN(PRECIOS!I6/PRECIOS!I5) -> -0.0030059257 | J6: =+LN(PRECIOS!J6/PRECIOS!J5) -> -0.0041252819
A7: =PRECIOS!A7 -> 45943 | B7: =+LN(PRECIOS!B7/PRECIOS!B6) -> 0.0040313604 | C7: =+LN(PRECIOS!C7/PRECIOS!C6) -> 0.019037734 | D7: =+LN(PRECIOS!D7/PRECIOS!D6) -> 0.0055908659 | E7: =+LN(PRECIOS!E7/PRECIOS!E6) -> -0.0053952555 | F7: =+LN(PRECIOS!F7/PRECIOS!F6) -> 0.013470189 | G7: =+LN(PRECIOS!G7/PRECIOS!G6) -> 0.012681793 | H7: =+LN(PRECIOS!H7/PRECIOS!H6) -> 0.0068807611 | I7: =+LN(PRECIOS!I7/PRECIOS!I6) -> 0.0098679215 | J7: =+LN(PRECIOS!J7/PRECIOS!J6) -> 0.0078307161
A8: =PRECIOS!A8 -> 45944 | B8: =+LN(PRECIOS!B8/PRECIOS!B7) -> -0.012256296 | C8: =+LN(PRECIOS!C8/PRECIOS!C7) -> -0.017560356 | D8: =+LN(PRECIOS!D8/PRECIOS!D7) -> -0.020482027 | E8: =+LN(PRECIOS!E8/PRECIOS!E7) -> 0.0073499718 | F8: =+LN(PRECIOS!F8/PRECIOS!F7) -> 0.025274177 | G8: =+LN(PRECIOS!G8/PRECIOS!G7) -> -0.02084182 | H8: =+LN(PRECIOS!H8/PRECIOS!H7) -> 0.016997576 | I8: =+LN(PRECIOS!I8/PRECIOS!I7) -> 0.017727263 | J8: =+LN(PRECIOS!J8/PRECIOS!J7) -> -0.0042595236
A9: =PRECIOS!A9 -> 45945 | B9: =+LN(PRECIOS!B9/PRECIOS!B8) -> 0.0078321291 | C9: =+LN(PRECIOS!C9/PRECIOS!C8) -> 0.0075374932 | D9: =+LN(PRECIOS!D9/PRECIOS!D8) -> 0.024528567 | E9: =+LN(PRECIOS!E9/PRECIOS!E8) -> -0.0088264712 | F9: =+LN(PRECIOS!F9/PRECIOS!F8) -> 0.030720092 | G9: =+LN(PRECIOS!G9/PRECIOS!G8) -> 0.016878279 | H9: =+LN(PRECIOS!H9/PRECIOS!H8) -> 0.012283795 | I9: =+LN(PRECIOS!I9/PRECIOS!I8) -> 0.051043479 | J9: =+LN(PRECIOS!J9/PRECIOS!J8) -> 0.013917853
A10: =PRECIOS!A10 -> 45946 | B10: =+LN(PRECIOS!B10/PRECIOS!B9) -> 0.021103688 | C10: =+LN(PRECIOS!C10/PRECIOS!C9) -> 0.0052972998 | D10: =+LN(PRECIOS!D10/PRECIOS!D9) -> 0.042496513 | E10: =+LN(PRECIOS!E10/PRECIOS!E9) -> 0.028964083 | F10: =+LN(PRECIOS!F10/PRECIOS!F9) -> -0.012175026 | G10: =+LN(PRECIOS!G10/PRECIOS!G9) -> 0.010216554 | H10: =+LN(PRECIOS!H10/PRECIOS!H9) -> 0.0055340484 | I10: =+LN(PRECIOS!I10/PRECIOS!I9) -> 0.01977374 | J10: =+LN(PRECIOS!J10/PRECIOS!J9) -> 0.014608162
A11: =PRECIOS!A11 -> 45947 | B11: =+LN(PRECIOS!B11/PRECIOS!B10) -> -0.011885488 | C11: =+LN(PRECIOS!C11/PRECIOS!C10) -> -0.010622811 | D11: =+LN(PRECIOS!D11/PRECIOS!D10) -> -0.0014524331 | E11: =+LN(PRECIOS!E11/PRECIOS!E10) -> -0.010420936 | F11: =+LN(PRECIOS!F11/PRECIOS!F10) -> -0.012888943 | G11: =+LN(PRECIOS!G11/PRECIOS!G10) -> -0.02865395 | H11: =+LN(PRECIOS!H11/PRECIOS!H10) -> -0.031392712 | I11: =+LN(PRECIOS!I11/PRECIOS!I10) -> -0.0088660208 | J11: =+LN(PRECIOS!J11/PRECIOS!J10) -> -0.012883754
A12: =PRECIOS!A12 -> 45950 | B12: =+LN(PRECIOS!B12/PRECIOS!B11) -> -0.0090498355 | C12: =+LN(PRECIOS!C12/PRECIOS!C11) -> 0.0020233613 | D12: =+LN(PRECIOS!D12/PRECIOS!D11) -> -0.0053437096 | E12: =+LN(PRECIOS!E12/PRECIOS!E11) -> 0.0097827739 | F12: =+LN(PRECIOS!F12/PRECIOS!F11) -> -0.0067911976 | G12: =+LN(PRECIOS!G12/PRECIOS!G11) -> -0.010631908 | H12: =+LN(PRECIOS!H12/PRECIOS!H11) -> 0.02807596 | I12: =+LN(PRECIOS!I12/PRECIOS!I11) -> -0.0021071407 | J12: =+LN(PRECIOS!J12/PRECIOS!J11) -> -0.0011598148
A13: =PRECIOS!A13 -> 45951 | B13: =+LN(PRECIOS!B13/PRECIOS!B12) -> -0.0057967914 | C13: =+LN(PRECIOS!C13/PRECIOS!C12) -> -0.017610984 | D13: =+LN(PRECIOS!D13/PRECIOS!D12) -> 0.00048697347 | E13: =+LN(PRECIOS!E13/PRECIOS!E12) -> -0.025375099 | F13: =+LN(PRECIOS!F13/PRECIOS!F12) -> -0.046492975 | G13: =+LN(PRECIOS!G13/PRECIOS!G12) -> 0.011382898 | H13: =+LN(PRECIOS!H13/PRECIOS!H12) -> -0.019005603 | I13: =+LN(PRECIOS!I13/PRECIOS!I12) -> 0.0011351659 | J13: =+LN(PRECIOS!J13/PRECIOS!J12) -> -0.014677248
A14: =PRECIOS!A14 -> 45952 | B14: =+LN(PRECIOS!B14/PRECIOS!B13) -> 0.01111372 | C14: =+LN(PRECIOS!C14/PRECIOS!C13) -> 0.0087515688 | D14: =+LN(PRECIOS!D14/PRECIOS!D13) -> 0.0072762873 | E14: =+LN(PRECIOS!E14/PRECIOS!E13) -> 0.0079889558 | F14: =+LN(PRECIOS!F14/PRECIOS!F13) -> 0.0094731318 | G14: =+LN(PRECIOS!G14/PRECIOS!G13) -> -0.0021967866 | H14: =+LN(PRECIOS!H14/PRECIOS!H13) -> 0.0045045121 | I14: =+LN(PRECIOS!I14/PRECIOS!I13) -> 0.0059788495 | J14: =+LN(PRECIOS!J14/PRECIOS!J13) -> 0.0087551564
... A251: =PRECIOS!A251 -> 46297 | B251: =+LN(PRECIOS!B251/PRECIOS!B250) -> 0.0085758094 | C251: =+LN(PRECIOS!C251/PRECIOS!C250) -> 0.0063534007 | D251: =+LN(PRECIOS!D251/PRECIOS!D250) -> 0.019296557 | E251: =+LN(PRECIOS!E251/PRECIOS!E250) -> -0.00054431644 | F251: =+LN(PRECIOS!F251/PRECIOS!F250) -> 0.0086381188 | G251: =+LN(PRECIOS!G251/PRECIOS!G250) -> 0.017176905 | H251: =+LN(PRECIOS!H251/PRECIOS!H250) -> 0.013488862 | I251: =+LN(PRECIOS!I251/PRECIOS!I250) -> -0.010342691 | J251: =+LN(PRECIOS!J251/PRECIOS!J250) -> 0.0109549

Sheet Matriz
D2: Matriz de desviaciones, correlaciones y varianzas-covarianzas (rendimientos logarítmicos diarios)
D6: SD | E6: AC | F6: ALSEA | G6: AMXB | H6: BIMBOA | I6: CEMEXCPO | J6: GFNORTEO | K6: TLEVISACPO | L6: WALMEX
D7: AC | E7: =STDEV(RENDIMIENTOS!$B$3:$B$251) -> 0.013648829 | F7: =STDEV(RENDIMIENTOS!$C$3:$C$251) -> 0.015618406 | G7: =STDEV(RENDIMIENTOS!$D$3:$D$251) -> 0.01540763 | H7: =STDEV(RENDIMIENTOS!$E$3:$E$251) -> 0.017745262 | I7: =STDEV(RENDIMIENTOS!$F$3:$F$251) -> 0.020648405 | J7: =STDEV(RENDIMIENTOS!$G$3:$G$251) -> 0.017207912 | K7: =STDEV(RENDIMIENTOS!$H$3:$H$251) -> 0.025109278 | L7: =STDEV(RENDIMIENTOS!$I$3:$I$251) -> 0.013790294
D8: ALSEA | E8: =STDEV(RENDIMIENTOS!$C$3:$C$251) -> 0.015618406
D9: AMXB | E9: =STDEV(RENDIMIENTOS!$D$3:$D$251) -> 0.01540763
D10: BIMBOA | E10: =STDEV(RENDIMIENTOS!$E$3:$E$251) -> 0.017745262
D11: CEMEXCPO | E11: =STDEV(RENDIMIENTOS!$F$3:$F$251) -> 0.020648405
D12: GFNORTEO | E12: =STDEV(RENDIMIENTOS!$G$3:$G$251) -> 0.017207912
D13: TLEVISACPO | E13: =STDEV(RENDIMIENTOS!$H$3:$H$251) -> 0.025109278
D14: WALMEX | E14: =STDEV(RENDIMIENTOS!$I$3:$I$251) -> 0.013790294
D19: Correlación | E19: AC | F19: ALSEA | G19: AMXB | H19: BIMBOA | I19: CEMEXCPO | J19: GFNORTEO | K19: TLEVISACPO | L19: WALMEX
D20: AC | E20: =CORREL(RENDIMIENTOS!$B$3:$B$251,RENDIMIENTOS!$B$3:$B$251) -> 1 | F20: =CORREL(RENDIMIENTOS!$B$3:$B$251,RENDIMIENTOS!$C$3:$C$251) -> 0.30516545 | G20: =CORREL(RENDIMIENTOS!$B$3:$B$251,RENDIMIENTOS!$D$3:$D$251) -> 0.31466337 | H20: =CORREL(RENDIMIENTOS!$B$3:$B$251,RENDIMIENTOS!$E$3:$E$251) -> 0.39072592 | I20: =CORREL(RENDIMIENTOS!$B$3:$B$251,RENDIMIENTOS!$F$3:$F$251) -> 0.31200975 | J20: =CORREL(RENDIMIENTOS!$B$3:$B$251,RENDIMIENTOS!$G$3:$G$251) -> 0.42661225 | K20: =CORREL(RENDIMIENTOS!$B$3:$B$251,RENDIMIENTOS!$H$3:$H$251) -> 0.054672237 | L20: =CORREL(RENDIMIENTOS!$B$3:$B$251,RENDIMIENTOS!$I$3:$I$251) -> 0.36268507
D21: ALSEA | E21: =CORREL(RENDIMIENTOS!$C$3:$C$251,RENDIMIENTOS!$B$3:$B$251) -> 0.30516545 | F21: =CORREL(RENDIMIENTOS!$C$3:$C$251,RENDIMIENTOS!$C$3:$C$251) -> 1 | G21: =CORREL(RENDIMIENTOS!$C$3:$C$251,RENDIMIENTOS!$D$3:$D$251) -> 0.18933631 | H21: =CORREL(RENDIMIENTOS!$C$3:$C$251,RENDIMIENTOS!$E$3:$E$251) -> 0.22650082 | I21: =CORREL(RENDIMIENTOS!$C$3:$C$251,RENDIMIENTOS!$F$3:$F$251) -> 0.14358085 | J21: =CORREL(RENDIMIENTOS!$C$3:$C$251,RENDIMIENTOS!$G$3:$G$251) -> 0.17520051 | K21: =CORREL(RENDIMIENTOS!$C$3:$C$251,RENDIMIENTOS!$H$3:$H$251) -> 0.066819812 | L21: =CORREL(RENDIMIENTOS!$C$3:$C$251,RENDIMIENTOS!$I$3:$I$251) -> 0.23461517
D22: AMXB | E22: =CORREL(RENDIMIENTOS!$D$3:$D$251,RENDIMIENTOS!$B$3:$B$251) -> 0.31466337 | F22: =CORREL(RENDIMIENTOS!$D$3:$D$251,RENDIMIENTOS!$C$3:$C$251) -> 0.18933631 | G22: =CORREL(RENDIMIENTOS!$D$3:$D$251,RENDIMIENTOS!$D$3:$D$251) -> 1 | H22: =CORREL(RENDIMIENTOS!$D$3:$D$251,RENDIMIENTOS!$E$3:$E$251) -> 0.277629 | I22: =CORREL(RENDIMIENTOS!$D$3:$D$251,RENDIMIENTOS!$F$3:$F$251) -> 0.31206995 | J22: =CORREL(RENDIMIENTOS!$D$3:$D$251,RENDIMIENTOS!$G$3:$G$251) -> 0.33014356 | K22: =CORREL(RENDIMIENTOS!$D$3:$D$251,RENDIMIENTOS!$H$3:$H$251) -> 0.12893387 | L22: =CORREL(RENDIMIENTOS!$D$3:$D$251,RENDIMIENTOS!$I$3:$I$251) -> 0.28376971
D23: BIMBOA | E23: =CORREL(RENDIMIENTOS!$E$3:$E$251,RENDIMIENTOS!$B$3:$B$251) -> 0.39072592 | F23: =CORREL(RENDIMIENTOS!$E$3:$E$251,RENDIMIENTOS!$C$3:$C$251) -> 0.22650082 | G23: =CORREL(RENDIMIENTOS!$E$3:$E$251,RENDIMIENTOS!$D$3:$D$251) -> 0.277629 | H23: =CORREL(RENDIMIENTOS!$E$3:$E$251,RENDIMIENTOS!$E$3:$E$251) -> 1 | I23: =CORREL(RENDIMIENTOS!$E$3:$E$251,RENDIMIENTOS!$F$3:$F$251) -> 0.26546751 | J23: =CORREL(RENDIMIENTOS!$E$3:$E$251,RENDIMIENTOS!$G$3:$G$251) -> 0.30886467 | K23: =CORREL(RENDIMIENTOS!$E$3:$E$251,RENDIMIENTOS!$H$3:$H$251) -> 0.19203535 | L23: =CORREL(RENDIMIENTOS!$E$3:$E$251,RENDIMIENTOS!$I$3:$I$251) -> 0.25690288
D24: CEMEXCPO | E24: =CORREL(RENDIMIENTOS!$F$3:$F$251,RENDIMIENTOS!$B$3:$B$251) -> 0.31200975 | F24: =CORREL(RENDIMIENTOS!$F$3:$F$251,RENDIMIENTOS!$C$3:$C$251) -> 0.14358085 | G24: =CORREL(RENDIMIENTOS!$F$3:$F$251,RENDIMIENTOS!$D$3:$D$251) -> 0.31206995 | H24: =CORREL(RENDIMIENTOS!$F$3:$F$251,RENDIMIENTOS!$E$3:$E$251) -> 0.26546751 | I24: =CORREL(RENDIMIENTOS!$F$3:$F$251,RENDIMIENTOS!$F$3:$F$251) -> 1 | J24: =CORREL(RENDIMIENTOS!$F$3:$F$251,RENDIMIENTOS!$G$3:$G$251) -> 0.36961365 | K24: =CORREL(RENDIMIENTOS!$F$3:$F$251,RENDIMIENTOS!$H$3:$H$251) -> 0.19710484 | L24: =CORREL(RENDIMIENTOS!$F$3:$F$251,RENDIMIENTOS!$I$3:$I$251) -> 0.23071775
D25: GFNORTEO | E25: =CORREL(RENDIMIENTOS!$G$3:$G$251,RENDIMIENTOS!$B$3:$B$251) -> 0.42661225 | F25: =CORREL(RENDIMIENTOS!$G$3:$G$251,RENDIMIENTOS!$C$3:$C$251) -> 0.17520051 | G25: =CORREL(RENDIMIENTOS!$G$3:$G$251,RENDIMIENTOS!$D$3:$D$251) -> 0.33014356 | H25: =CORREL(RENDIMIENTOS!$G$3:$G$251,RENDIMIENTOS!$E$3:$E$251) -> 0.30886467 | I25: =CORREL(RENDIMIENTOS!$G$3:$G$251,RENDIMIENTOS!$F$3:$F$251) -> 0.36961365 | J25: =CORREL(RENDIMIENTOS!$G$3:$G$251,RENDIMIENTOS!$G$3:$G$251) -> 1 | K25: =CORREL(RENDIMIENTOS!$G$3:$G$251,RENDIMIENTOS!$H$3:$H$251) -> 0.18018494 | L25: =CORREL(RENDIMIENTOS!$G$3:$G$251,RENDIMIENTOS!$I$3:$I$251) -> 0.31676577
D26: TLEVISACPO | E26: =CORREL(RENDIMIENTOS!$H$3:$H$251,RENDIMIENTOS!$B$3:$B$251) -> 0.054672237 | F26: =CORREL(RENDIMIENTOS!$H$3:$H$251,RENDIMIENTOS!$C$3:$C$251) -> 0.066819812 | G26: =CORREL(RENDIMIENTOS!$H$3:$H$251,RENDIMIENTOS!$D$3:$D$251) -> 0.12893387 | H26: =CORREL(RENDIMIENTOS!$H$3:$H$251,RENDIMIENTOS!$E$3:$E$251) -> 0.19203535 | I26: =CORREL(RENDIMIENTOS!$H$3:$H$251,RENDIMIENTOS!$F$3:$F$251) -> 0.19710484 | J26: =CORREL(RENDIMIENTOS!$H$3:$H$251,RENDIMIENTOS!$G$3:$G$251) -> 0.18018494 | K26: =CORREL(RENDIMIENTOS!$H$3:$H$251,RENDIMIENTOS!$H$3:$H$251) -> 1 | L26: =CORREL(RENDIMIENTOS!$H$3:$H$251,RENDIMIENTOS!$I$3:$I$251) -> 0.072346051
D27: WALMEX | E27: =CORREL(RENDIMIENTOS!$I$3:$I$251,RENDIMIENTOS!$B$3:$B$251) -> 0.36268507 | F27: =CORREL(RENDIMIENTOS!$I$3:$I$251,RENDIMIENTOS!$C$3:$C$251) -> 0.23461517 | G27: =CORREL(RENDIMIENTOS!$I$3:$I$251,RENDIMIENTOS!$D$3:$D$251) -> 0.28376971 | H27: =CORREL(RENDIMIENTOS!$I$3:$I$251,RENDIMIENTOS!$E$3:$E$251) -> 0.25690288 | I27: =CORREL(RENDIMIENTOS!$I$3:$I$251,RENDIMIENTOS!$F$3:$F$251) -> 0.23071775 | J27: =CORREL(RENDIMIENTOS!$I$3:$I$251,RENDIMIENTOS!$G$3:$G$251) -> 0.31676577 | K27: =CORREL(RENDIMIENTOS!$I$3:$I$251,RENDIMIENTOS!$H$3:$H$251) -> 0.072346051 | L27: =CORREL(RENDIMIENTOS!$I$3:$I$251,RENDIMIENTOS!$I$3:$I$251) -> 1
D30: VAR COVAR | E30: AC | F30: ALSEA | G30: AMXB | H30: BIMBOA | I30: CEMEXCPO | J30: GFNORTEO | K30: TLEVISACPO | L30: WALMEX
D31: AC | E31: =E$7*$E7*E20 -> 0.00018629054 | F31: =F$7*$E7*F20 -> 6.5053023e-05 | G31: =G$7*$E7*G20 -> 6.6172481e-05 | H31: =H$7*$E7*H20 -> 9.4634619e-05 | I31: =I$7*$E7*I20 -> 8.7932633e-05 | J31: =J$7*$E7*J20 -> 0.0001001975 | K31: =K$7*$E7*K20 -> 1.8736845e-05 | L31: =L$7*$E7*L20 -> 6.8265078e-05
D32: ALSEA | E32: =E$7*$E8*E21 -> 6.5053023e-05 | F32: =F$7*$E8*F21 -> 0.00024393462 | G32: =G$7*$E8*G21 -> 4.5562387e-05 | H32: =H$7*$E8*H21 -> 6.2775318e-05 | I32: =I$7*$E8*I21 -> 4.6304132e-05 | J32: =J$7*$E8*J21 -> 4.7086917e-05 | K32: =K$7*$E8*K21 -> 2.6204519e-05 | L32: =L$7*$E8*L21 -> 5.053198e-05
D33: AMXB | E33: =E$7*$E9*E22 -> 6.6172481e-05 | F33: =F$7*$E9*F22 -> 4.5562387e-05 | G33: =G$7*$E9*G22 -> 0.00023739505 | H33: =H$7*$E9*H22 -> 7.590722e-05 | I33: =I$7*$E9*I22 -> 9.9282864e-05 | J33: =J$7*$E9*J22 -> 8.7531998e-05 | K33: =K$7*$E9*K22 -> 4.988122e-05 | L33: =L$7*$E9*L22 -> 6.0294179e-05
D34: BIMBOA | E34: =E$7*$E10*E23 -> 9.4634619e-05 | F34: =F$7*$E10*F23 -> 6.2775318e-05 | G34: =G$7*$E10*G23 -> 7.590722e-05 | H34: =H$7*$E10*H23 -> 0.00031489434 | I34: =I$7*$E10*I23 -> 9.7270314e-05 | J34: =J$7*$E10*J23 -> 9.431458e-05 | K34: =K$7*$E10*K23 -> 8.556533e-05 | L34: =L$7*$E10*L23 -> 6.2867314e-05
D35: CEMEXCPO | E35: =E$7*$E11*E24 -> 8.7932633e-05 | F35: =F$7*$E11*F24 -> 4.6304132e-05 | G35: =G$7*$E11*G24 -> 9.9282864e-05 | H35: =H$7*$E11*H24 -> 9.7270314e-05 | I35: =I$7*$E11*I24 -> 0.00042635663 | J35: =J$7*$E11*J24 -> 0.00013132962 | K35: =K$7*$E11*K24 -> 0.00010219226 | L35: =L$7*$E11*L24 -> 6.5696318e-05
D36: GFNORTEO | E36: =E$7*$E12*E25 -> 0.0001001975 | F36: =F$7*$E12*F25 -> 4.7086917e-05 | G36: =G$7*$E12*G25 -> 8.7531998e-05 | H36: =H$7*$E12*H25 -> 9.431458e-05 | I36: =I$7*$E12*I25 -> 0.00013132962 | J36: =J$7*$E12*J25 -> 0.00029611223 | K36: =K$7*$E12*K25 -> 7.7853992e-05 | L36: =L$7*$E12*L25 -> 7.51692e-05
D37: TLEVISACPO | E37: =E$7*$E13*E26 -> 1.8736845e-05 | F37: =F$7*$E13*F26 -> 2.6204519e-05 | G37: =G$7*$E13*G26 -> 4.988122e-05 | H37: =H$7*$E13*H26 -> 8.556533e-05 | I37: =I$7*$E13*I26 -> 0.00010219226 | J37: =J$7*$E13*J26 -> 7.7853992e-05 | K37: =K$7*$E13*K26 -> 0.00063047585 | L37: =L$7*$E13*L26 -> 2.5050856e-05
D38: WALMEX | E38: =E$7*$E14*E27 -> 6.8265078e-05 | F38: =F$7*$E14*F27 -> 5.053198e-05 | G38: =G$7*$E14*G27 -> 6.0294179e-05 | H38: =H$7*$E14*H27 -> 6.2867314e-05 | I38: =I$7*$E14*I27 -> 6.5696318e-05 | J38: =J$7*$E14*J27 -> 7.51692e-05 | K38: =K$7*$E14*K27 -> 2.5050856e-05 | L38: =L$7*$E14*L27 -> 0.0001901722
D41: INVERSA DE VAR COVAR (Σ⁻¹) y constantes de la frontera automática
D42: Σ⁻¹ | E42: AC | F42: ALSEA | G42: AMXB | H42: BIMBOA | I42: CEMEXCPO | J42: GFNORTEO | K42: TLEVISACPO | L42: WALMEX
D43: AC | E43: {=MINVERSE(E31:L38)} -> 8124.9303 | F43: -1100.318 | G43: -606.87166 | H43: -1299.2874 | I43: -542.57259 | J43: -1512.6673 | K43: 353.55603 | L43: -1263.4869
D44: ALSEA | E44: -1100.318 | F44: 4683.5372 | G44: -296.56493 | H44: -391.82293 | I44: -20.158395 | J44: 22.126595 | K44: -60.159969 | L44: -619.8223
D45: AMXB | E45: -606.87166 | F45: -296.56493 | G45: 5307.6379 | H45: -465.59005 | I45: -624.15887 | J45: -675.16161 | K45: -112.63368 | L45: -734.89845
D46: BIMBOA | E46: -1299.2874 | F46: -391.82293 | G46: -465.59005 | H46: 4119.2081 | I46: -264.78551 | J46: -368.06807 | K46: -364.68822 | L46: -358.60692
D47: CEMEXCPO | E47: -542.57259 | F47: -20.158395 | G47: -624.15887 | H47: -264.78551 | I47: 2995.6502 | J47: -743.1889 | K47: -282.83182 | L47: -218.3084
D48: GFNORTEO | E48: -1512.6673 | F48: 22.126595 | G48: -675.16161 | H48: -368.06807 | I48: -743.1889 | J48: 4793.881 | K48: -295.24265 | L48: -726.39073
D49: TLEVISACPO | E49: 353.55603 | F49: -60.159969 | G49: -112.63368 | H49: -364.68822 | I49: -282.83182 | J49: -295.24265 | K49: 1717.4718 | L49: 33.509734
D50: WALMEX | E50: -1263.4869 | F50: -619.8223 | G50: -734.89845 | H50: -358.60692 | I50: -218.3084 | J50: -726.39073 | K50: 33.509734 | L50: 6586.3068
D52: Vectores | E52: AC | F52: ALSEA | G52: AMXB | H52: BIMBOA | I52: CEMEXCPO | J52: GFNORTEO | K52: TLEVISACPO | L52: WALMEX
D53: u = Σ⁻¹·1 | E53: =SUM($E43:$L43) -> 2153.2824 | F53: =SUM($E44:$L44) -> 2216.8173 | G53: =SUM($E45:$L45) -> 1791.7587 | H53: =SUM($E46:$L46) -> 606.35897 | I53: =SUM($E47:$L47) -> 299.64569 | J53: =SUM($E48:$L48) -> 495.28828 | K53: =SUM($E49:$L49) -> 988.98125 | L53: =SUM($E50:$L50) -> 2698.3029
...

Sheet Portafolio
B2: PORTAFOLIO DE INVERSIÓN – MÉTODO DE MARKOWITZ
H3: DÍAS HÁBILES / AÑO | I3: 252
H4: R ANUAL IPC | I4: =AVERAGE(RENDIMIENTOS!$J$3:$J$251)*$I$3 -> 0.066894152
H5: MÉTODO FRONTERA (1 ó 2) | I5: 2 | J5: 1 = fórmulas, se actualiza solo (permite ventas en corto) · 2 = Solver, solo largos (valores fijos)
C6: EMPRESA | D6: Wi | E6: R ANUAL | F6: BETA
C7: AC | D7: =INDEX(I$48:I$56,MATCH(MAX($K$19:$K$27),$K$19:$K$27,0)) -> 0 | E7: =AVERAGE(RENDIMIENTOS!$B$3:$B$251)*$I$3 -> 0.036244396 | F7: =SLOPE(RENDIMIENTOS!$B$3:$B$251,RENDIMIENTOS!$J$3:$J$251) -> 0.72415809 | H7: REND PORTAFOLIO | I7: =SUMPRODUCT(D7:D14,E7:E14) -> 0.081787582
C8: ALSEA | D8: =INDEX(J$48:J$56,MATCH(MAX($K$19:$K$27),$K$19:$K$27,0)) -> 0 | E8: =AVERAGE(RENDIMIENTOS!$C$3:$C$251)*$I$3 -> -0.23642949 | F8: =SLOPE(RENDIMIENTOS!$C$3:$C$251,RENDIMIENTOS!$J$3:$J$251) -> 0.54188281
C9: AMXB | D9: =INDEX(K$48:K$56,MATCH(MAX($K$19:$K$27),$K$19:$K$27,0)) -> 0 | E9: =AVERAGE(RENDIMIENTOS!$D$3:$D$251)*$I$3 -> 0.0099813504 | F9: =SLOPE(RENDIMIENTOS!$D$3:$D$251,RENDIMIENTOS!$J$3:$J$251) -> 0.77022271 | H9: VARIANZA PORT | I9: =SUMPRODUCT(MMULT(Matriz!$E$31:$L$38,D7:D14),D7:D14) -> 0.00029611223
C10: BIMBOA | D10: =INDEX(L$48:L$56,MATCH(MAX($K$19:$K$27),$K$19:$K$27,0)) -> 0 | E10: =AVERAGE(RENDIMIENTOS!$E$3:$E$251)*$I$3 -> -0.16738406 | F10: =SLOPE(RENDIMIENTOS!$E$3:$E$251,RENDIMIENTOS!$J$3:$J$251) -> 0.79717027
C11: CEMEXCPO | D11: =INDEX(M$48:M$56,MATCH(MAX($K$19:$K$27),$K$19:$K$27,0)) -> 0 | E11: =AVERAGE(RENDIMIENTOS!$F$3:$F$251)*$I$3 -> 0.057915343 | F11: =SLOPE(RENDIMIENTOS!$F$3:$F$251,RENDIMIENTOS!$J$3:$J$251) -> 1.2887443
C12: GFNORTEO | D12: =INDEX(N$48:N$56,MATCH(MAX($K$19:$K$27),$K$19:$K$27,0)) -> 1 | E12: =AVERAGE(RENDIMIENTOS!$G$3:$G$251)*$I$3 -> 0.081787582 | F12: =SLOPE(RENDIMIENTOS!$G$3:$G$251,RENDIMIENTOS!$J$3:$J$251) -> 1.1449889 | H12: SD PORTAFOLIO | I12: =SQRT(I9) -> 0.017207912
C13: TLEVISACPO | D13: =INDEX(O$48:O$56,MATCH(MAX($K$19:$K$27),$K$19:$K$27,0)) -> 0 | E13: =AVERAGE(RENDIMIENTOS!$H$3:$H$251)*$I$3 -> -0.13375246 | F13: =SLOPE(RENDIMIENTOS!$H$3:$H$251,RENDIMIENTOS!$J$3:$J$251) -> 0.52588603
C14: WALMEX | D14: =INDEX(P$48:P$56,MATCH(MAX($K$19:$K$27),$K$19:$K$27,0)) -> 0 | E14: =AVERAGE(RENDIMIENTOS!$I$3:$I$251)*$I$3 -> -0.17028009 | F14: =SLOPE(RENDIMIENTOS!$I$3:$I$251,RENDIMIENTOS!$J$3:$J$251) -> 0.55742145 | H14: TLR [RF] | I14: 0.065 | J14: ← Cetes 6.50% (dato que me diste)
C15: suma | D15: =SUM(D7:D14) -> 1 | E15: BETA P | F15: =SUMPRODUCT(D7:D14,F7:F14) -> 1.1449889
C16: Wi = portafolio de mayor Sharpe de la frontera (fórmula). Puedes escribir tus propios pesos encima. | H16: I SHARPE | I16: =+(I7-I14)/I12 -> 0.97557346
H18: PORTAFOLIO DE MARKOWITZ | I18: DESVIACIÓN ESTANDAR | J18: RENDIMIENTO ESPERADO | K18: ÍNDICE DE SHARPE | L18: BETA DEL PORTAFOLIO
H19: 1 | I19: =SQRT(SUMPRODUCT(MMULT($I48:$P48,Matriz!$E$31:$L$38),$I48:$P48)) -> 0.013429236 | J19: =SUMPRODUCT($I48:$P48,$I$46:$P$46) -> 0.064999995 | K19: =(J19-$I$14)/I19 -> -3.6267625e-07 | L19: =SUMPRODUCT($I48:$P48,$I$47:$P$47) -> 1.048137
H20: 2 | I20: =SQRT(SUMPRODUCT(MMULT($I49:$P49,Matriz!$E$31:$L$38),$I49:$P49)) -> 0.013760394 | J20: =SUMPRODUCT($I49:$P49,$I$46:$P$46) -> 0.067098449 | K20: =(J20-$I$14)/I20 -> 0.15249918 | L20: =SUMPRODUCT($I49:$P49,$I$47:$P$47) -> 1.0677364
H21: 3 | I21: =SQRT(SUMPRODUCT(MMULT($I50:$P50,Matriz!$E$31:$L$38),$I50:$P50)) -> 0.014126201 | J21: =SUMPRODUCT($I50:$P50,$I$46:$P$46) -> 0.069196881 | K21: =(J21-$I$14)/I21 -> 0.29709905 | L21: =SUMPRODUCT($I50:$P50,$I$47:$P$47) -> 1.0873353
H22: 4 | I22: =SQRT(SUMPRODUCT(MMULT($I51:$P51,Matriz!$E$31:$L$38),$I51:$P51)) -> 0.014524046 | J22: =SUMPRODUCT($I51:$P51,$I$46:$P$46) -> 0.071295335 | K22: =(J22-$I$14)/I22 -> 0.43344219 | L22: =SUMPRODUCT($I51:$P51,$I$47:$P$47) -> 1.1069346
H23: 5 | I23: =SQRT(SUMPRODUCT(MMULT($I52:$P52,Matriz!$E$31:$L$38),$I52:$P52)) -> 0.014951358 | J23: =SUMPRODUCT($I52:$P52,$I$46:$P$46) -> 0.07339373 | K23: =(J23-$I$14)/I23 -> 0.56140253 | L23: =SUMPRODUCT($I52:$P52,$I$47:$P$47) -> 1.1265327
H24: 6 | I24: =SQRT(SUMPRODUCT(MMULT($I53:$P53,Matriz!$E$31:$L$38),$I53:$P53)) -> 0.015405713 | J24: =SUMPRODUCT($I53:$P53,$I$46:$P$46) -> 0.07549222 | K24: =(J24-$I$14)/I24 -> 0.68106033 | L24: =SUMPRODUCT($I53:$P53,$I$47:$P$47) -> 1.1461328
H25: 7 | I25: =SQRT(SUMPRODUCT(MMULT($I54:$P54,Matriz!$E$31:$L$38),$I54:$P54)) -> 0.015884768 | J25: =SUMPRODUCT($I54:$P54,$I$46:$P$46) -> 0.077590674 | K25: =(J25-$I$14)/I25 -> 0.79262562 | L25: =SUMPRODUCT($I54:$P54,$I$47:$P$47) -> 1.1657322
H26: 8 | I26: =SQRT(SUMPRODUCT(MMULT($I55:$P55,Matriz!$E$31:$L$38),$I55:$P55)) -> 0.016452823 | J26: =SUMPRODUCT($I55:$P55,$I$46:$P$46) -> 0.079689141 | K26: =(J26-$I$14)/I26 -> 0.89280367 | L26: =SUMPRODUCT($I55:$P55,$I$47:$P$47) -> 1.1576254
H27: 9 | I27: =SQRT(SUMPRODUCT(MMULT($I56:$P56,Matriz!$E$31:$L$38),$I56:$P56)) -> 0.017207912 | J27: =SUMPRODUCT($I56:$P56,$I$46:$P$46) -> 0.081787582 | K27: =(J27-$I$14)/I27 -> 0.97557346 | L27: =SUMPRODUCT($I56:$P56,$I$47:$P$47) -> 1.1449889
H43: PESOS (Wi) QUE USA LA FRONTERA = según el método elegido en I5
H45: PORTAFOLIO | I45: AC | J45: ALSEA | K45: AMXB | L45: BIMBOA | M45: CEMEXCPO | N45: GFNORTEO | O45: TLEVISACPO | P45: WALMEX | Q45: SUMA | R45: R OBJETIVO
H46: R ANUAL → | I46: =$E$7 -> 0.036244396 | J46: =$E$8 -> -0.23642949 | K46: =$E$9 -> 0.0099813504 | L46: =$E$10 -> -0.16738406 | M46: =$E$11 -> 0.057915343 | N46: =$E$12 -> 0.081787582 | O46: =$E$13 -> -0.13375246 | P46: =$E$14 -> -0.17028009
H47: BETA → | I47: =$F$7 -> 0.72415809 | J47: =$F$8 -> 0.54188281 | K47: =$F$9 -> 0.77022271 | L47: =$F$10 -> 0.79717027 | M47: =$F$11 -> 1.2887443 | N47: =$F$12 -> 1.1449889 | O47: =$F$13 -> 0.52588603 | P47: =$F$14 -> 0.55742145
H48: 1 | I48: =IF($I$5=1,I61,I74) -> 0.284777 | J48: =IF($I$5=1,J61,J74) -> 0 | K48: =IF($I$5=1,K61,K74) -> 0 | L48: =IF($I$5=1,L61,L74) -> 0 | M48: =IF($I$5=1,M61,M74) -> 0.159932 | N48: =IF($I$5=1,N61,N74) -> 0.555291 | O48: =IF($I$5=1,O61,O74) -> 0 | P48: =IF($I$5=1,P61,P74) -> 0 | Q48: =SUM(I48:P48) -> 1 | R48: =$I$14+(MAX($E$7:$E$14)-$I$14)*0/8 -> 0.065
H49: 2 | I49: =IF($I$5=1,I62,I75) -> 0.2384 | J49: =IF($I$5=1,J62,J75) -> 0 | K49: =IF($I$5=1,K62,K75) -> 0 | L49: =IF($I$5=1,L62,L75) -> 0 | M49: =IF($I$5=1,M62,M75) -> 0.160506 | N49: =IF($I$5=1,N62,N75) -> 0.601094 | O49: =IF($I$5=1,O62,O75) -> 0 | P49: =IF($I$5=1,P62,P75) -> 0 | Q49: =SUM(I49:P49) -> 1 | R49: =$I$14+(MAX($E$7:$E$14)-$I$14)*1/8 -> 0.067098448
H50: 3 | I50: =IF($I$5=1,I63,I76) -> 0.192024 | J50: =IF($I$5=1,J63,J76) -> 0 | K50: =IF($I$5=1,K63,K76) -> 0 | L50: =IF($I$5=1,L63,L76) -> 0 | M50: =IF($I$5=1,M63,M76) -> 0.161079 | N50: =IF($I$5=1,N63,N76) -> 0.646897 | O50: =IF($I$5=1,O63,O76) -> 0 | P50: =IF($I$5=1,P63,P76) -> 0 | Q50: =SUM(I50:P50) -> 1 | R50: =$I$14+(MAX($E$7:$E$14)-$I$14)*2/8 -> 0.069196896
H51: 4 | I51: =IF($I$5=1,I64,I77) -> 0.145647 | J51: =IF($I$5=1,J64,J77) -> 0 | K51: =IF($I$5=1,K64,K77) -> 0 | L51: =IF($I$5=1,L64,L77) -> 0 | M51: =IF($I$5=1,M64,M77) -> 0.161653 | N51: =IF($I$5=1,N64,N77) -> 0.6927 | O51: =IF($I$5=1,O64,O77) -> 0 | P51: =IF($I$5=1,P64,P77) -> 0 | Q51: =SUM(I51:P51) -> 1 | R51: =$I$14+(MAX($E$7:$E$14)-$I$14)*3/8 -> 0.071295343
H52: 5 | I52: =IF($I$5=1,I65,I78) -> 0.09927 | J52: =IF($I$5=1,J65,J78) -> 0 | K52: =IF($I$5=1,K65,K78) -> 0 | L52: =IF($I$5=1,L65,L78) -> 0 | M52: =IF($I$5=1,M65,M78) -> 0.162226 | N52: =IF($I$5=1,N65,N78) -> 0.738503 | O52: =IF($I$5=1,O65,O78) -> 0 | P52: =IF($I$5=1,P65,P78) -> 0 | Q52: =SUM(I52:P52) -> 0.999999 | R52: =$I$14+(MAX($E$7:$E$14)-$I$14)*4/8 -> 0.073393791
H53: 6 | I53: =IF($I$5=1,I66,I79) -> 0.052894 | J53: =IF($I$5=1,J66,J79) -> 0 | K53: =IF($I$5=1,K66,K79) -> 0 | L53: =IF($I$5=1,L66,L79) -> 0 | M53: =IF($I$5=1,M66,M79) -> 0.1628 | N53: =IF($I$5=1,N66,N79) -> 0.784306 | O53: =IF($I$5=1,O66,O79) -> 0 | P53: =IF($I$5=1,P66,P79) -> 0 | Q53: =SUM(I53:P53) -> 1 | R53: =$I$14+(MAX($E$7:$E$14)-$I$14)*5/8 -> 0.075492239
H54: 7 | I54: =IF($I$5=1,I67,I80) -> 0.006517 | J54: =IF($I$5=1,J67,J80) -> 0 | K54: =IF($I$5=1,K67,K80) -> 0 | L54: =IF($I$5=1,L67,L80) -> 0 | M54: =IF($I$5=1,M67,M80) -> 0.163374 | N54: =IF($I$5=1,N67,N80) -> 0.830109 | O54: =IF($I$5=1,O67,O80) -> 0 | P54: =IF($I$5=1,P67,P80) -> 0 | Q54: =SUM(I54:P54) -> 1 | R54: =$I$14+(MAX($E$7:$E$14)-$I$14)*6/8 -> 0.077590687
H55: 8 | I55: =IF($I$5=1,I68,I81) -> 0 | J55: =IF($I$5=1,J68,J81) -> 0 | K55: =IF($I$5=1,K68,K81) -> 0 | L55: =IF($I$5=1,L68,L81) -> 0 | M55: =IF($I$5=1,M68,M81) -> 0.087903 | N55: =IF($I$5=1,N68,N81) -> 0.912097 | O55: =IF($I$5=1,O68,O81) -> 0 | P55: =IF($I$5=1,P68,P81) -> 0 | Q55: =SUM(I55:P55) -> 1 | R55: =$I$14+(MAX($E$7:$E$14)-$I$14)*7/8 -> 0.079689134
H56: 9 | I56: =IF($I$5=1,I69,I82) -> 0 | J56: =IF($I$5=1,J69,J82) -> 0 | K56: =IF($I$5=1,K69,K82) -> 0 | L56: =IF($I$5=1,L69,L82) -> 0 | M56: =IF($I$5=1,M69,M82) -> 0 | N56: =IF($I$5=1,N69,N82) -> 1 | O56: =IF($I$5=1,O69,O82) -> 0 | P56: =IF($I$5=1,P69,P82) -> 0 | Q56: =SUM(I56:P56) -> 1 | R56: =$I$14+(MAX($E$7:$E$14)-$I$14)*8/8 -> 0.081787582
H59: MÉTODO 1 – FRONTERA CON FÓRMULAS (Merton): w = [ (c − b·m)·u + (a·m − b)·v ] / d · permite ventas en corto
H60: PORTAFOLIO | I60: AC | J60: ALSEA | K60: AMXB | L60: BIMBOA | M60: CEMEXCPO | N60: GFNORTEO | O60: TLEVISACPO | P60: WALMEX | Q60: SUMA | R60: R OBJETIVO
...
