Workbook

Sheet Tabla de mortalidad
B1: Tabla de mortalidad
B2: Cuadro: Tabla de mortalidad de la generación mexicana de 1970, ambos sexos (CONAPO)
B3: x | C3: qx | D3: lx | E3: dx | F3: Lx | G3: Tx | H3: ex | K3: Nota técnica (qx)
C4: Probabilidad de muerte: defunciones xi/PI | D4: Supervivientes a una edad exacto | E4: Defunciones xi | F4: Años vividos entre aniversario | G4: Años vividos acumulados: Años que quedan por vivir | H4: La media de vida una generación hasta su extinción | K4: q(x): Probabilidad de muerte
B5: 0 | C5: =L9 -> 0.075645678 | D5: 100000 | E5: =ROUND(D5*C5,0) -> 7565 | F5: =ROUND(D6+(E5/2),0) -> 96218 | G5: =SUM(F5:F$105) -> 7093053 | H5: =G5/D5 -> 70.93053
B6: 1 | C6: ='Datos usados'!C6/('Datos usados'!D6+'Datos usados'!C6/2) -> 0.015049121 | D6: =D5-E5 -> 92435 | E6: =ROUND(D6*C6,0) -> 1391 | F6: =ROUND(D7+(E6/2),0) -> 91740 | G6: =SUM(F6:F$105) -> 6996835 | H6: =G6/D6 -> 75.69465 | K6: Nacimientos | L6: =INDEX('Nacimientos y e0'!B6:B106,MATCH(L16,'Nacimientos y e0'!A6:A106,0)) -> 2243380
B7: 2 | C7: ='Datos usados'!C7/('Datos usados'!D7+'Datos usados'!C7/2) -> 0.0069058968 | D7: =D6-E6 -> 91044 | E7: =ROUND(D7*C7,0) -> 629 | F7: =ROUND(D8+(E7/2),0) -> 90730 | G7: =SUM(F7:F$105) -> 6905095 | H7: =G7/D7 -> 75.843493 | K7: Defunciones (menores de 1 año) | L7: ='Datos usados'!C5 -> 169702
B8: 3 | C8: ='Datos usados'!C8/('Datos usados'!D8+'Datos usados'!C8/2) -> 0.0038794982 | D8: =D7-E7 -> 90415 | E8: =ROUND(D8*C8,0) -> 351 | F8: =ROUND(D9+(E8/2),0) -> 90240 | G8: =SUM(F8:F$105) -> 6814365 | H8: =G8/D8 -> 75.367638
B9: 4 | C9: ='Datos usados'!C9/('Datos usados'!D9+'Datos usados'!C9/2) -> 0.002377421 | D9: =D8-E8 -> 90064 | E9: =ROUND(D9*C9,0) -> 214 | F9: =ROUND(D10+(E9/2),0) -> 89957 | G9: =SUM(F9:F$105) -> 6724125 | H9: =G9/D9 -> 74.659409 | K9: q(x) | L9: =L7/L6 -> 0.075645678
B10: 5 | C10: ='Datos usados'!C10/('Datos usados'!D10+'Datos usados'!C10/2) -> 0.0015965009 | D10: =D9-E9 -> 89850 | E10: =ROUND(D10*C10,0) -> 143 | F10: =ROUND(D11+(E10/2),0) -> 89779 | G10: =SUM(F10:F$105) -> 6634168 | H10: =G10/D10 -> 73.836038 | K10: q(0) = defunciones de menores de 1 año / nacimientos
B11: 6 | C11: ='Datos usados'!C11/('Datos usados'!D11+'Datos usados'!C11/2) -> 0.0013220866 | D11: =D10-E10 -> 89707 | E11: =ROUND(D11*C11,0) -> 119 | F11: =ROUND(D12+(E11/2),0) -> 89648 | G11: =SUM(F11:F$105) -> 6544389 | H11: =G11/D11 -> 72.952936 | K11: q(x), x = 1…99 = defunciones / (población a mitad de año + defunciones/2)
B12: 7 | C12: ='Datos usados'!C12/('Datos usados'!D12+'Datos usados'!C12/2) -> 0.0011172994 | D12: =D11-E11 -> 89588 | E12: =ROUND(D12*C12,0) -> 100 | F12: =ROUND(D13+(E12/2),0) -> 89538 | G12: =SUM(F12:F$105) -> 6454741 | H12: =G12/D12 -> 72.04917 | K12: Lx | L12: Los que han sobrevivido a una determinada edad
B13: 8 | C13: ='Datos usados'!C13/('Datos usados'!D13+'Datos usados'!C13/2) -> 0.000856508 | D13: =D12-E12 -> 89488 | E13: =ROUND(D13*C13,0) -> 77 | F13: =ROUND(D14+(E13/2),0) -> 89450 | G13: =SUM(F13:F$105) -> 6365203 | H13: =G13/D13 -> 71.129123
B14: 9 | C14: ='Datos usados'!C14/('Datos usados'!D14+'Datos usados'!C14/2) -> 0.00080468055 | D14: =D13-E13 -> 89411 | E14: =ROUND(D14*C14,0) -> 72 | F14: =ROUND(D15+(E14/2),0) -> 89375 | G14: =SUM(F14:F$105) -> 6275753 | H14: =G14/D14 -> 70.189943 | K14: Lx= lx+1+(dx/2)
B15: 10 | C15: ='Datos usados'!C15/('Datos usados'!D15+'Datos usados'!C15/2) -> 0.00076480879 | D15: =D14-E14 -> 89339 | E15: =ROUND(D15*C15,0) -> 68 | F15: =ROUND(D16+(E15/2),0) -> 89305 | G15: =SUM(F15:F$105) -> 6186378 | H15: =G15/D15 -> 69.246108
B16: 11 | C16: ='Datos usados'!C16/('Datos usados'!D16+'Datos usados'!C16/2) -> 0.00075644944 | D16: =D15-E15 -> 89271 | E16: =ROUND(D16*C16,0) -> 68 | F16: =ROUND(D17+(E16/2),0) -> 89237 | G16: =SUM(F16:F$105) -> 6097073 | H16: =G16/D16 -> 68.298473 | K16: Generación (año de nacimiento) | L16: 1970
B17: 12 | C17: ='Datos usados'!C17/('Datos usados'!D17+'Datos usados'!C17/2) -> 0.00075119037 | D17: =D16-E16 -> 89203 | E17: =ROUND(D17*C17,0) -> 67 | F17: =ROUND(D18+(E17/2),0) -> 89170 | G17: =SUM(F17:F$105) -> 6007836 | H17: =G17/D17 -> 67.350156 | K17: Año calendario de la edad x = generación + x
B18: 13 | C18: ='Datos usados'!C18/('Datos usados'!D18+'Datos usados'!C18/2) -> 0.00073098433 | D18: =D17-E17 -> 89136 | E18: =ROUND(D18*C18,0) -> 65 | F18: =ROUND(D19+(E18/2),0) -> 89104 | G18: =SUM(F18:F$105) -> 5918666 | H18: =G18/D18 -> 66.400399
B19: 14 | C19: ='Datos usados'!C19/('Datos usados'!D19+'Datos usados'!C19/2) -> 0.00079344488 | D19: =D18-E18 -> 89071 | E19: =ROUND(D19*C19,0) -> 71 | F19: =ROUND(D20+(E19/2),0) -> 89036 | G19: =SUM(F19:F$105) -> 5829562 | H19: =G19/D19 -> 65.448485 | K19: Tx = Lx + L(x+1) + … + L100
B20: 15 | C20: ='Datos usados'!C20/('Datos usados'!D20+'Datos usados'!C20/2) -> 0.00088307112 | D20: =D19-E19 -> 89000 | E20: =ROUND(D20*C20,0) -> 79 | F20: =ROUND(D21+(E20/2),0) -> 88961 | G20: =SUM(F20:F$105) -> 5740526 | H20: =G20/D20 -> 64.500292 | K20: ex = Tx / lx
B21: 16 | C21: ='Datos usados'!C21/('Datos usados'!D21+'Datos usados'!C21/2) -> 0.00093989283 | D21: =D20-E20 -> 88921 | E21: =ROUND(D21*C21,0) -> 84 | F21: =ROUND(D22+(E21/2),0) -> 88879 | G21: =SUM(F21:F$105) -> 5651565 | H21: =G21/D21 -> 63.557146 | K21: Edad 100 = grupo abierto (100 y más): qx = 1
B22: 17 | C22: ='Datos usados'!C22/('Datos usados'!D22+'Datos usados'!C22/2) -> 0.0010033449 | D22: =D21-E21 -> 88837 | E22: =ROUND(D22*C22,0) -> 89 | F22: =ROUND(D23+(E22/2),0) -> 88793 | G22: =SUM(F22:F$105) -> 5562686 | H22: =G22/D22 -> 62.61677
B23: 18 | C23: ='Datos usados'!C23/('Datos usados'!D23+'Datos usados'!C23/2) -> 0.0010878458 | D23: =D22-E22 -> 88748 | E23: =ROUND(D23*C23,0) -> 97 | F23: =ROUND(D24+(E23/2),0) -> 88700 | G23: =SUM(F23:F$105) -> 5473893 | H23: =G23/D23 -> 61.679058 | K23: Control: suma de dx − radix | L23: =SUM(E5:E105)-D5 -> 0
B24: 19 | C24: ='Datos usados'!C24/('Datos usados'!D24+'Datos usados'!C24/2) -> 0.0011461597 | D24: =D23-E23 -> 88651 | E24: =ROUND(D24*C24,0) -> 102 | F24: =ROUND(D25+(E24/2),0) -> 88600 | G24: =SUM(F24:F$105) -> 5385193 | H24: =G24/D24 -> 60.745993
B25: 20 | C25: ='Datos usados'!C25/('Datos usados'!D25+'Datos usados'!C25/2) -> 0.0011995027 | D25: =D24-E24 -> 88549 | E25: =ROUND(D25*C25,0) -> 106 | F25: =ROUND(D26+(E25/2),0) -> 88496 | G25: =SUM(F25:F$105) -> 5296593 | H25: =G25/D25 -> 59.81539 | K25: Fuente: CONAPO, Conciliación demográfica de México 1950-2019 y Proyecciones de la población 2020-2070.
B26: 21 | C26: ='Datos usados'!C26/('Datos usados'!D26+'Datos usados'!C26/2) -> 0.0012720572 | D26: =D25-E25 -> 88443 | E26: =ROUND(D26*C26,0) -> 113 | F26: =ROUND(D27+(E26/2),0) -> 88387 | G26: =SUM(F26:F$105) -> 5208097 | H26: =G26/D26 -> 58.886481 | K26: Datos y bases usadas: hojas siguientes y carpeta bases_de_datos_CONAPO/.
B27: 22 | C27: ='Datos usados'!C27/('Datos usados'!D27+'Datos usados'!C27/2) -> 0.001339933 | D27: =D26-E26 -> 88330 | E27: =ROUND(D27*C27,0) -> 118 | F27: =ROUND(D28+(E27/2),0) -> 88271 | G27: =SUM(F27:F$105) -> 5119710 | H27: =G27/D27 -> 57.961168
B28: 23 | C28: ='Datos usados'!C28/('Datos usados'!D28+'Datos usados'!C28/2) -> 0.0013763753 | D28: =D27-E27 -> 88212 | E28: =ROUND(D28*C28,0) -> 121 | F28: =ROUND(D29+(E28/2),0) -> 88152 | G28: =SUM(F28:F$105) -> 5031439 | H28: =G28/D28 -> 57.038033
B29: 24 | C29: ='Datos usados'!C29/('Datos usados'!D29+'Datos usados'!C29/2) -> 0.0014491257 | D29: =D28-E28 -> 88091 | E29: =ROUND(D29*C29,0) -> 128 | F29: =ROUND(D30+(E29/2),0) -> 88027 | G29: =SUM(F29:F$105) -> 4943287 | H29: =G29/D29 -> 56.115687
B30: 25 | C30: ='Datos usados'!C30/('Datos usados'!D30+'Datos usados'!C30/2) -> 0.001503287 | D30: =D29-E29 -> 87963 | E30: =ROUND(D30*C30,0) -> 132 | F30: =ROUND(D31+(E30/2),0) -> 87897 | G30: =SUM(F30:F$105) -> 4855260 | H30: =G30/D30 -> 55.196617
B31: 26 | C31: ='Datos usados'!C31/('Datos usados'!D31+'Datos usados'!C31/2) -> 0.0015208322 | D31: =D30-E30 -> 87831 | E31: =ROUND(D31*C31,0) -> 134 | F31: =ROUND(D32+(E31/2),0) -> 87764 | G31: =SUM(F31:F$105) -> 4767363 | H31: =G31/D31 -> 54.27882
B32: 27 | C32: ='Datos usados'!C32/('Datos usados'!D32+'Datos usados'!C32/2) -> 0.0015713206 | D32: =D31-E31 -> 87697 | E32: =ROUND(D32*C32,0) -> 138 | F32: =ROUND(D33+(E32/2),0) -> 87628 | G32: =SUM(F32:F$105) -> 4679599 | H32: =G32/D32 -> 53.360993
B33: 28 | C33: ='Datos usados'!C33/('Datos usados'!D33+'Datos usados'!C33/2) -> 0.0016389313 | D33: =D32-E32 -> 87559 | E33: =ROUND(D33*C33,0) -> 144 | F33: =ROUND(D34+(E33/2),0) -> 87487 | G33: =SUM(F33:F$105) -> 4591971 | H33: =G33/D33 -> 52.444306
B34: 29 | C34: ='Datos usados'!C34/('Datos usados'!D34+'Datos usados'!C34/2) -> 0.0016084774 | D34: =D33-E33 -> 87415 | E34: =ROUND(D34*C34,0) -> 141 | F34: =ROUND(D35+(E34/2),0) -> 87345 | G34: =SUM(F34:F$105) -> 4504484 | H34: =G34/D34 -> 51.529875
B35: 30 | C35: ='Datos usados'!C35/('Datos usados'!D35+'Datos usados'!C35/2) -> 0.0016184375 | D35: =D34-E34 -> 87274 | E35: =ROUND(D35*C35,0) -> 141 | F35: =ROUND(D36+(E35/2),0) -> 87204 | G35: =SUM(F35:F$105) -> 4417139 | H35: =G35/D35 -> 50.612313
B36: 31 | C36: ='Datos usados'!C36/('Datos usados'!D36+'Datos usados'!C36/2) -> 0.001616369 | D36: =D35-E35 -> 87133 | E36: =ROUND(D36*C36,0) -> 141 | F36: =ROUND(D37+(E36/2),0) -> 87063 | G36: =SUM(F36:F$105) -> 4329935 | H36: =G36/D36 -> 49.6934
B37: 32 | C37: ='Datos usados'!C37/('Datos usados'!D37+'Datos usados'!C37/2) -> 0.001669061 | D37: =D36-E36 -> 86992 | E37: =ROUND(D37*C37,0) -> 145 | F37: =ROUND(D38+(E37/2),0) -> 86920 | G37: =SUM(F37:F$105) -> 4242872 | H37: =G37/D37 -> 48.773129
B38: 33 | C38: ='Datos usados'!C38/('Datos usados'!D38+'Datos usados'!C38/2) -> 0.0017504079 | D38: =D37-E37 -> 86847 | E38: =ROUND(D38*C38,0) -> 152 | F38: =ROUND(D39+(E38/2),0) -> 86771 | G38: =SUM(F38:F$105) -> 4155952 | H38: =G38/D38 -> 47.85372
... B104: 99 | C104: ='Datos usados'!C104/('Datos usados'!D104+'Datos usados'!C104/2) -> 0.16944034 | D104: =D103-E103 -> 9287 | E104: =ROUND(D104*C104,0) -> 1574 | F104: =ROUND(D105+(E104/2),0) -> 8500 | G104: =SUM(F104:F$105) -> 12357 | H104: =G104/D104 -> 1.3305696
B105: 100 | C105: 1 | D105: =D104-E104 -> 7713 | E105: =ROUND(D105*C105,0) -> 7713 | F105: =ROUND(E105/2,0) -> 3857 | G105: =SUM(F105:F$105) -> 3857 | H105: =G105/D105 -> 0.50006483

Sheet Datos usados
A1: Datos usados en la tabla: generación mexicana de 1970, ambos sexos
A2: Para cada edad x se toman las defunciones y la población a mitad de año del año g + x (hojas Defunciones y Población). Verde = vínculo a otra hoja; negro = fórmula.
A4: Edad x | B4: Año calendario (g + x) | C4: Defunciones de la edad x | D4: Población a mitad de año de la edad x | E4: q(x) = D / (P + D/2)
A5: 0 | B5: ='Tabla de mortalidad'!$L$16+A5 -> 1970 | C5: =INDEX(Defunciones!$B$6:$CX$115,$A5+1,MATCH($B5,Defunciones!$B$5:$CX$5,0)) -> 169702 | D5: =INDEX(Población!$B$6:$CX$115,$A5+1,MATCH($B5,Población!$B$5:$CX$5,0)) -> 2101069 | E5: ='Tabla de mortalidad'!C5 -> 0.075645678
A6: 1 | B6: ='Tabla de mortalidad'!$L$16+A6 -> 1971 | C6: =INDEX(Defunciones!$B$6:$CX$115,$A6+1,MATCH($B6,Defunciones!$B$5:$CX$5,0)) -> 30705 | D6: =INDEX(Población!$B$6:$CX$115,$A6+1,MATCH($B6,Población!$B$5:$CX$5,0)) -> 2024966 | E6: =C6/(D6+C6/2) -> 0.015049121
A7: 2 | B7: ='Tabla de mortalidad'!$L$16+A7 -> 1972 | C7: =INDEX(Defunciones!$B$6:$CX$115,$A7+1,MATCH($B7,Defunciones!$B$5:$CX$5,0)) -> 13842 | D7: =INDEX(Población!$B$6:$CX$115,$A7+1,MATCH($B7,Población!$B$5:$CX$5,0)) -> 1997453 | E7: =C7/(D7+C7/2) -> 0.0069058968
A8: 3 | B8: ='Tabla de mortalidad'!$L$16+A8 -> 1973 | C8: =INDEX(Defunciones!$B$6:$CX$115,$A8+1,MATCH($B8,Defunciones!$B$5:$CX$5,0)) -> 7697 | D8: =INDEX(Población!$B$6:$CX$115,$A8+1,MATCH($B8,Población!$B$5:$CX$5,0)) -> 1980171 | E8: =C8/(D8+C8/2) -> 0.0038794982
A9: 4 | B9: ='Tabla de mortalidad'!$L$16+A9 -> 1974 | C9: =INDEX(Defunciones!$B$6:$CX$115,$A9+1,MATCH($B9,Defunciones!$B$5:$CX$5,0)) -> 4683 | D9: =INDEX(Población!$B$6:$CX$115,$A9+1,MATCH($B9,Población!$B$5:$CX$5,0)) -> 1967440 | E9: =C9/(D9+C9/2) -> 0.002377421
A10: 5 | B10: ='Tabla de mortalidad'!$L$16+A10 -> 1975 | C10: =INDEX(Defunciones!$B$6:$CX$115,$A10+1,MATCH($B10,Defunciones!$B$5:$CX$5,0)) -> 3127 | D10: =INDEX(Población!$B$6:$CX$115,$A10+1,MATCH($B10,Población!$B$5:$CX$5,0)) -> 1957095 | E10: =C10/(D10+C10/2) -> 0.0015965009
A11: 6 | B11: ='Tabla de mortalidad'!$L$16+A11 -> 1976 | C11: =INDEX(Defunciones!$B$6:$CX$115,$A11+1,MATCH($B11,Defunciones!$B$5:$CX$5,0)) -> 2577 | D11: =INDEX(Población!$B$6:$CX$115,$A11+1,MATCH($B11,Población!$B$5:$CX$5,0)) -> 1947903 | E11: =C11/(D11+C11/2) -> 0.0013220866
A12: 7 | B12: ='Tabla de mortalidad'!$L$16+A12 -> 1977 | C12: =INDEX(Defunciones!$B$6:$CX$115,$A12+1,MATCH($B12,Defunciones!$B$5:$CX$5,0)) -> 2168 | D12: =INDEX(Población!$B$6:$CX$115,$A12+1,MATCH($B12,Población!$B$5:$CX$5,0)) -> 1939309 | E12: =C12/(D12+C12/2) -> 0.0011172994
A13: 8 | B13: ='Tabla de mortalidad'!$L$16+A13 -> 1978 | C13: =INDEX(Defunciones!$B$6:$CX$115,$A13+1,MATCH($B13,Defunciones!$B$5:$CX$5,0)) -> 1655 | D13: =INDEX(Población!$B$6:$CX$115,$A13+1,MATCH($B13,Población!$B$5:$CX$5,0)) -> 1931437 | E13: =C13/(D13+C13/2) -> 0.000856508
A14: 9 | B14: ='Tabla de mortalidad'!$L$16+A14 -> 1979 | C14: =INDEX(Defunciones!$B$6:$CX$115,$A14+1,MATCH($B14,Defunciones!$B$5:$CX$5,0)) -> 1549 | D14: =INDEX(Población!$B$6:$CX$115,$A14+1,MATCH($B14,Población!$B$5:$CX$5,0)) -> 1924213 | E14: =C14/(D14+C14/2) -> 0.00080468055
A15: 10 | B15: ='Tabla de mortalidad'!$L$16+A15 -> 1980 | C15: =INDEX(Defunciones!$B$6:$CX$115,$A15+1,MATCH($B15,Defunciones!$B$5:$CX$5,0)) -> 1467 | D15: =INDEX(Población!$B$6:$CX$115,$A15+1,MATCH($B15,Población!$B$5:$CX$5,0)) -> 1917393 | E15: =C15/(D15+C15/2) -> 0.00076480879
A16: 11 | B16: ='Tabla de mortalidad'!$L$16+A16 -> 1981 | C16: =INDEX(Defunciones!$B$6:$CX$115,$A16+1,MATCH($B16,Defunciones!$B$5:$CX$5,0)) -> 1446 | D16: =INDEX(Población!$B$6:$CX$115,$A16+1,MATCH($B16,Población!$B$5:$CX$5,0)) -> 1910839 | E16: =C16/(D16+C16/2) -> 0.00075644944
A17: 12 | B17: ='Tabla de mortalidad'!$L$16+A17 -> 1982 | C17: =INDEX(Defunciones!$B$6:$CX$115,$A17+1,MATCH($B17,Defunciones!$B$5:$CX$5,0)) -> 1431 | D17: =INDEX(Población!$B$6:$CX$115,$A17+1,MATCH($B17,Población!$B$5:$CX$5,0)) -> 1904261 | E17: =C17/(D17+C17/2) -> 0.00075119037
... A104: 99 | B104: ='Tabla de mortalidad'!$L$16+A104 -> 2069 | C104: =INDEX(Defunciones!$B$6:$CX$115,$A104+1,MATCH($B104,Defunciones!$B$5:$CX$5,0)) -> 28503 | D104: =INDEX(Población!$B$6:$CX$115,$A104+1,MATCH($B104,Población!$B$5:$CX$5,0)) -> 153967 | E104: =C104/(D104+C104/2) -> 0.16944034
A105: 100 | B105: ='Tabla de mortalidad'!$L$16+A105 -> 2070 | C105: grupo abierto: qx = 1
A108: q(0) usa nacimientos (hoja Nacimientos y e0): q(0) = defunciones de menores de 1 año / nacimientos.

Sheet Defunciones
A1: Defunciones por edad y año, México (1970-2070)
A2: Fuente: CONAPO, 01_Defunciones_1950_2070.csv (carpeta bases_de_datos_CONAPO/).
A3: Cada celda = suma de los 32 estados y de hombres + mujeres. Azul = dato de CONAPO. La tabla usa la diagonal edad x, año g + x.
A5: Edad \ Año | B5: 1970 | C5: 1971 | D5: 1972 | E5: 1973 | F5: 1974 | G5: 1975 | H5: 1976 | I5: 1977 | J5: 1978 | K5: 1979 | L5: 1980 | M5: 1981 | N5: 1982 | O5: 1983 | P5: 1984 | Q5: 1985 | R5: 1986 | S5: 1987 | T5: 1988 | U5: 1989 | V5: 1990 | W5: 1991 | X5: 1992 | Y5: 1993 | Z5: 1994 | AA5: 1995 | AB5: 1996 | AC5: 1997 | AD5: 1998 | AE5: 1999 | AF5: 2000 | AG5: 2001 | AH5: 2002 | AI5: 2003 | AJ5: 2004 | AK5: 2005 | AL5: 2006 | AM5: 2007 | AN5: 2008 | AO5: 2009 | AP5: 2010 | AQ5: 2011 | AR5: 2012 | AS5: 2013 | AT5: 2014 | AU5: 2015 | AV5: 2016 | AW5: 2017 | AX5: 2018 | AY5: 2019 | AZ5: 2020 | BA5: 2021 | BB5: 2022 | BC5: 2023 | BD5: 2024 | BE5: 2025 | BF5: 2026 | BG5: 2027 | BH5: 2028 | BI5: 2029 | BJ5: 2030 | BK5: 2031 | BL5: 2032 | BM5: 2033 | BN5: 2034 | BO5: 2035 | BP5: 2036 | BQ5: 2037 | BR5: 2038 | BS5: 2039 | BT5: 2040 | BU5: 2041 | BV5: 2042 | BW5: 2043 | BX5: 2044 | BY5: 2045 | BZ5: 2046 | CA5: 2047 | CB5: 2048 | CC5: 2049 | CD5: 2050 | CE5: 2051 | CF5: 2052 | CG5: 2053 | CH5: 2054 | CI5: 2055 | CJ5: 2056 | CK5: 2057 | CL5: 2058 | CM5: 2059 | CN5: 2060 | CO5: 2061 | CP5: 2062 | CQ5: 2063 | CR5: 2064 | CS5: 2065 | CT5: 2066 | CU5: 2067 | CV5: 2068 | CW5: 2069 | CX5: 2070
A6: 0 | B6: 169702 | C6: 160641 | D6: 159755 | E6: 158388 | F6: 155584 | G6: 151147 | H6: 145269 | I6: 138873 | J6: 132431 | K6: 126261 | L6: 120590 | M6: 115708 | N6: 111826 | O6: 108398 | P6: 105049 | Q6: 101415 | R6: 97469 | S6: 93411 | T6: 89198 | U6: 92554 | V6: 87922 | W6: 78495 | X6: 75494 | Y6: 72498 | Z6: 69519 | AA6: 66547 | AB6: 63576 | AC6: 60819 | AD6: 58335 | AE6: 55957 | AF6: 53167 | AG6: 50044 | AH6: 47006 | AI6: 44490 | AJ6: 42514 | AK6: 40984 | AL6: 39907 | AM6: 39263 | AN6: 38727 | AO6: 38032 | AP6: 37047 | AQ6: 35958 | AR6: 35012 | AS6: 34328 | AT6: 33685 | AU6: 33087 | AV6: 32317 | AW6: 31784 | AX6: 31130 | AY6: 30471 | AZ6: 11457 | BA6: 11279 | BB6: 25242 | BC6: 24338 | BD6: 23281 | BE6: 22320 | BF6: 21302 | BG6: 20354 | BH6: 19398 | BI6: 18498 | BJ6: 17609 | BK6: 16762 | BL6: 15936 | BM6: 15151 | BN6: 14398 | BO6: 13684 | BP6: 13002 | BQ6: 12353 | BR6: 11735 | BS6: 11150 | BT6: 10594 | BU6: 10070 | BV6: 9574 | BW6: 9103 | BX6: 8657 | BY6: 8236 | BZ6: 7836 | CA6: 7459 | CB6: 7102 | CC6: 6763 | CD6: 6440 | CE6: 6134 | CF6: 5846 | CG6: 5572 | CH6: 5311 | CI6: 5062 | CJ6: 4825 | CK6: 4600 | CL6: 4386 | CM6: 4181 | CN6: 3986 | CO6: 3798 | CP6: 3620 | CQ6: 3449 | CR6: 3286 | CS6: 3131 | CT6: 2982 | CU6: 2840 | CV6: 2704 | CW6: 2574 | CX6: 2451
A7: 1 | B7: 39963 | C7: 30705 | D7: 27048 | E7: 25240 | F7: 23428 | G7: 21650 | H7: 18810 | I7: 17484 | J7: 17177 | K7: 15577 | L7: 14329 | M7: 13746 | N7: 13224 | O7: 12401 | P7: 11546 | Q7: 10673 | R7: 10273 | S7: 9710 | T7: 8994 | U7: 8476 | V7: 7817 | W7: 7717 | X7: 7487 | Y7: 6910 | Z7: 6620 | AA7: 6035 | AB7: 5543 | AC7: 5137 | AD7: 4738 | AE7: 4426 | AF7: 4122 | AG7: 3779 | AH7: 3440 | AI7: 3223 | AJ7: 3034 | AK7: 2872 | AL7: 2851 | AM7: 2803 | AN7: 2793 | AO7: 2162 | AP7: 2116 | AQ7: 2049 | AR7: 2069 | AS7: 2063 | AT7: 2090 | AU7: 2086 | AV7: 2032 | AW7: 2031 | AX7: 1952 | AY7: 1931 | AZ7: 12190 | BA7: 12044 | BB7: 3209 | BC7: 3025 | BD7: 2839 | BE7: 2675 | BF7: 2504 | BG7: 2350 | BH7: 2197 | BI7: 2057 | BJ7: 1923 | BK7: 1798 | BL7: 1679 | BM7: 1569 | BN7: 1465 | BO7: 1369 | BP7: 1279 | BQ7: 1197 | BR7: 1118 | BS7: 1046 | BT7: 979 | BU7: 917 | BV7: 859 | BW7: 805 | BX7: 755 | BY7: 709 | BZ7: 665 | CA7: 625 | CB7: 588 | CC7: 553 | CD7: 520 | CE7: 490 | CF7: 461 | CG7: 435 | CH7: 410 | CI7: 387 | CJ7: 365 | CK7: 344 | CL7: 325 | CM7: 306 | CN7: 290 | CO7: 273 | CP7: 258 | CQ7: 244 | CR7: 230 | CS7: 218 | CT7: 205 | CU7: 194 | CV7: 183 | CW7: 173 | CX7: 164
A8: 2 | B8: 19815 | C8: 15257 | D8: 13842 | E8: 12458 | F8: 11315 | G8: 10377 | H8: 9549 | I8: 9027 | J8: 8515 | K8: 7864 | L8: 7211 | M8: 6713 | N8: 6340 | O8: 6009 | P8: 5686 | Q8: 5371 | R8: 5075 | S8: 4827 | T8: 4564 | U8: 4337 | V8: 4137 | W8: 3790 | X8: 3577 | Y8: 3427 | Z8: 3256 | AA8: 3090 | AB8: 2914 | AC8: 2720 | AD8: 2519 | AE8: 2317 | AF8: 2136 | AG8: 1980 | AH8: 1863 | AI8: 1776 | AJ8: 1706 | AK8: 1648 | AL8: 1599 | AM8: 1568 | AN8: 1543 | AO8: 1273 | AP8: 1245 | AQ8: 1210 | AR8: 1207 | AS8: 1200 | AT8: 1192 | AU8: 1163 | AV8: 1126 | AW8: 1069 | AX8: 1087 | AY8: 1060 | AZ8: 1124 | BA8: 1094 | BB8: 1268 | BC8: 1198 | BD8: 1106 | BE8: 1031 | BF8: 956 | BG8: 888 | BH8: 822 | BI8: 763 | BJ8: 706 | BK8: 654 | BL8: 606 | BM8: 561 | BN8: 519 | BO8: 480 | BP8: 445 | BQ8: 411 | BR8: 381 | BS8: 352 | BT8: 326 | BU8: 302 | BV8: 279 | BW8: 259 | BX8: 239 | BY8: 222 | BZ8: 205 | CA8: 190 | CB8: 176 | CC8: 163 | CD8: 151 | CE8: 140 | CF8: 130 | CG8: 120 | CH8: 111 | CI8: 104 | CJ8: 96 | CK8: 89 | CL8: 82 | CM8: 76 | CN8: 70 | CO8: 66 | CP8: 60 | CQ8: 56 | CR8: 51 | CS8: 47 | CT8: 45 | CU8: 41 | CV8: 38 | CW8: 35 | CX8: 32
A9: 3 | B9: 12002 | C9: 9391 | D9: 8782 | E9: 7697 | F9: 6882 | G9: 6290 | H9: 6078 | I9: 5828 | J9: 5354 | K9: 5045 | L9: 4633 | M9: 4220 | N9: 3925 | O9: 3751 | P9: 3593 | Q9: 3450 | R9: 3214 | S9: 3078 | T9: 2963 | U9: 2855 | V9: 2790 | W9: 2415 | X9: 2231 | Y9: 2190 | Z9: 2071 | AA9: 2031 | AB9: 1958 | AC9: 1844 | AD9: 1719 | AE9: 1571 | AF9: 1439 | AG9: 1338 | AH9: 1283 | AI9: 1242 | AJ9: 1215 | AK9: 1194 | AL9: 1139 | AM9: 1115 | AN9: 1086 | AO9: 937 | AP9: 917 | AQ9: 894 | AR9: 889 | AS9: 882 | AT9: 871 | AU9: 840 | AV9: 812 | AW9: 758 | AX9: 788 | AY9: 769 | AZ9: 698 | BA9: 678 | BB9: 773 | BC9: 730 | BD9: 683 | BE9: 633 | BF9: 589 | BG9: 548 | BH9: 508 | BI9: 472 | BJ9: 438 | BK9: 408 | BL9: 378 | BM9: 350 | BN9: 325 | BO9: 302 | BP9: 280 | BQ9: 259 | BR9: 241 | BS9: 224 | BT9: 208 | BU9: 193 | BV9: 178 | BW9: 166 | BX9: 154 | BY9: 143 | BZ9: 133 | CA9: 123 | CB9: 115 | CC9: 106 | CD9: 99 | CE9: 91 | CF9: 85 | CG9: 78 | CH9: 73 | CI9: 68 | CJ9: 62 | CK9: 58 | CL9: 54 | CM9: 50 | CN9: 46 | CO9: 43 | CP9: 40 | CQ9: 37 | CR9: 35 | CS9: 32 | CT9: 29 | CU9: 27 | CV9: 25 | CW9: 23 | CX9: 22
A10: 4 | B10: 8067 | C10: 6426 | D10: 6177 | E10: 5307 | F10: 4683 | G10: 4274 | H10: 4299 | I10: 4172 | J10: 3760 | K10: 3615 | L10: 3346 | M10: 3006 | N10: 2760 | O10: 2649 | P10: 2563 | Q10: 2492 | R10: 2295 | S10: 2213 | T10: 2162 | U10: 2119 | V10: 2111 | W10: 1745 | X10: 1587 | Y10: 1584 | Z10: 1487 | AA10: 1496 | AB10: 1471 | AC10: 1399 | AD10: 1315 | AE10: 1202 | AF10: 1098 | AG10: 1025 | AH10: 992 | AI10: 965 | AJ10: 959 | AK10: 957 | AL10: 906 | AM10: 886 | AN10: 857 | AO10: 764 | AP10: 749 | AQ10: 731 | AR10: 725 | AS10: 718 | AT10: 710 | AU10: 684 | AV10: 663 | AW10: 617 | AX10: 642 | AY10: 631 | AZ10: 550 | BA10: 522 | BB10: 588 | BC10: 556 | BD10: 521 | BE10: 491 | BF10: 454 | BG10: 425 | BH10: 396 | BI10: 369 | BJ10: 343 | BK10: 320 | BL10: 297 | BM10: 277 | BN10: 259 | BO10: 241 | BP10: 224 | BQ10: 209 | BR10: 194 | BS10: 182 | BT10: 168 | BU10: 157 | BV10: 146 | BW10: 136 | BX10: 127 | BY10: 118 | BZ10: 110 | CA10: 102 | CB10: 96 | CC10: 88 | CD10: 82 | CE10: 77 | CF10: 71 | CG10: 67 | CH10: 61 | CI10: 57 | CJ10: 54 | CK10: 50 | CL10: 46 | CM10: 44 | CN10: 40 | CO10: 38 | CP10: 34 | CQ10: 32 | CR10: 30 | CS10: 28 | CT10: 26 | CU10: 24 | CV10: 23 | CW10: 21 | CX10: 19
A11: 5 | B11: 5795 | C11: 4705 | D11: 4634 | E11: 3925 | F11: 3429 | G11: 3127 | H11: 3247 | I11: 3190 | J11: 2830 | K11: 2770 | L11: 2593 | M11: 2322 | N11: 2114 | O11: 2030 | P11: 1978 | Q11: 1942 | R11: 1771 | S11: 1720 | T11: 1699 | U11: 1692 | V11: 1714 | W11: 1368 | X11: 1229 | Y11: 1240 | Z11: 1158 | AA11: 1181 | AB11: 1179 | AC11: 1135 | AD11: 1076 | AE11: 987 | AF11: 905 | AG11: 849 | AH11: 828 | AI11: 804 | AJ11: 802 | AK11: 813 | AL11: 768 | AM11: 755 | AN11: 727 | AO11: 666 | AP11: 652 | AQ11: 636 | AR11: 631 | AS11: 622 | AT11: 618 | AU11: 596 | AV11: 584 | AW11: 549 | AX11: 564 | AY11: 556 | AZ11: 484 | BA11: 457 | BB11: 496 | BC11: 472 | BD11: 443 | BE11: 419 | BF11: 393 | BG11: 367 | BH11: 343 | BI11: 321 | BJ11: 300 | BK11: 280 | BL11: 262 | BM11: 245 | BN11: 229 | BO11: 214 | BP11: 201 | BQ11: 187 | BR11: 175 | BS11: 163 | BT11: 153 | BU11: 143 | BV11: 133 | BW11: 125 | BX11: 117 | BY11: 109 | BZ11: 102 | CA11: 95 | CB11: 89 | CC11: 83 | CD11: 78 | CE11: 72 | CF11: 68 | CG11: 64 | CH11: 59 | CI11: 55 | CJ11: 52 | CK11: 48 | CL11: 45 | CM11: 42 | CN11: 39 | CO11: 37 | CP11: 34 | CQ11: 31 | CR11: 29 | CS11: 27 | CT11: 25 | CU11: 24 | CV11: 23 | CW11: 21 | CX11: 19
A12: 6 | B12: 4356 | C12: 3620 | D12: 3649 | E12: 3065 | F12: 2660 | G12: 2429 | H12: 2577 | I12: 2569 | J12: 2250 | K12: 2233 | L12: 2115 | M12: 1905 | N12: 1730 | O12: 1658 | P12: 1624 | Q12: 1606 | R12: 1453 | S12: 1420 | T12: 1414 | U12: 1428 | V12: 1462 | W12: 1142 | X12: 1018 | Y12: 1030 | Z12: 964 | AA12: 987 | AB12: 992 | AC12: 964 | AD12: 924 | AE12: 854 | AF12: 786 | AG12: 746 | AH12: 732 | AI12: 709 | AJ12: 704 | AK12: 717 | AL12: 681 | AM12: 675 | AN12: 651 | AO12: 612 | AP12: 595 | AQ12: 580 | AR12: 574 | AS12: 563 | AT12: 563 | AU12: 546 | AV12: 540 | AW12: 521 | AX12: 524 | AY12: 515 | AZ12: 450 | BA12: 427 | BB12: 452 | BC12: 426 | BD12: 404 | BE12: 382 | BF12: 360 | BG12: 341 | BH12: 318 | BI12: 300 | BJ12: 281 | BK12: 263 | BL12: 247 | BM12: 232 | BN12: 218 | BO12: 205 | BP12: 192 | BQ12: 180 | BR12: 169 | BS12: 159 | BT12: 149 | BU12: 139 | BV12: 131 | BW12: 123 | BX12: 115 | BY12: 108 | BZ12: 102 | CA12: 95 | CB12: 90 | CC12: 84 | CD12: 78 | CE12: 74 | CF12: 68 | CG12: 64 | CH12: 60 | CI12: 56 | CJ12: 54 | CK12: 50 | CL12: 46 | CM12: 44 | CN12: 40 | CO12: 38 | CP12: 36 | CQ12: 34 | CR12: 32 | CS12: 30 | CT12: 28 | CU12: 26 | CV12: 24 | CW12: 22 | CX12: 22
A13: 7 | B13: 3396 | C13: 2893 | D13: 2990 | E13: 2514 | F13: 2175 | G13: 1994 | H13: 2139 | I13: 2168 | J13: 1882 | K13: 1887 | L13: 1805 | M13: 1645 | N13: 1499 | O13: 1431 | P13: 1409 | Q13: 1402 | R13: 1262 | S13: 1237 | T13: 1238 | U13: 1262 | V13: 1302 | W13: 1006 | X13: 894 | Y13: 904 | Z13: 851 | AA13: 869 | AB13: 876 | AC13: 853 | AD13: 827 | AE13: 774 | AF13: 717 | AG13: 688 | AH13: 681 | AI13: 659 | AJ13: 648 | AK13: 659 | AL13: 627 | AM13: 628 | AN13: 611 | AO13: 592 | AP13: 570 | AQ13: 554 | AR13: 547 | AS13: 531 | AT13: 538 | AU13: 522 | AV13: 521 | AW13: 523 | AX13: 512 | AY13: 503 | AZ13: 435 | BA13: 412 | BB13: 438 | BC13: 412 | BD13: 386 | BE13: 368 | BF13: 349 | BG13: 331 | BH13: 314 | BI13: 295 | BJ13: 278 | BK13: 261 | BL13: 246 | BM13: 232 | BN13: 219 | BO13: 206 | BP13: 194 | BQ13: 183 | BR13: 172 | BS13: 162 | BT13: 153 | BU13: 144 | BV13: 136 | BW13: 128 | BX13: 120 | BY13: 113 | BZ13: 107 | CA13: 101 | CB13: 94 | CC13: 89 | CD13: 84 | CE13: 78 | CF13: 74 | CG13: 70 | CH13: 66 | CI13: 62 | CJ13: 58 | CK13: 54 | CL13: 51 | CM13: 48 | CN13: 45 | CO13: 43 | CP13: 40 | CQ13: 37 | CR13: 35 | CS13: 33 | CT13: 31 | CU13: 29 | CV13: 27 | CW13: 26 | CX13: 25
A14: 8 | B14: 2743 | C14: 2394 | D14: 2534 | E14: 2159 | F14: 1876 | G14: 1726 | H14: 1855 | I14: 1917 | J14: 1655 | K14: 1670 | L14: 1612 | M14: 1493 | N14: 1366 | O14: 1297 | P14: 1287 | Q14: 1287 | R14: 1157 | S14: 1134 | T14: 1140 | U14: 1164 | V14: 1208 | W14: 933 | X14: 829 | Y14: 835 | Z14: 793 | AA14: 806 | AB14: 812 | AC14: 791 | AD14: 773 | AE14: 730 | AF14: 684 | AG14: 666 | AH14: 662 | AI14: 643 | AJ14: 626 | AK14: 634 | AL14: 606 | AM14: 609 | AN14: 599 | AO14: 600 | AP14: 574 | AQ14: 557 | AR14: 548 | AS14: 527 | AT14: 540 | AU14: 522 | AV14: 524 | AW14: 553 | AX14: 523 | AY14: 515 | AZ14: 442 | BA14: 410 | BB14: 442 | BC14: 421 | BD14: 394 | BE14: 373 | BF14: 355 | BG14: 338 | BH14: 322 | BI14: 306 | BJ14: 288 | BK14: 273 | BL14: 258 | BM14: 245 | BN14: 231 | BO14: 219 | BP14: 206 | BQ14: 195 | BR14: 185 | BS14: 175 | BT14: 165 | BU14: 156 | BV14: 148 | BW14: 139 | BX14: 132 | BY14: 124 | BZ14: 118 | CA14: 111 | CB14: 105 | CC14: 99 | CD14: 94 | CE14: 88 | CF14: 84 | CG14: 78 | CH14: 74 | CI14: 70 | CJ14: 66 | CK14: 63 | CL14: 59 | CM14: 55 | CN14: 53 | CO14: 50 | CP14: 47 | CQ14: 44 | CR14: 42 | CS14: 40 | CT14: 38 | CU14: 36 | CV14: 34 | CW14: 32 | CX14: 30
A15: 9 | B15: 2295 | C15: 2055 | D15: 2219 | E15: 1933 | F15: 1703 | G15: 1576 | H15: 1680 | I15: 1770 | J15: 1528 | K15: 1549 | L15: 1506 | M15: 1420 | N15: 1308 | O15: 1230 | P15: 1230 | Q15: 1241 | R15: 1119 | S15: 1092 | T15: 1100 | U15: 1120 | V15: 1163 | W15: 911 | X15: 811 | Y15: 810 | Z15: 779 | AA15: 787 | AB15: 792 | AC15: 770 | AD15: 760 | AE15: 722 | AF15: 684 | AG15: 676 | AH15: 675 | AI15: 659 | AJ15: 635 | AK15: 642 | AL15: 619 | AM15: 620 | AN15: 615 | AO15: 637 | AP15: 609 | AQ15: 595 | AR15: 583 | AS15: 552 | AT15: 573 | AU15: 552 | AV15: 555 | AW15: 615 | AX15: 559 | AY15: 554 | AZ15: 472 | BA15: 438 | BB15: 468 | BC15: 449 | BD15: 425 | BE15: 401 | BF15: 379 | BG15: 364 | BH15: 347 | BI15: 332 | BJ15: 317 | BK15: 301 | BL15: 285 | BM15: 271 | BN15: 257 | BO15: 244 | BP15: 232 | BQ15: 220 | BR15: 209 | BS15: 198 | BT15: 189 | BU15: 178 | BV15: 169 | BW15: 161 | BX15: 152 | BY15: 145 | BZ15: 137 | CA15: 130 | CB15: 124 | CC15: 117 | CD15: 111 | CE15: 105 | CF15: 100 | CG15: 94 | CH15: 90 | CI15: 85 | CJ15: 81 | CK15: 77 | CL15: 73 | CM15: 69 | CN15: 65 | CO15: 62 | CP15: 58 | CQ15: 56 | CR15: 52 | CS15: 50 | CT15: 47 | CU15: 45 | CV15: 43 | CW15: 41 | CX15: 38
A16: 10 | B16: 1989 | C16: 1829 | D16: 2011 | E16: 1797 | F16: 1615 | G16: 1510 | H16: 1590 | I16: 1699 | J16: 1478 | K16: 1498 | L16: 1467 | M16: 1409 | N16: 1307 | O16: 1214 | P16: 1222 | Q16: 1242 | R16: 1133 | S16: 1102 | T16: 1110 | U16: 1121 | V16: 1162 | W16: 929 | X16: 832 | Y16: 823 | Z16: 799 | AA16: 806 | AB16: 810 | AC16: 789 | AD16: 783 | AE16: 747 | AF16: 712 | AG16: 713 | AH16: 715 | AI16: 703 | AJ16: 672 | AK16: 681 | AL16: 666 | AM16: 663 | AN16: 662 | AO16: 701 | AP16: 681 | AQ16: 673 | AR16: 660 | AS16: 615 | AT16: 640 | AU16: 615 | AV16: 619 | AW16: 716 | AX16: 627 | AY16: 621 | AZ16: 529 | BA16: 512 | BB16: 523 | BC16: 503 | BD16: 480 | BE16: 458 | BF16: 432 | BG16: 412 | BH16: 396 | BI16: 380 | BJ16: 365 | BK16: 350 | BL16: 332 | BM16: 318 | BN16: 302 | BO16: 288 | BP16: 275 | BQ16: 262 | BR16: 250 | BS16: 238 | BT16: 227 | BU16: 216 | BV16: 206 | BW16: 196 | BX16: 187 | BY16: 177 | BZ16: 170 | CA16: 161 | CB16: 153 | CC16: 146 | CD16: 139 | CE16: 133 | CF16: 126 | CG16: 120 | CH16: 114 | CI16: 109 | CJ16: 104 | CK16: 99 | CL16: 94 | CM16: 90 | CN16: 85 | CO16: 81 | CP16: 77 | CQ16: 74 | CR16: 70 | CS16: 66 | CT16: 64 | CU16: 61 | CV16: 57 | CW16: 55 | CX16: 52
A17: 11 | B17: 1787 | C17: 1688 | D17: 1882 | E17: 1731 | F17: 1587 | G17: 1500 | H17: 1561 | I17: 1686 | J17: 1484 | K17: 1504 | L17: 1482 | M17: 1446 | N17: 1352 | O17: 1241 | P17: 1252 | Q17: 1281 | R17: 1188 | S17: 1156 | T17: 1162 | U17: 1162 | V17: 1197 | W17: 986 | X17: 889 | Y17: 871 | Z17: 851 | AA17: 857 | AB17: 861 | AC17: 842 | AD17: 840 | AE17: 805 | AF17: 770 | AG17: 777 | AH17: 783 | AI17: 773 | AJ17: 739 | AK17: 750 | AL17: 744 | AM17: 741 | AN17: 743 | AO17: 794 | AP17: 795 | AQ17: 794 | AR17: 785 | AS17: 719 | AT17: 745 | AU17: 716 | AV17: 720 | AW17: 862 | AX17: 731 | AY17: 726 | AZ17: 619 | BA17: 634 | BB17: 616 | BC17: 591 | BD17: 566 | BE17: 545 | BF17: 521 | BG17: 495 | BH17: 473 | BI17: 457 | BJ17: 440 | BK17: 424 | BL17: 409 | BM17: 389 | BN17: 373 | BO17: 357 | BP17: 342 | BQ17: 328 | BR17: 314 | BS17: 300 | BT17: 287 | BU17: 275 | BV17: 263 | BW17: 251 | BX17: 240 | BY17: 229 | BZ17: 220 | CA17: 210 | CB17: 201 | CC17: 192 | CD17: 183 | CE17: 175 | CF17: 168 | CG17: 161 | CH17: 154 | CI17: 147 | CJ17: 141 | CK17: 134 | CL17: 128 | CM17: 123 | CN17: 117 | CO17: 112 | CP17: 107 | CQ17: 103 | CR17: 98 | CS17: 94 | CT17: 90 | CU17: 85 | CV17: 82 | CW17: 78 | CX17: 75
... A115: 109 | B115: 0 | C115: 0 | D115: 2 | E115: 1 | F115: 1 | G115: 2 | H115: 1 | I115: 1 | J115: 1 | K115: 1 | L115: 1 | M115: 1 | N115: 1 | O115: 2 | P115: 2 | Q115: 2 | R115: 2 | S115: 2 | T115: 2 | U115: 2 | V115: 2 | W115: 2 | X115: 3 | Y115: 3 | Z115: 4 | AA115: 4 | AB115: 3 | AC115: 4 | AD115: 5 | AE115: 5 | AF115: 5 | AG115: 6 | AH115: 7 | AI115: 7 | AJ115: 8 | AK115: 9 | AL115: 10 | AM115: 11 | AN115: 13 | AO115: 14 | AP115: 14 | AQ115: 14 | AR115: 16 | AS115: 19 | AT115: 21 | AU115: 22 | AV115: 25 | AW115: 26 | AX115: 29 | AY115: 33 | AZ115: 75 | BA115: 90 | BB115: 64 | BC115: 69 | BD115: 74 | BE115: 79 | BF115: 84 | BG115: 87 | BH115: 89 | BI115: 94 | BJ115: 102 | BK115: 114 | BL115: 128 | BM115: 143 | BN115: 160 | BO115: 177 | BP115: 196 | BQ115: 212 | BR115: 231 | BS115: 251 | BT115: 274 | BU115: 298 | BV115: 324 | BW115: 351 | BX115: 380 | BY115: 412 | BZ115: 448 | CA115: 488 | CB115: 531 | CC115: 578 | CD115: 628 | CE115: 679 | CF115: 736 | CG115: 800 | CH115: 861 | CI115: 926 | CJ115: 994 | CK115: 1065 | CL115: 1139 | CM115: 1215 | CN115: 1310 | CO115: 1427 | CP115: 1558 | CQ115: 1714 | CR115: 1866 | CS115: 2019 | CT115: 2181 | CU115: 2363 | CV115: 2556 | CW115: 2761 | CX115: 2969

Sheet Población
A1: Población a mitad de año por edad y año, México (1970-2070)
A2: Fuente: CONAPO, 00_Pob_Mitad_1950_2070.csv (carpeta bases_de_datos_CONAPO/).
A3: Cada celda = suma de los 32 estados y de hombres + mujeres. Azul = dato de CONAPO. La tabla usa la diagonal edad x, año g + x.
A5: Edad \ Año | B5: 1970 | C5: 1971 | D5: 1972 | E5: 1973 | F5: 1974 | G5: 1975 | H5: 1976 | I5: 1977 | J5: 1978 | K5: 1979 | L5: 1980 | M5: 1981 | N5: 1982 | O5: 1983 | P5: 1984 | Q5: 1985 | R5: 1986 | S5: 1987 | T5: 1988 | U5: 1989 | V5: 1990 | W5: 1991 | X5: 1992 | Y5: 1993 | Z5: 1994 | AA5: 1995 | AB5: 1996 | AC5: 1997 | AD5: 1998 | AE5: 1999 | AF5: 2000 | AG5: 2001 | AH5: 2002 | AI5: 2003 | AJ5: 2004 | AK5: 2005 | AL5: 2006 | AM5: 2007 | AN5: 2008 | AO5: 2009 | AP5: 2010 | AQ5: 2011 | AR5: 2012 | AS5: 2013 | AT5: 2014 | AU5: 2015 | AV5: 2016 | AW5: 2017 | AX5: 2018 | AY5: 2019 | AZ5: 2020 | BA5: 2021 | BB5: 2022 | BC5: 2023 | BD5: 2024 | BE5: 2025 | BF5: 2026 | BG5: 2027 | BH5: 2028 | BI5: 2029 | BJ5: 2030 | BK5: 2031 | BL5: 2032 | BM5: 2033 | BN5: 2034 | BO5: 2035 | BP5: 2036 | BQ5: 2037 | BR5: 2038 | BS5: 2039 | BT5: 2040 | BU5: 2041 | BV5: 2042 | BW5: 2043 | BX5: 2044 | BY5: 2045 | BZ5: 2046 | CA5: 2047 | CB5: 2048 | CC5: 2049 | CD5: 2050 | CE5: 2051 | CF5: 2052 | CG5: 2053 | CH5: 2054 | CI5: 2055 | CJ5: 2056 | CK5: 2057 | CL5: 2058 | CM5: 2059 | CN5: 2060 | CO5: 2061 | CP5: 2062 | CQ5: 2063 | CR5: 2064 | CS5: 2065 | CT5: 2066 | CU5: 2067 | CV5: 2068 | CW5: 2069 | CX5: 2070
A6: 0 | B6: 2101069 | C6: 2145297 | D6: 2190434 | E6: 2230073 | F6: 2259096 | G6: 2273718 | H6: 2273169 | I6: 2263285 | J6: 2254671 | K6: 2253269 | L6: 2259742 | M6: 2272442 | N6: 2290705 | O6: 2312175 | P6: 2334181 | Q6: 2353905 | R6: 2368480 | S6: 2381110 | T6: 2396293 | U6: 2414553 | V6: 2437445 | W6: 2462595 | X6: 2477407 | Y6: 2476556 | Z6: 2464615 | AA6: 2444999 | AB6: 2421575 | AC6: 2402169 | AD6: 2395354 | AE6: 2400468 | AF6: 2403045 | AG6: 2391026 | AH6: 2366279 | AI6: 2339143 | AJ6: 2319353 | AK6: 2309835 | AL6: 2310619 | AM6: 2319971 | AN6: 2331377 | AO6: 2336688 | AP6: 2330140 | AQ6: 2311075 | AR6: 2283405 | AS6: 2257759 | AT6: 2237888 | AU6: 2213955 | AV6: 2176963 | AW6: 2138294 | AX6: 2121211 | AY6: 2117912 | AZ6: 2111632 | BA6: 2099100 | BB6: 2073914 | BC6: 2046960 | BD6: 2026101 | BE6: 2004194 | BF6: 1981566 | BG6: 1958553 | BH6: 1935457 | BI6: 1912534 | BJ6: 1889787 | BK6: 1867010 | BL6: 1844074 | BM6: 1821281 | BN6: 1799008 | BO6: 1777261 | BP6: 1755913 | BQ6: 1734817 | BR6: 1713909 | BS6: 1693292 | BT6: 1672972 | BU6: 1653013 | BV6: 1633485 | BW6: 1614231 | BX6: 1595087 | BY6: 1576028 | BZ6: 1557177 | CA6: 1538683 | CB6: 1520452 | CC6: 1502245 | CD6: 1484022 | CE6: 1465950 | CF6: 1448222 | CG6: 1430800 | CH6: 1413446 | CI6: 1396100 | CJ6: 1378898 | CK6: 1362011 | CL6: 1345453 | CM6: 1329057 | CN6: 1312755 | CO6: 1296597 | CP6: 1280668 | CQ6: 1265020 | CR6: 1249589 | CS6: 1234322 | CT6: 1219221 | CU6: 1204309 | CV6: 1189615 | CW6: 1175127 | CX6: 1160822
A7: 1 | B7: 1977695 | C7: 2024966 | D7: 2075003 | E7: 2122611 | F7: 2164455 | G7: 2196143 | H7: 2214169 | I7: 2217329 | J7: 2210882 | K7: 2205914 | L7: 2208138 | M7: 2217441 | N7: 2232253 | O7: 2252321 | P7: 2275434 | Q7: 2298831 | R7: 2319611 | S7: 2335111 | T7: 2348878 | U7: 2364215 | V7: 2382814 | W7: 2407729 | X7: 2434443 | Y7: 2450270 | Z7: 2450683 | AA7: 2439944 | AB7: 2421219 | AC7: 2398106 | AD7: 2378447 | AE7: 2370743 | AF7: 2376355 | AG7: 2381844 | AH7: 2372706 | AI7: 2349621 | AJ7: 2323190 | AK7: 2305040 | AL7: 2298720 | AM7: 2302704 | AN7: 2313278 | AO7: 2324515 | AP7: 2329682 | AQ7: 2322814 | AR7: 2302427 | AS7: 2273768 | AT7: 2247147 | AU7: 2225368 | AV7: 2200720 | AW7: 2164658 | AX7: 2127611 | AY7: 2111188 | AZ7: 2104453 | BA7: 2095010 | BB7: 2087221 | BC7: 2066714 | BD7: 2040039 | BE7: 2019330 | BF7: 1997510 | BG7: 1974956 | BH7: 1952026 | BI7: 1929042 | BJ7: 1906263 | BK7: 1883689 | BL7: 1861109 | BM7: 1838388 | BN7: 1815817 | BO7: 1793765 | BP7: 1772226 | BQ7: 1751061 | BR7: 1730113 | BS7: 1709317 | BT7: 1688780 | BU7: 1668517 | BV7: 1648608 | BW7: 1629130 | BX7: 1609933 | BY7: 1590860 | BZ7: 1571882 | CA7: 1553124 | CB7: 1534730 | CC7: 1516606 | CD7: 1498505 | CE7: 1480384 | CF7: 1462404 | CG7: 1444750 | CH7: 1427386 | CI7: 1410076 | CJ7: 1392765 | CK7: 1375594 | CL7: 1358738 | CM7: 1342218 | CN7: 1325865 | CO7: 1309615 | CP7: 1293515 | CQ7: 1277651 | CR7: 1262070 | CS7: 1246704 | CT7: 1231499 | CU7: 1216454 | CV7: 1201588 | CW7: 1186930 | CX7: 1172472
A8: 2 | B8: 1896819 | C8: 1946175 | D8: 1997453 | E8: 2049147 | F8: 2097997 | G8: 2140947 | H8: 2173817 | I8: 2192870 | J8: 2196660 | K8: 2191143 | L8: 2187289 | M8: 2190210 | N8: 2199878 | O8: 2215037 | P8: 2235438 | Q8: 2258681 | R8: 2281895 | S8: 2302326 | T8: 2317647 | U8: 2331396 | V8: 2346817 | W8: 2365482 | X8: 2390416 | Y8: 2417422 | Z8: 2433795 | AA8: 2434748 | AB8: 2424271 | AC8: 2405295 | AD8: 2381482 | AE8: 2360639 | AF8: 2353106 | AG8: 2361065 | AH8: 2368854 | AI8: 2360981 | AJ8: 2338414 | AK8: 2313536 | AL8: 2298435 | AM8: 2295142 | AN8: 2300269 | AO8: 2310670 | AP8: 2321738 | AQ8: 2326515 | AR8: 2318291 | AS8: 2296881 | AT8: 2267284 | AU8: 2238905 | AV8: 2216460 | AW8: 2192614 | AX8: 2157971 | AY8: 2121515 | AZ8: 2105531 | BA8: 2099419 | BB8: 2090134 | BC8: 2082413 | BD8: 2062047 | BE8: 2035425 | BF8: 2014698 | BG8: 1992855 | BH8: 1970294 | BI8: 1947389 | BJ8: 1924466 | BK8: 1901782 | BL8: 1879328 | BM8: 1856889 | BN8: 1834320 | BO8: 1811907 | BP8: 1790004 | BQ8: 1768590 | BR8: 1747521 | BS8: 1726635 | BT8: 1705871 | BU8: 1685347 | BV8: 1665092 | BW8: 1645194 | BX8: 1625737 | BY8: 1606575 | BZ8: 1587551 | CA8: 1568635 | CB8: 1549949 | CC8: 1531636 | CD8: 1513593 | CE8: 1495570 | CF8: 1477517 | CG8: 1459590 | CH8: 1441975 | CI8: 1424634 | CJ8: 1407339 | CK8: 1390042 | CL8: 1372886 | CM8: 1356050 | CN8: 1339557 | CO8: 1323241 | CP8: 1307035 | CQ8: 1290986 | CR8: 1275175 | CS8: 1259647 | CT8: 1244332 | CU8: 1229171 | CV8: 1214159 | CW8: 1199319 | CX8: 1184680
A9: 3 | B9: 1827528 | C9: 1876876 | D9: 1928067 | E9: 1980171 | F9: 2032720 | G9: 2082172 | H9: 2125430 | I9: 2158454 | J9: 2177865 | K9: 2182272 | L9: 2177382 | M9: 2174023 | N9: 2177242 | O9: 2187085 | P9: 2202305 | Q9: 2222548 | R9: 2245432 | S9: 2268186 | T9: 2288208 | U9: 2303291 | V9: 2316915 | W9: 2332348 | X9: 2351111 | Y9: 2376225 | Z9: 2403563 | AA9: 2420227 | AB9: 2421184 | AC9: 2410293 | AD9: 2390524 | AE9: 2365531 | AF9: 2344893 | AG9: 2339620 | AH9: 2349671 | AI9: 2358525 | AJ9: 2351085 | AK9: 2329995 | AL9: 2308072 | AM9: 2295916 | AN9: 2293712 | AO9: 2298557 | AP9: 2308690 | AQ9: 2319352 | AR9: 2322820 | AS9: 2313634 | AT9: 2291365 | AU9: 2260171 | AV9: 2231231 | AW9: 2209562 | AX9: 2187002 | AY9: 2152881 | AZ9: 2116845 | BA9: 2101415 | BB9: 2095469 | BC9: 2086262 | BD9: 2078607 | BE9: 2058236 | BF9: 2031568 | BG9: 2010784 | BH9: 1988904 | BI9: 1966339 | BJ9: 1943471 | BK9: 1920616 | BL9: 1898028 | BM9: 1875691 | BN9: 1853383 | BO9: 1830951 | BP9: 1808667 | BQ9: 1786874 | BR9: 1765541 | BS9: 1744518 | BT9: 1723649 | BU9: 1702885 | BV9: 1682355 | BW9: 1662098 | BX9: 1642209 | BY9: 1622775 | BZ9: 1603653 | CA9: 1584680 | CB9: 1565828 | CC9: 1547215 | CD9: 1528974 | CE9: 1511002 | CF9: 1493040 | CG9: 1475034 | CH9: 1457139 | CI9: 1439541 | CJ9: 1422208 | CK9: 1404919 | CL9: 1387630 | CM9: 1370490 | CN9: 1353676 | CO9: 1337214 | CP9: 1320938 | CQ9: 1304777 | CR9: 1288778 | CS9: 1273016 | CT9: 1257534 | CU9: 1242258 | CV9: 1227127 | CW9: 1212138 | CX9: 1197313
A10: 4 | B10: 1766357 | C10: 1812827 | D10: 1863076 | E10: 1914706 | F10: 1967440 | G10: 2020350 | H10: 2069778 | I10: 2112864 | J10: 2146086 | K10: 2165909 | L10: 2170691 | M10: 2166173 | N10: 2163073 | O10: 2166413 | P10: 2176231 | Q10: 2191216 | R10: 2211057 | S10: 2233451 | T10: 2255725 | U10: 2275409 | V10: 2290280 | W10: 2303893 | X10: 2319438 | Y10: 2338361 | Z10: 2363755 | AA10: 2391274 | AB10: 2407799 | AC10: 2408260 | AD10: 2396527 | AE10: 2375597 | AF10: 2350816 | AG10: 2332406 | AH10: 2329163 | AI10: 2340218 | AJ10: 2349457 | AK10: 2343403 | AL10: 2325178 | AM10: 2306112 | AN10: 2295005 | AO10: 2292479 | AP10: 2297019 | AQ10: 2306745 | AR10: 2316164 | AS10: 2318712 | AT10: 2308717 | AU10: 2284954 | AV10: 2253285 | AW10: 2225103 | AX10: 2204639 | AY10: 2182537 | AZ10: 2148782 | BA10: 2113285 | BB10: 2098038 | BC10: 2092159 | BD10: 2082995 | BE10: 2075294 | BF10: 2054847 | BG10: 2028118 | BH10: 2007281 | BI10: 1985385 | BJ10: 1962844 | BK10: 1940032 | BL10: 1917263 | BM10: 1894780 | BN10: 1872563 | BO10: 1850381 | BP10: 1828070 | BQ10: 1805889 | BR10: 1784168 | BS10: 1762875 | BT10: 1741862 | BU10: 1720985 | BV10: 1700208 | BW10: 1679668 | BX10: 1659415 | BY10: 1639544 | BZ10: 1620143 | CA10: 1601067 | CB10: 1582153 | CC10: 1563369 | CD10: 1544825 | CE10: 1526651 | CF10: 1508736 | CG10: 1490816 | CH10: 1472836 | CI10: 1454955 | CJ10: 1437361 | CK10: 1420031 | CL10: 1402747 | CM10: 1385468 | CN10: 1368347 | CO10: 1351562 | CP10: 1335137 | CQ10: 1318902 | CR10: 1302788 | CS10: 1286834 | CT10: 1271117 | CU10: 1255671 | CV10: 1240422 | CW10: 1225310 | CX10: 1210333
A11: 5 | B11: 1709847 | C11: 1754645 | D11: 1801550 | E11: 1852033 | F11: 1904143 | G11: 1957095 | H11: 2009836 | I11: 2058957 | J11: 2102149 | K11: 2135635 | L11: 2155656 | M11: 2160682 | N11: 2156372 | O11: 2153378 | P11: 2156678 | Q11: 2166246 | R11: 2180829 | S11: 2200191 | T11: 2222084 | U11: 2243980 | V11: 2263394 | W11: 2278223 | X11: 2291938 | Y11: 2307628 | Z11: 2326834 | AA11: 2352391 | AB11: 2379703 | AC11: 2395667 | AD11: 2395258 | AE11: 2382363 | AF11: 2361620 | AG11: 2339008 | AH11: 2322595 | AI11: 2320385 | AJ11: 2331824 | AK11: 2342372 | AL11: 2339057 | AM11: 2323586 | AN11: 2305525 | AO11: 2294074 | AP11: 2291233 | AQ11: 2295373 | AR11: 2303917 | AS11: 2312469 | AT11: 2314256 | AU11: 2302861 | AV11: 2278656 | AW11: 2247718 | AX11: 2220684 | AY11: 2200645 | AZ11: 2178869 | BA11: 2145609 | BB11: 2110318 | BC11: 2095146 | BD11: 2089291 | BE11: 2080070 | BF11: 2072264 | BG11: 2051736 | BH11: 2024955 | BI11: 2004094 | BJ11: 1982213 | BK11: 1959721 | BL11: 1936987 | BM11: 1914316 | BN11: 1891946 | BO11: 1869849 | BP11: 1847783 | BQ11: 1825569 | BR11: 1803457 | BS11: 1781772 | BT11: 1760483 | BU11: 1739457 | BV11: 1718562 | BW11: 1697770 | BX11: 1677230 | BY11: 1656991 | BZ11: 1637148 | CA11: 1617790 | CB11: 1598770 | CC11: 1579920 | CD11: 1561202 | CE11: 1542722 | CF11: 1524603 | CG11: 1506725 | CH11: 1488830 | CI11: 1470861 | CJ11: 1452980 | CK11: 1435386 | CL11: 1418057 | CM11: 1400781 | CN11: 1383519 | CO11: 1366424 | CP11: 1349672 | CQ11: 1333288 | CR11: 1317096 | CS11: 1301026 | CT11: 1285114 | CU11: 1269429 | CV11: 1254010 | CW11: 1238778 | CX11: 1223675
A12: 6 | B12: 1651800 | C12: 1700107 | D12: 1745065 | E12: 1792091 | F12: 1842935 | G12: 1895175 | H12: 1947903 | I12: 2000282 | J12: 2049442 | K12: 2092797 | L12: 2126373 | M12: 2146515 | N12: 2151670 | O12: 2147451 | P12: 2144419 | Q12: 2147466 | R12: 2156650 | S12: 2170776 | T12: 2189650 | U12: 2211163 | V12: 2232755 | W12: 2252094 | X12: 2267005 | Y12: 2280862 | Z12: 2296824 | AA12: 2316205 | AB12: 2341564 | AC12: 2368283 | AD12: 2383337 | AE12: 2381760 | AF12: 2369023 | AG12: 2350352 | AH12: 2329687 | AI12: 2314320 | AJ12: 2312554 | AK12: 2325272 | AL12: 2338421 | AM12: 2337739 | AN12: 2323224 | AO12: 2304816 | AP12: 2293038 | AQ12: 2289809 | AR12: 2292830 | AS12: 2300563 | AT12: 2308406 | AU12: 2308872 | AV12: 2297051 | AW12: 2273535 | AX12: 2243689 | AY12: 2217077 | AZ12: 2197339 | BA12: 2176004 | BB12: 2142940 | BC12: 2107744 | BD12: 2092597 | BE12: 2086671 | BF12: 2077342 | BG12: 2069432 | BH12: 2048839 | BI12: 2022036 | BJ12: 2001183 | BK12: 1979346 | BL12: 1956925 | BM12: 1934284 | BN12: 1911723 | BO12: 1889468 | BP12: 1867483 | BQ12: 1845510 | BR12: 1823362 | BS12: 1801281 | BT12: 1779598 | BU12: 1758294 | BV12: 1737245 | BW12: 1716332 | BX12: 1695536 | BY12: 1675005 | BZ12: 1654792 | CA12: 1634990 | CB12: 1615686 | CC12: 1596727 | CD12: 1577941 | CE12: 1559286 | CF12: 1540857 | CG12: 1522774 | CH12: 1504918 | CI12: 1487030 | CJ12: 1469060 | CK12: 1451176 | CL12: 1433582 | CM12: 1416258 | CN12: 1398996 | CO12: 1381758 | CP12: 1364695 | CQ12: 1347982 | CR12: 1331637 | CS12: 1315490 | CT12: 1299458 | CU12: 1283578 | CV12: 1267917 | CW12: 1252512 | CX12: 1237288
A13: 7 | B13: 1591222 | C13: 1643447 | D13: 1691734 | E13: 1736733 | F13: 1784036 | G13: 1834966 | H13: 1886958 | I13: 1939309 | J13: 1991674 | K13: 2040953 | L13: 2084325 | M13: 2117927 | N13: 2138109 | O13: 2143296 | P13: 2139028 | Q13: 2135767 | R13: 2138459 | S13: 2147208 | T13: 2160880 | U13: 2179387 | V13: 2200600 | W13: 2222097 | X13: 2241478 | Y13: 2256510 | Z13: 2270629 | AA13: 2286771 | AB13: 2305993 | AC13: 2330792 | AD13: 2356598 | AE13: 2370477 | AF13: 2369001 | AG13: 2358230 | AH13: 2341415 | AI13: 2321781 | AJ13: 2306922 | AK13: 2306441 | AL13: 2321658 | AM13: 2337308 | AN13: 2337530 | AO13: 2322659 | AP13: 2303929 | AQ13: 2291775 | AR13: 2287481 | AS13: 2289744 | AT13: 2296820 | AU13: 2303428 | AV13: 2303485 | AW13: 2292297 | AX13: 2269800 | AY13: 2240369 | AZ13: 2214057 | BA13: 2194738 | BB13: 2173581 | BC13: 2140603 | BD13: 2105447 | BE13: 2090236 | BF13: 2084196 | BG13: 2074762 | BH13: 2066764 | BI13: 2046137 | BJ13: 2019345 | BK13: 1998530 | BL13: 1976757 | BM13: 1954425 | BN13: 1931890 | BO13: 1909442 | BP13: 1887296 | BQ13: 1865403 | BR13: 1843493 | BS13: 1821375 | BT13: 1799294 | BU13: 1777592 | BV13: 1756262 | BW13: 1735192 | BX13: 1714271 | BY13: 1693482 | BZ13: 1672975 | CA13: 1652801 | CB13: 1633051 | CC13: 1613806 | CD13: 1594910 | CE13: 1576184 | CF13: 1557579 | CG13: 1539185 | CH13: 1521122 | CI13: 1503272 | CJ13: 1485380 | CK13: 1467405 | CL13: 1449519 | CM13: 1431927 | CN13: 1414617 | CO13: 1397376 | CP13: 1380168 | CQ13: 1363142 | CR13: 1346470 | CS13: 1330166 | CT13: 1314055 | CU13: 1298054 | CV13: 1282196 | CW13: 1266549 | CX13: 1251151
A14: 8 | B14: 1531521 | C14: 1583915 | D14: 1636010 | E14: 1684251 | F14: 1729455 | G14: 1776815 | H14: 1827495 | I14: 1879118 | J14: 1931437 | K14: 1983886 | L14: 2033124 | M14: 2076466 | N14: 2110036 | O14: 2130193 | P14: 2135303 | Q14: 2130804 | R14: 2127209 | S14: 2129507 | T14: 2137826 | U14: 2151155 | V14: 2169381 | W14: 2190492 | X14: 2212014 | Y14: 2231486 | Z14: 2246767 | AA14: 2261061 | AB14: 2277060 | AC14: 2295781 | AD14: 2319728 | AE14: 2344367 | AF14: 2358277 | AG14: 2358645 | AH14: 2349636 | AI14: 2333820 | AJ14: 2314709 | AK14: 2301141 | AL14: 2303084 | AM14: 2320686 | AN14: 2337191 | AO14: 2337057 | AP14: 2321864 | AQ14: 2302764 | AR14: 2289595 | AS14: 2284592 | AT14: 2286255 | AU14: 2292176 | AV14: 2298402 | AW14: 2299044 | AX14: 2288805 | AY14: 2266708 | AZ14: 2237559 | BA14: 2211659 | BB14: 2192515 | BC14: 2171426 | BD14: 2138484 | BE14: 2103285 | BF14: 2087968 | BG14: 2081818 | BH14: 2072297 | BI14: 2064246 | BJ14: 2043617 | BK14: 2016866 | BL14: 1996110 | BM14: 1974423 | BN14: 1952194 | BO14: 1929768 | BP14: 1907427 | BQ14: 1885372 | BR14: 1863541 | BS14: 1841659 | BT14: 1819540 | BU14: 1797438 | BV14: 1775708 | BW14: 1754354 | BX14: 1733274 | BY14: 1712358 | BZ14: 1691591 | CA14: 1671123 | CB14: 1650997 | CC14: 1631306 | CD14: 1612124 | CE14: 1593286 | CF14: 1574610 | CG14: 1556039 | CH14: 1537664 | CI14: 1519605 | CJ14: 1501749 | CK14: 1483851 | CL14: 1465870 | CM14: 1447987 | CN14: 1430405 | CO14: 1413114 | CP14: 1395903 | CQ14: 1378731 | CR14: 1361744 | CS14: 1345111 | CT14: 1328843 | CU14: 1312762 | CV14: 1296782 | CW14: 1280937 | CX14: 1265295
A15: 9 | B15: 1473035 | C15: 1525029 | D15: 1577225 | E15: 1629202 | F15: 1677576 | G15: 1722808 | H15: 1769940 | I15: 1820260 | J15: 1871829 | K15: 1924213 | L15: 1976604 | M15: 2025766 | N15: 2069020 | O15: 2102519 | P15: 2122553 | Q15: 2127399 | R15: 2122576 | S15: 2118615 | T15: 2120525 | U15: 2128534 | V15: 2141613 | W15: 2159738 | X15: 2180862 | Y15: 2202464 | Z15: 2222163 | AA15: 2237598 | AB15: 2251776 | AC15: 2267313 | AD15: 2285244 | AE15: 2308100 | AF15: 2332736 | AG15: 2348351 | AH15: 2350374 | AI15: 2342303 | AJ15: 2326997 | AK15: 2309170 | AL15: 2297961 | AM15: 2302202 | AN15: 2320619 | AO15: 2336762 | AP15: 2336309 | AQ15: 2320753 | AR15: 2300680 | AS15: 2286843 | AT15: 2281280 | AU15: 2281861 | AV15: 2287440 | AW15: 2294202 | AX15: 2295728 | AY15: 2285874 | AZ15: 2264030 | BA15: 2235282 | BB15: 2209568 | BC15: 2190499 | BD15: 2169441 | BE15: 2136458 | BF15: 2101176 | BG15: 2085761 | BH15: 2079519 | BI15: 2069943 | BJ15: 2061872 | BK15: 2041270 | BL15: 2014582 | BM15: 1993905 | BN15: 1972315 | BO15: 1950192 | BP15: 1927873 | BQ15: 1905622 | BR15: 1883629 | BS15: 1861826 | BT15: 1839944 | BU15: 1817804 | BV15: 1795674 | BW15: 1773919 | BX15: 1752553 | BY15: 1731476 | BZ15: 1710580 | CA15: 1689849 | CB15: 1669429 | CC15: 1649362 | CD15: 1629732 | CE15: 1610608 | CF15: 1591818 | CG15: 1573176 | CH15: 1554623 | CI15: 1536251 | CJ15: 1518186 | CK15: 1500323 | CL15: 1482418 | CM15: 1464438 | CN15: 1446564 | CO15: 1429002 | CP15: 1411739 | CQ15: 1394562 | CR15: 1377428 | CS15: 1360479 | CT15: 1343882 | CU15: 1327643 | CV15: 1311582 | CW15: 1295614 | CX15: 1279774
A16: 10 | B16: 1413608 | C16: 1467188 | D16: 1518949 | E16: 1570990 | F16: 1623026 | G16: 1671381 | H16: 1716401 | I16: 1763197 | J16: 1813450 | K16: 1865074 | L16: 1917393 | M16: 1969679 | N16: 2018728 | O16: 2061886 | P16: 2095228 | Q16: 2114941 | R16: 2119434 | S16: 2114259 | T16: 2109947 | U16: 2111576 | V16: 2119365 | W16: 2132363 | X16: 2150508 | Y16: 2171719 | Z16: 2193524 | AA16: 2213346 | AB16: 2228672 | AC16: 2242405 | AD16: 2257218 | AE16: 2274155 | AF16: 2297019 | AG16: 2323234 | AH16: 2340379 | AI16: 2343278 | AJ16: 2335699 | AK16: 2321641 | AL16: 2306093 | AM16: 2297107 | AN16: 2302127 | AO16: 2320185 | AP16: 2336000 | AQ16: 2335196 | AR16: 2318696 | AS16: 2297987 | AT16: 2283636 | AU16: 2277054 | AV16: 2277323 | AW16: 2283403 | AX16: 2290998 | AY16: 2292896 | AZ16: 2283270 | BA16: 2261801 | BB16: 2233252 | BC16: 2207640 | BD16: 2188614 | BE16: 2167516 | BF16: 2134453 | BG16: 2099091 | BH16: 2083590 | BI16: 2077286 | BJ16: 2067687 | BK16: 2059624 | BL16: 2039073 | BM16: 2012466 | BN16: 1991883 | BO16: 1970398 | BP16: 1948380 | BQ16: 1926150 | BR16: 1903964 | BS16: 1882002 | BT16: 1860199 | BU16: 1838296 | BV16: 1816126 | BW16: 1793971 | BX16: 1772204 | BY16: 1750840 | BZ16: 1729781 | CA16: 1708921 | CB16: 1688238 | CC16: 1667876 | CD16: 1647870 | CE16: 1628298 | CF16: 1609223 | CG16: 1590468 | CH16: 1571843 | CI16: 1553293 | CJ16: 1534916 | CK16: 1516842 | CL16: 1498971 | CM16: 1481066 | CN16: 1463096 | CO16: 1445239 | CP16: 1427704 | CQ16: 1410474 | CR16: 1393333 | CS16: 1376238 | CT16: 1359325 | CU16: 1342756 | CV16: 1326538 | CW16: 1310488 | CX16: 1294525
A17: 11 | B17: 1353594 | C17: 1408281 | D17: 1461597 | E17: 1513181 | F17: 1565233 | G17: 1617210 | H17: 1665363 | I17: 1710067 | J17: 1756791 | K17: 1807088 | L17: 1858645 | M17: 1910839 | N17: 1962982 | O17: 2011928 | P17: 2054903 | Q17: 2087886 | R17: 2107203 | S17: 2111310 | T17: 2105800 | U17: 2101249 | V17: 2102695 | W17: 2110416 | X17: 2123448 | Y17: 2141683 | Z17: 2163087 | AA17: 2185014 | AB17: 2204713 | AC17: 2219616 | AD17: 2232663 | AE17: 2246547 | AF17: 2263528 | AG17: 2287929 | AH17: 2315565 | AI17: 2333505 | AJ17: 2336861 | AK17: 2330481 | AL17: 2318624 | AM17: 2305222 | AN17: 2296977 | AO17: 2301640 | AP17: 2319369 | AQ17: 2334832 | AR17: 2333097 | AS17: 2315984 | AT17: 2294795 | AU17: 2279466 | AV17: 2272603 | AW17: 2273346 | AX17: 2280230 | AY17: 2288199 | AZ17: 2290304 | BA17: 2281011 | BB17: 2259749 | BC17: 2231340 | BD17: 2205801 | BE17: 2186751 | BF17: 2165573 | BG17: 2132430 | BH17: 2096999 | BI17: 2081439 | BJ17: 2075101 | BK17: 2065506 | BL17: 2057476 | BM17: 2036996 | BN17: 2010486 | BO17: 1990006 | BP17: 1968624 | BQ17: 1946697 | BR17: 1924533 | BS17: 1902380 | BT17: 1880421 | BU17: 1858599 | BV17: 1836668 | BW17: 1814474 | BX17: 1792306 | BY17: 1770540 | BZ17: 1749195 | CA17: 1728171 | CB17: 1707359 | CC17: 1686735 | CD17: 1666434 | CE17: 1646488 | CF17: 1626966 | CG17: 1607926 | CH17: 1589189 | CI17: 1570568 | CJ17: 1552013 | CK17: 1533626 | CL17: 1515545 | CM17: 1497672 | CN17: 1479775 | CO17: 1461822 | CP17: 1443992 | CQ17: 1426490 | CR17: 1409298 | CS17: 1392195 | CT17: 1375134 | CU17: 1358251 | CV17: 1341702 | CW17: 1325496 | CX17: 1309451
... A115: 109 | B115: 0 | C115: 2 | D115: 2 | E115: 2 | F115: 2 | G115: 2 | H115: 2 | I115: 1 | J115: 1 | K115: 1 | L115: 2 | M115: 2 | N115: 2 | O115: 2 | P115: 2 | Q115: 2 | R115: 2 | S115: 2 | T115: 2 | U115: 4 | V115: 5 | W115: 4 | X115: 5 | Y115: 5 | Z115: 7 | AA115: 7 | AB115: 5 | AC115: 7 | AD115: 8 | AE115: 8 | AF115: 10 | AG115: 10 | AH115: 11 | AI115: 11 | AJ115: 14 | AK115: 15 | AL115: 16 | AM115: 20 | AN115: 20 | AO115: 21 | AP115: 29 | AQ115: 35 | AR115: 30 | AS115: 33 | AT115: 37 | AU115: 41 | AV115: 44 | AW115: 51 | AX115: 57 | AY115: 62 | AZ115: 52 | BA115: 47 | BB115: 70 | BC115: 94 | BD115: 101 | BE115: 110 | BF115: 117 | BG115: 124 | BH115: 130 | BI115: 138 | BJ115: 150 | BK115: 167 | BL115: 188 | BM115: 215 | BN115: 243 | BO115: 274 | BP115: 308 | BQ115: 341 | BR115: 375 | BS115: 412 | BT115: 454 | BU115: 501 | BV115: 551 | BW115: 606 | BX115: 663 | BY115: 727 | BZ115: 800 | CA115: 880 | CB115: 968 | CC115: 1065 | CD115: 1170 | CE115: 1280 | CF115: 1400 | CG115: 1536 | CH115: 1678 | CI115: 1823 | CJ115: 1979 | CK115: 2142 | CL115: 2315 | CM115: 2495 | CN115: 2702 | CO115: 2957 | CP115: 3254 | CQ115: 3601 | CR115: 3978 | CS115: 4359 | CT115: 4758 | CU115: 5200 | CV115: 5684 | CW115: 6204 | CX115: 6752

Sheet Nacimientos y e0
A1: Nacimientos y otros indicadores nacionales de CONAPO, 1970-2070
A2: Fuente: CONAPO, 05_indicadores_demograficos_proyecciones.csv, fila 'República Mexicana'. Las columnas de verificación comparan los totales de CONAPO con la suma de las matrices de Defunciones y Población.
A5: Año | B5: Nacimientos (NAC) | C5: Defunciones totales (DEF) | D5: Defunciones: suma de la hoja Defunciones | E5: Diferencia | F5: Población a mitad de año (POB_MIT_ANIO) | G5: Población: suma de la hoja Población | H5: Diferencia | I5: Mortalidad infantil (TMI, por mil) | J5: e0 total (EV) | K5: e0 hombres (EVH) | L5: e0 mujeres (EVM)
A6: 1970 | B6: 2243380 | C6: 533249 | D6: =SUM(Defunciones!B6:B115) -> 533249 | E6: =D6-C6 -> 0 | F6: 51560567 | G6: =SUM(Población!B6:B115) -> 51560567 | H6: =G6-F6 -> 0 | I6: 75.65 | J6: 60.3 | K6: 58.37 | L6: 62.32
A7: 1971 | B7: 2285482 | C7: 491910 | D7: =SUM(Defunciones!C6:C115) -> 491910 | E7: =D7-C7 -> 0 | F7: 53133584 | G7: =SUM(Población!C6:C115) -> 53133584 | H7: =G7-F7 -> 0 | I7: 70.29 | J7: 62.35 | K7: 60.52 | L7: 64.23
A8: 1972 | B8: 2329428 | C8: 493549 | D8: =SUM(Defunciones!D6:D115) -> 493549 | E8: =D8-C8 -> 0 | F8: 54758696 | G8: =SUM(Población!D6:D115) -> 54758696 | H8: =G8-F8 -> 0 | I8: 68.58 | J8: 62.75 | K8: 60.8 | L8: 64.78
A9: 1973 | B9: 2365422 | C9: 495176 | D9: =SUM(Defunciones!E6:E115) -> 495176 | E9: =D9-C9 -> 0 | F9: 56414565 | G9: =SUM(Población!E6:E115) -> 56414565 | H9: =G9-F9 -> 0 | I9: 66.96 | J9: 63.07 | K9: 61.02 | L9: 65.2
A10: 1974 | B10: 2386659 | C10: 483720 | D10: =SUM(Defunciones!F6:F115) -> 483720 | E10: =D10-C10 -> 0 | F10: 58097331 | G10: =SUM(Población!F6:F115) -> 58097331 | H10: =G10-F10 -> 0 | I10: 65.19 | J10: 63.96 | K10: 61.5 | L10: 66.56
A11: 1975 | B11: 2391784 | C11: 481437 | D11: =SUM(Defunciones!G6:G115) -> 481437 | E11: =D11-C11 -> 0 | F11: 59792538 | G11: =SUM(Población!G6:G115) -> 59792538 | H11: =G11-F11 -> 0 | I11: 63.19 | J11: 64.41 | K11: 61.96 | L11: 66.99
A12: 1976 | B12: 2380585 | C12: 480050 | D12: =SUM(Defunciones!H6:H115) -> 480050 | E12: =D12-C12 -> 0 | F12: 61476071 | G12: =SUM(Población!H6:H115) -> 61476071 | H12: =G12-F12 -> 0 | I12: 61.02 | J12: 64.8 | K12: 62.23 | L12: 67.5
A13: 1977 | B13: 2365572 | C13: 473380 | D13: =SUM(Defunciones!I6:I115) -> 473380 | E13: =D13-C13 -> 0 | F13: 63139218 | G13: =SUM(Población!I6:I115) -> 63139218 | H13: =G13-F13 -> 0 | I13: 58.71 | J13: 65.37 | K13: 62.59 | L13: 68.31
A14: 1978 | B14: 2356245 | C14: 469651 | D14: =SUM(Defunciones!J6:J115) -> 469651 | E14: =D14-C14 -> 0 | F14: 64788304 | G14: =SUM(Población!J6:J115) -> 64788304 | H14: =G14-F14 -> 0 | I14: 56.2 | J14: 65.86 | K14: 63.03 | L14: 68.85
A15: 1979 | B15: 2355622 | C15: 468612 | D15: =SUM(Defunciones!K6:K115) -> 468612 | E15: =D15-C15 -> 0 | F15: 66431403 | G15: =SUM(Población!K6:K115) -> 66431403 | H15: =G15-F15 -> 0 | I15: 53.6 | J15: 66.23 | K15: 63.21 | L15: 69.43
A16: 1980 | B16: 2362498 | C16: 472136 | D16: =SUM(Defunciones!L6:L115) -> 472136 | E16: =D16-C16 -> 0 | F16: 68072118 | G16: =SUM(Población!L6:L115) -> 68072118 | H16: =G16-F16 -> 0 | I16: 51.04 | J16: 66.43 | K16: 63.32 | L16: 69.73
A17: 1981 | B17: 2375140 | C17: 464790 | D17: =SUM(Defunciones!M6:M115) -> 464790 | E17: =D17-C17 -> 0 | F17: 69715468 | G17: =SUM(Población!M6:M115) -> 69715468 | H17: =G17-F17 -> 0 | I17: 48.72 | J17: 67.1 | K17: 63.98 | L17: 70.39
A18: 1982 | B18: 2394231 | C18: 458486 | D18: =SUM(Defunciones!N6:N115) -> 458486 | E18: =D18-C18 -> 0 | F18: 71369508 | G18: =SUM(Población!N6:N115) -> 71369508 | H18: =G18-F18 -> 0 | I18: 46.71 | J18: 67.77 | K18: 64.57 | L18: 71.15
A19: 1983 | B19: 2414075 | C19: 456922 | D19: =SUM(Defunciones!O6:O115) -> 456922 | E19: =D19-C19 -> 0 | F19: 73034559 | G19: =SUM(Población!O6:O115) -> 73034559 | H19: =G19-F19 -> 0 | I19: 44.9 | J19: 68.26 | K19: 65.34 | L19: 71.32
A20: 1984 | B20: 2434522 | C20: 453838 | D20: =SUM(Defunciones!P6:P115) -> 453838 | E20: =D20-C20 -> 0 | F20: 74707346 | G20: =SUM(Población!P6:P115) -> 74707346 | H20: =G20-F20 -> 0 | I20: 43.15 | J20: 68.8 | K20: 65.92 | L20: 71.8
A21: 1985 | B21: 2449740 | C21: 458609 | D21: =SUM(Defunciones!Q6:Q115) -> 458609 | E21: =D21-C21 -> 0 | F21: 76375259 | G21: =SUM(Población!Q6:Q115) -> 76375259 | H21: =G21-F21 -> 0 | I21: 41.4 | J21: 69 | K21: 66.15 | L21: 71.97
A22: 1986 | B22: 2459509 | C22: 448911 | D22: =SUM(Defunciones!R6:R115) -> 448911 | E22: =D22-C22 -> 0 | F22: 78028665 | G22: =SUM(Población!R6:R115) -> 78028665 | H22: =G22-F22 -> 0 | I22: 39.63 | J22: 69.79 | K22: 66.97 | L22: 72.71
A23: 1987 | B23: 2470501 | C23: 448535 | D23: =SUM(Defunciones!S6:S115) -> 448535 | E23: =D23-C23 -> 0 | F23: 79665004 | G23: =SUM(Población!S6:S115) -> 79665004 | H23: =G23-F23 -> 0 | I23: 37.81 | J23: 70.18 | K23: 67.39 | L23: 73.07
A24: 1988 | B24: 2485018 | C24: 454729 | D24: =SUM(Defunciones!T6:T115) -> 454729 | E24: =D24-C24 -> 0 | F24: 81282371 | G24: =SUM(Población!T6:T115) -> 81282371 | H24: =G24-F24 -> 0 | I24: 35.89 | J24: 70.33 | K24: 67.44 | L24: 73.33
A25: 1989 | B25: 2507098 | C25: 460980 | D25: =SUM(Defunciones!U6:U115) -> 460980 | E25: =D25-C25 -> 0 | F25: 82889981 | G25: =SUM(Población!U6:U115) -> 82889981 | H25: =G25-F25 -> 0 | I25: 36.92 | J25: 70.52 | K25: 67.67 | L25: 73.46
A26: 1990 | B26: 2530460 | C26: 456665 | D26: =SUM(Defunciones!V6:V115) -> 456665 | E26: =D26-C26 -> 0 | F26: 84502988 | G26: =SUM(Población!V6:V115) -> 84502988 | H26: =G26-F26 -> 0 | I26: 34.75 | J26: 71.07 | K26: 68.28 | L26: 73.91
A27: 1991 | B27: 2547866 | C27: 449860 | D27: =SUM(Defunciones!W6:W115) -> 449860 | E27: =D27-C27 -> 0 | F27: 86127477 | G27: =SUM(Población!W6:W115) -> 86127477 | H27: =G27-F27 -> 0 | I27: 30.81 | J27: 71.65 | K27: 68.88 | L27: 74.48
A28: 1992 | B28: 2551319 | C28: 452648 | D28: =SUM(Defunciones!X6:X115) -> 452648 | E28: =D28-C28 -> 0 | F28: 87753131 | G28: =SUM(Población!X6:X115) -> 87753131 | H28: =G28-F28 -> 0 | I28: 29.59 | J28: 71.93 | K28: 69.16 | L28: 74.75
A29: 1993 | B29: 2541501 | C29: 459704 | D29: =SUM(Defunciones!Y6:Y115) -> 459704 | E29: =D29-C29 -> 0 | F29: 89364560 | G29: =SUM(Población!Y6:Y115) -> 89364560 | H29: =G29-F29 -> 0 | I29: 28.53 | J29: 72.05 | K29: 69.44 | L29: 74.7
A30: 1994 | B30: 2522437 | C30: 463160 | D30: =SUM(Defunciones!Z6:Z115) -> 463160 | E30: =D30-C30 -> 0 | F30: 90953505 | G30: =SUM(Población!Z6:Z115) -> 90953505 | H30: =G30-F30 -> 0 | I30: 27.56 | J30: 72.3 | K30: 69.69 | L30: 74.94
A31: 1995 | B31: 2497265 | C31: 474986 | D31: =SUM(Defunciones!AA6:AA115) -> 474986 | E31: =D31-C31 -> 0 | F31: 92506744 | G31: =SUM(Población!AA6:AA115) -> 92506744 | H31: =G31-F31 -> 0 | I31: 26.65 | J31: 72.27 | K31: 69.79 | L31: 74.79
