Workbook

Sheet Leeme
A1: Tablas de mortalidad de generaciones mexicanas (1950, 1960, 1970, 1980, 1990, 2000)
A3: Fuente | B3: ONU, División de Población, World Population Prospects 2024 (variante media): población a mitad de año y defunciones por edad simple, México, 1950-2100 (https://population.un.org/wpp/). 1950-2023 estimaciones; 2024-2100 proyecciones.
A4: Radix (l0) | B4: 100000 | C4: <- nombre definido 'Radix'; se usa en todas las tablas
A6: Método | B6: Generación g = personas nacidas en el año g. La edad x de esa generación se observa en el año calendario g + x.
B7: qx = defunciones(x, g+x) / (población a mitad de año(x, g+x) + defunciones(x, g+x)/2)
B8: Edad 100 = grupo abierto (100+): qx = 1.
B9: lx: l0 = radix; l(x+1) = lx − dx. dx = lx · qx.
B10: Lx = l(x+1) + dx/2 (a la edad 100, l101 = 0, así que L100 = d100/2 = l100/2).
B11: Tx = suma de Lx desde x hasta 100. ex = Tx / lx.
A13: Hojas | B13: Gen_1950 … Gen_2000: tabla completa por generación, con Hombres, Mujeres y Ambos sexos (columnas C-J, K-R, S-Z).
B14: Comparacion: indicadores y gráficos de ex, lx y e0 por año calendario (datos en Datos_Graficos).
B15: Validacion: contraste con la esperanza de vida oficial de la ONU (apoyada en Periodo, ONU_e0, ONU_qx y Val_Diagonal_ONU).
B16: Datos_ONU, ONU_qx, ONU_e0: datos de entrada de la ONU (México).
A18: Colores | B18: Azul = dato fijo / entrada. Negro = fórmula. Verde = vínculo a otra hoja. Fondo amarillo = supuesto editable.
A19: Limitaciones | B19: (1) Defunciones y población son de periodo-edad, no de triángulos de Lexis: aproximan la generación con la población de edad x a mitad del año g + x. (2) Con qx = 1 a los 100 años, e100 = 0.5 años (la ONU estima 1.3-3.0): subestima e0 hasta ≈ 0.1 años en la generación 2000 (ver Validacion). (2b) q0 = D/(P + D/2) sobrestima algo la mortalidad infantil de 1950 (0.163 vs 0.157 oficial). (3) Los años posteriores a 2023 son proyección: las generaciones 1960-2000 son tablas parcialmente proyectadas.

Sheet Gen_1950
A1: Tabla de mortalidad de la generación 1950 - México (ONU WPP 2024)
A2: Generación (año de nacimiento): | D2: 1950 | F2: Radix: | G2: =Radix -> 100000
E3: e0: | F3: =J6 -> 52.443355 | G3: Control Σdx−radix: | I3: =SUM(G6:G106)-Radix -> 0 | M3: e0: | N3: =R6 -> 57.88133 | O3: Control Σdx−radix: | Q3: =SUM(O6:O106)-Radix -> 0 | U3: e0: | V3: =Z6 -> 55.110432 | W3: Control Σdx−radix: | Y3: =SUM(W6:W106)-Radix -> 0
C4: Hombres | K4: Mujeres | S4: Ambos sexos
A5: Edad x | B5: Año calendario | C5: Población a mitad de año (miles) | D5: Defunciones (miles) | E5: qx | F5: lx | G5: dx | H5: Lx | I5: Tx | J5: ex | K5: Población a mitad de año (miles) | L5: Defunciones (miles) | M5: qx | N5: lx | O5: dx | P5: Lx | Q5: Tx | R5: ex | S5: Población a mitad de año (miles) | T5: Defunciones (miles) | U5: qx | V5: lx | W5: dx | X5: Lx | Y5: Tx | Z5: ex
A6: 0 | B6: =$D$2+$A6 -> 1950 | C6: =INDEX(Datos_ONU!$B$6:$EV$106,MATCH($A6,Datos_ONU!$A$6:$A$106,0),MATCH($B6,Datos_ONU!$B$5:$EV$5,0)) -> 608.731 | D6: =INDEX(Datos_ONU!$B$321:$EV$421,MATCH($A6,Datos_ONU!$A$321:$A$421,0),MATCH($B6,Datos_ONU!$B$320:$EV$320,0)) -> 114.79 | E6: =IF($A6=100,1,D6/(C6+D6/2)) -> 0.17232476 | F6: =Radix -> 100000 | G6: =F6*E6 -> 17232.476 | H6: =F7+G6/2 -> 91383.762 | I6: =SUM(H6:H$106) -> 5244335.5 | J6: =I6/F6 -> 52.443355 | K6: =INDEX(Datos_ONU!$B$111:$EV$211,MATCH($A6,Datos_ONU!$A$111:$A$211,0),MATCH($B6,Datos_ONU!$B$110:$EV$110,0)) -> 593.594 | L6: =INDEX(Datos_ONU!$B$426:$EV$526,MATCH($A6,Datos_ONU!$A$426:$A$526,0),MATCH($B6,Datos_ONU!$B$425:$EV$425,0)) -> 98.595 | M6: =IF($A6=100,1,L6/(K6+L6/2)) -> 0.1533618 | N6: =Radix -> 100000 | O6: =N6*M6 -> 15336.18 | P6: =N7+O6/2 -> 92331.91 | Q6: =SUM(P6:P$106) -> 5788133 | R6: =Q6/N6 -> 57.88133 | S6: =INDEX(Datos_ONU!$B$216:$EV$316,MATCH($A6,Datos_ONU!$A$216:$A$316,0),MATCH($B6,Datos_ONU!$B$215:$EV$215,0)) -> 1202.325 | T6: =INDEX(Datos_ONU!$B$531:$EV$631,MATCH($A6,Datos_ONU!$A$531:$A$631,0),MATCH($B6,Datos_ONU!$B$530:$EV$530,0)) -> 213.385 | U6: =IF($A6=100,1,T6/(S6+T6/2)) -> 0.16301157 | V6: =Radix -> 100000 | W6: =V6*U6 -> 16301.157 | X6: =V7+W6/2 -> 91849.421 | Y6: =SUM(X6:X$106) -> 5511043.2 | Z6: =Y6/V6 -> 55.110432
A7: 1 | B7: =$D$2+$A7 -> 1951 | C7: =INDEX(Datos_ONU!$B$6:$EV$106,MATCH($A7,Datos_ONU!$A$6:$A$106,0),MATCH($B7,Datos_ONU!$B$5:$EV$5,0)) -> 561.197 | D7: =INDEX(Datos_ONU!$B$321:$EV$421,MATCH($A7,Datos_ONU!$A$321:$A$421,0),MATCH($B7,Datos_ONU!$B$320:$EV$320,0)) -> 25.572 | E7: =IF($A7=100,1,D7/(C7+D7/2)) -> 0.044551842 | F7: =F6-G6 -> 82767.524 | G7: =F7*E7 -> 3687.4457 | H7: =F8+G7/2 -> 80923.802 | I7: =SUM(H7:H$106) -> 5152951.7 | J7: =I7/F7 -> 62.258135 | K7: =INDEX(Datos_ONU!$B$111:$EV$211,MATCH($A7,Datos_ONU!$A$111:$A$211,0),MATCH($B7,Datos_ONU!$B$110:$EV$110,0)) -> 550.08 | L7: =INDEX(Datos_ONU!$B$426:$EV$526,MATCH($A7,Datos_ONU!$A$426:$A$526,0),MATCH($B7,Datos_ONU!$B$425:$EV$425,0)) -> 24.34 | M7: =IF($A7=100,1,L7/(K7+L7/2)) -> 0.043290351 | N7: =N6-O6 -> 84663.82 | O7: =N7*M7 -> 3665.1265 | P7: =N8+O7/2 -> 82831.256 | Q7: =SUM(P7:P$106) -> 5695801.1 | R7: =Q7/N7 -> 67.275503 | S7: =INDEX(Datos_ONU!$B$216:$EV$316,MATCH($A7,Datos_ONU!$A$216:$A$316,0),MATCH($B7,Datos_ONU!$B$215:$EV$215,0)) -> 1111.276 | T7: =INDEX(Datos_ONU!$B$531:$EV$631,MATCH($A7,Datos_ONU!$A$531:$A$631,0),MATCH($B7,Datos_ONU!$B$530:$EV$530,0)) -> 49.912 | U7: =IF($A7=100,1,T7/(S7+T7/2)) -> 0.043927649 | V7: =V6-W6 -> 83698.843 | W7: =V7*U7 -> 3676.6934 | X7: =V8+W7/2 -> 81860.496 | Y7: =SUM(X7:X$106) -> 5419193.8 | Z7: =Y7/V7 -> 64.746341
A8: 2 | B8: =$D$2+$A8 -> 1952 | C8: =INDEX(Datos_ONU!$B$6:$EV$106,MATCH($A8,Datos_ONU!$A$6:$A$106,0),MATCH($B8,Datos_ONU!$B$5:$EV$5,0)) -> 540.859 | D8: =INDEX(Datos_ONU!$B$321:$EV$421,MATCH($A8,Datos_ONU!$A$321:$A$421,0),MATCH($B8,Datos_ONU!$B$320:$EV$320,0)) -> 14.668 | E8: =IF($A8=100,1,D8/(C8+D8/2)) -> 0.026757 | F8: =F7-G7 -> 79080.079 | G8: =F8*E8 -> 2115.9457 | H8: =F9+G8/2 -> 78022.106 | I8: =SUM(H8:H$106) -> 5072027.9 | J8: =I8/F8 -> 64.137871 | K8: =INDEX(Datos_ONU!$B$111:$EV$211,MATCH($A8,Datos_ONU!$A$111:$A$211,0),MATCH($B8,Datos_ONU!$B$110:$EV$110,0)) -> 530.672 | L8: =INDEX(Datos_ONU!$B$426:$EV$526,MATCH($A8,Datos_ONU!$A$426:$A$526,0),MATCH($B8,Datos_ONU!$B$425:$EV$425,0)) -> 14.1 | M8: =IF($A8=100,1,L8/(K8+L8/2)) -> 0.026221728 | N8: =N7-O7 -> 80998.693 | O8: =N8*M8 -> 2123.9257 | P8: =N9+O8/2 -> 79936.73 | Q8: =SUM(P8:P$106) -> 5612969.8 | R8: =Q8/N8 -> 69.297042 | S8: =INDEX(Datos_ONU!$B$216:$EV$316,MATCH($A8,Datos_ONU!$A$216:$A$316,0),MATCH($B8,Datos_ONU!$B$215:$EV$215,0)) -> 1071.53 | T8: =INDEX(Datos_ONU!$B$531:$EV$631,MATCH($A8,Datos_ONU!$A$531:$A$631,0),MATCH($B8,Datos_ONU!$B$530:$EV$530,0)) -> 28.768 | U8: =IF($A8=100,1,T8/(S8+T8/2)) -> 0.026491969 | V8: =V7-W7 -> 80022.149 | W8: =V8*U8 -> 2119.9443 | X8: =V9+W8/2 -> 78962.177 | Y8: =SUM(X8:X$106) -> 5337333.3 | Z8: =Y8/V8 -> 66.698199
A9: 3 | B9: =$D$2+$A9 -> 1953 | C9: =INDEX(Datos_ONU!$B$6:$EV$106,MATCH($A9,Datos_ONU!$A$6:$A$106,0),MATCH($B9,Datos_ONU!$B$5:$EV$5,0)) -> 528.694 | D9: =INDEX(Datos_ONU!$B$321:$EV$421,MATCH($A9,Datos_ONU!$A$321:$A$421,0),MATCH($B9,Datos_ONU!$B$320:$EV$320,0)) -> 8.641 | E9: =IF($A9=100,1,D9/(C9+D9/2)) -> 0.016211566 | F9: =F8-G8 -> 76964.133 | G9: =F9*E9 -> 1247.7092 | H9: =F10+G9/2 -> 76340.279 | I9: =SUM(H9:H$106) -> 4994005.8 | J9: =I9/F9 -> 64.887443 | K9: =INDEX(Datos_ONU!$B$111:$EV$211,MATCH($A9,Datos_ONU!$A$111:$A$211,0),MATCH($B9,Datos_ONU!$B$110:$EV$110,0)) -> 518.913 | L9: =INDEX(Datos_ONU!$B$426:$EV$526,MATCH($A9,Datos_ONU!$A$426:$A$526,0),MATCH($B9,Datos_ONU!$B$425:$EV$425,0)) -> 8.444 | M9: =IF($A9=100,1,L9/(K9+L9/2)) -> 0.016141149 | N9: =N8-O8 -> 78874.767 | O9: =N9*M9 -> 1273.1294 | P9: =N10+O9/2 -> 78238.203 | Q9: =SUM(P9:P$106) -> 5533033.1 | R9: =Q9/N9 -> 70.149596 | S9: =INDEX(Datos_ONU!$B$216:$EV$316,MATCH($A9,Datos_ONU!$A$216:$A$316,0),MATCH($B9,Datos_ONU!$B$215:$EV$215,0)) -> 1047.607 | T9: =INDEX(Datos_ONU!$B$531:$EV$631,MATCH($A9,Datos_ONU!$A$531:$A$631,0),MATCH($B9,Datos_ONU!$B$530:$EV$530,0)) -> 17.085 | U9: =IF($A9=100,1,T9/(S9+T9/2)) -> 0.016176687 | V9: =V8-W8 -> 77902.205 | W9: =V9*U9 -> 1260.1996 | X9: =V10+W9/2 -> 77272.105 | Y9: =SUM(X9:X$106) -> 5258371.1 | Z9: =Y9/V9 -> 67.499644
A10: 4 | B10: =$D$2+$A10 -> 1954 | C10: =INDEX(Datos_ONU!$B$6:$EV$106,MATCH($A10,Datos_ONU!$A$6:$A$106,0),MATCH($B10,Datos_ONU!$B$5:$EV$5,0)) -> 521.215 | D10: =INDEX(Datos_ONU!$B$321:$EV$421,MATCH($A10,Datos_ONU!$A$321:$A$421,0),MATCH($B10,Datos_ONU!$B$320:$EV$320,0)) -> 5.302 | E10: =IF($A10=100,1,D10/(C10+D10/2)) -> 0.010120909 | F10: =F9-G9 -> 75716.424 | G10: =F10*E10 -> 766.31902 | H10: =F11+G10/2 -> 75333.264 | I10: =SUM(H10:H$106) -> 4917665.5 | J10: =I10/F10 -> 64.948465 | K10: =INDEX(Datos_ONU!$B$111:$EV$211,MATCH($A10,Datos_ONU!$A$111:$A$211,0),MATCH($B10,Datos_ONU!$B$110:$EV$110,0)) -> 511.571 | L10: =INDEX(Datos_ONU!$B$426:$EV$526,MATCH($A10,Datos_ONU!$A$426:$A$526,0),MATCH($B10,Datos_ONU!$B$425:$EV$425,0)) -> 5.265 | M10: =IF($A10=100,1,L10/(K10+L10/2)) -> 0.010239137 | N10: =N9-O9 -> 77601.638 | O10: =N10*M10 -> 794.57379 | P10: =N11+O10/2 -> 77204.351 | Q10: =SUM(P10:P$106) -> 5454794.9 | R10: =Q10/N10 -> 70.292265 | S10: =INDEX(Datos_ONU!$B$216:$EV$316,MATCH($A10,Datos_ONU!$A$216:$A$316,0),MATCH($B10,Datos_ONU!$B$215:$EV$215,0)) -> 1032.786 | T10: =INDEX(Datos_ONU!$B$531:$EV$631,MATCH($A10,Datos_ONU!$A$531:$A$631,0),MATCH($B10,Datos_ONU!$B$530:$EV$530,0)) -> 10.568 | U10: =IF($A10=100,1,T10/(S10+T10/2)) -> 0.010180431 | V10: =V9-W9 -> 76642.006 | W10: =V10*U10 -> 780.24865 | X10: =V11+W10/2 -> 76251.881 | Y10: =SUM(X10:X$106) -> 5181099 | Z10: =Y10/V10 -> 67.601297
A11: 5 | B11: =$D$2+$A11 -> 1955 | C11: =INDEX(Datos_ONU!$B$6:$EV$106,MATCH($A11,Datos_ONU!$A$6:$A$106,0),MATCH($B11,Datos_ONU!$B$5:$EV$5,0)) -> 516.495 | D11: =INDEX(Datos_ONU!$B$321:$EV$421,MATCH($A11,Datos_ONU!$A$321:$A$421,0),MATCH($B11,Datos_ONU!$B$320:$EV$320,0)) -> 3.083 | E11: =IF($A11=100,1,D11/(C11+D11/2)) -> 0.0059513181 | F11: =F10-G10 -> 74950.105 | G11: =F11*E11 -> 446.05192 | H11: =F12+G11/2 -> 74727.079 | I11: =SUM(H11:H$106) -> 4842332.3 | J11: =I11/F11 -> 64.607411 | K11: =INDEX(Datos_ONU!$B$111:$EV$211,MATCH($A11,Datos_ONU!$A$111:$A$211,0),MATCH($B11,Datos_ONU!$B$110:$EV$110,0)) -> 506.872 | L11: =INDEX(Datos_ONU!$B$426:$EV$526,MATCH($A11,Datos_ONU!$A$426:$A$526,0),MATCH($B11,Datos_ONU!$B$425:$EV$425,0)) -> 3.125 | M11: =IF($A11=100,1,L11/(K11+L11/2)) -> 0.0061463178 | N11: =N10-O10 -> 76807.064 | O11: =N11*M11 -> 472.08062 | P11: =N12+O11/2 -> 76571.024 | Q11: =SUM(P11:P$106) -> 5377590.6 | R11: =Q11/N11 -> 70.01427 | S11: =INDEX(Datos_ONU!$B$216:$EV$316,MATCH($A11,Datos_ONU!$A$216:$A$316,0),MATCH($B11,Datos_ONU!$B$215:$EV$215,0)) -> 1023.366 | T11: =INDEX(Datos_ONU!$B$531:$EV$631,MATCH($A11,Datos_ONU!$A$531:$A$631,0),MATCH($B11,Datos_ONU!$B$530:$EV$530,0)) -> 6.208 | U11: =IF($A11=100,1,T11/(S11+T11/2)) -> 0.0060479118 | V11: =V10-W10 -> 75861.757 | W11: =V11*U11 -> 458.80521 | X11: =V12+W11/2 -> 75632.354 | Y11: =SUM(X11:X$106) -> 5104847.1 | Z11: =Y11/V11 -> 67.291443
A12: 6 | B12: =$D$2+$A12 -> 1956 | C12: =INDEX(Datos_ONU!$B$6:$EV$106,MATCH($A12,Datos_ONU!$A$6:$A$106,0),MATCH($B12,Datos_ONU!$B$5:$EV$5,0)) -> 513.368 | D12: =INDEX(Datos_ONU!$B$321:$EV$421,MATCH($A12,Datos_ONU!$A$321:$A$421,0),MATCH($B12,Datos_ONU!$B$320:$EV$320,0)) -> 2.06 | E12: =IF($A12=100,1,D12/(C12+D12/2)) -> 0.0040046812 | F12: =F11-G11 -> 74504.053 | G12: =F12*E12 -> 298.36498 | H12: =F13+G12/2 -> 74354.871 | I12: =SUM(H12:H$106) -> 4767605.2 | J12: =I12/F12 -> 63.991219 | K12: =INDEX(Datos_ONU!$B$111:$EV$211,MATCH($A12,Datos_ONU!$A$111:$A$211,0),MATCH($B12,Datos_ONU!$B$110:$EV$110,0)) -> 503.74 | L12: =INDEX(Datos_ONU!$B$426:$EV$526,MATCH($A12,Datos_ONU!$A$426:$A$526,0),MATCH($B12,Datos_ONU!$B$425:$EV$425,0)) -> 2.083 | M12: =IF($A12=100,1,L12/(K12+L12/2)) -> 0.0041265379 | N12: =N11-O11 -> 76334.984 | O12: =N12*M12 -> 314.9992 | P12: =N13+O12/2 -> 76177.484 | Q12: =SUM(P12:P$106) -> 5301019.5 | R12: =Q12/N12 -> 69.444169 | S12: =INDEX(Datos_ONU!$B$216:$EV$316,MATCH($A12,Datos_ONU!$A$216:$A$316,0),MATCH($B12,Datos_ONU!$B$215:$EV$215,0)) -> 1017.108 | T12: =INDEX(Datos_ONU!$B$531:$EV$631,MATCH($A12,Datos_ONU!$A$531:$A$631,0),MATCH($B12,Datos_ONU!$B$530:$EV$530,0)) -> 4.143 | U12: =IF($A12=100,1,T12/(S12+T12/2)) -> 0.0040650347 | V12: =V11-W11 -> 75402.952 | W12: =V12*U12 -> 306.51561 | X12: =V13+W12/2 -> 75249.694 | Y12: =SUM(X12:X$106) -> 5029214.8 | Z12: =Y12/V12 -> 66.69785
A13: 7 | B13: =$D$2+$A13 -> 1957 | C13: =INDEX(Datos_ONU!$B$6:$EV$106,MATCH($A13,Datos_ONU!$A$6:$A$106,0),MATCH($B13,Datos_ONU!$B$5:$EV$5,0)) -> 511.041 | D13: =INDEX(Datos_ONU!$B$321:$EV$421,MATCH($A13,Datos_ONU!$A$321:$A$421,0),MATCH($B13,Datos_ONU!$B$320:$EV$320,0)) -> 1.445 | E13: =IF($A13=100,1,D13/(C13+D13/2)) -> 0.0028235699 | F13: =F12-G12 -> 74205.688 | G13: =F13*E13 -> 209.52495 | H13: =F14+G13/2 -> 74100.926 | I13: =SUM(H13:H$106) -> 4693250.3 | J13: =I13/F13 -> 63.246504 | K13: =INDEX(Datos_ONU!$B$111:$EV$211,MATCH($A13,Datos_ONU!$A$111:$A$211,0),MATCH($B13,Datos_ONU!$B$110:$EV$110,0)) -> 501.443 | L13: =INDEX(Datos_ONU!$B$426:$EV$526,MATCH($A13,Datos_ONU!$A$426:$A$526,0),MATCH($B13,Datos_ONU!$B$425:$EV$425,0)) -> 1.424 | M13: =IF($A13=100,1,L13/(K13+L13/2)) -> 0.0028357778 | N13: =N12-O12 -> 76019.984 | O13: =N13*M13 -> 215.57578 | P13: =N14+O13/2 -> 75912.197 | Q13: =SUM(P13:P$106) -> 5224842 | R13: =Q13/N13 -> 68.729849 | S13: =INDEX(Datos_ONU!$B$216:$EV$316,MATCH($A13,Datos_ONU!$A$216:$A$316,0),MATCH($B13,Datos_ONU!$B$215:$EV$215,0)) -> 1012.484 | T13: =INDEX(Datos_ONU!$B$531:$EV$631,MATCH($A13,Datos_ONU!$A$531:$A$631,0),MATCH($B13,Datos_ONU!$B$530:$EV$530,0)) -> 2.869 | U13: =IF($A13=100,1,T13/(S13+T13/2)) -> 0.002829616 | V13: =V12-W12 -> 75096.436 | W13: =V13*U13 -> 212.49408 | X13: =V14+W13/2 -> 74990.189 | Y13: =SUM(X13:X$106) -> 4953965.1 | Z13: =Y13/V13 -> 65.968045
A14: 8 | B14: =$D$2+$A14 -> 1958 | C14: =INDEX(Datos_ONU!$B$6:$EV$106,MATCH($A14,Datos_ONU!$A$6:$A$106,0),MATCH($B14,Datos_ONU!$B$5:$EV$5,0)) -> 509.091 | D14: =INDEX(Datos_ONU!$B$321:$EV$421,MATCH($A14,Datos_ONU!$A$321:$A$421,0),MATCH($B14,Datos_ONU!$B$320:$EV$320,0)) -> 1.239 | E14: =IF($A14=100,1,D14/(C14+D14/2)) -> 0.0024307916 | F14: =F13-G13 -> 73996.163 | G14: =F14*E14 -> 179.86925 | H14: =F15+G14/2 -> 73906.228 | I14: =SUM(H14:H$106) -> 4619149.4 | J14: =I14/F14 -> 62.424174 | K14: =INDEX(Datos_ONU!$B$111:$EV$211,MATCH($A14,Datos_ONU!$A$111:$A$211,0),MATCH($B14,Datos_ONU!$B$110:$EV$110,0)) -> 499.566 | L14: =INDEX(Datos_ONU!$B$426:$EV$526,MATCH($A14,Datos_ONU!$A$426:$A$526,0),MATCH($B14,Datos_ONU!$B$425:$EV$425,0)) -> 1.18 | M14: =IF($A14=100,1,L14/(K14+L14/2)) -> 0.0023592639 | N14: =N13-O13 -> 75804.409 | O14: =N14*M14 -> 178.84261 | P14: =N15+O14/2 -> 75714.987 | Q14: =SUM(P14:P$106) -> 5148929.8 | R14: =Q14/N14 -> 67.923884 | S14: =INDEX(Datos_ONU!$B$216:$EV$316,MATCH($A14,Datos_ONU!$A$216:$A$316,0),MATCH($B14,Datos_ONU!$B$215:$EV$215,0)) -> 1008.658 | T14: =INDEX(Datos_ONU!$B$531:$EV$631,MATCH($A14,Datos_ONU!$A$531:$A$631,0),MATCH($B14,Datos_ONU!$B$530:$EV$530,0)) -> 2.419 | U14: =IF($A14=100,1,T14/(S14+T14/2)) -> 0.0023953637 | V14: =V13-W13 -> 74883.942 | W14: =V14*U14 -> 179.37428 | X14: =V15+W14/2 -> 74794.255 | Y14: =SUM(X14:X$106) -> 4878974.9 | Z14: =Y14/V14 -> 65.15382
A15: 9 | B15: =$D$2+$A15 -> 1959 | C15: =INDEX(Datos_ONU!$B$6:$EV$106,MATCH($A15,Datos_ONU!$A$6:$A$106,0),MATCH($B15,Datos_ONU!$B$5:$EV$5,0)) -> 507.317 | D15: =INDEX(Datos_ONU!$B$321:$EV$421,MATCH($A15,Datos_ONU!$A$321:$A$421,0),MATCH($B15,Datos_ONU!$B$320:$EV$320,0)) -> 1.077 | E15: =IF($A15=100,1,D15/(C15+D15/2)) -> 0.002120682 | F15: =F14-G14 -> 73816.294 | G15: =F15*E15 -> 156.54088 | H15: =F16+G15/2 -> 73738.023 | I15: =SUM(H15:H$106) -> 4545243.2 | J15: =I15/F15 -> 61.575066 | K15: =INDEX(Datos_ONU!$B$111:$EV$211,MATCH($A15,Datos_ONU!$A$111:$A$211,0),MATCH($B15,Datos_ONU!$B$110:$EV$110,0)) -> 497.901 | L15: =INDEX(Datos_ONU!$B$426:$EV$526,MATCH($A15,Datos_ONU!$A$426:$A$526,0),MATCH($B15,Datos_ONU!$B$425:$EV$425,0)) -> 0.982 | M15: =IF($A15=100,1,L15/(K15+L15/2)) -> 0.0019703366 | N15: =N14-O14 -> 75625.566 | O15: =N15*M15 -> 149.00782 | P15: =N16+O15/2 -> 75551.062 | Q15: =SUM(P15:P$106) -> 5073214.9 | R15: =Q15/N15 -> 67.083331 | S15: =INDEX(Datos_ONU!$B$216:$EV$316,MATCH($A15,Datos_ONU!$A$216:$A$316,0),MATCH($B15,Datos_ONU!$B$215:$EV$215,0)) -> 1005.218 | T15: =INDEX(Datos_ONU!$B$531:$EV$631,MATCH($A15,Datos_ONU!$A$531:$A$631,0),MATCH($B15,Datos_ONU!$B$530:$EV$530,0)) -> 2.059 | U15: =IF($A15=100,1,T15/(S15+T15/2)) -> 0.0020462163 | V15: =V14-W14 -> 74704.568 | W15: =V15*U15 -> 152.8617 | X15: =V16+W15/2 -> 74628.137 | Y15: =SUM(X15:X$106) -> 4804180.6 | Z15: =Y15/V15 -> 64.309061
A16: 10 | B16: =$D$2+$A16 -> 1960 | C16: =INDEX(Datos_ONU!$B$6:$EV$106,MATCH($A16,Datos_ONU!$A$6:$A$106,0),MATCH($B16,Datos_ONU!$B$5:$EV$5,0)) -> 505.916 | D16: =INDEX(Datos_ONU!$B$321:$EV$421,MATCH($A16,Datos_ONU!$A$321:$A$421,0),MATCH($B16,Datos_ONU!$B$320:$EV$320,0)) -> 0.918 | E16: =IF($A16=100,1,D16/(C16+D16/2)) -> 0.0018128857 | F16: =F15-G15 -> 73659.753 | G16: =F16*E16 -> 133.53671 | H16: =F17+G16/2 -> 73592.985 | I16: =SUM(H16:H$106) -> 4471505.1 | J16: =I16/F16 -> 60.704862 | K16: =INDEX(Datos_ONU!$B$111:$EV$211,MATCH($A16,Datos_ONU!$A$111:$A$211,0),MATCH($B16,Datos_ONU!$B$110:$EV$110,0)) -> 496.391 | L16: =INDEX(Datos_ONU!$B$426:$EV$526,MATCH($A16,Datos_ONU!$A$426:$A$526,0),MATCH($B16,Datos_ONU!$B$425:$EV$425,0)) -> 0.797 | M16: =IF($A16=100,1,L16/(K16+L16/2)) -> 0.0016043012 | N16: =N15-O15 -> 75476.558 | O16: =N16*M16 -> 121.08713 | P16: =N17+O16/2 -> 75416.015 | Q16: =SUM(P16:P$106) -> 4997663.8 | R16: =Q16/N16 -> 66.214781 | S16: =INDEX(Datos_ONU!$B$216:$EV$316,MATCH($A16,Datos_ONU!$A$216:$A$316,0),MATCH($B16,Datos_ONU!$B$215:$EV$215,0)) -> 1002.308 | T16: =INDEX(Datos_ONU!$B$531:$EV$631,MATCH($A16,Datos_ONU!$A$531:$A$631,0),MATCH($B16,Datos_ONU!$B$530:$EV$530,0)) -> 1.716 | U16: =IF($A16=100,1,T16/(S16+T16/2)) -> 0.0017105843 | V16: =V15-W15 -> 74551.706 | W16: =V16*U16 -> 127.52698 | X16: =V17+W16/2 -> 74487.943 | Y16: =SUM(X16:X$106) -> 4729552.5 | Z16: =Y16/V16 -> 63.439896
A17: 11 | B17: =$D$2+$A17 -> 1961 | C17: =INDEX(Datos_ONU!$B$6:$EV$106,MATCH($A17,Datos_ONU!$A$6:$A$106,0),MATCH($B17,Datos_ONU!$B$5:$EV$5,0)) -> 504.926 | D17: =INDEX(Datos_ONU!$B$321:$EV$421,MATCH($A17,Datos_ONU!$A$321:$A$421,0),MATCH($B17,Datos_ONU!$B$320:$EV$320,0)) -> 0.821 | E17: =IF($A17=100,1,D17/(C17+D17/2)) -> 0.00162466 | F17: =F16-G16 -> 73526.216 | G17: =F17*E17 -> 119.4551 | H17: =F18+G17/2 -> 73466.489 | I17: =SUM(H17:H$106) -> 4397912.2 | J17: =I17/F17 -> 59.814205 | K17: =INDEX(Datos_ONU!$B$111:$EV$211,MATCH($A17,Datos_ONU!$A$111:$A$211,0),MATCH($B17,Datos_ONU!$B$110:$EV$110,0)) -> 495.511 | L17: =INDEX(Datos_ONU!$B$426:$EV$526,MATCH($A17,Datos_ONU!$A$426:$A$526,0),MATCH($B17,Datos_ONU!$B$425:$EV$425,0)) -> 0.716 | M17: =IF($A17=100,1,L17/(K17+L17/2)) -> 0.0014439297 | N17: =N16-O16 -> 75355.471 | O17: =N17*M17 -> 108.80801 | P17: =N18+O17/2 -> 75301.067 | Q17: =SUM(P17:P$106) -> 4922247.8 | R17: =Q17/N17 -> 65.320377 | S17: =INDEX(Datos_ONU!$B$216:$EV$316,MATCH($A17,Datos_ONU!$A$216:$A$316,0),MATCH($B17,Datos_ONU!$B$215:$EV$215,0)) -> 1000.438 | T17: =INDEX(Datos_ONU!$B$531:$EV$631,MATCH($A17,Datos_ONU!$A$531:$A$631,0),MATCH($B17,Datos_ONU!$B$530:$EV$530,0)) -> 1.537 | U17: =IF($A17=100,1,T17/(S17+T17/2)) -> 0.0015351478 | V17: =V16-W16 -> 74424.179 | W17: =V17*U17 -> 114.25212 | X17: =V18+W17/2 -> 74367.053 | Y17: =SUM(X17:X$106) -> 4655064.5 | Z17: =Y17/V17 -> 62.547745
A18: 12 | B18: =$D$2+$A18 -> 1962 | C18: =INDEX(Datos_ONU!$B$6:$EV$106,MATCH($A18,Datos_ONU!$A$6:$A$106,0),MATCH($B18,Datos_ONU!$B$5:$EV$5,0)) -> 504.002 | D18: =INDEX(Datos_ONU!$B$321:$EV$421,MATCH($A18,Datos_ONU!$A$321:$A$421,0),MATCH($B18,Datos_ONU!$B$320:$EV$320,0)) -> 0.794 | E18: =IF($A18=100,1,D18/(C18+D18/2)) -> 0.0015741506 | F18: =F17-G17 -> 73406.761 | G18: =F18*E18 -> 115.5533 | H18: =F19+G18/2 -> 73348.985 | I18: =SUM(H18:H$106) -> 4324445.7 | J18: =I18/F18 -> 58.910727 | K18: =INDEX(Datos_ONU!$B$111:$EV$211,MATCH($A18,Datos_ONU!$A$111:$A$211,0),MATCH($B18,Datos_ONU!$B$110:$EV$110,0)) -> 494.697 | L18: =INDEX(Datos_ONU!$B$426:$EV$526,MATCH($A18,Datos_ONU!$A$426:$A$526,0),MATCH($B18,Datos_ONU!$B$425:$EV$425,0)) -> 0.661 | M18: =IF($A18=100,1,L18/(K18+L18/2)) -> 0.0013352794 | N18: =N17-O17 -> 75246.663 | O18: =N18*M18 -> 100.47532 | P18: =N19+O18/2 -> 75196.425 | Q18: =SUM(P18:P$106) -> 4846946.7 | R18: =Q18/N18 -> 64.414108 | S18: =INDEX(Datos_ONU!$B$216:$EV$316,MATCH($A18,Datos_ONU!$A$216:$A$316,0),MATCH($B18,Datos_ONU!$B$215:$EV$215,0)) -> 998.699 | T18: =INDEX(Datos_ONU!$B$531:$EV$631,MATCH($A18,Datos_ONU!$A$531:$A$631,0),MATCH($B18,Datos_ONU!$B$530:$EV$530,0)) -> 1.455 | U18: =IF($A18=100,1,T18/(S18+T18/2)) -> 0.0014558349 | V18: =V17-W17 -> 74309.927 | W18: =V18*U18 -> 108.18299 | X18: =V19+W18/2 -> 74255.835 | Y18: =SUM(X18:X$106) -> 4580697.5 | Z18: =Y18/V18 -> 61.643144
... A105: 99 | B105: =$D$2+$A105 -> 2049 | C105: =INDEX(Datos_ONU!$B$6:$EV$106,MATCH($A105,Datos_ONU!$A$6:$A$106,0),MATCH($B105,Datos_ONU!$B$5:$EV$5,0)) -> 7.36 | D105: =INDEX(Datos_ONU!$B$321:$EV$421,MATCH($A105,Datos_ONU!$A$321:$A$421,0),MATCH($B105,Datos_ONU!$B$320:$EV$320,0)) -> 2.437 | E105: =IF($A105=100,1,D105/(C105+D105/2)) -> 0.2840823 | F105: =F104-G104 -> 1470.0092 | G105: =F105*E105 -> 417.60359 | H105: =F106+G105/2 -> 1261.2074 | I105: =SUM(H105:H$106) -> 1787.4102 | J105: =I105/F105 -> 1.2159177 | K105: =INDEX(Datos_ONU!$B$111:$EV$211,MATCH($A105,Datos_ONU!$A$111:$A$211,0),MATCH($B105,Datos_ONU!$B$110:$EV$110,0)) -> 7.885 | L105: =INDEX(Datos_ONU!$B$426:$EV$526,MATCH($A105,Datos_ONU!$A$426:$A$526,0),MATCH($B105,Datos_ONU!$B$425:$EV$425,0)) -> 3.147 | M105: =IF($A105=100,1,L105/(K105+L105/2)) -> 0.3327166 | N105: =N104-O104 -> 1685.8857 | O105: =N105*M105 -> 560.92216 | P105: =N106+O105/2 -> 1405.4246 | Q105: =SUM(P105:P$106) -> 1967.9064 | R105: =Q105/N105 -> 1.1672834 | S105: =INDEX(Datos_ONU!$B$216:$EV$316,MATCH($A105,Datos_ONU!$A$216:$A$316,0),MATCH($B105,Datos_ONU!$B$215:$EV$215,0)) -> 15.245 | T105: =INDEX(Datos_ONU!$B$531:$EV$631,MATCH($A105,Datos_ONU!$A$531:$A$631,0),MATCH($B105,Datos_ONU!$B$530:$EV$530,0)) -> 5.584 | U105: =IF($A105=100,1,T105/(S105+T105/2)) -> 0.30958585 | V105: =V104-W104 -> 1575.849 | W105: =V105*U105 -> 487.86057 | X105: =V106+W105/2 -> 1331.9188 | Y105: =SUM(X105:X$106) -> 1875.913 | Z105: =Y105/V105 -> 1.1904141
A106: 100 | B106: =$D$2+$A106 -> 2050 | C106: =INDEX(Datos_ONU!$B$6:$EV$106,MATCH($A106,Datos_ONU!$A$6:$A$106,0),MATCH($B106,Datos_ONU!$B$5:$EV$5,0)) -> 13.771 | D106: =INDEX(Datos_ONU!$B$321:$EV$421,MATCH($A106,Datos_ONU!$A$321:$A$421,0),MATCH($B106,Datos_ONU!$B$320:$EV$320,0)) -> 5.57 | E106: =IF($A106=100,1,D106/(C106+D106/2)) -> 1 | F106: =F105-G105 -> 1052.4056 | G106: =F106*E106 -> 1052.4056 | H106: =G106/2 -> 526.2028 | I106: =SUM(H106:H$106) -> 526.2028 | J106: =I106/F106 -> 0.5 | K106: =INDEX(Datos_ONU!$B$111:$EV$211,MATCH($A106,Datos_ONU!$A$111:$A$211,0),MATCH($B106,Datos_ONU!$B$110:$EV$110,0)) -> 13.957 | L106: =INDEX(Datos_ONU!$B$426:$EV$526,MATCH($A106,Datos_ONU!$A$426:$A$526,0),MATCH($B106,Datos_ONU!$B$425:$EV$425,0)) -> 5.526 | M106: =IF($A106=100,1,L106/(K106+L106/2)) -> 1 | N106: =N105-O105 -> 1124.9635 | O106: =N106*M106 -> 1124.9635 | P106: =O106/2 -> 562.48176 | Q106: =SUM(P106:P$106) -> 562.48176 | R106: =Q106/N106 -> 0.5 | S106: =INDEX(Datos_ONU!$B$216:$EV$316,MATCH($A106,Datos_ONU!$A$216:$A$316,0),MATCH($B106,Datos_ONU!$B$215:$EV$215,0)) -> 27.729 | T106: =INDEX(Datos_ONU!$B$531:$EV$631,MATCH($A106,Datos_ONU!$A$531:$A$631,0),MATCH($B106,Datos_ONU!$B$530:$EV$530,0)) -> 11.096 | U106: =IF($A106=100,1,T106/(S106+T106/2)) -> 1 | V106: =V105-W105 -> 1087.9885 | W106: =V106*U106 -> 1087.9885 | X106: =W106/2 -> 543.99424 | Y106: =SUM(X106:X$106) -> 543.99424 | Z106: =Y106/V106 -> 0.5
A108: Notas: qx = defunciones / (población a mitad de año + defunciones/2); edad 100 = grupo abierto (qx = 1, Lx = dx/2). lx(x+1) = lx − dx; Lx = l(x+1) + dx/2; Tx = suma de Lx desde x; ex = Tx/lx. Población y defunciones se leen de la hoja Datos_ONU en el año g + x.

Sheet Gen_1960
A1: Tabla de mortalidad de la generación 1960 - México (ONU WPP 2024)
A2: Generación (año de nacimiento): | D2: 1960 | F2: Radix: | G2: =Radix -> 100000
E3: e0: | F3: =J6 -> 60.010149 | G3: Control Σdx−radix: | I3: =SUM(G6:G106)-Radix -> 0 | M3: e0: | N3: =R6 -> 66.41444 | O3: Control Σdx−radix: | Q3: =SUM(O6:O106)-Radix -> 0 | U3: e0: | V3: =Z6 -> 63.20282 | W3: Control Σdx−radix: | Y3: =SUM(W6:W106)-Radix -> 0
C4: Hombres | K4: Mujeres | S4: Ambos sexos
A5: Edad x | B5: Año calendario | C5: Población a mitad de año (miles) | D5: Defunciones (miles) | E5: qx | F5: lx | G5: dx | H5: Lx | I5: Tx | J5: ex | K5: Población a mitad de año (miles) | L5: Defunciones (miles) | M5: qx | N5: lx | O5: dx | P5: Lx | Q5: Tx | R5: ex | S5: Población a mitad de año (miles) | T5: Defunciones (miles) | U5: qx | V5: lx | W5: dx | X5: Lx | Y5: Tx | Z5: ex
A6: 0 | B6: =$D$2+$A6 -> 1960 | C6: =INDEX(Datos_ONU!$B$6:$EV$106,MATCH($A6,Datos_ONU!$A$6:$A$106,0),MATCH($B6,Datos_ONU!$B$5:$EV$5,0)) -> 791.372 | D6: =INDEX(Datos_ONU!$B$321:$EV$421,MATCH($A6,Datos_ONU!$A$321:$A$421,0),MATCH($B6,Datos_ONU!$B$320:$EV$320,0)) -> 100.915 | E6: =IF($A6=100,1,D6/(C6+D6/2)) -> 0.11987582 | F6: =Radix -> 100000 | G6: =F6*E6 -> 11987.582 | H6: =F7+G6/2 -> 94006.209 | I6: =SUM(H6:H$106) -> 6001014.9 | J6: =I6/F6 -> 60.010149 | K6: =INDEX(Datos_ONU!$B$111:$EV$211,MATCH($A6,Datos_ONU!$A$111:$A$211,0),MATCH($B6,Datos_ONU!$B$110:$EV$110,0)) -> 772.698 | L6: =INDEX(Datos_ONU!$B$426:$EV$526,MATCH($A6,Datos_ONU!$A$426:$A$526,0),MATCH($B6,Datos_ONU!$B$425:$EV$425,0)) -> 86.328 | M6: =IF($A6=100,1,L6/(K6+L6/2)) -> 0.10581201 | N6: =Radix -> 100000 | O6: =N6*M6 -> 10581.201 | P6: =N7+O6/2 -> 94709.399 | Q6: =SUM(P6:P$106) -> 6641444 | R6: =Q6/N6 -> 66.41444 | S6: =INDEX(Datos_ONU!$B$216:$EV$316,MATCH($A6,Datos_ONU!$A$216:$A$316,0),MATCH($B6,Datos_ONU!$B$215:$EV$215,0)) -> 1564.071 | T6: =INDEX(Datos_ONU!$B$531:$EV$631,MATCH($A6,Datos_ONU!$A$531:$A$631,0),MATCH($B6,Datos_ONU!$B$530:$EV$530,0)) -> 187.244 | U6: =IF($A6=100,1,T6/(S6+T6/2)) -> 0.11295457 | V6: =Radix -> 100000 | W6: =V6*U6 -> 11295.457 | X6: =V7+W6/2 -> 94352.272 | Y6: =SUM(X6:X$106) -> 6320282 | Z6: =Y6/V6 -> 63.20282
A7: 1 | B7: =$D$2+$A7 -> 1961 | C7: =INDEX(Datos_ONU!$B$6:$EV$106,MATCH($A7,Datos_ONU!$A$6:$A$106,0),MATCH($B7,Datos_ONU!$B$5:$EV$5,0)) -> 753.311 | D7: =INDEX(Datos_ONU!$B$321:$EV$421,MATCH($A7,Datos_ONU!$A$321:$A$421,0),MATCH($B7,Datos_ONU!$B$320:$EV$320,0)) -> 15.801 | E7: =IF($A7=100,1,D7/(C7+D7/2)) -> 0.0207577 | F7: =F6-G6 -> 88012.418 | G7: =F7*E7 -> 1826.9354 | H7: =F8+G7/2 -> 87098.951 | I7: =SUM(H7:H$106) -> 5907008.7 | J7: =I7/F7 -> 67.115627 | K7: =INDEX(Datos_ONU!$B$111:$EV$211,MATCH($A7,Datos_ONU!$A$111:$A$211,0),MATCH($B7,Datos_ONU!$B$110:$EV$110,0)) -> 738.135 | L7: =INDEX(Datos_ONU!$B$426:$EV$526,MATCH($A7,Datos_ONU!$A$426:$A$526,0),MATCH($B7,Datos_ONU!$B$425:$EV$425,0)) -> 14.829 | M7: =IF($A7=100,1,L7/(K7+L7/2)) -> 0.019890027 | N7: =N6-O6 -> 89418.799 | O7: =N7*M7 -> 1778.5424 | P7: =N8+O7/2 -> 88529.528 | Q7: =SUM(P7:P$106) -> 6546734.6 | R7: =Q7/N7 -> 73.214298 | S7: =INDEX(Datos_ONU!$B$216:$EV$316,MATCH($A7,Datos_ONU!$A$216:$A$316,0),MATCH($B7,Datos_ONU!$B$215:$EV$215,0)) -> 1491.446 | T7: =INDEX(Datos_ONU!$B$531:$EV$631,MATCH($A7,Datos_ONU!$A$531:$A$631,0),MATCH($B7,Datos_ONU!$B$530:$EV$530,0)) -> 30.629 | U7: =IF($A7=100,1,T7/(S7+T7/2)) -> 0.020327716 | V7: =V6-W6 -> 88704.543 | W7: =V7*U7 -> 1803.1608 | X7: =V8+W7/2 -> 87802.963 | Y7: =SUM(X7:X$106) -> 6225929.7 | Z7: =Y7/V7 -> 70.18727
A8: 2 | B8: =$D$2+$A8 -> 1962 | C8: =INDEX(Datos_ONU!$B$6:$EV$106,MATCH($A8,Datos_ONU!$A$6:$A$106,0),MATCH($B8,Datos_ONU!$B$5:$EV$5,0)) -> 740.375 | D8: =INDEX(Datos_ONU!$B$321:$EV$421,MATCH($A8,Datos_ONU!$A$321:$A$421,0),MATCH($B8,Datos_ONU!$B$320:$EV$320,0)) -> 9.649 | E8: =IF($A8=100,1,D8/(C8+D8/2)) -> 0.012948211 | F8: =F7-G7 -> 86185.483 | G8: =F8*E8 -> 1115.9478 | H8: =F9+G8/2 -> 85627.509 | I8: =SUM(H8:H$106) -> 5819909.7 | J8: =I8/F8 -> 67.527727 | K8: =INDEX(Datos_ONU!$B$111:$EV$211,MATCH($A8,Datos_ONU!$A$111:$A$211,0),MATCH($B8,Datos_ONU!$B$110:$EV$110,0)) -> 725.912 | L8: =INDEX(Datos_ONU!$B$426:$EV$526,MATCH($A8,Datos_ONU!$A$426:$A$526,0),MATCH($B8,Datos_ONU!$B$425:$EV$425,0)) -> 9.213 | M8: =IF($A8=100,1,L8/(K8+L8/2)) -> 0.01261159 | N8: =N7-O7 -> 87640.256 | O8: =N8*M8 -> 1105.283 | P8: =N9+O8/2 -> 87087.615 | Q8: =SUM(P8:P$106) -> 6458205.1 | R8: =Q8/N8 -> 73.689938 | S8: =INDEX(Datos_ONU!$B$216:$EV$316,MATCH($A8,Datos_ONU!$A$216:$A$316,0),MATCH($B8,Datos_ONU!$B$215:$EV$215,0)) -> 1466.287 | T8: =INDEX(Datos_ONU!$B$531:$EV$631,MATCH($A8,Datos_ONU!$A$531:$A$631,0),MATCH($B8,Datos_ONU!$B$530:$EV$530,0)) -> 18.862 | U8: =IF($A8=100,1,T8/(S8+T8/2)) -> 0.012781575 | V8: =V7-W7 -> 86901.382 | W8: =V8*U8 -> 1110.7365 | X8: =V9+W8/2 -> 86346.014 | Y8: =SUM(X8:X$106) -> 6138126.8 | Z8: =Y8/V8 -> 70.633247
A9: 3 | B9: =$D$2+$A9 -> 1963 | C9: =INDEX(Datos_ONU!$B$6:$EV$106,MATCH($A9,Datos_ONU!$A$6:$A$106,0),MATCH($B9,Datos_ONU!$B$5:$EV$5,0)) -> 732.254 | D9: =INDEX(Datos_ONU!$B$321:$EV$421,MATCH($A9,Datos_ONU!$A$321:$A$421,0),MATCH($B9,Datos_ONU!$B$320:$EV$320,0)) -> 6.104 | E9: =IF($A9=100,1,D9/(C9+D9/2)) -> 0.0083013059 | F9: =F8-G8 -> 85069.535 | G9: =F9*E9 -> 706.18823 | H9: =F10+G9/2 -> 84716.441 | I9: =SUM(H9:H$106) -> 5734282.2 | J9: =I9/F9 -> 67.407001 | K9: =INDEX(Datos_ONU!$B$111:$EV$211,MATCH($A9,Datos_ONU!$A$111:$A$211,0),MATCH($B9,Datos_ONU!$B$110:$EV$110,0)) -> 718.092 | L9: =INDEX(Datos_ONU!$B$426:$EV$526,MATCH($A9,Datos_ONU!$A$426:$A$526,0),MATCH($B9,Datos_ONU!$B$425:$EV$425,0)) -> 5.927 | M9: =IF($A9=100,1,L9/(K9+L9/2)) -> 0.0082198943 | N9: =N8-O8 -> 86534.973 | O9: =N9*M9 -> 711.30834 | P9: =N10+O9/2 -> 86179.319 | Q9: =SUM(P9:P$106) -> 6371117.5 | R9: =Q9/N9 -> 73.624769 | S9: =INDEX(Datos_ONU!$B$216:$EV$316,MATCH($A9,Datos_ONU!$A$216:$A$316,0),MATCH($B9,Datos_ONU!$B$215:$EV$215,0)) -> 1450.346 | T9: =INDEX(Datos_ONU!$B$531:$EV$631,MATCH($A9,Datos_ONU!$A$531:$A$631,0),MATCH($B9,Datos_ONU!$B$530:$EV$530,0)) -> 12.031 | U9: =IF($A9=100,1,T9/(S9+T9/2)) -> 0.0082609984 | V9: =V8-W8 -> 85790.646 | W9: =V9*U9 -> 708.71639 | X9: =V10+W9/2 -> 85436.288 | Y9: =SUM(X9:X$106) -> 6051780.8 | Z9: =Y9/V9 -> 70.541266
A10: 4 | B10: =$D$2+$A10 -> 1964 | C10: =INDEX(Datos_ONU!$B$6:$EV$106,MATCH($A10,Datos_ONU!$A$6:$A$106,0),MATCH($B10,Datos_ONU!$B$5:$EV$5,0)) -> 726.944 | D10: =INDEX(Datos_ONU!$B$321:$EV$421,MATCH($A10,Datos_ONU!$A$321:$A$421,0),MATCH($B10,Datos_ONU!$B$320:$EV$320,0)) -> 3.999 | E10: =IF($A10=100,1,D10/(C10+D10/2)) -> 0.0054860219 | F10: =F9-G9 -> 84363.347 | G10: =F10*E10 -> 462.81917 | H10: =F11+G10/2 -> 84131.937 | I10: =SUM(H10:H$106) -> 5649565.8 | J10: =I10/F10 -> 66.967065 | K10: =INDEX(Datos_ONU!$B$111:$EV$211,MATCH($A10,Datos_ONU!$A$111:$A$211,0),MATCH($B10,Datos_ONU!$B$110:$EV$110,0)) -> 712.909 | L10: =INDEX(Datos_ONU!$B$426:$EV$526,MATCH($A10,Datos_ONU!$A$426:$A$526,0),MATCH($B10,Datos_ONU!$B$425:$EV$425,0)) -> 3.922 | M10: =IF($A10=100,1,L10/(K10+L10/2)) -> 0.0054863122 | N10: =N9-O9 -> 85823.665 | O10: =N10*M10 -> 470.85542 | P10: =N11+O10/2 -> 85588.237 | Q10: =SUM(P10:P$106) -> 6284938.1 | R10: =Q10/N10 -> 73.230829 | S10: =INDEX(Datos_ONU!$B$216:$EV$316,MATCH($A10,Datos_ONU!$A$216:$A$316,0),MATCH($B10,Datos_ONU!$B$215:$EV$215,0)) -> 1439.853 | T10: =INDEX(Datos_ONU!$B$531:$EV$631,MATCH($A10,Datos_ONU!$A$531:$A$631,0),MATCH($B10,Datos_ONU!$B$530:$EV$530,0)) -> 7.921 | U10: =IF($A10=100,1,T10/(S10+T10/2)) -> 0.0054861656 | V10: =V9-W9 -> 85081.929 | W10: =V10*U10 -> 466.77356 | X10: =V11+W10/2 -> 84848.543 | Y10: =SUM(X10:X$106) -> 5966344.5 | Z10: =Y10/V10 -> 70.124697
A11: 5 | B11: =$D$2+$A11 -> 1965 | C11: =INDEX(Datos_ONU!$B$6:$EV$106,MATCH($A11,Datos_ONU!$A$6:$A$106,0),MATCH($B11,Datos_ONU!$B$5:$EV$5,0)) -> 723.329 | D11: =INDEX(Datos_ONU!$B$321:$EV$421,MATCH($A11,Datos_ONU!$A$321:$A$421,0),MATCH($B11,Datos_ONU!$B$320:$EV$320,0)) -> 2.733 | E11: =IF($A11=100,1,D11/(C11+D11/2)) -> 0.0037712391 | F11: =F10-G10 -> 83900.528 | G11: =F11*E11 -> 316.40895 | H11: =F12+G11/2 -> 83742.323 | I11: =SUM(H11:H$106) -> 5565433.8 | J11: =I11/F11 -> 66.333717 | K11: =INDEX(Datos_ONU!$B$111:$EV$211,MATCH($A11,Datos_ONU!$A$111:$A$211,0),MATCH($B11,Datos_ONU!$B$110:$EV$110,0)) -> 709.39 | L11: =INDEX(Datos_ONU!$B$426:$EV$526,MATCH($A11,Datos_ONU!$A$426:$A$526,0),MATCH($B11,Datos_ONU!$B$425:$EV$425,0)) -> 2.617 | M11: =IF($A11=100,1,L11/(K11+L11/2)) -> 0.0036822928 | N11: =N10-O10 -> 85352.81 | O11: =N11*M11 -> 314.29404 | P11: =N12+O11/2 -> 85195.663 | Q11: =SUM(P11:P$106) -> 6199349.9 | R11: =Q11/N11 -> 72.632054 | S11: =INDEX(Datos_ONU!$B$216:$EV$316,MATCH($A11,Datos_ONU!$A$216:$A$316,0),MATCH($B11,Datos_ONU!$B$215:$EV$215,0)) -> 1432.719 | T11: =INDEX(Datos_ONU!$B$531:$EV$631,MATCH($A11,Datos_ONU!$A$531:$A$631,0),MATCH($B11,Datos_ONU!$B$530:$EV$530,0)) -> 5.35 | U11: =IF($A11=100,1,T11/(S11+T11/2)) -> 0.0037271996 | V11: =V10-W10 -> 84615.156 | W11: =V11*U11 -> 315.37758 | X11: =V12+W11/2 -> 84457.467 | Y11: =SUM(X11:X$106) -> 5881495.9 | Z11: =Y11/V11 -> 69.508776
A12: 6 | B12: =$D$2+$A12 -> 1966 | C12: =INDEX(Datos_ONU!$B$6:$EV$106,MATCH($A12,Datos_ONU!$A$6:$A$106,0),MATCH($B12,Datos_ONU!$B$5:$EV$5,0)) -> 720.763 | D12: =INDEX(Datos_ONU!$B$321:$EV$421,MATCH($A12,Datos_ONU!$A$321:$A$421,0),MATCH($B12,Datos_ONU!$B$320:$EV$320,0)) -> 1.919 | E12: =IF($A12=100,1,D12/(C12+D12/2)) -> 0.0026589167 | F12: =F11-G11 -> 83584.119 | G12: =F12*E12 -> 222.24321 | H12: =F13+G12/2 -> 83472.997 | I12: =SUM(H12:H$106) -> 5481691.5 | J12: =I12/F12 -> 65.582931 | K12: =INDEX(Datos_ONU!$B$111:$EV$211,MATCH($A12,Datos_ONU!$A$111:$A$211,0),MATCH($B12,Datos_ONU!$B$110:$EV$110,0)) -> 706.955 | L12: =INDEX(Datos_ONU!$B$426:$EV$526,MATCH($A12,Datos_ONU!$A$426:$A$526,0),MATCH($B12,Datos_ONU!$B$425:$EV$425,0)) -> 1.779 | M12: =IF($A12=100,1,L12/(K12+L12/2)) -> 0.0025132639 | N12: =N11-O11 -> 85038.516 | O12: =N12*M12 -> 213.72423 | P12: =N13+O12/2 -> 84931.653 | Q12: =SUM(P12:P$106) -> 6114154.2 | R12: =Q12/N12 -> 71.898647 | S12: =INDEX(Datos_ONU!$B$216:$EV$316,MATCH($A12,Datos_ONU!$A$216:$A$316,0),MATCH($B12,Datos_ONU!$B$215:$EV$215,0)) -> 1427.718 | T12: =INDEX(Datos_ONU!$B$531:$EV$631,MATCH($A12,Datos_ONU!$A$531:$A$631,0),MATCH($B12,Datos_ONU!$B$530:$EV$530,0)) -> 3.698 | U12: =IF($A12=100,1,T12/(S12+T12/2)) -> 0.0025867973 | V12: =V11-W11 -> 84299.778 | W12: =V12*U12 -> 218.06644 | X12: =V13+W12/2 -> 84190.745 | Y12: =SUM(X12:X$106) -> 5797038.5 | Z12: =Y12/V12 -> 68.766948
A13: 7 | B13: =$D$2+$A13 -> 1967 | C13: =INDEX(Datos_ONU!$B$6:$EV$106,MATCH($A13,Datos_ONU!$A$6:$A$106,0),MATCH($B13,Datos_ONU!$B$5:$EV$5,0)) -> 718.79 | D13: =INDEX(Datos_ONU!$B$321:$EV$421,MATCH($A13,Datos_ONU!$A$321:$A$421,0),MATCH($B13,Datos_ONU!$B$320:$EV$320,0)) -> 1.548 | E13: =IF($A13=100,1,D13/(C13+D13/2)) -> 0.0021513027 | F13: =F12-G12 -> 83361.875 | G13: =F13*E13 -> 179.33663 | H13: =F14+G13/2 -> 83272.207 | I13: =SUM(H13:H$106) -> 5398218.5 | J13: =I13/F13 -> 64.756443 | K13: =INDEX(Datos_ONU!$B$111:$EV$211,MATCH($A13,Datos_ONU!$A$111:$A$211,0),MATCH($B13,Datos_ONU!$B$110:$EV$110,0)) -> 705.142 | L13: =INDEX(Datos_ONU!$B$426:$EV$526,MATCH($A13,Datos_ONU!$A$426:$A$526,0),MATCH($B13,Datos_ONU!$B$425:$EV$425,0)) -> 1.364 | M13: =IF($A13=100,1,L13/(K13+L13/2)) -> 0.0019324931 | N13: =N12-O12 -> 84824.791 | O13: =N13*M13 -> 163.92332 | P13: =N14+O13/2 -> 84742.83 | Q13: =SUM(P13:P$106) -> 6029222.6 | R13: =Q13/N13 -> 71.078543 | S13: =INDEX(Datos_ONU!$B$216:$EV$316,MATCH($A13,Datos_ONU!$A$216:$A$316,0),MATCH($B13,Datos_ONU!$B$215:$EV$215,0)) -> 1423.932 | T13: =INDEX(Datos_ONU!$B$531:$EV$631,MATCH($A13,Datos_ONU!$A$531:$A$631,0),MATCH($B13,Datos_ONU!$B$530:$EV$530,0)) -> 2.912 | U13: =IF($A13=100,1,T13/(S13+T13/2)) -> 0.0020429525 | V13: =V12-W12 -> 84081.712 | W13: =V13*U13 -> 171.77494 | X13: =V14+W13/2 -> 83995.824 | Y13: =SUM(X13:X$106) -> 5712847.7 | Z13: =Y13/V13 -> 67.943999
A14: 8 | B14: =$D$2+$A14 -> 1968 | C14: =INDEX(Datos_ONU!$B$6:$EV$106,MATCH($A14,Datos_ONU!$A$6:$A$106,0),MATCH($B14,Datos_ONU!$B$5:$EV$5,0)) -> 717.133 | D14: =INDEX(Datos_ONU!$B$321:$EV$421,MATCH($A14,Datos_ONU!$A$321:$A$421,0),MATCH($B14,Datos_ONU!$B$320:$EV$320,0)) -> 1.297 | E14: =IF($A14=100,1,D14/(C14+D14/2)) -> 0.0018069566 | F14: =F13-G13 -> 83182.539 | G14: =F14*E14 -> 150.30724 | H14: =F15+G14/2 -> 83107.385 | I14: =SUM(H14:H$106) -> 5314946.3 | J14: =I14/F14 -> 63.894976 | K14: =INDEX(Datos_ONU!$B$111:$EV$211,MATCH($A14,Datos_ONU!$A$111:$A$211,0),MATCH($B14,Datos_ONU!$B$110:$EV$110,0)) -> 703.674 | L14: =INDEX(Datos_ONU!$B$426:$EV$526,MATCH($A14,Datos_ONU!$A$426:$A$526,0),MATCH($B14,Datos_ONU!$B$425:$EV$425,0)) -> 1.106 | M14: =IF($A14=100,1,L14/(K14+L14/2)) -> 0.0015705163 | N14: =N13-O13 -> 84660.868 | O14: =N14*M14 -> 132.96128 | P14: =N15+O14/2 -> 84594.387 | Q14: =SUM(P14:P$106) -> 5944479.8 | R14: =Q14/N14 -> 70.2152 | S14: =INDEX(Datos_ONU!$B$216:$EV$316,MATCH($A14,Datos_ONU!$A$216:$A$316,0),MATCH($B14,Datos_ONU!$B$215:$EV$215,0)) -> 1420.807 | T14: =INDEX(Datos_ONU!$B$531:$EV$631,MATCH($A14,Datos_ONU!$A$531:$A$631,0),MATCH($B14,Datos_ONU!$B$530:$EV$530,0)) -> 2.403 | U14: =IF($A14=100,1,T14/(S14+T14/2)) -> 0.0016898633 | V14: =V13-W13 -> 83909.937 | W14: =V14*U14 -> 141.79632 | X14: =V15+W14/2 -> 83839.039 | Y14: =SUM(X14:X$106) -> 5628851.9 | Z14: =Y14/V14 -> 67.082066
A15: 9 | B15: =$D$2+$A15 -> 1969 | C15: =INDEX(Datos_ONU!$B$6:$EV$106,MATCH($A15,Datos_ONU!$A$6:$A$106,0),MATCH($B15,Datos_ONU!$B$5:$EV$5,0)) -> 715.644 | D15: =INDEX(Datos_ONU!$B$321:$EV$421,MATCH($A15,Datos_ONU!$A$321:$A$421,0),MATCH($B15,Datos_ONU!$B$320:$EV$320,0)) -> 1.189 | E15: =IF($A15=100,1,D15/(C15+D15/2)) -> 0.0016600616 | F15: =F14-G14 -> 83032.232 | G15: =F15*E15 -> 137.83862 | H15: =F16+G15/2 -> 82963.312 | I15: =SUM(H15:H$106) -> 5231838.9 | J15: =I15/F15 -> 63.009735 | K15: =INDEX(Datos_ONU!$B$111:$EV$211,MATCH($A15,Datos_ONU!$A$111:$A$211,0),MATCH($B15,Datos_ONU!$B$110:$EV$110,0)) -> 702.378 | L15: =INDEX(Datos_ONU!$B$426:$EV$526,MATCH($A15,Datos_ONU!$A$426:$A$526,0),MATCH($B15,Datos_ONU!$B$425:$EV$425,0)) -> 0.998 | M15: =IF($A15=100,1,L15/(K15+L15/2)) -> 0.0014198786 | N15: =N14-O14 -> 84527.907 | O15: =N15*M15 -> 120.01936 | P15: =N16+O15/2 -> 84467.897 | Q15: =SUM(P15:P$106) -> 5859885.4 | R15: =Q15/N15 -> 69.324861 | S15: =INDEX(Datos_ONU!$B$216:$EV$316,MATCH($A15,Datos_ONU!$A$216:$A$316,0),MATCH($B15,Datos_ONU!$B$215:$EV$215,0)) -> 1418.022 | T15: =INDEX(Datos_ONU!$B$531:$EV$631,MATCH($A15,Datos_ONU!$A$531:$A$631,0),MATCH($B15,Datos_ONU!$B$530:$EV$530,0)) -> 2.187 | U15: =IF($A15=100,1,T15/(S15+T15/2)) -> 0.0015411008 | V15: =V14-W14 -> 83768.14 | W15: =V15*U15 -> 129.09515 | X15: =V16+W15/2 -> 83703.593 | Y15: =SUM(X15:X$106) -> 5545012.9 | Z15: =Y15/V15 -> 66.194771
A16: 10 | B16: =$D$2+$A16 -> 1970 | C16: =INDEX(Datos_ONU!$B$6:$EV$106,MATCH($A16,Datos_ONU!$A$6:$A$106,0),MATCH($B16,Datos_ONU!$B$5:$EV$5,0)) -> 714.283 | D16: =INDEX(Datos_ONU!$B$321:$EV$421,MATCH($A16,Datos_ONU!$A$321:$A$421,0),MATCH($B16,Datos_ONU!$B$320:$EV$320,0)) -> 1.026 | E16: =IF($A16=100,1,D16/(C16+D16/2)) -> 0.0014353746 | F16: =F15-G15 -> 82894.393 | G16: =F16*E16 -> 118.9845 | H16: =F17+G16/2 -> 82834.901 | I16: =SUM(H16:H$106) -> 5148875.6 | J16: =I16/F16 -> 62.113678 | K16: =INDEX(Datos_ONU!$B$111:$EV$211,MATCH($A16,Datos_ONU!$A$111:$A$211,0),MATCH($B16,Datos_ONU!$B$110:$EV$110,0)) -> 701.194 | L16: =INDEX(Datos_ONU!$B$426:$EV$526,MATCH($A16,Datos_ONU!$A$426:$A$526,0),MATCH($B16,Datos_ONU!$B$425:$EV$425,0)) -> 0.856 | M16: =IF($A16=100,1,L16/(K16+L16/2)) -> 0.0012200302 | N16: =N15-O15 -> 84407.887 | O16: =N16*M16 -> 102.98017 | P16: =N17+O16/2 -> 84356.397 | Q16: =SUM(P16:P$106) -> 5775417.5 | R16: =Q16/N16 -> 68.422723 | S16: =INDEX(Datos_ONU!$B$216:$EV$316,MATCH($A16,Datos_ONU!$A$216:$A$316,0),MATCH($B16,Datos_ONU!$B$215:$EV$215,0)) -> 1415.476 | T16: =INDEX(Datos_ONU!$B$531:$EV$631,MATCH($A16,Datos_ONU!$A$531:$A$631,0),MATCH($B16,Datos_ONU!$B$530:$EV$530,0)) -> 1.883 | U16: =IF($A16=100,1,T16/(S16+T16/2)) -> 0.0013294103 | V16: =V15-W15 -> 83639.045 | W16: =V16*U16 -> 111.19061 | X16: =V17+W16/2 -> 83583.45 | Y16: =SUM(X16:X$106) -> 5461309.3 | Z16: =Y16/V16 -> 65.296169
A17: 11 | B17: =$D$2+$A17 -> 1971 | C17: =INDEX(Datos_ONU!$B$6:$EV$106,MATCH($A17,Datos_ONU!$A$6:$A$106,0),MATCH($B17,Datos_ONU!$B$5:$EV$5,0)) -> 712.979 | D17: =INDEX(Datos_ONU!$B$321:$EV$421,MATCH($A17,Datos_ONU!$A$321:$A$421,0),MATCH($B17,Datos_ONU!$B$320:$EV$320,0)) -> 0.988 | E17: =IF($A17=100,1,D17/(C17+D17/2)) -> 0.0013847756 | F17: =F16-G16 -> 82775.408 | G17: =F17*E17 -> 114.62537 | H17: =F18+G17/2 -> 82718.096 | I17: =SUM(H17:H$106) -> 5066040.7 | J17: =I17/F17 -> 61.202243 | K17: =INDEX(Datos_ONU!$B$111:$EV$211,MATCH($A17,Datos_ONU!$A$111:$A$211,0),MATCH($B17,Datos_ONU!$B$110:$EV$110,0)) -> 700.063 | L17: =INDEX(Datos_ONU!$B$426:$EV$526,MATCH($A17,Datos_ONU!$A$426:$A$526,0),MATCH($B17,Datos_ONU!$B$425:$EV$425,0)) -> 0.79 | M17: =IF($A17=100,1,L17/(K17+L17/2)) -> 0.0011278335 | N17: =N16-O16 -> 84304.907 | O17: =N17*M17 -> 95.081899 | P17: =N18+O17/2 -> 84257.366 | Q17: =SUM(P17:P$106) -> 5691061.1 | R17: =Q17/N17 -> 67.505692 | S17: =INDEX(Datos_ONU!$B$216:$EV$316,MATCH($A17,Datos_ONU!$A$216:$A$316,0),MATCH($B17,Datos_ONU!$B$215:$EV$215,0)) -> 1413.042 | T17: =INDEX(Datos_ONU!$B$531:$EV$631,MATCH($A17,Datos_ONU!$A$531:$A$631,0),MATCH($B17,Datos_ONU!$B$530:$EV$530,0)) -> 1.778 | U17: =IF($A17=100,1,T17/(S17+T17/2)) -> 0.0012574871 | V17: =V16-W16 -> 83527.855 | W17: =V17*U17 -> 105.0352 | X17: =V18+W17/2 -> 83475.337 | Y17: =SUM(X17:X$106) -> 5377725.8 | Z17: =Y17/V17 -> 64.382425
A18: 12 | B18: =$D$2+$A18 -> 1972 | C18: =INDEX(Datos_ONU!$B$6:$EV$106,MATCH($A18,Datos_ONU!$A$6:$A$106,0),MATCH($B18,Datos_ONU!$B$5:$EV$5,0)) -> 711.616 | D18: =INDEX(Datos_ONU!$B$321:$EV$421,MATCH($A18,Datos_ONU!$A$321:$A$421,0),MATCH($B18,Datos_ONU!$B$320:$EV$320,0)) -> 0.982 | E18: =IF($A18=100,1,D18/(C18+D18/2)) -> 0.0013790062 | F18: =F17-G17 -> 82660.783 | G18: =F18*E18 -> 113.98974 | H18: =F19+G18/2 -> 82603.788 | I18: =SUM(H18:H$106) -> 4983322.6 | J18: =I18/F18 -> 60.286419 | K18: =INDEX(Datos_ONU!$B$111:$EV$211,MATCH($A18,Datos_ONU!$A$111:$A$211,0),MATCH($B18,Datos_ONU!$B$110:$EV$110,0)) -> 698.896 | L18: =INDEX(Datos_ONU!$B$426:$EV$526,MATCH($A18,Datos_ONU!$A$426:$A$526,0),MATCH($B18,Datos_ONU!$B$425:$EV$425,0)) -> 0.736 | M18: =IF($A18=100,1,L18/(K18+L18/2)) -> 0.0010525352 | N18: =N17-O17 -> 84209.825 | O18: =N18*M18 -> 88.633808 | P18: =N19+O18/2 -> 84165.508 | Q18: =SUM(P18:P$106) -> 5606803.7 | R18: =Q18/N18 -> 66.581348 | S18: =INDEX(Datos_ONU!$B$216:$EV$316,MATCH($A18,Datos_ONU!$A$216:$A$316,0),MATCH($B18,Datos_ONU!$B$215:$EV$215,0)) -> 1410.513 | T18: =INDEX(Datos_ONU!$B$531:$EV$631,MATCH($A18,Datos_ONU!$A$531:$A$631,0),MATCH($B18,Datos_ONU!$B$530:$EV$530,0)) -> 1.718 | U18: =IF($A18=100,1,T18/(S18+T18/2)) -> 0.0012172553 | V18: =V17-W17 -> 83422.82 | W18: =V18*U18 -> 101.54687 | X18: =V19+W18/2 -> 83372.046 | Y18: =SUM(X18:X$106) -> 5294250.5 | Z18: =Y18/V18 -> 63.462857
... A105: 99 | B105: =$D$2+$A105 -> 2059 | C105: =INDEX(Datos_ONU!$B$6:$EV$106,MATCH($A105,Datos_ONU!$A$6:$A$106,0),MATCH($B105,Datos_ONU!$B$5:$EV$5,0)) -> 13.091 | D105: =INDEX(Datos_ONU!$B$321:$EV$421,MATCH($A105,Datos_ONU!$A$321:$A$421,0),MATCH($B105,Datos_ONU!$B$320:$EV$320,0)) -> 4.232 | E105: =IF($A105=100,1,D105/(C105+D105/2)) -> 0.27829289 | F105: =F104-G104 -> 2098.4667 | G105: =F105*E105 -> 583.98835 | H105: =F106+G105/2 -> 1806.4725 | I105: =SUM(H105:H$106) -> 2563.7116 | J105: =I105/F105 -> 1.2217071 | K105: =INDEX(Datos_ONU!$B$111:$EV$211,MATCH($A105,Datos_ONU!$A$111:$A$211,0),MATCH($B105,Datos_ONU!$B$110:$EV$110,0)) -> 16.113 | L105: =INDEX(Datos_ONU!$B$426:$EV$526,MATCH($A105,Datos_ONU!$A$426:$A$526,0),MATCH($B105,Datos_ONU!$B$425:$EV$425,0)) -> 6.1 | M105: =IF($A105=100,1,L105/(K105+L105/2)) -> 0.31832177 | N105: =N104-O104 -> 2639.8138 | O105: =N105*M105 -> 840.31019 | P105: =N106+O105/2 -> 2219.6587 | Q105: =SUM(P105:P$106) -> 3119.4105 | R105: =Q105/N105 -> 1.1816782 | S105: =INDEX(Datos_ONU!$B$216:$EV$316,MATCH($A105,Datos_ONU!$A$216:$A$316,0),MATCH($B105,Datos_ONU!$B$215:$EV$215,0)) -> 29.204 | T105: =INDEX(Datos_ONU!$B$531:$EV$631,MATCH($A105,Datos_ONU!$A$531:$A$631,0),MATCH($B105,Datos_ONU!$B$530:$EV$530,0)) -> 10.332 | U105: =IF($A105=100,1,T105/(S105+T105/2)) -> 0.300611 | V105: =V104-W104 -> 2368.7822 | W105: =V105*U105 -> 712.08198 | X105: =V106+W105/2 -> 2012.7412 | Y105: =SUM(X105:X$106) -> 2841.0913 | Z105: =Y105/V105 -> 1.199389
A106: 100 | B106: =$D$2+$A106 -> 2060 | C106: =INDEX(Datos_ONU!$B$6:$EV$106,MATCH($A106,Datos_ONU!$A$6:$A$106,0),MATCH($B106,Datos_ONU!$B$5:$EV$5,0)) -> 24.843 | D106: =INDEX(Datos_ONU!$B$321:$EV$421,MATCH($A106,Datos_ONU!$A$321:$A$421,0),MATCH($B106,Datos_ONU!$B$320:$EV$320,0)) -> 9.777 | E106: =IF($A106=100,1,D106/(C106+D106/2)) -> 1 | F106: =F105-G105 -> 1514.4783 | G106: =F106*E106 -> 1514.4783 | H106: =G106/2 -> 757.23915 | I106: =SUM(H106:H$106) -> 757.23915 | J106: =I106/F106 -> 0.5 | K106: =INDEX(Datos_ONU!$B$111:$EV$211,MATCH($A106,Datos_ONU!$A$111:$A$211,0),MATCH($B106,Datos_ONU!$B$110:$EV$110,0)) -> 29.654 | L106: =INDEX(Datos_ONU!$B$426:$EV$526,MATCH($A106,Datos_ONU!$A$426:$A$526,0),MATCH($B106,Datos_ONU!$B$425:$EV$425,0)) -> 11.299 | M106: =IF($A106=100,1,L106/(K106+L106/2)) -> 1 | N106: =N105-O105 -> 1799.5036 | O106: =N106*M106 -> 1799.5036 | P106: =O106/2 -> 899.7518 | Q106: =SUM(P106:P$106) -> 899.7518 | R106: =Q106/N106 -> 0.5 | S106: =INDEX(Datos_ONU!$B$216:$EV$316,MATCH($A106,Datos_ONU!$A$216:$A$316,0),MATCH($B106,Datos_ONU!$B$215:$EV$215,0)) -> 54.498 | T106: =INDEX(Datos_ONU!$B$531:$EV$631,MATCH($A106,Datos_ONU!$A$531:$A$631,0),MATCH($B106,Datos_ONU!$B$530:$EV$530,0)) -> 21.076 | U106: =IF($A106=100,1,T106/(S106+T106/2)) -> 1 | V106: =V105-W105 -> 1656.7002 | W106: =V106*U106 -> 1656.7002 | X106: =W106/2 -> 828.35011 | Y106: =SUM(X106:X$106) -> 828.35011 | Z106: =Y106/V106 -> 0.5
A108: Notas: qx = defunciones / (población a mitad de año + defunciones/2); edad 100 = grupo abierto (qx = 1, Lx = dx/2). lx(x+1) = lx − dx; Lx = l(x+1) + dx/2; Tx = suma de Lx desde x; ex = Tx/lx. Población y defunciones se leen de la hoja Datos_ONU en el año g + x.

Sheet Gen_1970
A1: Tabla de mortalidad de la generación 1970 - México (ONU WPP 2024)
A2: Generación (año de nacimiento): | D2: 1970 | F2: Radix: | G2: =Radix -> 100000
E3: e0: | F3: =J6 -> 65.835312 | G3: Control Σdx−radix: | I3: =SUM(G6:G106)-Radix -> 0 | M3: e0: | N3: =R6 -> 72.214601 | O3: Control Σdx−radix: | Q3: =SUM(O6:O106)-Radix -> 0 | U3: e0: | V3: =Z6 -> 69.079189 | W3: Control Σdx−radix: | Y3: =SUM(W6:W106)-Radix -> 0
C4: Hombres | K4: Mujeres | S4: Ambos sexos
A5: Edad x | B5: Año calendario | C5: Población a mitad de año (miles) | D5: Defunciones (miles) | E5: qx | F5: lx | G5: dx | H5: Lx | I5: Tx | J5: ex | K5: Población a mitad de año (miles) | L5: Defunciones (miles) | M5: qx | N5: lx | O5: dx | P5: Lx | Q5: Tx | R5: ex | S5: Población a mitad de año (miles) | T5: Defunciones (miles) | U5: qx | V5: lx | W5: dx | X5: Lx | Y5: Tx | Z5: ex
A6: 0 | B6: =$D$2+$A6 -> 1970 | C6: =INDEX(Datos_ONU!$B$6:$EV$106,MATCH($A6,Datos_ONU!$A$6:$A$106,0),MATCH($B6,Datos_ONU!$B$5:$EV$5,0)) -> 1071.13 | D6: =INDEX(Datos_ONU!$B$321:$EV$421,MATCH($A6,Datos_ONU!$A$321:$A$421,0),MATCH($B6,Datos_ONU!$B$320:$EV$320,0)) -> 97.079 | E6: =IF($A6=100,1,D6/(C6+D6/2)) -> 0.086703264 | F6: =Radix -> 100000 | G6: =F6*E6 -> 8670.3264 | H6: =F7+G6/2 -> 95664.837 | I6: =SUM(H6:H$106) -> 6583531.2 | J6: =I6/F6 -> 65.835312 | K6: =INDEX(Datos_ONU!$B$111:$EV$211,MATCH($A6,Datos_ONU!$A$111:$A$211,0),MATCH($B6,Datos_ONU!$B$110:$EV$110,0)) -> 1041.872 | L6: =INDEX(Datos_ONU!$B$426:$EV$526,MATCH($A6,Datos_ONU!$A$426:$A$526,0),MATCH($B6,Datos_ONU!$B$425:$EV$425,0)) -> 81.877 | M6: =IF($A6=100,1,L6/(K6+L6/2)) -> 0.075615262 | N6: =Radix -> 100000 | O6: =N6*M6 -> 7561.5262 | P6: =N7+O6/2 -> 96219.237 | Q6: =SUM(P6:P$106) -> 7221460.1 | R6: =Q6/N6 -> 72.214601 | S6: =INDEX(Datos_ONU!$B$216:$EV$316,MATCH($A6,Datos_ONU!$A$216:$A$316,0),MATCH($B6,Datos_ONU!$B$215:$EV$215,0)) -> 2113.003 | T6: =INDEX(Datos_ONU!$B$531:$EV$631,MATCH($A6,Datos_ONU!$A$531:$A$631,0),MATCH($B6,Datos_ONU!$B$530:$EV$530,0)) -> 178.956 | U6: =IF($A6=100,1,T6/(S6+T6/2)) -> 0.081252006 | V6: =Radix -> 100000 | W6: =V6*U6 -> 8125.2006 | X6: =V7+W6/2 -> 95937.4 | Y6: =SUM(X6:X$106) -> 6907918.9 | Z6: =Y6/V6 -> 69.079189
A7: 1 | B7: =$D$2+$A7 -> 1971 | C7: =INDEX(Datos_ONU!$B$6:$EV$106,MATCH($A7,Datos_ONU!$A$6:$A$106,0),MATCH($B7,Datos_ONU!$B$5:$EV$5,0)) -> 1035.682 | D7: =INDEX(Datos_ONU!$B$321:$EV$421,MATCH($A7,Datos_ONU!$A$321:$A$421,0),MATCH($B7,Datos_ONU!$B$320:$EV$320,0)) -> 11.346 | E7: =IF($A7=100,1,D7/(C7+D7/2)) -> 0.01089542 | F7: =F6-G6 -> 91329.674 | G7: =F7*E7 -> 995.07514 | H7: =F8+G7/2 -> 90832.136 | I7: =SUM(H7:H$106) -> 6487866.4 | J7: =I7/F7 -> 71.03788 | K7: =INDEX(Datos_ONU!$B$111:$EV$211,MATCH($A7,Datos_ONU!$A$111:$A$211,0),MATCH($B7,Datos_ONU!$B$110:$EV$110,0)) -> 1010.014 | L7: =INDEX(Datos_ONU!$B$426:$EV$526,MATCH($A7,Datos_ONU!$A$426:$A$526,0),MATCH($B7,Datos_ONU!$B$425:$EV$425,0)) -> 10.703 | M7: =IF($A7=100,1,L7/(K7+L7/2)) -> 0.010541032 | N7: =N6-O6 -> 92438.474 | O7: =N7*M7 -> 974.39689 | P7: =N8+O7/2 -> 91951.275 | Q7: =SUM(P7:P$106) -> 7125240.9 | R7: =Q7/N7 -> 77.080902 | S7: =INDEX(Datos_ONU!$B$216:$EV$316,MATCH($A7,Datos_ONU!$A$216:$A$316,0),MATCH($B7,Datos_ONU!$B$215:$EV$215,0)) -> 2045.696 | T7: =INDEX(Datos_ONU!$B$531:$EV$631,MATCH($A7,Datos_ONU!$A$531:$A$631,0),MATCH($B7,Datos_ONU!$B$530:$EV$530,0)) -> 22.048 | U7: =IF($A7=100,1,T7/(S7+T7/2)) -> 0.010719981 | V7: =V6-W6 -> 91874.799 | W7: =V7*U7 -> 984.89613 | X7: =V8+W7/2 -> 91382.351 | Y7: =SUM(X7:X$106) -> 6811981.5 | Z7: =Y7/V7 -> 74.144178
A8: 2 | B8: =$D$2+$A8 -> 1972 | C8: =INDEX(Datos_ONU!$B$6:$EV$106,MATCH($A8,Datos_ONU!$A$6:$A$106,0),MATCH($B8,Datos_ONU!$B$5:$EV$5,0)) -> 1025.059 | D8: =INDEX(Datos_ONU!$B$321:$EV$421,MATCH($A8,Datos_ONU!$A$321:$A$421,0),MATCH($B8,Datos_ONU!$B$320:$EV$320,0)) -> 7.663 | E8: =IF($A8=100,1,D8/(C8+D8/2)) -> 0.0074478285 | F8: =F7-G7 -> 90334.598 | G8: =F8*E8 -> 672.7966 | H8: =F9+G8/2 -> 89998.2 | I8: =SUM(H8:H$106) -> 6397034.3 | J8: =I8/F8 -> 70.814886 | K8: =INDEX(Datos_ONU!$B$111:$EV$211,MATCH($A8,Datos_ONU!$A$111:$A$211,0),MATCH($B8,Datos_ONU!$B$110:$EV$110,0)) -> 999.944 | L8: =INDEX(Datos_ONU!$B$426:$EV$526,MATCH($A8,Datos_ONU!$A$426:$A$526,0),MATCH($B8,Datos_ONU!$B$425:$EV$425,0)) -> 7.208 | M8: =IF($A8=100,1,L8/(K8+L8/2)) -> 0.0071825164 | N8: =N7-O7 -> 91464.077 | O8: =N8*M8 -> 656.94224 | P8: =N9+O8/2 -> 91135.606 | Q8: =SUM(P8:P$106) -> 7033289.6 | R8: =Q8/N8 -> 76.896743 | S8: =INDEX(Datos_ONU!$B$216:$EV$316,MATCH($A8,Datos_ONU!$A$216:$A$316,0),MATCH($B8,Datos_ONU!$B$215:$EV$215,0)) -> 2025.004 | T8: =INDEX(Datos_ONU!$B$531:$EV$631,MATCH($A8,Datos_ONU!$A$531:$A$631,0),MATCH($B8,Datos_ONU!$B$530:$EV$530,0)) -> 14.871 | U8: =IF($A8=100,1,T8/(S8+T8/2)) -> 0.007316823 | V8: =V7-W7 -> 90889.903 | W8: =V8*U8 -> 665.02533 | X8: =V9+W8/2 -> 90557.391 | Y8: =SUM(X8:X$106) -> 6720599.2 | Z8: =Y8/V8 -> 73.942197
A9: 3 | B9: =$D$2+$A9 -> 1973 | C9: =INDEX(Datos_ONU!$B$6:$EV$106,MATCH($A9,Datos_ONU!$A$6:$A$106,0),MATCH($B9,Datos_ONU!$B$5:$EV$5,0)) -> 1017.758 | D9: =INDEX(Datos_ONU!$B$321:$EV$421,MATCH($A9,Datos_ONU!$A$321:$A$421,0),MATCH($B9,Datos_ONU!$B$320:$EV$320,0)) -> 5.025 | E9: =IF($A9=100,1,D9/(C9+D9/2)) -> 0.0049251645 | F9: =F8-G8 -> 89661.802 | G9: =F9*E9 -> 441.59912 | H9: =F10+G9/2 -> 89441.002 | I9: =SUM(H9:H$106) -> 6307036.1 | J9: =I9/F9 -> 70.342508 | K9: =INDEX(Datos_ONU!$B$111:$EV$211,MATCH($A9,Datos_ONU!$A$111:$A$211,0),MATCH($B9,Datos_ONU!$B$110:$EV$110,0)) -> 993.053 | L9: =INDEX(Datos_ONU!$B$426:$EV$526,MATCH($A9,Datos_ONU!$A$426:$A$526,0),MATCH($B9,Datos_ONU!$B$425:$EV$425,0)) -> 4.648 | M9: =IF($A9=100,1,L9/(K9+L9/2)) -> 0.0046695875 | N9: =N8-O8 -> 90807.135 | O9: =N9*M9 -> 424.03186 | P9: =N10+O9/2 -> 90595.119 | Q9: =SUM(P9:P$106) -> 6942154 | R9: =Q9/N9 -> 76.449434 | S9: =INDEX(Datos_ONU!$B$216:$EV$316,MATCH($A9,Datos_ONU!$A$216:$A$316,0),MATCH($B9,Datos_ONU!$B$215:$EV$215,0)) -> 2010.811 | T9: =INDEX(Datos_ONU!$B$531:$EV$631,MATCH($A9,Datos_ONU!$A$531:$A$631,0),MATCH($B9,Datos_ONU!$B$530:$EV$530,0)) -> 9.673 | U9: =IF($A9=100,1,T9/(S9+T9/2)) -> 0.0047989542 | V9: =V8-W8 -> 90224.878 | W9: =V9*U9 -> 432.98506 | X9: =V10+W9/2 -> 90008.385 | Y9: =SUM(X9:X$106) -> 6630041.8 | Z9: =Y9/V9 -> 73.483522
A10: 4 | B10: =$D$2+$A10 -> 1974 | C10: =INDEX(Datos_ONU!$B$6:$EV$106,MATCH($A10,Datos_ONU!$A$6:$A$106,0),MATCH($B10,Datos_ONU!$B$5:$EV$5,0)) -> 1012.809 | D10: =INDEX(Datos_ONU!$B$321:$EV$421,MATCH($A10,Datos_ONU!$A$321:$A$421,0),MATCH($B10,Datos_ONU!$B$320:$EV$320,0)) -> 3.184 | E10: =IF($A10=100,1,D10/(C10+D10/2)) -> 0.0031387982 | F10: =F9-G9 -> 89220.203 | G10: =F10*E10 -> 280.04421 | H10: =F11+G10/2 -> 89080.181 | I10: =SUM(H10:H$106) -> 6217595.1 | J10: =I10/F10 -> 69.688197 | K10: =INDEX(Datos_ONU!$B$111:$EV$211,MATCH($A10,Datos_ONU!$A$111:$A$211,0),MATCH($B10,Datos_ONU!$B$110:$EV$110,0)) -> 988.482 | L10: =INDEX(Datos_ONU!$B$426:$EV$526,MATCH($A10,Datos_ONU!$A$426:$A$526,0),MATCH($B10,Datos_ONU!$B$425:$EV$425,0)) -> 2.807 | M10: =IF($A10=100,1,L10/(K10+L10/2)) -> 0.0028356815 | N10: =N9-O9 -> 90383.103 | O10: =N10*M10 -> 256.29769 | P10: =N11+O10/2 -> 90254.954 | Q10: =SUM(P10:P$106) -> 6851558.9 | R10: =Q10/N10 -> 75.80575 | S10: =INDEX(Datos_ONU!$B$216:$EV$316,MATCH($A10,Datos_ONU!$A$216:$A$316,0),MATCH($B10,Datos_ONU!$B$215:$EV$215,0)) -> 2001.292 | T10: =INDEX(Datos_ONU!$B$531:$EV$631,MATCH($A10,Datos_ONU!$A$531:$A$631,0),MATCH($B10,Datos_ONU!$B$530:$EV$530,0)) -> 5.991 | U10: =IF($A10=100,1,T10/(S10+T10/2)) -> 0.0029890921 | V10: =V9-W9 -> 89791.893 | W10: =V10*U10 -> 268.39624 | X10: =V11+W10/2 -> 89657.695 | Y10: =SUM(X10:X$106) -> 6540033.4 | Z10: =Y10/V10 -> 72.835455
A11: 5 | B11: =$D$2+$A11 -> 1975 | C11: =INDEX(Datos_ONU!$B$6:$EV$106,MATCH($A11,Datos_ONU!$A$6:$A$106,0),MATCH($B11,Datos_ONU!$B$5:$EV$5,0)) -> 1009.422 | D11: =INDEX(Datos_ONU!$B$321:$EV$421,MATCH($A11,Datos_ONU!$A$321:$A$421,0),MATCH($B11,Datos_ONU!$B$320:$EV$320,0)) -> 2.109 | E11: =IF($A11=100,1,D11/(C11+D11/2)) -> 0.0020871341 | F11: =F10-G10 -> 88940.159 | G11: =F11*E11 -> 185.63004 | H11: =F12+G11/2 -> 88847.344 | I11: =SUM(H11:H$106) -> 6128514.9 | J11: =I11/F11 -> 68.906048 | K11: =INDEX(Datos_ONU!$B$111:$EV$211,MATCH($A11,Datos_ONU!$A$111:$A$211,0),MATCH($B11,Datos_ONU!$B$110:$EV$110,0)) -> 985.462 | L11: =INDEX(Datos_ONU!$B$426:$EV$526,MATCH($A11,Datos_ONU!$A$426:$A$526,0),MATCH($B11,Datos_ONU!$B$425:$EV$425,0)) -> 1.757 | M11: =IF($A11=100,1,L11/(K11+L11/2)) -> 0.0017813321 | N11: =N10-O10 -> 90126.805 | O11: =N11*M11 -> 160.54577 | P11: =N12+O11/2 -> 90046.532 | Q11: =SUM(P11:P$106) -> 6761303.9 | R11: =Q11/N11 -> 75.0199 | S11: =INDEX(Datos_ONU!$B$216:$EV$316,MATCH($A11,Datos_ONU!$A$216:$A$316,0),MATCH($B11,Datos_ONU!$B$215:$EV$215,0)) -> 1994.884 | T11: =INDEX(Datos_ONU!$B$531:$EV$631,MATCH($A11,Datos_ONU!$A$531:$A$631,0),MATCH($B11,Datos_ONU!$B$530:$EV$530,0)) -> 3.865 | U11: =IF($A11=100,1,T11/(S11+T11/2)) -> 0.001935581 | V11: =V10-W10 -> 89523.497 | W11: =V11*U11 -> 173.27998 | X11: =V12+W11/2 -> 89436.857 | Y11: =SUM(X11:X$106) -> 6450375.7 | Z11: =Y11/V11 -> 72.052321
A12: 6 | B12: =$D$2+$A12 -> 1976 | C12: =INDEX(Datos_ONU!$B$6:$EV$106,MATCH($A12,Datos_ONU!$A$6:$A$106,0),MATCH($B12,Datos_ONU!$B$5:$EV$5,0)) -> 1006.93 | D12: =INDEX(Datos_ONU!$B$321:$EV$421,MATCH($A12,Datos_ONU!$A$321:$A$421,0),MATCH($B12,Datos_ONU!$B$320:$EV$320,0)) -> 1.539 | E12: =IF($A12=100,1,D12/(C12+D12/2)) -> 0.001527241 | F12: =F11-G11 -> 88754.529 | G12: =F12*E12 -> 135.54956 | H12: =F13+G12/2 -> 88686.754 | I12: =SUM(H12:H$106) -> 6039667.5 | J12: =I12/F12 -> 68.04912 | K12: =INDEX(Datos_ONU!$B$111:$EV$211,MATCH($A12,Datos_ONU!$A$111:$A$211,0),MATCH($B12,Datos_ONU!$B$110:$EV$110,0)) -> 983.313 | L12: =INDEX(Datos_ONU!$B$426:$EV$526,MATCH($A12,Datos_ONU!$A$426:$A$526,0),MATCH($B12,Datos_ONU!$B$425:$EV$425,0)) -> 1.214 | M12: =IF($A12=100,1,L12/(K12+L12/2)) -> 0.0012338401 | N12: =N11-O11 -> 89966.259 | O12: =N12*M12 -> 111.00398 | P12: =N13+O12/2 -> 89910.757 | Q12: =SUM(P12:P$106) -> 6671257.4 | R12: =Q12/N12 -> 74.152882 | S12: =INDEX(Datos_ONU!$B$216:$EV$316,MATCH($A12,Datos_ONU!$A$216:$A$316,0),MATCH($B12,Datos_ONU!$B$215:$EV$215,0)) -> 1990.243 | T12: =INDEX(Datos_ONU!$B$531:$EV$631,MATCH($A12,Datos_ONU!$A$531:$A$631,0),MATCH($B12,Datos_ONU!$B$530:$EV$530,0)) -> 2.753 | U12: =IF($A12=100,1,T12/(S12+T12/2)) -> 0.0013822921 | V12: =V11-W11 -> 89350.217 | W12: =V12*U12 -> 123.5081 | X12: =V13+W12/2 -> 89288.463 | Y12: =SUM(X12:X$106) -> 6360938.8 | Z12: =Y12/V12 -> 71.191085
A13: 7 | B13: =$D$2+$A13 -> 1977 | C13: =INDEX(Datos_ONU!$B$6:$EV$106,MATCH($A13,Datos_ONU!$A$6:$A$106,0),MATCH($B13,Datos_ONU!$B$5:$EV$5,0)) -> 1004.947 | D13: =INDEX(Datos_ONU!$B$321:$EV$421,MATCH($A13,Datos_ONU!$A$321:$A$421,0),MATCH($B13,Datos_ONU!$B$320:$EV$320,0)) -> 1.22 | E13: =IF($A13=100,1,D13/(C13+D13/2)) -> 0.0012132579 | F13: =F12-G12 -> 88618.979 | G13: =F13*E13 -> 107.51768 | H13: =F14+G13/2 -> 88565.22 | I13: =SUM(H13:H$106) -> 5950980.8 | J13: =I13/F13 -> 67.152441 | K13: =INDEX(Datos_ONU!$B$111:$EV$211,MATCH($A13,Datos_ONU!$A$111:$A$211,0),MATCH($B13,Datos_ONU!$B$110:$EV$110,0)) -> 981.65 | L13: =INDEX(Datos_ONU!$B$426:$EV$526,MATCH($A13,Datos_ONU!$A$426:$A$526,0),MATCH($B13,Datos_ONU!$B$425:$EV$425,0)) -> 0.913 | M13: =IF($A13=100,1,L13/(K13+L13/2)) -> 0.00092963441 | N13: =N12-O12 -> 89855.255 | O13: =N13*M13 -> 83.532538 | P13: =N14+O13/2 -> 89813.489 | Q13: =SUM(P13:P$106) -> 6581346.7 | R13: =Q13/N13 -> 73.24387 | S13: =INDEX(Datos_ONU!$B$216:$EV$316,MATCH($A13,Datos_ONU!$A$216:$A$316,0),MATCH($B13,Datos_ONU!$B$215:$EV$215,0)) -> 1986.598 | T13: =INDEX(Datos_ONU!$B$531:$EV$631,MATCH($A13,Datos_ONU!$A$531:$A$631,0),MATCH($B13,Datos_ONU!$B$530:$EV$530,0)) -> 2.133 | U13: =IF($A13=100,1,T13/(S13+T13/2)) -> 0.0010731187 | V13: =V12-W12 -> 89226.709 | W13: =V13*U13 -> 95.750852 | X13: =V14+W13/2 -> 89178.833 | Y13: =SUM(X13:X$106) -> 6271650.4 | Z13: =Y13/V13 -> 70.288936
A14: 8 | B14: =$D$2+$A14 -> 1978 | C14: =INDEX(Datos_ONU!$B$6:$EV$106,MATCH($A14,Datos_ONU!$A$6:$A$106,0),MATCH($B14,Datos_ONU!$B$5:$EV$5,0)) -> 1003.29 | D14: =INDEX(Datos_ONU!$B$321:$EV$421,MATCH($A14,Datos_ONU!$A$321:$A$421,0),MATCH($B14,Datos_ONU!$B$320:$EV$320,0)) -> 1.027 | E14: =IF($A14=100,1,D14/(C14+D14/2)) -> 0.0010231086 | F14: =F13-G13 -> 88511.461 | G14: =F14*E14 -> 90.556838 | H14: =F15+G14/2 -> 88466.183 | I14: =SUM(H14:H$106) -> 5862415.6 | J14: =I14/F14 -> 66.233406 | K14: =INDEX(Datos_ONU!$B$111:$EV$211,MATCH($A14,Datos_ONU!$A$111:$A$211,0),MATCH($B14,Datos_ONU!$B$110:$EV$110,0)) -> 980.295 | L14: =INDEX(Datos_ONU!$B$426:$EV$526,MATCH($A14,Datos_ONU!$A$426:$A$526,0),MATCH($B14,Datos_ONU!$B$425:$EV$425,0)) -> 0.745 | M14: =IF($A14=100,1,L14/(K14+L14/2)) -> 0.00075968664 | N14: =N13-O13 -> 89771.723 | O14: =N14*M14 -> 68.198379 | P14: =N15+O14/2 -> 89737.624 | Q14: =SUM(P14:P$106) -> 6491533.2 | R14: =Q14/N14 -> 72.311558 | S14: =INDEX(Datos_ONU!$B$216:$EV$316,MATCH($A14,Datos_ONU!$A$216:$A$316,0),MATCH($B14,Datos_ONU!$B$215:$EV$215,0)) -> 1983.585 | T14: =INDEX(Datos_ONU!$B$531:$EV$631,MATCH($A14,Datos_ONU!$A$531:$A$631,0),MATCH($B14,Datos_ONU!$B$530:$EV$530,0)) -> 1.772 | U14: =IF($A14=100,1,T14/(S14+T14/2)) -> 0.00089293318 | V14: =V13-W13 -> 89130.958 | W14: =V14*U14 -> 79.587989 | X14: =V15+W14/2 -> 89091.164 | Y14: =SUM(X14:X$106) -> 6182471.5 | Z14: =Y14/V14 -> 69.363908
