Workbook

Sheet Tabla de mortalidad
B1: Tabla de mortalidad
B2: Cuadro: Tabla de mortalidad de México, 2019, ambos sexos (INEGI)
B3: x | C3: qx | D3: lx | E3: dx | F3: Lx | G3: Tx | H3: ex | K3: Nota técnica (qx)
C4: Probabilidad de muerte: defunciones xi/PI | D4: Supervivientes a una edad exacto | E4: Defunciones xi | F4: Años vividos entre aniversario | G4: Años vividos acumulados: Años que quedan por vivir | H4: La media de vida una generación hasta su extinción | K4: q(x): Probabilidad de muerte
B5: 0 | C5: =L9 -> 0.012423606 | D5: 100000 | E5: =ROUND(D5*C5,0) -> 1242 | F5: =ROUND(D6+(E5/2),0) -> 99379 | G5: =SUM(F5:F$105) -> 7598754 | H5: =G5/D5 -> 75.98754
B6: 1 | C6: =Insumos!B6/(Insumos!C6+Insumos!B6/2) -> 0.0011211947 | D6: =D5-E5 -> 98758 | E6: =ROUND(D6*C6,0) -> 111 | F6: =ROUND(D7+(E6/2),0) -> 98703 | G6: =SUM(F6:F$105) -> 7499375 | H6: =G6/D6 -> 75.936886 | K6: Nacimientos | L6: =Insumos!F5 -> 1844913
B7: 2 | C7: =Insumos!B7/(Insumos!C7+Insumos!B7/2) -> 0.00054663931 | D7: =D6-E6 -> 98647 | E7: =ROUND(D7*C7,0) -> 54 | F7: =ROUND(D8+(E7/2),0) -> 98620 | G7: =SUM(F7:F$105) -> 7400672 | H7: =G7/D7 -> 75.021764 | K7: Defunciones (menores de 1 año) | L7: =Insumos!B5 -> 22920.473
B8: 3 | C8: =Insumos!B8/(Insumos!C8+Insumos!B8/2) -> 0.00036188774 | D8: =D7-E7 -> 98593 | E8: =ROUND(D8*C8,0) -> 36 | F8: =ROUND(D9+(E8/2),0) -> 98575 | G8: =SUM(F8:F$105) -> 7302052 | H8: =G8/D8 -> 74.062581
B9: 4 | C9: =Insumos!B9/(Insumos!C9+Insumos!B9/2) -> 0.00029213142 | D9: =D8-E8 -> 98557 | E9: =ROUND(D9*C9,0) -> 29 | F9: =ROUND(D10+(E9/2),0) -> 98543 | G9: =SUM(F9:F$105) -> 7203477 | H9: =G9/D9 -> 73.089451 | K9: q(x) | L9: =L7/L6 -> 0.012423606
B10: 5 | C10: =Insumos!B10/(Insumos!C10+Insumos!B10/2) -> 0.00025376692 | D10: =D9-E9 -> 98528 | E10: =ROUND(D10*C10,0) -> 25 | F10: =ROUND(D11+(E10/2),0) -> 98516 | G10: =SUM(F10:F$105) -> 7104934 | H10: =G10/D10 -> 72.110811 | K10: q(0) = defunciones de menores de 1 año / nacimientos
B11: 6 | C11: =Insumos!B11/(Insumos!C11+Insumos!B11/2) -> 0.00022742464 | D11: =D10-E10 -> 98503 | E11: =ROUND(D11*C11,0) -> 22 | F11: =ROUND(D12+(E11/2),0) -> 98492 | G11: =SUM(F11:F$105) -> 7006418 | H11: =G11/D11 -> 71.128981 | K11: q(x), x = 1…99 = defunciones / (población + defunciones/2)
B12: 7 | C12: =Insumos!B12/(Insumos!C12+Insumos!B12/2) -> 0.00022952075 | D12: =D11-E11 -> 98481 | E12: =ROUND(D12*C12,0) -> 23 | F12: =ROUND(D13+(E12/2),0) -> 98470 | G12: =SUM(F12:F$105) -> 6907926 | H12: =G12/D12 -> 70.144759 | K12: Lx | L12: Los que han sobrevivido a una determinada edad
B13: 8 | C13: =Insumos!B13/(Insumos!C13+Insumos!B13/2) -> 0.00020111728 | D13: =D12-E12 -> 98458 | E13: =ROUND(D13*C13,0) -> 20 | F13: =ROUND(D14+(E13/2),0) -> 98448 | G13: =SUM(F13:F$105) -> 6809456 | H13: =G13/D13 -> 69.161023
B14: 9 | C14: =Insumos!B14/(Insumos!C14+Insumos!B14/2) -> 0.00024450211 | D14: =D13-E13 -> 98438 | E14: =ROUND(D14*C14,0) -> 24 | F14: =ROUND(D15+(E14/2),0) -> 98426 | G14: =SUM(F14:F$105) -> 6711008 | H14: =G14/D14 -> 68.174973 | K14: Lx= lx+1+(dx/2)
B15: 10 | C15: =Insumos!B15/(Insumos!C15+Insumos!B15/2) -> 0.0002345525 | D15: =D14-E14 -> 98414 | E15: =ROUND(D15*C15,0) -> 23 | F15: =ROUND(D16+(E15/2),0) -> 98403 | G15: =SUM(F15:F$105) -> 6612582 | H15: =G15/D15 -> 67.191477
B16: 11 | C16: =Insumos!B16/(Insumos!C16+Insumos!B16/2) -> 0.00025925762 | D16: =D15-E15 -> 98391 | E16: =ROUND(D16*C16,0) -> 26 | F16: =ROUND(D17+(E16/2),0) -> 98378 | G16: =SUM(F16:F$105) -> 6514179 | H16: =G16/D16 -> 66.207062 | K16: Año de referencia | L16: 2019
B17: 12 | C17: =Insumos!B17/(Insumos!C17+Insumos!B17/2) -> 0.00028946272 | D17: =D16-E16 -> 98365 | E17: =ROUND(D17*C17,0) -> 28 | F17: =ROUND(D18+(E17/2),0) -> 98351 | G17: =SUM(F17:F$105) -> 6415801 | H17: =G17/D17 -> 65.224429 | K17: Defunciones y nacimientos ocurridos en 2019; población del Censo 2020
B18: 13 | C18: =Insumos!B18/(Insumos!C18+Insumos!B18/2) -> 0.00035052086 | D18: =D17-E17 -> 98337 | E18: =ROUND(D18*C18,0) -> 34 | F18: =ROUND(D19+(E18/2),0) -> 98320 | G18: =SUM(F18:F$105) -> 6317450 | H18: =G18/D18 -> 64.242859
B19: 14 | C19: =Insumos!B19/(Insumos!C19+Insumos!B19/2) -> 0.00044609752 | D19: =D18-E18 -> 98303 | E19: =ROUND(D19*C19,0) -> 44 | F19: =ROUND(D20+(E19/2),0) -> 98281 | G19: =SUM(F19:F$105) -> 6219130 | H19: =G19/D19 -> 63.264905 | K19: Defunciones y población de cada edad: hoja Insumos (preparadas en el libro 1_Preparacion_datos_INEGI_2019.xlsx)
B20: 15 | C20: =Insumos!B20/(Insumos!C20+Insumos!B20/2) -> 0.00055888298 | D20: =D19-E19 -> 98259 | E20: =ROUND(D20*C20,0) -> 55 | F20: =ROUND(D21+(E20/2),0) -> 98232 | G20: =SUM(F20:F$105) -> 6120849 | H20: =G20/D20 -> 62.293011
B21: 16 | C21: =Insumos!B21/(Insumos!C21+Insumos!B21/2) -> 0.00068733218 | D21: =D20-E20 -> 98204 | E21: =ROUND(D21*C21,0) -> 67 | F21: =ROUND(D22+(E21/2),0) -> 98171 | G21: =SUM(F21:F$105) -> 6022617 | H21: =G21/D21 -> 61.327614 | K21: Tx = Lx + L(x+1) + … + L100
B22: 17 | C22: =Insumos!B22/(Insumos!C22+Insumos!B22/2) -> 0.0008400822 | D22: =D21-E21 -> 98137 | E22: =ROUND(D22*C22,0) -> 82 | F22: =ROUND(D23+(E22/2),0) -> 98096 | G22: =SUM(F22:F$105) -> 5924446 | H22: =G22/D22 -> 60.369137 | K22: ex = Tx / lx
B23: 18 | C23: =Insumos!B23/(Insumos!C23+Insumos!B23/2) -> 0.00097674265 | D23: =D22-E22 -> 98055 | E23: =ROUND(D23*C23,0) -> 96 | F23: =ROUND(D24+(E23/2),0) -> 98007 | G23: =SUM(F23:F$105) -> 5826350 | H23: =G23/D23 -> 59.419204 | K23: Edad 100 = grupo abierto (100 y más): qx = 1
B24: 19 | C24: =Insumos!B24/(Insumos!C24+Insumos!B24/2) -> 0.0011180078 | D24: =D23-E23 -> 97959 | E24: =ROUND(D24*C24,0) -> 110 | F24: =ROUND(D25+(E24/2),0) -> 97904 | G24: =SUM(F24:F$105) -> 5728343 | H24: =G24/D24 -> 58.476944
B25: 20 | C25: =Insumos!B25/(Insumos!C25+Insumos!B25/2) -> 0.0012334081 | D25: =D24-E24 -> 97849 | E25: =ROUND(D25*C25,0) -> 121 | F25: =ROUND(D26+(E25/2),0) -> 97789 | G25: =SUM(F25:F$105) -> 5630439 | H25: =G25/D25 -> 57.542121 | K25: Control: suma de dx − radix | L25: =SUM(E5:E105)-D5 -> 0
B26: 21 | C26: =Insumos!B26/(Insumos!C26+Insumos!B26/2) -> 0.0013665092 | D26: =D25-E25 -> 97728 | E26: =ROUND(D26*C26,0) -> 134 | F26: =ROUND(D27+(E26/2),0) -> 97661 | G26: =SUM(F26:F$105) -> 5532650 | H26: =G26/D26 -> 56.612741
B27: 22 | C27: =Insumos!B27/(Insumos!C27+Insumos!B27/2) -> 0.0014459661 | D27: =D26-E26 -> 97594 | E27: =ROUND(D27*C27,0) -> 141 | F27: =ROUND(D28+(E27/2),0) -> 97524 | G27: =SUM(F27:F$105) -> 5434989 | H27: =G27/D27 -> 55.689786 | K27: Fuente: INEGI (Estadística de Nacimientos Registrados, Estadísticas de Defunciones Registradas y Censo de Población y Vivienda 2020).
B28: 23 | C28: =Insumos!B28/(Insumos!C28+Insumos!B28/2) -> 0.0015462703 | D28: =D27-E27 -> 97453 | E28: =ROUND(D28*C28,0) -> 151 | F28: =ROUND(D29+(E28/2),0) -> 97378 | G28: =SUM(F28:F$105) -> 5337465 | H28: =G28/D28 -> 54.769633 | K28: Datos: hoja Insumos. Cómo se obtuvieron: libro 1_Preparacion_datos_INEGI_2019.xlsx y carpeta bases_de_datos_INEGI/.
B29: 24 | C29: =Insumos!B29/(Insumos!C29+Insumos!B29/2) -> 0.0015957572 | D29: =D28-E28 -> 97302 | E29: =ROUND(D29*C29,0) -> 155 | F29: =ROUND(D30+(E29/2),0) -> 97225 | G29: =SUM(F29:F$105) -> 5240087 | H29: =G29/D29 -> 53.853847
B30: 25 | C30: =Insumos!B30/(Insumos!C30+Insumos!B30/2) -> 0.001696138 | D30: =D29-E29 -> 97147 | E30: =ROUND(D30*C30,0) -> 165 | F30: =ROUND(D31+(E30/2),0) -> 97065 | G30: =SUM(F30:F$105) -> 5142862 | H30: =G30/D30 -> 52.938969
B31: 26 | C31: =Insumos!B31/(Insumos!C31+Insumos!B31/2) -> 0.0017366627 | D31: =D30-E30 -> 96982 | E31: =ROUND(D31*C31,0) -> 168 | F31: =ROUND(D32+(E31/2),0) -> 96898 | G31: =SUM(F31:F$105) -> 5045797 | H31: =G31/D31 -> 52.02818
B32: 27 | C32: =Insumos!B32/(Insumos!C32+Insumos!B32/2) -> 0.0018041345 | D32: =D31-E31 -> 96814 | E32: =ROUND(D32*C32,0) -> 175 | F32: =ROUND(D33+(E32/2),0) -> 96727 | G32: =SUM(F32:F$105) -> 4948899 | H32: =G32/D32 -> 51.117597
B33: 28 | C33: =Insumos!B33/(Insumos!C33+Insumos!B33/2) -> 0.0017980826 | D33: =D32-E32 -> 96639 | E33: =ROUND(D33*C33,0) -> 174 | F33: =ROUND(D34+(E33/2),0) -> 96552 | G33: =SUM(F33:F$105) -> 4852172 | H33: =G33/D33 -> 50.209253
B34: 29 | C34: =Insumos!B34/(Insumos!C34+Insumos!B34/2) -> 0.0018948607 | D34: =D33-E33 -> 96465 | E34: =ROUND(D34*C34,0) -> 183 | F34: =ROUND(D35+(E34/2),0) -> 96374 | G34: =SUM(F34:F$105) -> 4755620 | H34: =G34/D34 -> 49.298917
B35: 30 | C35: =Insumos!B35/(Insumos!C35+Insumos!B35/2) -> 0.0018833385 | D35: =D34-E34 -> 96282 | E35: =ROUND(D35*C35,0) -> 181 | F35: =ROUND(D36+(E35/2),0) -> 96192 | G35: =SUM(F35:F$105) -> 4659246 | H35: =G35/D35 -> 48.391662
B36: 31 | C36: =Insumos!B36/(Insumos!C36+Insumos!B36/2) -> 0.001947577 | D36: =D35-E35 -> 96101 | E36: =ROUND(D36*C36,0) -> 187 | F36: =ROUND(D37+(E36/2),0) -> 96008 | G36: =SUM(F36:F$105) -> 4563054 | H36: =G36/D36 -> 47.481858
B37: 32 | C37: =Insumos!B37/(Insumos!C37+Insumos!B37/2) -> 0.0019868891 | D37: =D36-E36 -> 95914 | E37: =ROUND(D37*C37,0) -> 191 | F37: =ROUND(D38+(E37/2),0) -> 95819 | G37: =SUM(F37:F$105) -> 4467046 | H37: =G37/D37 -> 46.573451
B38: 33 | C38: =Insumos!B38/(Insumos!C38+Insumos!B38/2) -> 0.0021012488 | D38: =D37-E37 -> 95723 | E38: =ROUND(D38*C38,0) -> 201 | F38: =ROUND(D39+(E38/2),0) -> 95623 | G38: =SUM(F38:F$105) -> 4371227 | H38: =G38/D38 -> 45.665378
B39: 34 | C39: =Insumos!B39/(Insumos!C39+Insumos!B39/2) -> 0.0020702917 | D39: =D38-E38 -> 95522 | E39: =ROUND(D39*C39,0) -> 198 | F39: =ROUND(D40+(E39/2),0) -> 95423 | G39: =SUM(F39:F$105) -> 4275604 | H39: =G39/D39 -> 44.760411
B40: 35 | C40: =Insumos!B40/(Insumos!C40+Insumos!B40/2) -> 0.0022249365 | D40: =D39-E39 -> 95324 | E40: =ROUND(D40*C40,0) -> 212 | F40: =ROUND(D41+(E40/2),0) -> 95218 | G40: =SUM(F40:F$105) -> 4180181 | H40: =G40/D40 -> 43.852346
...

Sheet Insumos
A1: Insumos de la tabla de mortalidad: defunciones y población usadas, México 2019, ambos sexos
A2: Valores tomados del libro 1_Preparacion_datos_INEGI_2019.xlsx (hoja Preparación, columnas D y F). Aquí solo se leen; la tabla los usa en la fórmula q(x) = D / (P + D/2).
A4: Edad x | B4: Defunciones usadas (D) | C4: Población usada (P) | E4: Dato | F4: Valor
A5: 0 | B5: 22920.473 | C5: 1812977 | E5: Nacimientos 2019 (ENR) | F5: 1844913
A6: 1 | B6: 2142.6359 | C6: 1909958
A7: 2 | B7: 1116.0609 | C7: 2041119
A8: 3 | B8: 763.14436 | C8: 2108406
A9: 4 | B9: 635.45091 | C9: 2174905
A10: 5 | B10: 553.00316 | C10: 2178901
A11: 6 | B11: 476.58818 | C11: 2095349
A12: 7 | B12: 492.67555 | C12: 2146294
A13: 8 | B13: 449.44075 | C13: 2234495
A14: 9 | B14: 515.80113 | C14: 2109340
A15: 10 | B15: 515.80113 | C15: 2198828.2
A16: 11 | B16: 565.26978 | C16: 2180057.4
A17: 12 | B17: 633.64108 | C17: 2188708
... A105: 100 | B105: 4305.381 | C105: 18295
A107: Edad 0: defunciones de menores de 1 año (se divide entre nacimientos, no entre población). Edad 100: grupo abierto, q = 1.
