Workbook

Sheet Fuentes de datos
B2: TABLAS DE MORTALIDAD
B3: Aplicación de "Tablas Transversales Abreviadas" con datos de INEGI 2025
B4: Cohorte ficticio
B6: Poblacionales
B7: Encuesta Intercensal (EIC) 2025
B8: https://www.inegi.org.mx/programas/eic/2025/#tabulados
B35: Tamaño de localidad | C35: Grupos quinquenales de edad | D35: Estimador | E35: Población total en viviendas particulares habitadas | F35: Mujeres | H35: Hombres
F36: Absolutos | G36: Relativos | H36: Absolutos | I36: Relativos
B37: Estados Unidos Mexicanos | C37: 00-04 años | D37: Valor | E37: 7569573 | F37: 3741386 | G37: 49.426645 | H37: 3828187 | I37: 50.573355
B38: Estados Unidos Mexicanos | C38: 05-09 años | D38: Valor | E38: 9669960 | F38: 4785294 | G38: 49.486182 | H38: 4884666 | I38: 50.513818
B39: Estados Unidos Mexicanos | C39: 10-14 años | D39: Valor | E39: 10885388 | F39: 5353603 | G39: 49.181554 | H39: 5531785 | I39: 50.818446
B40: Estados Unidos Mexicanos | C40: 15-19 años | D40: Valor | E40: 10833608 | F40: 5349921 | G40: 49.382634 | H40: 5483687 | I40: 50.617366
B41: Estados Unidos Mexicanos | C41: 20-24 años | D41: Valor | E41: 10360929 | F41: 5319788 | G41: 51.344701 | H41: 5041141 | I41: 48.655299
B42: Estados Unidos Mexicanos | C42: 25-29 años | D42: Valor | E42: 9810773 | F42: 5104330 | G42: 52.027807 | H42: 4706443 | I42: 47.972193
B43: Estados Unidos Mexicanos | C43: 30-34 años | D43: Valor | E43: 10027553 | F43: 5282566 | G43: 52.680509 | H43: 4744987 | I43: 47.319491
B44: Estados Unidos Mexicanos | C44: 35-39 años | D44: Valor | E44: 9620908 | F44: 5095386 | G44: 52.961592 | H44: 4525522 | I44: 47.038408
B45: Estados Unidos Mexicanos | C45: 40-44 años | D45: Valor | E45: 8974041 | F45: 4742766 | G45: 52.849837 | H45: 4231275 | I45: 47.150163
B46: Estados Unidos Mexicanos | C46: 45-49 años | D46: Valor | E46: 8374000 | F46: 4437822 | G46: 52.995247 | H46: 3936178 | I46: 47.004753
B47: Estados Unidos Mexicanos | C47: 50-54 años | D47: Valor | E47: 8352139 | F47: 4409290 | G47: 52.792345 | H47: 3942849 | I47: 47.207655
B48: Estados Unidos Mexicanos | C48: 55-59 años | D48: Valor | E48: 6709847 | F48: 3553454 | G48: 52.958793 | H48: 3156393 | I48: 47.041207
... B52: Estados Unidos Mexicanos | C52: 75 años y más | D52: Valor | E52: 4964838 | F52: 2784501 | G52: 56.084428 | H52: 2180337 | I52: 43.915572
B53: Mortalidad
B54: Encuesta Intercensal (EIC) 2025
B55: https://www.inegi.org.mx/sistemas/olap/Proyectos/bd/continuas/mortalidad/MortalidadGeneral.asp?
B56: https://www.inegi.org.mx/sistemas/olap/consulta/general_ver4/MDXQueryDatos.asp?#Regreso&c=
C106: Total | D106: Hombre | E106: Mujer | F106: No especificado
B107: Total | C107: 762,494 | D107: 426,340 | E107: 335,625 | F107: 529
B108: Menores de 1 año | C108: 12,207 | D108: 6,864 | E108: 5,307 | F108: 36
B109: 1-4 años | C109: 2,821 | D109: 1,514 | E109: 1,306 | F109: 1
B110: 5-9 años | C110: 1,918 | D110: 1,087 | E110: 831
B111: 10-14 años | C111: 3,046 | D111: 1,734 | E111: 1,312
B112: 15-19 años | C112: 8,916 | D112: 6,652 | E112: 2,264
B113: 20-24 años | C113: 13,045 | D113: 10,260 | E113: 2,784 | F113: 1
B114: 25-29 años | C114: 15,271 | D114: 11,793 | E114: 3,477 | F114: 1
B115: 30-34 años | C115: 18,455 | D115: 13,802 | E115: 4,652 | F115: 1
B116: 35-39 años | C116: 20,688 | D116: 14,902 | E116: 5,784 | F116: 2
B117: 40-44 años | C117: 24,421 | D117: 16,673 | E117: 7,746 | F117: 2
B118: 45-49 años | C118: 32,179 | D118: 20,907 | E118: 11,271 | F118: 1
B119: 50-54 años | C119: 43,236 | D119: 27,195 | E119: 16,040 | F119: 1
B120: 55-59 años | C120: 51,417 | D120: 31,028 | E120: 20,383 | F120: 6
...

Sheet Cohorte ficticio
B2: COHORTE FICTICIO
B3: Insumos de las "Tablas Transversales Abreviadas" con datos de INEGI 2025: Encuesta Intercensal (EIC) y defunciones registradas
B5: Radix de la cohorte ficticia (l0) | D5: 100000 | E5: Supuesto: 100,000 nacimientos hipotéticos que viven toda su vida con las tasas de mortalidad de 2025 (cohorte ficticia). Se puede cambiar.
B6: Letra azul sobre amarillo = supuesto que se puede cambiar. Todo lo demás son fórmulas que leen la hoja 'Fuentes de datos'.
B8: A. Defunciones registradas 2025 (INEGI): se reparten el sexo y la edad no especificados
B9: Paso 1: el sexo no especificado se reparte entre hombres y mujeres en proporción a sus defunciones, edad por edad. Paso 2: las defunciones de edad no especificada se reparten entre todas las edades en proporción a las ya ajustadas, por sexo. Las cifras de INEGI vienen como texto con comas; aquí se convierten a número.
B10: Grupo de edad | C10: Hombres (INEGI) | D10: Mujeres (INEGI) | E10: Sexo no especificado | F10: Hombres (paso 1) | G10: Mujeres (paso 1) | H10: Hombres (paso 2) | I10: Mujeres (paso 2)
B11: ='Fuentes de datos'!B108 -> Menores de 1 año | C11: =IF('Fuentes de datos'!D108="",0,VALUE(SUBSTITUTE('Fuentes de datos'!D108,",",""))) -> 6864 | D11: =IF('Fuentes de datos'!E108="",0,VALUE(SUBSTITUTE('Fuentes de datos'!E108,",",""))) -> 5307 | E11: =IF('Fuentes de datos'!F108="",0,VALUE(SUBSTITUTE('Fuentes de datos'!F108,",",""))) -> 36 | F11: =C11+E11*C11/(C11+D11) -> 6884.3027 | G11: =D11+E11*D11/(C11+D11) -> 5322.6973 | H11: =F11*$F$32 -> 6943.8098 | I11: =G11*$G$32 -> 5328.3863
B12: ='Fuentes de datos'!B109 -> 1-4 años | C12: =IF('Fuentes de datos'!D109="",0,VALUE(SUBSTITUTE('Fuentes de datos'!D109,",",""))) -> 1514 | D12: =IF('Fuentes de datos'!E109="",0,VALUE(SUBSTITUTE('Fuentes de datos'!E109,",",""))) -> 1306 | E12: =IF('Fuentes de datos'!F109="",0,VALUE(SUBSTITUTE('Fuentes de datos'!F109,",",""))) -> 1 | F12: =C12+E12*C12/(C12+D12) -> 1514.5369 | G12: =D12+E12*D12/(C12+D12) -> 1306.4631 | H12: =F12*$F$32 -> 1527.6284 | I12: =G12*$G$32 -> 1307.8595
B13: ='Fuentes de datos'!B110 -> 5-9 años | C13: =IF('Fuentes de datos'!D110="",0,VALUE(SUBSTITUTE('Fuentes de datos'!D110,",",""))) -> 1087 | D13: =IF('Fuentes de datos'!E110="",0,VALUE(SUBSTITUTE('Fuentes de datos'!E110,",",""))) -> 831 | E13: =IF('Fuentes de datos'!F110="",0,VALUE(SUBSTITUTE('Fuentes de datos'!F110,",",""))) -> 0 | F13: =C13+E13*C13/(C13+D13) -> 1087 | G13: =D13+E13*D13/(C13+D13) -> 831 | H13: =F13*$F$32 -> 1096.3959 | I13: =G13*$G$32 -> 831.88818
B14: ='Fuentes de datos'!B111 -> 10-14 años | C14: =IF('Fuentes de datos'!D111="",0,VALUE(SUBSTITUTE('Fuentes de datos'!D111,",",""))) -> 1734 | D14: =IF('Fuentes de datos'!E111="",0,VALUE(SUBSTITUTE('Fuentes de datos'!E111,",",""))) -> 1312 | E14: =IF('Fuentes de datos'!F111="",0,VALUE(SUBSTITUTE('Fuentes de datos'!F111,",",""))) -> 0 | F14: =C14+E14*C14/(C14+D14) -> 1734 | G14: =D14+E14*D14/(C14+D14) -> 1312 | H14: =F14*$F$32 -> 1748.9885 | I14: =G14*$G$32 -> 1313.4023
B15: ='Fuentes de datos'!B112 -> 15-19 años | C15: =IF('Fuentes de datos'!D112="",0,VALUE(SUBSTITUTE('Fuentes de datos'!D112,",",""))) -> 6652 | D15: =IF('Fuentes de datos'!E112="",0,VALUE(SUBSTITUTE('Fuentes de datos'!E112,",",""))) -> 2264 | E15: =IF('Fuentes de datos'!F112="",0,VALUE(SUBSTITUTE('Fuentes de datos'!F112,",",""))) -> 0 | F15: =C15+E15*C15/(C15+D15) -> 6652 | G15: =D15+E15*D15/(C15+D15) -> 2264 | H15: =F15*$F$32 -> 6709.4991 | I15: =G15*$G$32 -> 2266.4198
B16: ='Fuentes de datos'!B113 -> 20-24 años | C16: =IF('Fuentes de datos'!D113="",0,VALUE(SUBSTITUTE('Fuentes de datos'!D113,",",""))) -> 10260 | D16: =IF('Fuentes de datos'!E113="",0,VALUE(SUBSTITUTE('Fuentes de datos'!E113,",",""))) -> 2784 | E16: =IF('Fuentes de datos'!F113="",0,VALUE(SUBSTITUTE('Fuentes de datos'!F113,",",""))) -> 1 | F16: =C16+E16*C16/(C16+D16) -> 10260.787 | G16: =D16+E16*D16/(C16+D16) -> 2784.2134 | H16: =F16*$F$32 -> 10349.48 | I16: =G16*$G$32 -> 2787.1892
B17: ='Fuentes de datos'!B114 -> 25-29 años | C17: =IF('Fuentes de datos'!D114="",0,VALUE(SUBSTITUTE('Fuentes de datos'!D114,",",""))) -> 11793 | D17: =IF('Fuentes de datos'!E114="",0,VALUE(SUBSTITUTE('Fuentes de datos'!E114,",",""))) -> 3477 | E17: =IF('Fuentes de datos'!F114="",0,VALUE(SUBSTITUTE('Fuentes de datos'!F114,",",""))) -> 1 | F17: =C17+E17*C17/(C17+D17) -> 11793.772 | G17: =D17+E17*D17/(C17+D17) -> 3477.2277 | H17: =F17*$F$32 -> 11895.716 | I17: =G17*$G$32 -> 3480.9442
B18: ='Fuentes de datos'!B115 -> 30-34 años | C18: =IF('Fuentes de datos'!D115="",0,VALUE(SUBSTITUTE('Fuentes de datos'!D115,",",""))) -> 13802 | D18: =IF('Fuentes de datos'!E115="",0,VALUE(SUBSTITUTE('Fuentes de datos'!E115,",",""))) -> 4652 | E18: =IF('Fuentes de datos'!F115="",0,VALUE(SUBSTITUTE('Fuentes de datos'!F115,",",""))) -> 1 | F18: =C18+E18*C18/(C18+D18) -> 13802.748 | G18: =D18+E18*D18/(C18+D18) -> 4652.2521 | H18: =F18*$F$32 -> 13922.057 | I18: =G18*$G$32 -> 4657.2245
B19: ='Fuentes de datos'!B116 -> 35-39 años | C19: =IF('Fuentes de datos'!D116="",0,VALUE(SUBSTITUTE('Fuentes de datos'!D116,",",""))) -> 14902 | D19: =IF('Fuentes de datos'!E116="",0,VALUE(SUBSTITUTE('Fuentes de datos'!E116,",",""))) -> 5784 | E19: =IF('Fuentes de datos'!F116="",0,VALUE(SUBSTITUTE('Fuentes de datos'!F116,",",""))) -> 2 | F19: =C19+E19*C19/(C19+D19) -> 14903.441 | G19: =D19+E19*D19/(C19+D19) -> 5784.5592 | H19: =F19*$F$32 -> 15032.264 | I19: =G19*$G$32 -> 5790.7418
B20: ='Fuentes de datos'!B117 -> 40-44 años | C20: =IF('Fuentes de datos'!D117="",0,VALUE(SUBSTITUTE('Fuentes de datos'!D117,",",""))) -> 16673 | D20: =IF('Fuentes de datos'!E117="",0,VALUE(SUBSTITUTE('Fuentes de datos'!E117,",",""))) -> 7746 | E20: =IF('Fuentes de datos'!F117="",0,VALUE(SUBSTITUTE('Fuentes de datos'!F117,",",""))) -> 2 | F20: =C20+E20*C20/(C20+D20) -> 16674.366 | G20: =D20+E20*D20/(C20+D20) -> 7746.6344 | H20: =F20*$F$32 -> 16818.497 | I20: =G20*$G$32 -> 7754.9141
B21: ='Fuentes de datos'!B118 -> 45-49 años | C21: =IF('Fuentes de datos'!D118="",0,VALUE(SUBSTITUTE('Fuentes de datos'!D118,",",""))) -> 20907 | D21: =IF('Fuentes de datos'!E118="",0,VALUE(SUBSTITUTE('Fuentes de datos'!E118,",",""))) -> 11271 | E21: =IF('Fuentes de datos'!F118="",0,VALUE(SUBSTITUTE('Fuentes de datos'!F118,",",""))) -> 1 | F21: =C21+E21*C21/(C21+D21) -> 20907.65 | G21: =D21+E21*D21/(C21+D21) -> 11271.35 | H21: =F21*$F$32 -> 21088.373 | I21: =G21*$G$32 -> 11283.397
B22: ='Fuentes de datos'!B119 -> 50-54 años | C22: =IF('Fuentes de datos'!D119="",0,VALUE(SUBSTITUTE('Fuentes de datos'!D119,",",""))) -> 27195 | D22: =IF('Fuentes de datos'!E119="",0,VALUE(SUBSTITUTE('Fuentes de datos'!E119,",",""))) -> 16040 | E22: =IF('Fuentes de datos'!F119="",0,VALUE(SUBSTITUTE('Fuentes de datos'!F119,",",""))) -> 1 | F22: =C22+E22*C22/(C22+D22) -> 27195.629 | G22: =D22+E22*D22/(C22+D22) -> 16040.371 | H22: =F22*$F$32 -> 27430.705 | I22: =G22*$G$32 -> 16057.515
... B29: ='Fuentes de datos'!B126 -> 85 años y más | C29: =IF('Fuentes de datos'!D126="",0,VALUE(SUBSTITUTE('Fuentes de datos'!D126,",",""))) -> 58901 | D29: =IF('Fuentes de datos'!E126="",0,VALUE(SUBSTITUTE('Fuentes de datos'!E126,",",""))) -> 81299 | E29: =IF('Fuentes de datos'!F126="",0,VALUE(SUBSTITUTE('Fuentes de datos'!F126,",",""))) -> 7 | F29: =C29+E29*C29/(C29+D29) -> 58903.941 | G29: =D29+E29*D29/(C29+D29) -> 81303.059 | H29: =F29*$F$32 -> 59413.1 | I29: =G29*$G$32 -> 81389.957
B30: ='Fuentes de datos'!B127 -> No especificado | C30: =IF('Fuentes de datos'!D127="",0,VALUE(SUBSTITUTE('Fuentes de datos'!D127,",",""))) -> 3235 | D30: =IF('Fuentes de datos'!E127="",0,VALUE(SUBSTITUTE('Fuentes de datos'!E127,",",""))) -> 317 | E30: =IF('Fuentes de datos'!F127="",0,VALUE(SUBSTITUTE('Fuentes de datos'!F127,",",""))) -> 464 | F30: =C30+E30*C30/(C30+D30) -> 3657.5901 | G30: =D30+E30*D30/(C30+D30) -> 358.40991
B31: Total | C31: =SUM(C11:C30) -> 426340 | D31: =SUM(D11:D30) -> 335625 | E31: =SUM(E11:E30) -> 529 | F31: =SUM(F11:F30) -> 426799.6 | G31: =SUM(G11:G30) -> 335694.4 | H31: =SUM(H11:H30) -> 426799.6 | I31: =SUM(I11:I30) -> 335694.4
B32: Factor del paso 2 | F32: =SUM(F11:F30)/SUM(F11:F29) -> 1.0086439 | G32: =SUM(G11:G30)/SUM(G11:G29) -> 1.0010688
B33: Control: H + M (paso 2) − total de INEGI | H33: =ROUND(SUM(H11:I29)-IF('Fuentes de datos'!C107="",0,VALUE(SUBSTITUTE('Fuentes de datos'!C107,",",""))),6) -> 0 | I33: ← debe ser 0
B35: B. Población (EIC 2025): se separan los menores de 1 año
B36: La EIC trae 0-4 años junto, y la tabla necesita el año 0 por separado. Supuesto: las cohortes de nacimiento crecen hacia atrás a tasa constante r, r = ln(P5-9 / P0-4) / 5; entonces la fracción de 0-4 con menos de 1 año es (e^r − 1) / (e^(5r) − 1).
C37: Hombres | D37: Mujeres
B38: Población 0-4 | C38: ='Fuentes de datos'!H37 -> 3828187 | D38: ='Fuentes de datos'!F37 -> 3741386
B39: Población 5-9 | C39: ='Fuentes de datos'!H38 -> 4884666 | D39: ='Fuentes de datos'!F38 -> 4785294
B40: r (crecimiento de las cohortes) | C40: =LN(C39/C38)/5 -> 0.048741918 | D40: =LN(D39/D38)/5 -> 0.049218267
B41: Fracción de 0-4 con menos de 1 año | C41: =(EXP(C40)-1)/(EXP(5*C40)-1) -> 0.18099311 | D41: =(EXP(D40)-1)/(EXP(5*D40)-1) -> 0.18081233
B42: Población menor de 1 año | C42: =C38*C41 -> 692875.48 | D42: =D38*D41 -> 676488.74
B43: Población de 1 a 4 años | C43: =C38-C42 -> 3135311.5 | D43: =D38-D42 -> 3064897.3
B45: C. Población y defunciones por grupo de la tabla: 0, 1-4, 5-9, ..., 70-74 y 75+
B46: 75-79, 80-84 y 85+ de defunciones se suman en 75+, porque la EIC llega solo a 75 años y más.
B47: Grupo de edad | C47: Población hombres | D47: Defunciones hombres | E47: Población mujeres | F47: Defunciones mujeres | G47: Población ambos sexos | H47: Defunciones ambos sexos
B48: 0 | C48: =C42 -> 692875.48 | D48: =H11 -> 6943.8098 | E48: =D42 -> 676488.74 | F48: =I11 -> 5328.3863 | G48: =C48+E48 -> 1369364.2 | H48: =D48+F48 -> 12272.196
B49: 1-4 | C49: =C43 -> 3135311.5 | D49: =H12 -> 1527.6284 | E49: =D43 -> 3064897.3 | F49: =I12 -> 1307.8595 | G49: =C49+E49 -> 6200208.8 | H49: =D49+F49 -> 2835.4878
B50: 5-9 | C50: ='Fuentes de datos'!H38 -> 4884666 | D50: =H13 -> 1096.3959 | E50: ='Fuentes de datos'!F38 -> 4785294 | F50: =I13 -> 831.88818 | G50: =C50+E50 -> 9669960 | H50: =D50+F50 -> 1928.2841
B51: 10-14 | C51: ='Fuentes de datos'!H39 -> 5531785 | D51: =H14 -> 1748.9885 | E51: ='Fuentes de datos'!F39 -> 5353603 | F51: =I14 -> 1313.4023 | G51: =C51+E51 -> 10885388 | H51: =D51+F51 -> 3062.3908
...

Sheet Tabla hombres
B2: TABLA TRANSVERSAL ABREVIADA: HOMBRES
B3: México 2025. Cohorte ficticia de 100,000 nacimientos con las tasas de mortalidad por edad observadas (INEGI: EIC 2025 y defunciones registradas)
B5: Radix l0 | D5: ='Cohorte ficticio'!D5 -> 100000
B6: nMx = D/P; nqx = n·nMx / (1 + (n − nax)·nMx); lx+n = lx·(1 − nqx); ndx = lx − lx+n; nLx = n·lx+n + nax·ndx; Tx = suma de nLx hacia abajo; ex = Tx/lx. Grupo abierto 75+: q = 1 y L = l/M.
B7: nax: para 0 y 1-4, Coale-Demeny según la mortalidad infantil y el sexo (en ambos sexos, el promedio de hombres y mujeres); n/2 en los demás grupos. Valores sin redondear.
B8: Edad | C8: x | D8: n | E8: P (población) | F8: D (defunciones) | G8: nMx | H8: nax | I8: nqx | J8: npx | K8: lx | L8: ndx | M8: nLx | N8: Tx | O8: ex
B9: ='Cohorte ficticio'!B48 -> 0 | C9: 0 | D9: 1 | E9: ='Cohorte ficticio'!C48 -> 692875.48 | F9: ='Cohorte ficticio'!D48 -> 6943.8098 | G9: =F9/E9 -> 0.010021728 | H9: =IF($G$9>=0.107,0.33,0.045+2.684*$G$9) -> 0.071898319 | I9: =D9*G9/(1+(D9-H9)*G9) -> 0.0099293734 | J9: =1-I9 -> 0.99007063 | K9: =$D$5 -> 100000 | L9: =K9*I9 -> 992.93734 | M9: =D9*K10+H9*L9 -> 99078.453 | N9: =SUM(M9:$M$25) -> 7664264.5 | O9: =N9/K9 -> 76.642645
B10: ='Cohorte ficticio'!B49 -> 1-4 | C10: 1 | D10: 4 | E10: ='Cohorte ficticio'!C49 -> 3135311.5 | F10: ='Cohorte ficticio'!D49 -> 1527.6284 | G10: =F10/E10 -> 0.00048723336 | H10: =IF($G$9>=0.107,1.352,1.651-2.816*$G$9) -> 1.6227788 | I10: =D10*G10/(1+(D10-H10)*G10) -> 0.0019466787 | J10: =1-I10 -> 0.99805332 | K10: =K9-L9 -> 99007.063 | L10: =K10*I10 -> 192.73494 | M10: =D10*K11+H10*L10 -> 395570.08 | N10: =SUM(M10:$M$25) -> 7565186 | O10: =N10/K10 -> 76.410569
B11: ='Cohorte ficticio'!B50 -> 5-9 | C11: 5 | D11: 5 | E11: ='Cohorte ficticio'!C50 -> 4884666 | F11: ='Cohorte ficticio'!D50 -> 1096.3959 | G11: =F11/E11 -> 0.00022445668 | H11: =D11/2 -> 2.5 | I11: =D11*G11/(1+(D11-H11)*G11) -> 0.001121654 | J11: =1-I11 -> 0.99887835 | K11: =K10-L10 -> 98814.328 | L11: =K11*I11 -> 110.83548 | M11: =D11*K12+H11*L11 -> 493794.55 | N11: =SUM(M11:$M$25) -> 7169616 | O11: =N11/K11 -> 72.556441
B12: ='Cohorte ficticio'!B51 -> 10-14 | C12: 10 | D12: 5 | E12: ='Cohorte ficticio'!C51 -> 5531785 | F12: ='Cohorte ficticio'!D51 -> 1748.9885 | G12: =F12/E12 -> 0.00031617073 | H12: =D12/2 -> 2.5 | I12: =D12*G12/(1+(D12-H12)*G12) -> 0.0015796051 | J12: =1-I12 -> 0.99842039 | K12: =K11-L11 -> 98703.492 | L12: =K12*I12 -> 155.91254 | M12: =D12*K13+H12*L12 -> 493127.68 | N12: =SUM(M12:$M$25) -> 6675821.4 | O12: =N12/K12 -> 67.635109
B13: ='Cohorte ficticio'!B52 -> 15-19 | C13: 15 | D13: 5 | E13: ='Cohorte ficticio'!C52 -> 5483687 | F13: ='Cohorte ficticio'!D52 -> 6709.4991 | G13: =F13/E13 -> 0.0012235379 | H13: =D13/2 -> 2.5 | I13: =D13*G13/(1+(D13-H13)*G13) -> 0.0060990337 | J13: =1-I13 -> 0.99390097 | K13: =K12-L12 -> 98547.58 | L13: =K13*I13 -> 601.04501 | M13: =D13*K14+H13*L13 -> 491235.29 | N13: =SUM(M13:$M$25) -> 6182693.7 | O13: =N13/K13 -> 62.738159
B14: ='Cohorte ficticio'!B53 -> 20-24 | C14: 20 | D14: 5 | E14: ='Cohorte ficticio'!C53 -> 5041141 | F14: ='Cohorte ficticio'!D53 -> 10349.48 | G14: =F14/E14 -> 0.0020530034 | H14: =D14/2 -> 2.5 | I14: =D14*G14/(1+(D14-H14)*G14) -> 0.010212601 | J14: =1-I14 -> 0.9897874 | K14: =K13-L13 -> 97946.535 | L14: =K14*I14 -> 1000.2889 | M14: =D14*K15+H14*L14 -> 487231.95 | N14: =SUM(M14:$M$25) -> 5691458.4 | O14: =N14/K14 -> 58.107808
B15: ='Cohorte ficticio'!B54 -> 25-29 | C15: 25 | D15: 5 | E15: ='Cohorte ficticio'!C54 -> 4706443 | F15: ='Cohorte ficticio'!D54 -> 11895.716 | G15: =F15/E15 -> 0.0025275386 | H15: =D15/2 -> 2.5 | I15: =D15*G15/(1+(D15-H15)*G15) -> 0.012558339 | J15: =1-I15 -> 0.98744166 | K15: =K14-L14 -> 96946.246 | L15: =K15*I15 -> 1217.4838 | M15: =D15*K16+H15*L15 -> 481687.52 | N15: =SUM(M15:$M$25) -> 5204226.5 | O15: =N15/K15 -> 53.681568
B16: ='Cohorte ficticio'!B55 -> 30-34 | C16: 30 | D16: 5 | E16: ='Cohorte ficticio'!C55 -> 4744987 | F16: ='Cohorte ficticio'!D55 -> 13922.057 | G16: =F16/E16 -> 0.0029340559 | H16: =D16/2 -> 2.5 | I16: =D16*G16/(1+(D16-H16)*G16) -> 0.014563455 | J16: =1-I16 -> 0.98543655 | K16: =K15-L15 -> 95728.762 | L16: =K16*I16 -> 1394.1415 | M16: =D16*K17+H16*L16 -> 475158.46 | N16: =SUM(M16:$M$25) -> 4722539 | O16: =N16/K16 -> 49.332498
B17: ='Cohorte ficticio'!B56 -> 35-39 | C17: 35 | D17: 5 | E17: ='Cohorte ficticio'!C56 -> 4525522 | F17: ='Cohorte ficticio'!D56 -> 15032.264 | G17: =F17/E17 -> 0.0033216642 | H17: =D17/2 -> 2.5 | I17: =D17*G17/(1+(D17-H17)*G17) -> 0.016471539 | J17: =1-I17 -> 0.98352846 | K17: =K16-L16 -> 94334.621 | L17: =K17*I17 -> 1553.8363 | M17: =D17*K18+H17*L17 -> 467788.51 | N17: =SUM(M17:$M$25) -> 4247380.5 | O17: =N17/K17 -> 45.024621
B18: ='Cohorte ficticio'!B57 -> 40-44 | C18: 40 | D18: 5 | E18: ='Cohorte ficticio'!C57 -> 4231275 | F18: ='Cohorte ficticio'!D57 -> 16818.497 | G18: =F18/E18 -> 0.0039748059 | H18: =D18/2 -> 2.5 | I18: =D18*G18/(1+(D18-H18)*G18) -> 0.019678484 | J18: =1-I18 -> 0.98032152 | K18: =K17-L17 -> 92780.784 | L18: =K18*I18 -> 1825.7852 | M18: =D18*K19+H18*L18 -> 459339.46 | N18: =SUM(M18:$M$25) -> 3779592 | O18: =N18/K18 -> 40.736797
B19: ='Cohorte ficticio'!B58 -> 45-49 | C19: 45 | D19: 5 | E19: ='Cohorte ficticio'!C58 -> 3936178 | F19: ='Cohorte ficticio'!D58 -> 21088.373 | G19: =F19/E19 -> 0.0053575761 | H19: =D19/2 -> 2.5 | I19: =D19*G19/(1+(D19-H19)*G19) -> 0.026433827 | J19: =1-I19 -> 0.97356617 | K19: =K18-L18 -> 90954.999 | L19: =K19*I19 -> 2404.2887 | M19: =D19*K20+H19*L19 -> 448764.27 | N19: =SUM(M19:$M$25) -> 3320252.5 | O19: =N19/K19 -> 36.504344
B20: ='Cohorte ficticio'!B59 -> 50-54 | C20: 50 | D20: 5 | E20: ='Cohorte ficticio'!C59 -> 3942849 | F20: ='Cohorte ficticio'!D59 -> 27430.705 | G20: =F20/E20 -> 0.0069570772 | H20: =D20/2 -> 2.5 | I20: =D20*G20/(1+(D20-H20)*G20) -> 0.034190717 | J20: =1-I20 -> 0.96580928 | K20: =K19-L19 -> 88550.71 | L20: =K20*I20 -> 3027.6123 | M20: =D20*K21+H20*L20 -> 435184.52 | N20: =SUM(M20:$M$25) -> 2871488.3 | O20: =N20/K20 -> 32.427614
B21: ='Cohorte ficticio'!B60 -> 55-59 | C21: 55 | D21: 5 | E21: ='Cohorte ficticio'!C60 -> 3156393 | F21: ='Cohorte ficticio'!D60 -> 31299.855 | G21: =F21/E21 -> 0.0099163364 | H21: =D21/2 -> 2.5 | I21: =D21*G21/(1+(D21-H21)*G21) -> 0.048382246 | J21: =1-I21 -> 0.95161775 | K21: =K20-L20 -> 85523.098 | L21: =K21*I21 -> 4137.7995 | M21: =D21*K22+H21*L21 -> 417270.99 | N21: =SUM(M21:$M$25) -> 2436303.8 | O21: =N21/K21 -> 28.487085
B22: ='Cohorte ficticio'!B61 -> 60-64 | C22: 60 | D22: 5 | E22: ='Cohorte ficticio'!C61 -> 2734019 | F22: ='Cohorte ficticio'!D61 -> 36964.356 | G22: =F22/E22 -> 0.013520153 | H22: =D22/2 -> 2.5 | I22: =D22*G22/(1+(D22-H22)*G22) -> 0.065390541 | J22: =1-I22 -> 0.93460946 | K22: =K21-L21 -> 81385.298 | L22: =K22*I22 -> 5321.8287 | M22: =D22*K23+H22*L22 -> 393621.92 | N22: =SUM(M22:$M$25) -> 2019032.8 | O22: =N22/K22 -> 24.808323
... B24: ='Cohorte ficticio'!B63 -> 70-74 | C24: 70 | D24: 5 | E24: ='Cohorte ficticio'!C63 -> 1561618 | F24: ='Cohorte ficticio'!D63 -> 42245.032 | G24: =F24/E24 -> 0.027052091 | H24: =D24/2 -> 2.5 | I24: =D24*G24/(1+(D24-H24)*G24) -> 0.12669223 | J24: =1-I24 -> 0.87330777 | K24: =K23-L23 -> 69385.898 | L24: =K24*I24 -> 8790.6541 | M24: =D24*K25+H24*L24 -> 324952.85 | N24: =SUM(M24:$M$25) -> 1261787.4 | O24: =N24/K24 -> 18.18507
B25: ='Cohorte ficticio'!B64 -> 75+ | C25: 75 | D25: abierto | E25: ='Cohorte ficticio'!C64 -> 2180337 | F25: ='Cohorte ficticio'!D64 -> 141026.02 | G25: =F25/E25 -> 0.064680837 | H25: - | I25: 1 | J25: =1-I25 -> 0 | K25: =K24-L24 -> 60595.244 | L25: =K25*I25 -> 60595.244 | M25: =K25/G25 -> 936834.57 | N25: =SUM(M25:$M$25) -> 936834.57 | O25: =N25/K25 -> 15.46053
B27: Control: suma de ndx − l0 | E27: =ROUND(SUM(L9:L25)-D5,6) -> 0 | F27: ← debe ser 0
B28: q0 (mortalidad infantil, por mil) | E28: =I9*1000 -> 9.9293734

Sheet Tabla mujeres
B2: TABLA TRANSVERSAL ABREVIADA: MUJERES
B3: México 2025. Cohorte ficticia de 100,000 nacimientos con las tasas de mortalidad por edad observadas (INEGI: EIC 2025 y defunciones registradas)
B5: Radix l0 | D5: ='Cohorte ficticio'!D5 -> 100000
B6: nMx = D/P; nqx = n·nMx / (1 + (n − nax)·nMx); lx+n = lx·(1 − nqx); ndx = lx − lx+n; nLx = n·lx+n + nax·ndx; Tx = suma de nLx hacia abajo; ex = Tx/lx. Grupo abierto 75+: q = 1 y L = l/M.
B7: nax: para 0 y 1-4, Coale-Demeny según la mortalidad infantil y el sexo (en ambos sexos, el promedio de hombres y mujeres); n/2 en los demás grupos. Valores sin redondear.
B8: Edad | C8: x | D8: n | E8: P (población) | F8: D (defunciones) | G8: nMx | H8: nax | I8: nqx | J8: npx | K8: lx | L8: ndx | M8: nLx | N8: Tx | O8: ex
B9: ='Cohorte ficticio'!B48 -> 0 | C9: 0 | D9: 1 | E9: ='Cohorte ficticio'!E48 -> 676488.74 | F9: ='Cohorte ficticio'!F48 -> 5328.3863 | G9: =F9/E9 -> 0.0078765336 | H9: =IF($G$9>=0.107,0.35,0.053+2.8*$G$9) -> 0.075054294 | I9: =D9*G9/(1+(D9-H9)*G9) -> 0.0078195652 | J9: =1-I9 -> 0.99218043 | K9: =$D$5 -> 100000 | L9: =K9*I9 -> 781.95652 | M9: =D9*K10+H9*L9 -> 99276.733 | N9: =SUM(M9:$M$25) -> 8392453.7 | O9: =N9/K9 -> 83.924537
B10: ='Cohorte ficticio'!B49 -> 1-4 | C10: 1 | D10: 4 | E10: ='Cohorte ficticio'!E49 -> 3064897.3 | F10: ='Cohorte ficticio'!F49 -> 1307.8595 | G10: =F10/E10 -> 0.00042672213 | H10: =IF($G$9>=0.107,1.361,1.522-1.518*$G$9) -> 1.5100434 | I10: =D10*G10/(1+(D10-H10)*G10) -> 0.0017050768 | J10: =1-I10 -> 0.99829492 | K10: =K9-L9 -> 99218.043 | L10: =K10*I10 -> 169.17439 | M10: =D10*K11+H10*L10 -> 396450.94 | N10: =SUM(M10:$M$25) -> 8293176.9 | O10: =N10/K10 -> 83.585371
B11: ='Cohorte ficticio'!B50 -> 5-9 | C11: 5 | D11: 5 | E11: ='Cohorte ficticio'!E50 -> 4785294 | F11: ='Cohorte ficticio'!F50 -> 831.88818 | G11: =F11/E11 -> 0.00017384265 | H11: =D11/2 -> 2.5 | I11: =D11*G11/(1+(D11-H11)*G11) -> 0.00086883564 | J11: =1-I11 -> 0.99913116 | K11: =K10-L10 -> 99048.869 | L11: =K11*I11 -> 86.057187 | M11: =D11*K12+H11*L11 -> 495029.2 | N11: =SUM(M11:$M$25) -> 7896726 | O11: =N11/K11 -> 79.725554
B12: ='Cohorte ficticio'!B51 -> 10-14 | C12: 10 | D12: 5 | E12: ='Cohorte ficticio'!E51 -> 5353603 | F12: ='Cohorte ficticio'!F51 -> 1313.4023 | G12: =F12/E12 -> 0.00024533053 | H12: =D12/2 -> 2.5 | I12: =D12*G12/(1+(D12-H12)*G12) -> 0.0012259008 | J12: =1-I12 -> 0.9987741 | K12: =K11-L11 -> 98962.812 | L12: =K12*I12 -> 121.31859 | M12: =D12*K13+H12*L12 -> 494510.76 | N12: =SUM(M12:$M$25) -> 7401696.8 | O12: =N12/K12 -> 74.792709
B13: ='Cohorte ficticio'!B52 -> 15-19 | C13: 15 | D13: 5 | E13: ='Cohorte ficticio'!E52 -> 5349921 | F13: ='Cohorte ficticio'!F52 -> 2266.4198 | G13: =F13/E13 -> 0.00042363612 | H13: =D13/2 -> 2.5 | I13: =D13*G13/(1+(D13-H13)*G13) -> 0.0021159396 | J13: =1-I13 -> 0.99788406 | K13: =K12-L12 -> 98841.493 | L13: =K13*I13 -> 209.14263 | M13: =D13*K14+H13*L13 -> 493684.61 | N13: =SUM(M13:$M$25) -> 6907186 | O13: =N13/K13 -> 69.881442
B14: ='Cohorte ficticio'!B53 -> 20-24 | C14: 20 | D14: 5 | E14: ='Cohorte ficticio'!E53 -> 5319788 | F14: ='Cohorte ficticio'!F53 -> 2787.1892 | G14: =F14/E14 -> 0.00052392863 | H14: =D14/2 -> 2.5 | I14: =D14*G14/(1+(D14-H14)*G14) -> 0.0026162164 | J14: =1-I14 -> 0.99738378 | K14: =K13-L13 -> 98632.351 | L14: =K14*I14 -> 258.04357 | M14: =D14*K15+H14*L14 -> 492516.64 | N14: =SUM(M14:$M$25) -> 6413501.4 | O14: =N14/K14 -> 65.024319
B15: ='Cohorte ficticio'!B54 -> 25-29 | C15: 25 | D15: 5 | E15: ='Cohorte ficticio'!E54 -> 5104330 | F15: ='Cohorte ficticio'!F54 -> 3480.9442 | G15: =F15/E15 -> 0.00068195908 | H15: =D15/2 -> 2.5 | I15: =D15*G15/(1+(D15-H15)*G15) -> 0.0034039919 | J15: =1-I15 -> 0.99659601 | K15: =K14-L14 -> 98374.307 | L15: =K15*I15 -> 334.86535 | M15: =D15*K16+H15*L15 -> 491034.37 | N15: =SUM(M15:$M$25) -> 5920984.8 | O15: =N15/K15 -> 60.188325
B16: ='Cohorte ficticio'!B55 -> 30-34 | C16: 30 | D16: 5 | E16: ='Cohorte ficticio'!E55 -> 5282566 | F16: ='Cohorte ficticio'!F55 -> 4657.2245 | G16: =F16/E16 -> 0.00088162163 | H16: =D16/2 -> 2.5 | I16: =D16*G16/(1+(D16-H16)*G16) -> 0.0043984138 | J16: =1-I16 -> 0.99560159 | K16: =K15-L15 -> 98039.442 | L16: =K16*I16 -> 431.21803 | M16: =D16*K17+H16*L16 -> 489119.16 | N16: =SUM(M16:$M$25) -> 5429950.4 | O16: =N16/K16 -> 55.385367
B17: ='Cohorte ficticio'!B56 -> 35-39 | C17: 35 | D17: 5 | E17: ='Cohorte ficticio'!E56 -> 5095386 | F17: ='Cohorte ficticio'!F56 -> 5790.7418 | G17: =F17/E17 -> 0.0011364677 | H17: =D17/2 -> 2.5 | I17: =D17*G17/(1+(D17-H17)*G17) -> 0.0056662399 | J17: =1-I17 -> 0.99433376 | K17: =K16-L16 -> 97608.224 | L17: =K17*I17 -> 553.07162 | M17: =D17*K18+H17*L17 -> 486658.44 | N17: =SUM(M17:$M$25) -> 4940831.3 | O17: =N17/K17 -> 50.619006
B18: ='Cohorte ficticio'!B57 -> 40-44 | C18: 40 | D18: 5 | E18: ='Cohorte ficticio'!E57 -> 4742766 | F18: ='Cohorte ficticio'!F57 -> 7754.9141 | G18: =F18/E18 -> 0.0016351037 | H18: =D18/2 -> 2.5 | I18: =D18*G18/(1+(D18-H18)*G18) -> 0.0081422349 | J18: =1-I18 -> 0.99185777 | K18: =K17-L17 -> 97055.152 | L18: =K18*I18 -> 790.24584 | M18: =D18*K19+H18*L18 -> 483300.15 | N18: =SUM(M18:$M$25) -> 4454172.8 | O18: =N18/K18 -> 45.893213
B19: ='Cohorte ficticio'!B58 -> 45-49 | C19: 45 | D19: 5 | E19: ='Cohorte ficticio'!E58 -> 4437822 | F19: ='Cohorte ficticio'!F58 -> 11283.397 | G19: =F19/E19 -> 0.0025425529 | H19: =D19/2 -> 2.5 | I19: =D19*G19/(1+(D19-H19)*G19) -> 0.012632468 | J19: =1-I19 -> 0.98736753 | K19: =K18-L18 -> 96264.906 | L19: =K19*I19 -> 1216.0633 | M19: =D19*K20+H19*L19 -> 478284.37 | N19: =SUM(M19:$M$25) -> 3970872.7 | O19: =N19/K19 -> 41.249432
B20: ='Cohorte ficticio'!B59 -> 50-54 | C20: 50 | D20: 5 | E20: ='Cohorte ficticio'!E59 -> 4409290 | F20: ='Cohorte ficticio'!F59 -> 16057.515 | G20: =F20/E20 -> 0.0036417462 | H20: =D20/2 -> 2.5 | I20: =D20*G20/(1+(D20-H20)*G20) -> 0.018044448 | J20: =1-I20 -> 0.98195555 | K20: =K19-L19 -> 95048.843 | L20: =K20*I20 -> 1715.1039 | M20: =D20*K21+H20*L20 -> 470956.46 | N20: =SUM(M20:$M$25) -> 3492588.3 | O20: =N20/K20 -> 36.745195
B21: ='Cohorte ficticio'!B60 -> 55-59 | C21: 55 | D21: 5 | E21: ='Cohorte ficticio'!E60 -> 3553454 | F21: ='Cohorte ficticio'!F60 -> 20407.167 | G21: =F21/E21 -> 0.0057429101 | H21: =D21/2 -> 2.5 | I21: =D21*G21/(1+(D21-H21)*G21) -> 0.028308123 | J21: =1-I21 -> 0.97169188 | K21: =K20-L20 -> 93333.739 | L21: =K21*I21 -> 2642.103 | M21: =D21*K22+H21*L21 -> 460063.44 | N21: =SUM(M21:$M$25) -> 3021631.8 | O21: =N21/K21 -> 32.374486
B22: ='Cohorte ficticio'!B61 -> 60-64 | C22: 60 | D22: 5 | E22: ='Cohorte ficticio'!E61 -> 3257527 | F22: ='Cohorte ficticio'!F61 -> 26735.967 | G22: =F22/E22 -> 0.0082074428 | H22: =D22/2 -> 2.5 | I22: =D22*G22/(1+(D22-H22)*G22) -> 0.040212118 | J22: =1-I22 -> 0.95978788 | K22: =K21-L21 -> 90691.636 | L22: =K22*I22 -> 3646.9027 | M22: =D22*K23+H22*L22 -> 444340.92 | N22: =SUM(M22:$M$25) -> 2561568.4 | O22: =N22/K22 -> 28.244814
... B24: ='Cohorte ficticio'!B63 -> 70-74 | C24: 70 | D24: 5 | E24: ='Cohorte ficticio'!E63 -> 1838237 | F24: ='Cohorte ficticio'!F63 -> 35302.692 | G24: =F24/E24 -> 0.019204646 | H24: =D24/2 -> 2.5 | I24: =D24*G24/(1+(D24-H24)*G24) -> 0.091624206 | J24: =1-I24 -> 0.90837579 | K24: =K23-L23 -> 81982.431 | L24: =K24*I24 -> 7511.5752 | M24: =D24*K25+H24*L24 -> 391133.22 | N24: =SUM(M24:$M$25) -> 1694659.6 | O24: =N24/K24 -> 20.671009
B25: ='Cohorte ficticio'!B64 -> 75+ | C25: 75 | D25: abierto | E25: ='Cohorte ficticio'!E64 -> 2784501 | F25: ='Cohorte ficticio'!F64 -> 159079.39 | G25: =F25/E25 -> 0.057130304 | H25: - | I25: 1 | J25: =1-I25 -> 0 | K25: =K24-L24 -> 74470.856 | L25: =K25*I25 -> 74470.856 | M25: =K25/G25 -> 1303526.3 | N25: =SUM(M25:$M$25) -> 1303526.3 | O25: =N25/K25 -> 17.503845
B27: Control: suma de ndx − l0 | E27: =ROUND(SUM(L9:L25)-D5,6) -> 0 | F27: ← debe ser 0
B28: q0 (mortalidad infantil, por mil) | E28: =I9*1000 -> 7.8195652

Sheet Tabla ambos sexos
B2: TABLA TRANSVERSAL ABREVIADA: AMBOS SEXOS
B3: México 2025. Cohorte ficticia de 100,000 nacimientos con las tasas de mortalidad por edad observadas (INEGI: EIC 2025 y defunciones registradas)
B5: Radix l0 | D5: ='Cohorte ficticio'!D5 -> 100000
B6: nMx = D/P; nqx = n·nMx / (1 + (n − nax)·nMx); lx+n = lx·(1 − nqx); ndx = lx − lx+n; nLx = n·lx+n + nax·ndx; Tx = suma de nLx hacia abajo; ex = Tx/lx. Grupo abierto 75+: q = 1 y L = l/M.
B7: nax: para 0 y 1-4, Coale-Demeny según la mortalidad infantil y el sexo (en ambos sexos, el promedio de hombres y mujeres); n/2 en los demás grupos. Valores sin redondear.
B8: Edad | C8: x | D8: n | E8: P (población) | F8: D (defunciones) | G8: nMx | H8: nax | I8: nqx | J8: npx | K8: lx | L8: ndx | M8: nLx | N8: Tx | O8: ex
B9: ='Cohorte ficticio'!B48 -> 0 | C9: 0 | D9: 1 | E9: ='Cohorte ficticio'!G48 -> 1369364.2 | F9: ='Cohorte ficticio'!H48 -> 12272.196 | G9: =F9/E9 -> 0.0089619664 | H9: =(IF($G$9>=0.107,0.33,0.045+2.684*$G$9)+IF($G$9>=0.107,0.35,0.053+2.8*$G$9))/2 -> 0.073573712 | I9: =D9*G9/(1+(D9-H9)*G9) -> 0.0088881714 | J9: =1-I9 -> 0.99111183 | K9: =$D$5 -> 100000 | L9: =K9*I9 -> 888.81714 | M9: =D9*K10+H9*L9 -> 99176.576 | N9: =SUM(M9:$M$25) -> 8030941.4 | O9: =N9/K9 -> 80.309414
B10: ='Cohorte ficticio'!B49 -> 1-4 | C10: 1 | D10: 4 | E10: ='Cohorte ficticio'!G49 -> 6200208.8 | F10: ='Cohorte ficticio'!H49 -> 2835.4878 | G10: =F10/E10 -> 0.00045732135 | H10: =(IF($G$9>=0.107,1.352,1.651-2.816*$G$9)+IF($G$9>=0.107,1.361,1.522-1.518*$G$9))/2 -> 1.5670794 | I10: =D10*G10/(1+(D10-H10)*G10) -> 0.0018272523 | J10: =1-I10 -> 0.99817275 | K10: =K9-L9 -> 99111.183 | L10: =K10*I10 -> 181.10114 | M10: =D10*K11+H10*L10 -> 396004.13 | N10: =SUM(M10:$M$25) -> 7931764.8 | O10: =N10/K10 -> 80.028959
B11: ='Cohorte ficticio'!B50 -> 5-9 | C11: 5 | D11: 5 | E11: ='Cohorte ficticio'!G50 -> 9669960 | F11: ='Cohorte ficticio'!H50 -> 1928.2841 | G11: =F11/E11 -> 0.00019940973 | H11: =D11/2 -> 2.5 | I11: =D11*G11/(1+(D11-H11)*G11) -> 0.00099655183 | J11: =1-I11 -> 0.99900345 | K11: =K10-L10 -> 98930.082 | L11: =K11*I11 -> 98.588954 | M11: =D11*K12+H11*L11 -> 494403.94 | N11: =SUM(M11:$M$25) -> 7535760.7 | O11: =N11/K11 -> 76.172592
B12: ='Cohorte ficticio'!B51 -> 10-14 | C12: 10 | D12: 5 | E12: ='Cohorte ficticio'!G51 -> 10885388 | F12: ='Cohorte ficticio'!H51 -> 3062.3908 | G12: =F12/E12 -> 0.00028133042 | H12: =D12/2 -> 2.5 | I12: =D12*G12/(1+(D12-H12)*G12) -> 0.0014056635 | J12: =1-I12 -> 0.99859434 | K12: =K11-L11 -> 98831.493 | L12: =K12*I12 -> 138.92382 | M12: =D12*K13+H12*L12 -> 493810.15 | N12: =SUM(M12:$M$25) -> 7041356.8 | O12: =N12/K12 -> 71.246083
B13: ='Cohorte ficticio'!B52 -> 15-19 | C13: 15 | D13: 5 | E13: ='Cohorte ficticio'!G52 -> 10833608 | F13: ='Cohorte ficticio'!H52 -> 8975.9189 | G13: =F13/E13 -> 0.00082852535 | H13: =D13/2 -> 2.5 | I13: =D13*G13/(1+(D13-H13)*G13) -> 0.0041340638 | J13: =1-I13 -> 0.99586594 | K13: =K12-L12 -> 98692.569 | L13: =K13*I13 -> 408.00138 | M13: =D13*K14+H13*L13 -> 492442.84 | N13: =SUM(M13:$M$25) -> 6547546.6 | O13: =N13/K13 -> 66.342853
B14: ='Cohorte ficticio'!B53 -> 20-24 | C14: 20 | D14: 5 | E14: ='Cohorte ficticio'!G53 -> 10360929 | F14: ='Cohorte ficticio'!H53 -> 13136.669 | G14: =F14/E14 -> 0.0012679045 | H14: =D14/2 -> 2.5 | I14: =D14*G14/(1+(D14-H14)*G14) -> 0.0063194914 | J14: =1-I14 -> 0.99368051 | K14: =K13-L13 -> 98284.568 | L14: =K14*I14 -> 621.10848 | M14: =D14*K15+H14*L14 -> 489870.07 | N14: =SUM(M14:$M$25) -> 6055103.8 | O14: =N14/K14 -> 61.607879
B15: ='Cohorte ficticio'!B54 -> 25-29 | C15: 25 | D15: 5 | E15: ='Cohorte ficticio'!G54 -> 9810773 | F15: ='Cohorte ficticio'!H54 -> 15376.66 | G15: =F15/E15 -> 0.0015673241 | H15: =D15/2 -> 2.5 | I15: =D15*G15/(1+(D15-H15)*G15) -> 0.0078060338 | J15: =1-I15 -> 0.99219397 | K15: =K14-L14 -> 97663.459 | L15: =K15*I15 -> 762.36426 | M15: =D15*K16+H15*L15 -> 486411.38 | N15: =SUM(M15:$M$25) -> 5565233.7 | O15: =N15/K15 -> 56.983787
B16: ='Cohorte ficticio'!B55 -> 30-34 | C16: 30 | D16: 5 | E16: ='Cohorte ficticio'!G55 -> 10027553 | F16: ='Cohorte ficticio'!H55 -> 18579.282 | G16: =F16/E16 -> 0.0018528231 | H16: =D16/2 -> 2.5 | I16: =D16*G16/(1+(D16-H16)*G16) -> 0.0092214014 | J16: =1-I16 -> 0.9907786 | K16: =K15-L15 -> 96901.095 | L16: =K16*I16 -> 893.56389 | M16: =D16*K17+H16*L16 -> 482271.56 | N16: =SUM(M16:$M$25) -> 5078822.3 | O16: =N16/K16 -> 52.412435
B17: ='Cohorte ficticio'!B56 -> 35-39 | C17: 35 | D17: 5 | E17: ='Cohorte ficticio'!G56 -> 9620908 | F17: ='Cohorte ficticio'!H56 -> 20823.006 | G17: =F17/E17 -> 0.0021643494 | H17: =D17/2 -> 2.5 | I17: =D17*G17/(1+(D17-H17)*G17) -> 0.010763507 | J17: =1-I17 -> 0.98923649 | K17: =K16-L16 -> 96007.531 | L17: =K17*I17 -> 1033.3777 | M17: =D17*K18+H17*L17 -> 477454.21 | N17: =SUM(M17:$M$25) -> 4596550.8 | O17: =N17/K17 -> 47.876981
B18: ='Cohorte ficticio'!B57 -> 40-44 | C18: 40 | D18: 5 | E18: ='Cohorte ficticio'!G57 -> 8974041 | F18: ='Cohorte ficticio'!H57 -> 24573.411 | G18: =F18/E18 -> 0.0027382771 | H18: =D18/2 -> 2.5 | I18: =D18*G18/(1+(D18-H18)*G18) -> 0.013598296 | J18: =1-I18 -> 0.9864017 | K18: =K17-L17 -> 94974.153 | L18: =K18*I18 -> 1291.4866 | M18: =D18*K19+H18*L18 -> 471642.05 | N18: =SUM(M18:$M$25) -> 4119096.5 | O18: =N18/K18 -> 43.370711
B19: ='Cohorte ficticio'!B58 -> 45-49 | C19: 45 | D19: 5 | E19: ='Cohorte ficticio'!G58 -> 8374000 | F19: ='Cohorte ficticio'!H58 -> 32371.77 | G19: =F19/E19 -> 0.0038657476 | H19: =D19/2 -> 2.5 | I19: =D19*G19/(1+(D19-H19)*G19) -> 0.019143726 | J19: =1-I19 -> 0.98085627 | K19: =K18-L18 -> 93682.667 | L19: =K19*I19 -> 1793.4353 | M19: =D19*K20+H19*L19 -> 463929.74 | N19: =SUM(M19:$M$25) -> 3647454.5 | O19: =N19/K19 -> 38.934145
B20: ='Cohorte ficticio'!B59 -> 50-54 | C20: 50 | D20: 5 | E20: ='Cohorte ficticio'!G59 -> 8352139 | F20: ='Cohorte ficticio'!H59 -> 43488.22 | G20: =F20/E20 -> 0.0052068362 | H20: =D20/2 -> 2.5 | I20: =D20*G20/(1+(D20-H20)*G20) -> 0.025699647 | J20: =1-I20 -> 0.97430035 | K20: =K19-L19 -> 91889.231 | L20: =K20*I20 -> 2361.5208 | M20: =D20*K21+H20*L20 -> 453542.35 | N20: =SUM(M20:$M$25) -> 3183524.8 | O20: =N20/K20 -> 34.645243
B21: ='Cohorte ficticio'!B60 -> 55-59 | C21: 55 | D21: 5 | E21: ='Cohorte ficticio'!G60 -> 6709847 | F21: ='Cohorte ficticio'!H60 -> 51707.022 | G21: =F21/E21 -> 0.0077061402 | H21: =D21/2 -> 2.5 | I21: =D21*G21/(1+(D21-H21)*G21) -> 0.037802424 | J21: =1-I21 -> 0.96219758 | K21: =K20-L20 -> 89527.711 | L21: =K21*I21 -> 3384.3645 | M21: =D21*K22+H21*L21 -> 439177.64 | N21: =SUM(M21:$M$25) -> 2729982.4 | O21: =N21/K21 -> 30.493155
B22: ='Cohorte ficticio'!B61 -> 60-64 | C22: 60 | D22: 5 | E22: ='Cohorte ficticio'!G61 -> 5991546 | F22: ='Cohorte ficticio'!H61 -> 63700.322 | G22: =F22/E22 -> 0.0106317 | H22: =D22/2 -> 2.5 | I22: =D22*G22/(1+(D22-H22)*G22) -> 0.051782171 | J22: =1-I22 -> 0.94821783 | K22: =K21-L21 -> 86143.346 | L22: =K22*I22 -> 4460.6895 | M22: =D22*K23+H22*L22 -> 419565.01 | N22: =SUM(M22:$M$25) -> 2290804.8 | O22: =N22/K22 -> 26.592939
... B24: ='Cohorte ficticio'!B63 -> 70-74 | C24: 70 | D24: 5 | E24: ='Cohorte ficticio'!G63 -> 3399855 | F24: ='Cohorte ficticio'!H63 -> 77547.723 | G24: =F24/E24 -> 0.022809127 | H24: =D24/2 -> 2.5 | I24: =D24*G24/(1+(D24-H24)*G24) -> 0.10789326 | J24: =1-I24 -> 0.89210674 | K24: =K23-L23 -> 75812.255 | L24: =K24*I24 -> 8179.6311 | M24: =D24*K25+H24*L24 -> 358612.2 | N24: =SUM(M24:$M$25) -> 1477502.5 | O24: =N24/K24 -> 19.488966
B25: ='Cohorte ficticio'!B64 -> 75+ | C25: 75 | D25: abierto | E25: ='Cohorte ficticio'!G64 -> 4964838 | F25: ='Cohorte ficticio'!H64 -> 300105.41 | G25: =F25/E25 -> 0.060446164 | H25: - | I25: 1 | J25: =1-I25 -> 0 | K25: =K24-L24 -> 67632.624 | L25: =K25*I25 -> 67632.624 | M25: =K25/G25 -> 1118890.3 | N25: =SUM(M25:$M$25) -> 1118890.3 | O25: =N25/K25 -> 16.543647
B27: Control: suma de ndx − l0 | E27: =ROUND(SUM(L9:L25)-D5,6) -> 0 | F27: ← debe ser 0
B28: q0 (mortalidad infantil, por mil) | E28: =I9*1000 -> 8.8881714

Sheet Gráficos y resumen
B2: GRÁFICOS Y RESUMEN
B3: Tablas transversales abreviadas, México 2025: indicadores, gráficos y notas
B5: Indicadores principales (se recalculan desde las tablas)
B6: Indicador | C6: Hombres | D6: Mujeres | E6: Ambos sexos
B7: Esperanza de vida al nacer, e0 (años) | C7: ='Tabla hombres'!O9 -> 76.642645 | D7: ='Tabla mujeres'!O9 -> 83.924537 | E7: ='Tabla ambos sexos'!O9 -> 80.309414
B8: Esperanza de vida a los 5 años, e5 | C8: ='Tabla hombres'!O11 -> 72.556441 | D8: ='Tabla mujeres'!O11 -> 79.725554 | E8: ='Tabla ambos sexos'!O11 -> 76.172592
B9: Esperanza de vida a los 65 años, e65 | C9: ='Tabla hombres'!O22 -> 24.808323 | D9: ='Tabla mujeres'!O22 -> 28.244814 | E9: ='Tabla ambos sexos'!O22 -> 26.592939
B10: Esperanza de vida a los 75 años, e75 | C10: ='Tabla hombres'!O25 -> 15.46053 | D10: ='Tabla mujeres'!O25 -> 17.503845 | E10: ='Tabla ambos sexos'!O25 -> 16.543647
B11: Mortalidad infantil, q0 por mil | C11: ='Tabla hombres'!I9*1000 -> 9.9293734 | D11: ='Tabla mujeres'!I9*1000 -> 7.8195652 | E11: ='Tabla ambos sexos'!I9*1000 -> 8.8881714
B12: Mortalidad de menores de 5 años, 5q0 por mil | C12: =(1-'Tabla hombres'!J9*'Tabla hombres'!J10)*1000 -> 11.856723 | D12: =(1-'Tabla mujeres'!J9*'Tabla mujeres'!J10)*1000 -> 9.5113091 | E12: =(1-'Tabla ambos sexos'!J9*'Tabla ambos sexos'!J10)*1000 -> 10.699183
B13: Sobrevivientes a los 65 años (de 100,000), l65 | C13: ='Tabla hombres'!K22 -> 81385.298 | D13: ='Tabla mujeres'!K22 -> 90691.636 | E13: ='Tabla ambos sexos'!K22 -> 86143.346
B14: Sobrevivientes a los 75 años (de 100,000), l75 | C14: ='Tabla hombres'!K25 -> 60595.244 | D14: ='Tabla mujeres'!K25 -> 74470.856 | E14: ='Tabla ambos sexos'!K25 -> 67632.624
B16: e0 de CONAPO, proyecciones 2025 (referencia) | C16: 72.57 | D16: 79.04 | E16: 75.67
B17: Diferencia: estas tablas − CONAPO (años) | C17: =C7-C16 -> 4.0726449 | D17: =D7-D16 -> 4.8845368 | E17: =E7-E16 -> 4.6394141
B18: CONAPO: base de indicadores demográficos del repositorio (EVH, EVM, EV, año 2025, total nacional), capturada a mano.
B21: Método, supuestos y alertas
B22: 1. Tabla transversal (de periodo): las tasas de mortalidad por edad observadas en 2025 se aplican a una cohorte ficticia de 100,000 nacimientos.
B23: 2. Grupos 0, 1-4, 5-9, ..., 70-74 y 75+ (abierto): el máximo detalle que permite la población de la EIC (llega a 75 años y más).
B24: 3. Las defunciones de sexo no especificado (529) y de edad no especificada (4,016) se reparten en proporción (hoja 'Cohorte ficticio', bloque A).
B25: 4. La EIC junta 0-4 años: el año 0 se separa suponiendo cohortes de nacimiento con crecimiento constante (bloque B). Es un supuesto y afecta sobre todo a q0.
B26: 5. nqx = n·nMx / (1 + (n − nax)·nMx), con nax = n/2 salvo 0 y 1-4 (Coale-Demeny). En 75+ se usa e75 = 1/M, muy sensible a las defunciones de adultos mayores.
B27: 6. ALERTA: la e0 sale 4 a 5 años por encima de la de CONAPO. En la captura de INEGI de la hoja 'Fuentes de datos' se lee que las cifras de 2025 son preliminares y aún no concluyen los procesos de generación (son defunciones por año de registro). Las 762,494 defunciones del archivo quedan por debajo de las 836,585 que proyecta CONAPO para 2025, y las 12,207 defunciones infantiles son pocas para ~2.0 millones de nacimientos. Con datos definitivos la e0 bajaría.
