Workbook

Sheet Resumen
B1: Tablas transversales abreviadas: INEGI, México 2025
B2: U2TC: INEGI Tablas transversales. Cohorte ficticia de 100,000 nacimientos con las tasas de mortalidad de 2025 (población: EIC 2025; defunciones: INEGI).
B4: Indicadores principales (todo se recalcula desde las tablas)
B5: Indicador | C5: Hombres | D5: Mujeres | E5: Ambos sexos
B6: Esperanza de vida al nacer, e0 (años) | C6: =Hombres!O9 -> 76.642645 | D6: =Mujeres!O9 -> 83.924537 | E6: ='Ambos sexos'!O9 -> 80.309414
B7: Esperanza de vida a los 5 años, e5 | C7: =Hombres!O11 -> 72.556441 | D7: =Mujeres!O11 -> 79.725554 | E7: ='Ambos sexos'!O11 -> 76.172592
B8: Esperanza de vida a los 65 años, e65 | C8: =Hombres!O22 -> 24.808323 | D8: =Mujeres!O22 -> 28.244814 | E8: ='Ambos sexos'!O22 -> 26.592939
B9: Esperanza de vida a los 75 años, e75 | C9: =Hombres!O25 -> 15.46053 | D9: =Mujeres!O25 -> 17.503845 | E9: ='Ambos sexos'!O25 -> 16.543647
B10: Mortalidad infantil: q0 por mil | C10: =Hombres!I9*1000 -> 9.9293734 | D10: =Mujeres!I9*1000 -> 7.8195652 | E10: ='Ambos sexos'!I9*1000 -> 8.8881714
B11: Mortalidad de menores de 5 años: 5q0 por mil | C11: =(1-Hombres!J9*Hombres!J10)*1000 -> 11.856723 | D11: =(1-Mujeres!J9*Mujeres!J10)*1000 -> 9.5113091 | E11: =(1-'Ambos sexos'!J9*'Ambos sexos'!J10)*1000 -> 10.699183
B12: Sobrevivientes a los 65 años (de 100,000): l65 | C12: =Hombres!K22 -> 81385.298 | D12: =Mujeres!K22 -> 90691.636 | E12: ='Ambos sexos'!K22 -> 86143.346
B13: Sobrevivientes a los 75 años (de 100,000): l75 | C13: =Hombres!K25 -> 60595.244 | D13: =Mujeres!K25 -> 74470.856 | E13: ='Ambos sexos'!K25 -> 67632.624
B15: Referencia externa: e0 de CONAPO, proyecciones 2025 (en el repositorio: tarea-conapo-generacion-1970/bases_de_datos_CONAPO)
C16: Hombres | D16: Mujeres | E16: Ambos sexos
B17: e0 CONAPO 2025 (años) | C17: 72.57 | D17: 79.04 | E17: 75.67
B18: Diferencia: tabla de este libro − CONAPO (años) | C18: =C6-C17 -> 4.0726449 | D18: =D6-D17 -> 4.8845368 | E18: =E6-E17 -> 4.6394141
B19: Dato de CONAPO capturado a mano de su base de indicadores demográficos (EVH, EVM, EV, año 2025, total nacional).
B21: Método y supuestos
B22: 1. Tabla transversal (de periodo): las tasas de mortalidad por edad observadas en un solo año se aplican a una cohorte ficticia de 100,000 nacimientos (l0 en Insumos!C4).
B23: 2. Grupos de edad: 0, 1-4, 5-9, ..., 70-74 y 75+ (abierto). Es el máximo detalle que permite la población de la EIC, que termina en 75 años y más.
B24: 3. Las defunciones de sexo no especificado (529) y de edad no especificada (4,016) se reparten proporcionalmente (hoja Insumos, bloque A).
B25: 4. La EIC junta 0-4 años: el año 0 se separa suponiendo que las cohortes de nacimiento crecen a tasa constante (hoja Insumos, bloque B). Es un supuesto; afecta sobre todo a q0.
B26: 5. nqx = n·nMx / (1 + (n − nax)·nMx), con nax = n/2 salvo 0 y 1-4 (Coale-Demeny). En 75+ se usa e75 = 1/M, que es sensible a la cobertura de defunciones de adultos mayores.
B27: 6. Las defunciones del archivo no traen año ni indican si son ocurridas o registradas; se usan tal cual como defunciones de 2025.
B28: 7. Alerta: la e0 que sale es 4 a 5 años mayor que la de CONAPO 2025. Las defunciones infantiles del archivo (12,207) son bajas frente a los ~2.0 millones de nacimientos de CONAPO, y las tasas de adultos mayores parecen bajas. Hay que confirmar con la maestra el año y la cobertura de las defunciones.
B30: Leyenda de colores: azul = dato de entrada o supuesto; negro = fórmula; verde = vínculo a otra hoja; amarillo = supuesto que se puede cambiar.

Sheet Fuentes
B1: Fuentes de consulta (INEGI)
B2: Datos tal cual vienen en 'Fuentes de consulta.xlsx' (la que entregó la maestra). Letra azul = dato de entrada.
B4: 1. Población por grupos quinquenales de edad y sexo: Encuesta Intercensal (EIC) 2025, total nacional, viviendas particulares habitadas
B5: https://www.inegi.org.mx/programas/eic/2025/#tabulados
B6: Grupo de edad | C6: Población total | D6: Mujeres | E6: Hombres
B7: 00-04 | C7: 7569573 | D7: 3741386 | E7: 3828187
B8: 05-09 | C8: 9669960 | D8: 4785294 | E8: 4884666
B9: 10-14 | C9: 10885388 | D9: 5353603 | E9: 5531785
B10: 15-19 | C10: 10833608 | D10: 5349921 | E10: 5483687
B11: 20-24 | C11: 10360929 | D11: 5319788 | E11: 5041141
B12: 25-29 | C12: 9810773 | D12: 5104330 | E12: 4706443
B13: 30-34 | C13: 10027553 | D13: 5282566 | E13: 4744987
B14: 35-39 | C14: 9620908 | D14: 5095386 | E14: 4525522
B15: 40-44 | C15: 8974041 | D15: 4742766 | E15: 4231275
B16: 45-49 | C16: 8374000 | D16: 4437822 | E16: 3936178
B17: 50-54 | C17: 8352139 | D17: 4409290 | E17: 3942849
B18: 55-59 | C18: 6709847 | D18: 3553454 | E18: 3156393
... B22: 75+ | C22: 4964838 | D22: 2784501 | E22: 2180337
B23: Total | C23: =SUM(C7:C22) -> 130374800 | D23: =SUM(D7:D22) -> 67669367 | E23: =SUM(E7:E22) -> 62705433
B25: 2. Defunciones por grupos de edad y sexo: Mortalidad, INEGI (el archivo no indica el año de las defunciones; aquí se tratan como las de 2025)
B26: https://www.inegi.org.mx/sistemas/olap/Proyectos/bd/continuas/mortalidad/MortalidadGeneral.asp?
B27: Grupo de edad | C27: Total | D27: Hombres | E27: Mujeres | F27: Sexo no especificado
B28: Total | C28: 762494 | D28: 426340 | E28: 335625 | F28: 529
B29: <1 | C29: 12207 | D29: 6864 | E29: 5307 | F29: 36
B30: 1-4 | C30: 2821 | D30: 1514 | E30: 1306 | F30: 1
B31: 5-9 | C31: 1918 | D31: 1087 | E31: 831 | F31: 0
B32: 10-14 | C32: 3046 | D32: 1734 | E32: 1312 | F32: 0
B33: 15-19 | C33: 8916 | D33: 6652 | E33: 2264 | F33: 0
B34: 20-24 | C34: 13045 | D34: 10260 | E34: 2784 | F34: 1
B35: 25-29 | C35: 15271 | D35: 11793 | E35: 3477 | F35: 1
B36: 30-34 | C36: 18455 | D36: 13802 | E36: 4652 | F36: 1
B37: 35-39 | C37: 20688 | D37: 14902 | E37: 5784 | F37: 2
B38: 40-44 | C38: 24421 | D38: 16673 | E38: 7746 | F38: 2
B39: 45-49 | C39: 32179 | D39: 20907 | E39: 11271 | F39: 1
... B48: No especificado | C48: 4016 | D48: 3235 | E48: 317 | F48: 464

Sheet Insumos
B1: Insumos: del dato de INEGI a los 17 grupos de edad de la tabla
B2: Letra negra = fórmula; letra verde = vínculo a otra hoja; letra azul sobre amarillo = supuesto que se puede cambiar.
B4: Radix de la cohorte ficticia (l0) | C4: 100000 | D4: Supuesto: se parte de 100,000 nacimientos hipotéticos (cohorte ficticia), como en la plantilla de la maestra.
B6: A. Defunciones: reparto de 'sexo no especificado' y de 'edad no especificada'
B7: Paso 1: el sexo no especificado se reparte entre hombres y mujeres en proporción a sus defunciones, edad por edad. Paso 2: las defunciones de edad no especificada se reparten entre las edades en proporción a las ya ajustadas, por sexo.
B8: Grupo de edad | C8: Hombres (INEGI) | D8: Mujeres (INEGI) | E8: Sexo no esp. | F8: Hombres (paso 1) | G8: Mujeres (paso 1) | H8: Hombres (paso 2) | I8: Mujeres (paso 2)
B9: =Fuentes!B29 -> <1 | C9: =Fuentes!D29 -> 6864 | D9: =Fuentes!E29 -> 5307 | E9: =Fuentes!F29 -> 36 | F9: =C9+E9*C9/(C9+D9) -> 6884.3027 | G9: =D9+E9*D9/(C9+D9) -> 5322.6973 | H9: =F9*$F$30 -> 6943.8098 | I9: =G9*$G$30 -> 5328.3863
B10: =Fuentes!B30 -> 1-4 | C10: =Fuentes!D30 -> 1514 | D10: =Fuentes!E30 -> 1306 | E10: =Fuentes!F30 -> 1 | F10: =C10+E10*C10/(C10+D10) -> 1514.5369 | G10: =D10+E10*D10/(C10+D10) -> 1306.4631 | H10: =F10*$F$30 -> 1527.6284 | I10: =G10*$G$30 -> 1307.8595
B11: =Fuentes!B31 -> 5-9 | C11: =Fuentes!D31 -> 1087 | D11: =Fuentes!E31 -> 831 | E11: =Fuentes!F31 -> 0 | F11: =C11+E11*C11/(C11+D11) -> 1087 | G11: =D11+E11*D11/(C11+D11) -> 831 | H11: =F11*$F$30 -> 1096.3959 | I11: =G11*$G$30 -> 831.88818
B12: =Fuentes!B32 -> 10-14 | C12: =Fuentes!D32 -> 1734 | D12: =Fuentes!E32 -> 1312 | E12: =Fuentes!F32 -> 0 | F12: =C12+E12*C12/(C12+D12) -> 1734 | G12: =D12+E12*D12/(C12+D12) -> 1312 | H12: =F12*$F$30 -> 1748.9885 | I12: =G12*$G$30 -> 1313.4023
B13: =Fuentes!B33 -> 15-19 | C13: =Fuentes!D33 -> 6652 | D13: =Fuentes!E33 -> 2264 | E13: =Fuentes!F33 -> 0 | F13: =C13+E13*C13/(C13+D13) -> 6652 | G13: =D13+E13*D13/(C13+D13) -> 2264 | H13: =F13*$F$30 -> 6709.4991 | I13: =G13*$G$30 -> 2266.4198
B14: =Fuentes!B34 -> 20-24 | C14: =Fuentes!D34 -> 10260 | D14: =Fuentes!E34 -> 2784 | E14: =Fuentes!F34 -> 1 | F14: =C14+E14*C14/(C14+D14) -> 10260.787 | G14: =D14+E14*D14/(C14+D14) -> 2784.2134 | H14: =F14*$F$30 -> 10349.48 | I14: =G14*$G$30 -> 2787.1892
B15: =Fuentes!B35 -> 25-29 | C15: =Fuentes!D35 -> 11793 | D15: =Fuentes!E35 -> 3477 | E15: =Fuentes!F35 -> 1 | F15: =C15+E15*C15/(C15+D15) -> 11793.772 | G15: =D15+E15*D15/(C15+D15) -> 3477.2277 | H15: =F15*$F$30 -> 11895.716 | I15: =G15*$G$30 -> 3480.9442
B16: =Fuentes!B36 -> 30-34 | C16: =Fuentes!D36 -> 13802 | D16: =Fuentes!E36 -> 4652 | E16: =Fuentes!F36 -> 1 | F16: =C16+E16*C16/(C16+D16) -> 13802.748 | G16: =D16+E16*D16/(C16+D16) -> 4652.2521 | H16: =F16*$F$30 -> 13922.057 | I16: =G16*$G$30 -> 4657.2245
B17: =Fuentes!B37 -> 35-39 | C17: =Fuentes!D37 -> 14902 | D17: =Fuentes!E37 -> 5784 | E17: =Fuentes!F37 -> 2 | F17: =C17+E17*C17/(C17+D17) -> 14903.441 | G17: =D17+E17*D17/(C17+D17) -> 5784.5592 | H17: =F17*$F$30 -> 15032.264 | I17: =G17*$G$30 -> 5790.7418
B18: =Fuentes!B38 -> 40-44 | C18: =Fuentes!D38 -> 16673 | D18: =Fuentes!E38 -> 7746 | E18: =Fuentes!F38 -> 2 | F18: =C18+E18*C18/(C18+D18) -> 16674.366 | G18: =D18+E18*D18/(C18+D18) -> 7746.6344 | H18: =F18*$F$30 -> 16818.497 | I18: =G18*$G$30 -> 7754.9141
B19: =Fuentes!B39 -> 45-49 | C19: =Fuentes!D39 -> 20907 | D19: =Fuentes!E39 -> 11271 | E19: =Fuentes!F39 -> 1 | F19: =C19+E19*C19/(C19+D19) -> 20907.65 | G19: =D19+E19*D19/(C19+D19) -> 11271.35 | H19: =F19*$F$30 -> 21088.373 | I19: =G19*$G$30 -> 11283.397
B20: =Fuentes!B40 -> 50-54 | C20: =Fuentes!D40 -> 27195 | D20: =Fuentes!E40 -> 16040 | E20: =Fuentes!F40 -> 1 | F20: =C20+E20*C20/(C20+D20) -> 27195.629 | G20: =D20+E20*D20/(C20+D20) -> 16040.371 | H20: =F20*$F$30 -> 27430.705 | I20: =G20*$G$30 -> 16057.515
... B27: =Fuentes!B47 -> 85+ | C27: =Fuentes!D47 -> 58901 | D27: =Fuentes!E47 -> 81299 | E27: =Fuentes!F47 -> 7 | F27: =C27+E27*C27/(C27+D27) -> 58903.941 | G27: =D27+E27*D27/(C27+D27) -> 81303.059 | H27: =F27*$F$30 -> 59413.1 | I27: =G27*$G$30 -> 81389.957
B28: Edad no especificada | C28: =Fuentes!D48 -> 3235 | D28: =Fuentes!E48 -> 317 | E28: =Fuentes!F48 -> 464 | F28: =C28+E28*C28/(C28+D28) -> 3657.5901 | G28: =D28+E28*D28/(C28+D28) -> 358.40991
B29: Total | C29: =SUM(C9:C28) -> 426340 | D29: =SUM(D9:D28) -> 335625 | E29: =SUM(E9:E28) -> 529 | F29: =SUM(F9:F28) -> 426799.6 | G29: =SUM(G9:G28) -> 335694.4 | H29: =SUM(H9:H28) -> 426799.6 | I29: =SUM(I9:I28) -> 335694.4
B30: Factor del paso 2 (todas las defunciones / las de edad conocida) | F30: =SUM(F9:F28)/SUM(F9:F27) -> 1.0086439 | G30: =SUM(G9:G28)/SUM(G9:G27) -> 1.0010688
B31: Control: hombres + mujeres (paso 2) menos el total de INEGI (debe ser 0) | H31: =ROUND(SUM(H9:I27)-Fuentes!C28,6) -> 0
B33: B. Población: la EIC trae 0-4 años junto; hay que separar los menores de 1 año
B34: Supuesto: las cohortes de nacimiento crecen hacia atrás a tasa constante r (r = ln(P5-9 / P0-4) / 5). Entonces la fracción de 0-4 que tiene menos de 1 año es (e^r - 1) / (e^(5r) - 1).
C35: Hombres | D35: Mujeres
B36: Población 0-4 | C36: =Fuentes!E7 -> 3828187 | D36: =Fuentes!D7 -> 3741386
B37: Población 5-9 | C37: =Fuentes!E8 -> 4884666 | D37: =Fuentes!D8 -> 4785294
B38: r (tasa de crecimiento de las cohortes) | C38: =LN(C37/C36)/5 -> 0.048741918 | D38: =LN(D37/D36)/5 -> 0.049218267
B39: Fracción de 0-4 con menos de 1 año | C39: =(EXP(C38)-1)/(EXP(5*C38)-1) -> 0.18099311 | D39: =(EXP(D38)-1)/(EXP(5*D38)-1) -> 0.18081233
B40: Población de menores de 1 año | C40: =C36*C39 -> 692875.48 | D40: =D36*D39 -> 676488.74
B41: Población de 1 a 4 años | C41: =C36-C40 -> 3135311.5 | D41: =D36-D40 -> 3064897.3
B43: C. Insumos de las tablas: 17 grupos (0, 1-4, 5-9, ..., 70-74, 75+)
B44: En defunciones, 75-79, 80-84 y 85+ se suman en 75+ porque la EIC llega solo a 75 años y más.
B45: Grupo de edad | C45: Población hombres | D45: Defunciones hombres | E45: Población mujeres | F45: Defunciones mujeres | G45: Población ambos sexos | H45: Defunciones ambos sexos
B46: 0 | C46: =C40 -> 692875.48 | D46: =H9 -> 6943.8098 | E46: =D40 -> 676488.74 | F46: =I9 -> 5328.3863 | G46: =C46+E46 -> 1369364.2 | H46: =D46+F46 -> 12272.196
B47: 1-4 | C47: =C41 -> 3135311.5 | D47: =H10 -> 1527.6284 | E47: =D41 -> 3064897.3 | F47: =I10 -> 1307.8595 | G47: =C47+E47 -> 6200208.8 | H47: =D47+F47 -> 2835.4878
B48: 5-9 | C48: =Fuentes!E8 -> 4884666 | D48: =H11 -> 1096.3959 | E48: =Fuentes!D8 -> 4785294 | F48: =I11 -> 831.88818 | G48: =C48+E48 -> 9669960 | H48: =D48+F48 -> 1928.2841
B49: 10-14 | C49: =Fuentes!E9 -> 5531785 | D49: =H12 -> 1748.9885 | E49: =Fuentes!D9 -> 5353603 | F49: =I12 -> 1313.4023 | G49: =C49+E49 -> 10885388 | H49: =D49+F49 -> 3062.3908
B50: 15-19 | C50: =Fuentes!E10 -> 5483687 | D50: =H13 -> 6709.4991 | E50: =Fuentes!D10 -> 5349921 | F50: =I13 -> 2266.4198 | G50: =C50+E50 -> 10833608 | H50: =D50+F50 -> 8975.9189
...

Sheet Hombres
B1: Tabla de mortalidad transversal abreviada de México, 2025: hombres
B2: Cohorte ficticia de 100,000 nacimientos expuesta a las tasas de mortalidad por edad observadas en México (INEGI: EIC 2025 y defunciones).
B4: Radix l0 | E4: =Insumos!C4 -> 100000
B5: Fórmulas: nMx = D/P; nqx = n·nMx / (1 + (n − nax)·nMx); lx+n = lx·(1 − nqx); ndx = lx − lx+n; nLx = n·lx+n + nax·ndx; Tx = Σ nLx; ex = Tx/lx. Grupo abierto 75+: q = 1, L = l/M.
B6: nax: 0 y 1-4 de Coale-Demeny (según nM0 y sexo; en ambos sexos, promedio de los dos); resto n/2. Valores sin redondear (se muestran sin decimales).
B8: Edad | C8: x | D8: n | E8: P (población) | F8: D (defunciones) | G8: nMx | H8: nax | I8: nqx | J8: npx | K8: lx | L8: ndx | M8: nLx | N8: Tx | O8: ex
B9: =Insumos!B46 -> 0 | C9: 0 | D9: 1 | E9: =Insumos!C46 -> 692875.48 | F9: =Insumos!D46 -> 6943.8098 | G9: =F9/E9 -> 0.010021728 | H9: =IF($G$9>=0.107,0.33,0.045+2.684*$G$9) -> 0.071898319 | I9: =D9*G9/(1+(D9-H9)*G9) -> 0.0099293734 | J9: =1-I9 -> 0.99007063 | K9: =$E$4 -> 100000 | L9: =K9*I9 -> 992.93734 | M9: =D9*K10+H9*L9 -> 99078.453 | N9: =SUM(M9:$M$25) -> 7664264.5 | O9: =N9/K9 -> 76.642645
B10: =Insumos!B47 -> 1-4 | C10: 1 | D10: 4 | E10: =Insumos!C47 -> 3135311.5 | F10: =Insumos!D47 -> 1527.6284 | G10: =F10/E10 -> 0.00048723336 | H10: =IF($G$9>=0.107,1.352,1.651-2.816*$G$9) -> 1.6227788 | I10: =D10*G10/(1+(D10-H10)*G10) -> 0.0019466787 | J10: =1-I10 -> 0.99805332 | K10: =K9-L9 -> 99007.063 | L10: =K10*I10 -> 192.73494 | M10: =D10*K11+H10*L10 -> 395570.08 | N10: =SUM(M10:$M$25) -> 7565186 | O10: =N10/K10 -> 76.410569
B11: =Insumos!B48 -> 5-9 | C11: 5 | D11: 5 | E11: =Insumos!C48 -> 4884666 | F11: =Insumos!D48 -> 1096.3959 | G11: =F11/E11 -> 0.00022445668 | H11: =D11/2 -> 2.5 | I11: =D11*G11/(1+(D11-H11)*G11) -> 0.001121654 | J11: =1-I11 -> 0.99887835 | K11: =K10-L10 -> 98814.328 | L11: =K11*I11 -> 110.83548 | M11: =D11*K12+H11*L11 -> 493794.55 | N11: =SUM(M11:$M$25) -> 7169616 | O11: =N11/K11 -> 72.556441
B12: =Insumos!B49 -> 10-14 | C12: 10 | D12: 5 | E12: =Insumos!C49 -> 5531785 | F12: =Insumos!D49 -> 1748.9885 | G12: =F12/E12 -> 0.00031617073 | H12: =D12/2 -> 2.5 | I12: =D12*G12/(1+(D12-H12)*G12) -> 0.0015796051 | J12: =1-I12 -> 0.99842039 | K12: =K11-L11 -> 98703.492 | L12: =K12*I12 -> 155.91254 | M12: =D12*K13+H12*L12 -> 493127.68 | N12: =SUM(M12:$M$25) -> 6675821.4 | O12: =N12/K12 -> 67.635109
B13: =Insumos!B50 -> 15-19 | C13: 15 | D13: 5 | E13: =Insumos!C50 -> 5483687 | F13: =Insumos!D50 -> 6709.4991 | G13: =F13/E13 -> 0.0012235379 | H13: =D13/2 -> 2.5 | I13: =D13*G13/(1+(D13-H13)*G13) -> 0.0060990337 | J13: =1-I13 -> 0.99390097 | K13: =K12-L12 -> 98547.58 | L13: =K13*I13 -> 601.04501 | M13: =D13*K14+H13*L13 -> 491235.29 | N13: =SUM(M13:$M$25) -> 6182693.7 | O13: =N13/K13 -> 62.738159
B14: =Insumos!B51 -> 20-24 | C14: 20 | D14: 5 | E14: =Insumos!C51 -> 5041141 | F14: =Insumos!D51 -> 10349.48 | G14: =F14/E14 -> 0.0020530034 | H14: =D14/2 -> 2.5 | I14: =D14*G14/(1+(D14-H14)*G14) -> 0.010212601 | J14: =1-I14 -> 0.9897874 | K14: =K13-L13 -> 97946.535 | L14: =K14*I14 -> 1000.2889 | M14: =D14*K15+H14*L14 -> 487231.95 | N14: =SUM(M14:$M$25) -> 5691458.4 | O14: =N14/K14 -> 58.107808
B15: =Insumos!B52 -> 25-29 | C15: 25 | D15: 5 | E15: =Insumos!C52 -> 4706443 | F15: =Insumos!D52 -> 11895.716 | G15: =F15/E15 -> 0.0025275386 | H15: =D15/2 -> 2.5 | I15: =D15*G15/(1+(D15-H15)*G15) -> 0.012558339 | J15: =1-I15 -> 0.98744166 | K15: =K14-L14 -> 96946.246 | L15: =K15*I15 -> 1217.4838 | M15: =D15*K16+H15*L15 -> 481687.52 | N15: =SUM(M15:$M$25) -> 5204226.5 | O15: =N15/K15 -> 53.681568
B16: =Insumos!B53 -> 30-34 | C16: 30 | D16: 5 | E16: =Insumos!C53 -> 4744987 | F16: =Insumos!D53 -> 13922.057 | G16: =F16/E16 -> 0.0029340559 | H16: =D16/2 -> 2.5 | I16: =D16*G16/(1+(D16-H16)*G16) -> 0.014563455 | J16: =1-I16 -> 0.98543655 | K16: =K15-L15 -> 95728.762 | L16: =K16*I16 -> 1394.1415 | M16: =D16*K17+H16*L16 -> 475158.46 | N16: =SUM(M16:$M$25) -> 4722539 | O16: =N16/K16 -> 49.332498
B17: =Insumos!B54 -> 35-39 | C17: 35 | D17: 5 | E17: =Insumos!C54 -> 4525522 | F17: =Insumos!D54 -> 15032.264 | G17: =F17/E17 -> 0.0033216642 | H17: =D17/2 -> 2.5 | I17: =D17*G17/(1+(D17-H17)*G17) -> 0.016471539 | J17: =1-I17 -> 0.98352846 | K17: =K16-L16 -> 94334.621 | L17: =K17*I17 -> 1553.8363 | M17: =D17*K18+H17*L17 -> 467788.51 | N17: =SUM(M17:$M$25) -> 4247380.5 | O17: =N17/K17 -> 45.024621
B18: =Insumos!B55 -> 40-44 | C18: 40 | D18: 5 | E18: =Insumos!C55 -> 4231275 | F18: =Insumos!D55 -> 16818.497 | G18: =F18/E18 -> 0.0039748059 | H18: =D18/2 -> 2.5 | I18: =D18*G18/(1+(D18-H18)*G18) -> 0.019678484 | J18: =1-I18 -> 0.98032152 | K18: =K17-L17 -> 92780.784 | L18: =K18*I18 -> 1825.7852 | M18: =D18*K19+H18*L18 -> 459339.46 | N18: =SUM(M18:$M$25) -> 3779592 | O18: =N18/K18 -> 40.736797
B19: =Insumos!B56 -> 45-49 | C19: 45 | D19: 5 | E19: =Insumos!C56 -> 3936178 | F19: =Insumos!D56 -> 21088.373 | G19: =F19/E19 -> 0.0053575761 | H19: =D19/2 -> 2.5 | I19: =D19*G19/(1+(D19-H19)*G19) -> 0.026433827 | J19: =1-I19 -> 0.97356617 | K19: =K18-L18 -> 90954.999 | L19: =K19*I19 -> 2404.2887 | M19: =D19*K20+H19*L19 -> 448764.27 | N19: =SUM(M19:$M$25) -> 3320252.5 | O19: =N19/K19 -> 36.504344
B20: =Insumos!B57 -> 50-54 | C20: 50 | D20: 5 | E20: =Insumos!C57 -> 3942849 | F20: =Insumos!D57 -> 27430.705 | G20: =F20/E20 -> 0.0069570772 | H20: =D20/2 -> 2.5 | I20: =D20*G20/(1+(D20-H20)*G20) -> 0.034190717 | J20: =1-I20 -> 0.96580928 | K20: =K19-L19 -> 88550.71 | L20: =K20*I20 -> 3027.6123 | M20: =D20*K21+H20*L20 -> 435184.52 | N20: =SUM(M20:$M$25) -> 2871488.3 | O20: =N20/K20 -> 32.427614
B21: =Insumos!B58 -> 55-59 | C21: 55 | D21: 5 | E21: =Insumos!C58 -> 3156393 | F21: =Insumos!D58 -> 31299.855 | G21: =F21/E21 -> 0.0099163364 | H21: =D21/2 -> 2.5 | I21: =D21*G21/(1+(D21-H21)*G21) -> 0.048382246 | J21: =1-I21 -> 0.95161775 | K21: =K20-L20 -> 85523.098 | L21: =K21*I21 -> 4137.7995 | M21: =D21*K22+H21*L21 -> 417270.99 | N21: =SUM(M21:$M$25) -> 2436303.8 | O21: =N21/K21 -> 28.487085
B22: =Insumos!B59 -> 60-64 | C22: 60 | D22: 5 | E22: =Insumos!C59 -> 2734019 | F22: =Insumos!D59 -> 36964.356 | G22: =F22/E22 -> 0.013520153 | H22: =D22/2 -> 2.5 | I22: =D22*G22/(1+(D22-H22)*G22) -> 0.065390541 | J22: =1-I22 -> 0.93460946 | K22: =K21-L21 -> 81385.298 | L22: =K22*I22 -> 5321.8287 | M22: =D22*K23+H22*L22 -> 393621.92 | N22: =SUM(M22:$M$25) -> 2019032.8 | O22: =N22/K22 -> 24.808323
... B24: =Insumos!B61 -> 70-74 | C24: 70 | D24: 5 | E24: =Insumos!C61 -> 1561618 | F24: =Insumos!D61 -> 42245.032 | G24: =F24/E24 -> 0.027052091 | H24: =D24/2 -> 2.5 | I24: =D24*G24/(1+(D24-H24)*G24) -> 0.12669223 | J24: =1-I24 -> 0.87330777 | K24: =K23-L23 -> 69385.898 | L24: =K24*I24 -> 8790.6541 | M24: =D24*K25+H24*L24 -> 324952.85 | N24: =SUM(M24:$M$25) -> 1261787.4 | O24: =N24/K24 -> 18.18507
B25: =Insumos!B62 -> 75+ | C25: 75 | D25: abierto | E25: =Insumos!C62 -> 2180337 | F25: =Insumos!D62 -> 141026.02 | G25: =F25/E25 -> 0.064680837 | H25: - | I25: 1 | J25: =1-I25 -> 0 | K25: =K24-L24 -> 60595.244 | L25: =K25*I25 -> 60595.244 | M25: =K25/G25 -> 936834.57 | N25: =SUM(M25:$M$25) -> 936834.57 | O25: =N25/K25 -> 15.46053
B27: Control: suma de ndx menos l0 (debe ser 0) | L27: =ROUND(SUM(L9:L25)-E4,6) -> 0
B28: q0: mortalidad infantil de la tabla (por mil) | L28: =I9*1000 -> 9.9293734

Sheet Mujeres
B1: Tabla de mortalidad transversal abreviada de México, 2025: mujeres
B2: Cohorte ficticia de 100,000 nacimientos expuesta a las tasas de mortalidad por edad observadas en México (INEGI: EIC 2025 y defunciones).
B4: Radix l0 | E4: =Insumos!C4 -> 100000
B5: Fórmulas: nMx = D/P; nqx = n·nMx / (1 + (n − nax)·nMx); lx+n = lx·(1 − nqx); ndx = lx − lx+n; nLx = n·lx+n + nax·ndx; Tx = Σ nLx; ex = Tx/lx. Grupo abierto 75+: q = 1, L = l/M.
B6: nax: 0 y 1-4 de Coale-Demeny (según nM0 y sexo; en ambos sexos, promedio de los dos); resto n/2. Valores sin redondear (se muestran sin decimales).
B8: Edad | C8: x | D8: n | E8: P (población) | F8: D (defunciones) | G8: nMx | H8: nax | I8: nqx | J8: npx | K8: lx | L8: ndx | M8: nLx | N8: Tx | O8: ex
B9: =Insumos!B46 -> 0 | C9: 0 | D9: 1 | E9: =Insumos!E46 -> 676488.74 | F9: =Insumos!F46 -> 5328.3863 | G9: =F9/E9 -> 0.0078765336 | H9: =IF($G$9>=0.107,0.35,0.053+2.8*$G$9) -> 0.075054294 | I9: =D9*G9/(1+(D9-H9)*G9) -> 0.0078195652 | J9: =1-I9 -> 0.99218043 | K9: =$E$4 -> 100000 | L9: =K9*I9 -> 781.95652 | M9: =D9*K10+H9*L9 -> 99276.733 | N9: =SUM(M9:$M$25) -> 8392453.7 | O9: =N9/K9 -> 83.924537
B10: =Insumos!B47 -> 1-4 | C10: 1 | D10: 4 | E10: =Insumos!E47 -> 3064897.3 | F10: =Insumos!F47 -> 1307.8595 | G10: =F10/E10 -> 0.00042672213 | H10: =IF($G$9>=0.107,1.361,1.522-1.518*$G$9) -> 1.5100434 | I10: =D10*G10/(1+(D10-H10)*G10) -> 0.0017050768 | J10: =1-I10 -> 0.99829492 | K10: =K9-L9 -> 99218.043 | L10: =K10*I10 -> 169.17439 | M10: =D10*K11+H10*L10 -> 396450.94 | N10: =SUM(M10:$M$25) -> 8293176.9 | O10: =N10/K10 -> 83.585371
B11: =Insumos!B48 -> 5-9 | C11: 5 | D11: 5 | E11: =Insumos!E48 -> 4785294 | F11: =Insumos!F48 -> 831.88818 | G11: =F11/E11 -> 0.00017384265 | H11: =D11/2 -> 2.5 | I11: =D11*G11/(1+(D11-H11)*G11) -> 0.00086883564 | J11: =1-I11 -> 0.99913116 | K11: =K10-L10 -> 99048.869 | L11: =K11*I11 -> 86.057187 | M11: =D11*K12+H11*L11 -> 495029.2 | N11: =SUM(M11:$M$25) -> 7896726 | O11: =N11/K11 -> 79.725554
B12: =Insumos!B49 -> 10-14 | C12: 10 | D12: 5 | E12: =Insumos!E49 -> 5353603 | F12: =Insumos!F49 -> 1313.4023 | G12: =F12/E12 -> 0.00024533053 | H12: =D12/2 -> 2.5 | I12: =D12*G12/(1+(D12-H12)*G12) -> 0.0012259008 | J12: =1-I12 -> 0.9987741 | K12: =K11-L11 -> 98962.812 | L12: =K12*I12 -> 121.31859 | M12: =D12*K13+H12*L12 -> 494510.76 | N12: =SUM(M12:$M$25) -> 7401696.8 | O12: =N12/K12 -> 74.792709
B13: =Insumos!B50 -> 15-19 | C13: 15 | D13: 5 | E13: =Insumos!E50 -> 5349921 | F13: =Insumos!F50 -> 2266.4198 | G13: =F13/E13 -> 0.00042363612 | H13: =D13/2 -> 2.5 | I13: =D13*G13/(1+(D13-H13)*G13) -> 0.0021159396 | J13: =1-I13 -> 0.99788406 | K13: =K12-L12 -> 98841.493 | L13: =K13*I13 -> 209.14263 | M13: =D13*K14+H13*L13 -> 493684.61 | N13: =SUM(M13:$M$25) -> 6907186 | O13: =N13/K13 -> 69.881442
B14: =Insumos!B51 -> 20-24 | C14: 20 | D14: 5 | E14: =Insumos!E51 -> 5319788 | F14: =Insumos!F51 -> 2787.1892 | G14: =F14/E14 -> 0.00052392863 | H14: =D14/2 -> 2.5 | I14: =D14*G14/(1+(D14-H14)*G14) -> 0.0026162164 | J14: =1-I14 -> 0.99738378 | K14: =K13-L13 -> 98632.351 | L14: =K14*I14 -> 258.04357 | M14: =D14*K15+H14*L14 -> 492516.64 | N14: =SUM(M14:$M$25) -> 6413501.4 | O14: =N14/K14 -> 65.024319
B15: =Insumos!B52 -> 25-29 | C15: 25 | D15: 5 | E15: =Insumos!E52 -> 5104330 | F15: =Insumos!F52 -> 3480.9442 | G15: =F15/E15 -> 0.00068195908 | H15: =D15/2 -> 2.5 | I15: =D15*G15/(1+(D15-H15)*G15) -> 0.0034039919 | J15: =1-I15 -> 0.99659601 | K15: =K14-L14 -> 98374.307 | L15: =K15*I15 -> 334.86535 | M15: =D15*K16+H15*L15 -> 491034.37 | N15: =SUM(M15:$M$25) -> 5920984.8 | O15: =N15/K15 -> 60.188325
B16: =Insumos!B53 -> 30-34 | C16: 30 | D16: 5 | E16: =Insumos!E53 -> 5282566 | F16: =Insumos!F53 -> 4657.2245 | G16: =F16/E16 -> 0.00088162163 | H16: =D16/2 -> 2.5 | I16: =D16*G16/(1+(D16-H16)*G16) -> 0.0043984138 | J16: =1-I16 -> 0.99560159 | K16: =K15-L15 -> 98039.442 | L16: =K16*I16 -> 431.21803 | M16: =D16*K17+H16*L16 -> 489119.16 | N16: =SUM(M16:$M$25) -> 5429950.4 | O16: =N16/K16 -> 55.385367
B17: =Insumos!B54 -> 35-39 | C17: 35 | D17: 5 | E17: =Insumos!E54 -> 5095386 | F17: =Insumos!F54 -> 5790.7418 | G17: =F17/E17 -> 0.0011364677 | H17: =D17/2 -> 2.5 | I17: =D17*G17/(1+(D17-H17)*G17) -> 0.0056662399 | J17: =1-I17 -> 0.99433376 | K17: =K16-L16 -> 97608.224 | L17: =K17*I17 -> 553.07162 | M17: =D17*K18+H17*L17 -> 486658.44 | N17: =SUM(M17:$M$25) -> 4940831.3 | O17: =N17/K17 -> 50.619006
B18: =Insumos!B55 -> 40-44 | C18: 40 | D18: 5 | E18: =Insumos!E55 -> 4742766 | F18: =Insumos!F55 -> 7754.9141 | G18: =F18/E18 -> 0.0016351037 | H18: =D18/2 -> 2.5 | I18: =D18*G18/(1+(D18-H18)*G18) -> 0.0081422349 | J18: =1-I18 -> 0.99185777 | K18: =K17-L17 -> 97055.152 | L18: =K18*I18 -> 790.24584 | M18: =D18*K19+H18*L18 -> 483300.15 | N18: =SUM(M18:$M$25) -> 4454172.8 | O18: =N18/K18 -> 45.893213
B19: =Insumos!B56 -> 45-49 | C19: 45 | D19: 5 | E19: =Insumos!E56 -> 4437822 | F19: =Insumos!F56 -> 11283.397 | G19: =F19/E19 -> 0.0025425529 | H19: =D19/2 -> 2.5 | I19: =D19*G19/(1+(D19-H19)*G19) -> 0.012632468 | J19: =1-I19 -> 0.98736753 | K19: =K18-L18 -> 96264.906 | L19: =K19*I19 -> 1216.0633 | M19: =D19*K20+H19*L19 -> 478284.37 | N19: =SUM(M19:$M$25) -> 3970872.7 | O19: =N19/K19 -> 41.249432
B20: =Insumos!B57 -> 50-54 | C20: 50 | D20: 5 | E20: =Insumos!E57 -> 4409290 | F20: =Insumos!F57 -> 16057.515 | G20: =F20/E20 -> 0.0036417462 | H20: =D20/2 -> 2.5 | I20: =D20*G20/(1+(D20-H20)*G20) -> 0.018044448 | J20: =1-I20 -> 0.98195555 | K20: =K19-L19 -> 95048.843 | L20: =K20*I20 -> 1715.1039 | M20: =D20*K21+H20*L20 -> 470956.46 | N20: =SUM(M20:$M$25) -> 3492588.3 | O20: =N20/K20 -> 36.745195
B21: =Insumos!B58 -> 55-59 | C21: 55 | D21: 5 | E21: =Insumos!E58 -> 3553454 | F21: =Insumos!F58 -> 20407.167 | G21: =F21/E21 -> 0.0057429101 | H21: =D21/2 -> 2.5 | I21: =D21*G21/(1+(D21-H21)*G21) -> 0.028308123 | J21: =1-I21 -> 0.97169188 | K21: =K20-L20 -> 93333.739 | L21: =K21*I21 -> 2642.103 | M21: =D21*K22+H21*L21 -> 460063.44 | N21: =SUM(M21:$M$25) -> 3021631.8 | O21: =N21/K21 -> 32.374486
B22: =Insumos!B59 -> 60-64 | C22: 60 | D22: 5 | E22: =Insumos!E59 -> 3257527 | F22: =Insumos!F59 -> 26735.967 | G22: =F22/E22 -> 0.0082074428 | H22: =D22/2 -> 2.5 | I22: =D22*G22/(1+(D22-H22)*G22) -> 0.040212118 | J22: =1-I22 -> 0.95978788 | K22: =K21-L21 -> 90691.636 | L22: =K22*I22 -> 3646.9027 | M22: =D22*K23+H22*L22 -> 444340.92 | N22: =SUM(M22:$M$25) -> 2561568.4 | O22: =N22/K22 -> 28.244814
... B24: =Insumos!B61 -> 70-74 | C24: 70 | D24: 5 | E24: =Insumos!E61 -> 1838237 | F24: =Insumos!F61 -> 35302.692 | G24: =F24/E24 -> 0.019204646 | H24: =D24/2 -> 2.5 | I24: =D24*G24/(1+(D24-H24)*G24) -> 0.091624206 | J24: =1-I24 -> 0.90837579 | K24: =K23-L23 -> 81982.431 | L24: =K24*I24 -> 7511.5752 | M24: =D24*K25+H24*L24 -> 391133.22 | N24: =SUM(M24:$M$25) -> 1694659.6 | O24: =N24/K24 -> 20.671009
B25: =Insumos!B62 -> 75+ | C25: 75 | D25: abierto | E25: =Insumos!E62 -> 2784501 | F25: =Insumos!F62 -> 159079.39 | G25: =F25/E25 -> 0.057130304 | H25: - | I25: 1 | J25: =1-I25 -> 0 | K25: =K24-L24 -> 74470.856 | L25: =K25*I25 -> 74470.856 | M25: =K25/G25 -> 1303526.3 | N25: =SUM(M25:$M$25) -> 1303526.3 | O25: =N25/K25 -> 17.503845
B27: Control: suma de ndx menos l0 (debe ser 0) | L27: =ROUND(SUM(L9:L25)-E4,6) -> 0
B28: q0: mortalidad infantil de la tabla (por mil) | L28: =I9*1000 -> 7.8195652

Sheet Ambos sexos
B1: Tabla de mortalidad transversal abreviada de México, 2025: ambos sexos
B2: Cohorte ficticia de 100,000 nacimientos expuesta a las tasas de mortalidad por edad observadas en México (INEGI: EIC 2025 y defunciones).
B4: Radix l0 | E4: =Insumos!C4 -> 100000
B5: Fórmulas: nMx = D/P; nqx = n·nMx / (1 + (n − nax)·nMx); lx+n = lx·(1 − nqx); ndx = lx − lx+n; nLx = n·lx+n + nax·ndx; Tx = Σ nLx; ex = Tx/lx. Grupo abierto 75+: q = 1, L = l/M.
B6: nax: 0 y 1-4 de Coale-Demeny (según nM0 y sexo; en ambos sexos, promedio de los dos); resto n/2. Valores sin redondear (se muestran sin decimales).
B8: Edad | C8: x | D8: n | E8: P (población) | F8: D (defunciones) | G8: nMx | H8: nax | I8: nqx | J8: npx | K8: lx | L8: ndx | M8: nLx | N8: Tx | O8: ex
B9: =Insumos!B46 -> 0 | C9: 0 | D9: 1 | E9: =Insumos!G46 -> 1369364.2 | F9: =Insumos!H46 -> 12272.196 | G9: =F9/E9 -> 0.0089619664 | H9: =(IF($G$9>=0.107,0.33,0.045+2.684*$G$9)+IF($G$9>=0.107,0.35,0.053+2.8*$G$9))/2 -> 0.073573712 | I9: =D9*G9/(1+(D9-H9)*G9) -> 0.0088881714 | J9: =1-I9 -> 0.99111183 | K9: =$E$4 -> 100000 | L9: =K9*I9 -> 888.81714 | M9: =D9*K10+H9*L9 -> 99176.576 | N9: =SUM(M9:$M$25) -> 8030941.4 | O9: =N9/K9 -> 80.309414
B10: =Insumos!B47 -> 1-4 | C10: 1 | D10: 4 | E10: =Insumos!G47 -> 6200208.8 | F10: =Insumos!H47 -> 2835.4878 | G10: =F10/E10 -> 0.00045732135 | H10: =(IF($G$9>=0.107,1.352,1.651-2.816*$G$9)+IF($G$9>=0.107,1.361,1.522-1.518*$G$9))/2 -> 1.5670794 | I10: =D10*G10/(1+(D10-H10)*G10) -> 0.0018272523 | J10: =1-I10 -> 0.99817275 | K10: =K9-L9 -> 99111.183 | L10: =K10*I10 -> 181.10114 | M10: =D10*K11+H10*L10 -> 396004.13 | N10: =SUM(M10:$M$25) -> 7931764.8 | O10: =N10/K10 -> 80.028959
B11: =Insumos!B48 -> 5-9 | C11: 5 | D11: 5 | E11: =Insumos!G48 -> 9669960 | F11: =Insumos!H48 -> 1928.2841 | G11: =F11/E11 -> 0.00019940973 | H11: =D11/2 -> 2.5 | I11: =D11*G11/(1+(D11-H11)*G11) -> 0.00099655183 | J11: =1-I11 -> 0.99900345 | K11: =K10-L10 -> 98930.082 | L11: =K11*I11 -> 98.588954 | M11: =D11*K12+H11*L11 -> 494403.94 | N11: =SUM(M11:$M$25) -> 7535760.7 | O11: =N11/K11 -> 76.172592
B12: =Insumos!B49 -> 10-14 | C12: 10 | D12: 5 | E12: =Insumos!G49 -> 10885388 | F12: =Insumos!H49 -> 3062.3908 | G12: =F12/E12 -> 0.00028133042 | H12: =D12/2 -> 2.5 | I12: =D12*G12/(1+(D12-H12)*G12) -> 0.0014056635 | J12: =1-I12 -> 0.99859434 | K12: =K11-L11 -> 98831.493 | L12: =K12*I12 -> 138.92382 | M12: =D12*K13+H12*L12 -> 493810.15 | N12: =SUM(M12:$M$25) -> 7041356.8 | O12: =N12/K12 -> 71.246083
B13: =Insumos!B50 -> 15-19 | C13: 15 | D13: 5 | E13: =Insumos!G50 -> 10833608 | F13: =Insumos!H50 -> 8975.9189 | G13: =F13/E13 -> 0.00082852535 | H13: =D13/2 -> 2.5 | I13: =D13*G13/(1+(D13-H13)*G13) -> 0.0041340638 | J13: =1-I13 -> 0.99586594 | K13: =K12-L12 -> 98692.569 | L13: =K13*I13 -> 408.00138 | M13: =D13*K14+H13*L13 -> 492442.84 | N13: =SUM(M13:$M$25) -> 6547546.6 | O13: =N13/K13 -> 66.342853
B14: =Insumos!B51 -> 20-24 | C14: 20 | D14: 5 | E14: =Insumos!G51 -> 10360929 | F14: =Insumos!H51 -> 13136.669 | G14: =F14/E14 -> 0.0012679045 | H14: =D14/2 -> 2.5 | I14: =D14*G14/(1+(D14-H14)*G14) -> 0.0063194914 | J14: =1-I14 -> 0.99368051 | K14: =K13-L13 -> 98284.568 | L14: =K14*I14 -> 621.10848 | M14: =D14*K15+H14*L14 -> 489870.07 | N14: =SUM(M14:$M$25) -> 6055103.8 | O14: =N14/K14 -> 61.607879
B15: =Insumos!B52 -> 25-29 | C15: 25 | D15: 5 | E15: =Insumos!G52 -> 9810773 | F15: =Insumos!H52 -> 15376.66 | G15: =F15/E15 -> 0.0015673241 | H15: =D15/2 -> 2.5 | I15: =D15*G15/(1+(D15-H15)*G15) -> 0.0078060338 | J15: =1-I15 -> 0.99219397 | K15: =K14-L14 -> 97663.459 | L15: =K15*I15 -> 762.36426 | M15: =D15*K16+H15*L15 -> 486411.38 | N15: =SUM(M15:$M$25) -> 5565233.7 | O15: =N15/K15 -> 56.983787
B16: =Insumos!B53 -> 30-34 | C16: 30 | D16: 5 | E16: =Insumos!G53 -> 10027553 | F16: =Insumos!H53 -> 18579.282 | G16: =F16/E16 -> 0.0018528231 | H16: =D16/2 -> 2.5 | I16: =D16*G16/(1+(D16-H16)*G16) -> 0.0092214014 | J16: =1-I16 -> 0.9907786 | K16: =K15-L15 -> 96901.095 | L16: =K16*I16 -> 893.56389 | M16: =D16*K17+H16*L16 -> 482271.56 | N16: =SUM(M16:$M$25) -> 5078822.3 | O16: =N16/K16 -> 52.412435
B17: =Insumos!B54 -> 35-39 | C17: 35 | D17: 5 | E17: =Insumos!G54 -> 9620908 | F17: =Insumos!H54 -> 20823.006 | G17: =F17/E17 -> 0.0021643494 | H17: =D17/2 -> 2.5 | I17: =D17*G17/(1+(D17-H17)*G17) -> 0.010763507 | J17: =1-I17 -> 0.98923649 | K17: =K16-L16 -> 96007.531 | L17: =K17*I17 -> 1033.3777 | M17: =D17*K18+H17*L17 -> 477454.21 | N17: =SUM(M17:$M$25) -> 4596550.8 | O17: =N17/K17 -> 47.876981
B18: =Insumos!B55 -> 40-44 | C18: 40 | D18: 5 | E18: =Insumos!G55 -> 8974041 | F18: =Insumos!H55 -> 24573.411 | G18: =F18/E18 -> 0.0027382771 | H18: =D18/2 -> 2.5 | I18: =D18*G18/(1+(D18-H18)*G18) -> 0.013598296 | J18: =1-I18 -> 0.9864017 | K18: =K17-L17 -> 94974.153 | L18: =K18*I18 -> 1291.4866 | M18: =D18*K19+H18*L18 -> 471642.05 | N18: =SUM(M18:$M$25) -> 4119096.5 | O18: =N18/K18 -> 43.370711
B19: =Insumos!B56 -> 45-49 | C19: 45 | D19: 5 | E19: =Insumos!G56 -> 8374000 | F19: =Insumos!H56 -> 32371.77 | G19: =F19/E19 -> 0.0038657476 | H19: =D19/2 -> 2.5 | I19: =D19*G19/(1+(D19-H19)*G19) -> 0.019143726 | J19: =1-I19 -> 0.98085627 | K19: =K18-L18 -> 93682.667 | L19: =K19*I19 -> 1793.4353 | M19: =D19*K20+H19*L19 -> 463929.74 | N19: =SUM(M19:$M$25) -> 3647454.5 | O19: =N19/K19 -> 38.934145
B20: =Insumos!B57 -> 50-54 | C20: 50 | D20: 5 | E20: =Insumos!G57 -> 8352139 | F20: =Insumos!H57 -> 43488.22 | G20: =F20/E20 -> 0.0052068362 | H20: =D20/2 -> 2.5 | I20: =D20*G20/(1+(D20-H20)*G20) -> 0.025699647 | J20: =1-I20 -> 0.97430035 | K20: =K19-L19 -> 91889.231 | L20: =K20*I20 -> 2361.5208 | M20: =D20*K21+H20*L20 -> 453542.35 | N20: =SUM(M20:$M$25) -> 3183524.8 | O20: =N20/K20 -> 34.645243
B21: =Insumos!B58 -> 55-59 | C21: 55 | D21: 5 | E21: =Insumos!G58 -> 6709847 | F21: =Insumos!H58 -> 51707.022 | G21: =F21/E21 -> 0.0077061402 | H21: =D21/2 -> 2.5 | I21: =D21*G21/(1+(D21-H21)*G21) -> 0.037802424 | J21: =1-I21 -> 0.96219758 | K21: =K20-L20 -> 89527.711 | L21: =K21*I21 -> 3384.3645 | M21: =D21*K22+H21*L21 -> 439177.64 | N21: =SUM(M21:$M$25) -> 2729982.4 | O21: =N21/K21 -> 30.493155
B22: =Insumos!B59 -> 60-64 | C22: 60 | D22: 5 | E22: =Insumos!G59 -> 5991546 | F22: =Insumos!H59 -> 63700.322 | G22: =F22/E22 -> 0.0106317 | H22: =D22/2 -> 2.5 | I22: =D22*G22/(1+(D22-H22)*G22) -> 0.051782171 | J22: =1-I22 -> 0.94821783 | K22: =K21-L21 -> 86143.346 | L22: =K22*I22 -> 4460.6895 | M22: =D22*K23+H22*L22 -> 419565.01 | N22: =SUM(M22:$M$25) -> 2290804.8 | O22: =N22/K22 -> 26.592939
... B24: =Insumos!B61 -> 70-74 | C24: 70 | D24: 5 | E24: =Insumos!G61 -> 3399855 | F24: =Insumos!H61 -> 77547.723 | G24: =F24/E24 -> 0.022809127 | H24: =D24/2 -> 2.5 | I24: =D24*G24/(1+(D24-H24)*G24) -> 0.10789326 | J24: =1-I24 -> 0.89210674 | K24: =K23-L23 -> 75812.255 | L24: =K24*I24 -> 8179.6311 | M24: =D24*K25+H24*L24 -> 358612.2 | N24: =SUM(M24:$M$25) -> 1477502.5 | O24: =N24/K24 -> 19.488966
B25: =Insumos!B62 -> 75+ | C25: 75 | D25: abierto | E25: =Insumos!G62 -> 4964838 | F25: =Insumos!H62 -> 300105.41 | G25: =F25/E25 -> 0.060446164 | H25: - | I25: 1 | J25: =1-I25 -> 0 | K25: =K24-L24 -> 67632.624 | L25: =K25*I25 -> 67632.624 | M25: =K25/G25 -> 1118890.3 | N25: =SUM(M25:$M$25) -> 1118890.3 | O25: =N25/K25 -> 16.543647
B27: Control: suma de ndx menos l0 (debe ser 0) | L27: =ROUND(SUM(L9:L25)-E4,6) -> 0
B28: q0: mortalidad infantil de la tabla (por mil) | L28: =I9*1000 -> 8.8881714
